Workbook

Sheet README
A1: EgoAnchor Experiment 3 — Frozen v9 Data Collection and Analysis Workbook
A3: 冻结事实 | B3: 设计 | C3: 参与者 | D3: 条件 | E3: 物体 | F3: 问卷时点 | G3: 评分数量 | H3: 禁止事项
A4: 正式版本 | B4: 2×3 完全交叉被试内；物体作为执行区块，方法在物体内比较 | C4: 24 名有效参与者 | D4: EgoAnchor vs One-Euro | E4: 无线鼠标、固定闭合订书机、游戏手柄 | F4: 每个方法–物体条件结束后立即填写 7 项 | G4: 每人 2×3×7 = 42 个七点评分 | H4: 不得称为 CRIQ；不得合并总分；不得报告 Cronbach’s α 或 McDonald’s ω
A7: 采集步骤 | B7: 填写工作表 | C7: 填写时点 | D7: 主要输入列 | E7: 自动/预填内容 | F7: 说明
A8: 1 | B8: Participants | C8: 参与者开始前 | D8: 人口统计、纳入、同意、完成状态 | E8: 物体顺序与方法序列 | F8: 24 人排程已冻结
A9: 2 | B9: ConditionRatings | C9: 每个方法–物体条件的三个任务完成后 | D9: Q1–Q7、完成与有效性、技术异常 | E9: 参与者、物体、方法、区块位置、A/B 标签 | F9: 每人 6 行，共 144 行
A10: 3 | B10: AuditLog | C10: 每个方法–物体条件中或结束后 | D10: 会话、重置、崩溃、重初始化、协议偏离 | E10: 条件排程 | F10: 仅作操纵检查与审计，不作为客观因变量
A11: 4 | B11: FinalFeedback | C11: 全部六个条件完成后 | D11: 最终偏好、两个开放问题、安全检查 | E11: Participant_ID | F11: 不计入 42 个评分
A12: 5 | B12: DataChecks | C12: 每天采集结束后 | D12: 无需手填 | E12: 自动完整性与平衡检查 | F12: 先修复 CHECK 再继续采集
A13: 6 | B13: Descriptives / AnalysisPlan / RCode / ResultsTemplate | C13: 采集完成后 | D13: 统计输出与论文回填 | E13: 预设分析结构 | F13: 七项逐项分析
A16: 颜色图例 | B16: 黄色 | C16: 绿色 | D16: 蓝色 | E16: 白色
A17: 用途 | B17: 实验员手工填写 | C17: 公式或预填字段，不应覆盖 | D17: 说明/冻结设计 | E17: 普通结果或待回填

Sheet Protocol
A1: 实验执行协议（物体外层、方法内层）
A3: 阶段 | B3: 步骤 | C3: 标准化操作 | D3: 冻结时长/幅度 | E3: 数据填写 | F3: 实验控制 | G3: 允许偏差 | H3: 偏差记录
A4: 训练 | B4: 训练物体 | C4: 使用耳机盒熟悉 T1–T3、A/B 条件和 1–7 评分界面；不进入正式统计 | D4: 约 3–5 min | E4: 不填写正式评分 | F4: 不透露方法机制 | G4: 仅允许措辞澄清 | H4: 记录在 Participants 备注
A5: 物体区块 | B5: 启动对象程序 | C5: 启动当前物体对应的 Python 感知服务；加载冻结模型、尺度、局部坐标系和附着变换 | D5: 每个物体一次启动为优先方案 | E5: AuditLog: Python_Session_ID / Ready_Time | F5: 同一物体两种方法尽量共享同一感知会话 | G5: 若必须重启，保持同一配置 | H5: AuditLog
A6: 条件 | B6: 条件 A / 第一方法 | C6: 参与者只看到 A；实验员按排程运行真实方法 | D6: 约 45–60 s | E6: ConditionRatings 第 1 行 | F6: 不提供表现反馈 | G6: 无 | H6: AuditLog
A7: T1 | B7: 静止观察 | C7: 物体静置；按语音提示正面观察、头部左移、右移、略微靠近 | D7: 约 12–15 s | E7: 结束后不单独问卷 | F7: 相同初始位置、相同虚拟内容 | G7: 轻微自然头动差异 | H7: 协议偏离列
A8: T2 | B8: 拿起–移动–放下 | C8: 单手拿起；平移 25–30 cm；自然旋转 30–45°；空中保持约 2 s；放到目标区域；放置后观察约 5 s | D8: 约 20–25 s | E8: 结束后不单独问卷 | F8: 不要求尽快完成；不计时、不计正确率 | G8: 自然动作速度差异 | H8: 协议偏离列
A9: T3 | B9: 遮挡–恢复 | C9: 将物体滑入固定不透明遮挡板后方；保持冻结时长；移回后观察恢复 | D9: 遮挡 0.6–0.9 s；恢复观察 5–7 s | E9: 结束后进入 7 项问卷 | F9: 固定挡板、路径、提示节奏 | G9: 预实验后冻结单一时长 | H9: AuditLog: Occlusion_Duration_s
A10: 问卷 | B10: 条件后 7 项 | C10: 隐藏虚拟内容；头锁 UI 每屏一题；标题：请根据刚才在这个物体上的体验作答 | D10: 约 45–75 s | E10: Q1–Q7 | F10: 不得显示方法真实名称或前次答案 | G10: 参与者可要求重复读题 | H10: Notes
A11: 重置 | B11: 条件间重置 | C11: 物体回到相同初始位姿；清空滤波、StaticLock、候选历史、生命周期与锚点状态；重新初始化 | D11: 约 30–60 s | E11: AuditLog: Anchor_State_Cleared / Object_Reset_OK | F11: 第二方法前必须完成 | G11: 技术失败时重新执行 | H11: Reinit_Count
A12: 条件 | B12: 条件 B / 第二方法 | C12: 重复完全相同的 T1–T3 和 7 项问卷 | D12: 约 45–60 s | E12: ConditionRatings 第 2 行 | F12: 除锚定运行时外全部相同 | G12: 无 | H12: AuditLog
A13: 物体切换 | B13: 关闭当前对象程序 | C13: 完成两种方法后关闭当前物体会话，再按排程进入下一物体 | D13: 建议短休息 1–2 min | E13: 无需新增评分 | F13: 不讨论两个条件表现 | G13: 参与者可要求额外休息 | H13: Notes
A14: 结束 | B14: 最终反馈 | C14: 完成三个物体共六个条件后，填写总体偏好、开放问题和不适检查 | D14: 约 3–5 min | E14: FinalFeedback | F14: A/B 解盲后记录真实偏好 | G14: 无 | H14: FinalFeedback

Sheet Questionnaire
A1: 七项条件–物体问卷及最终反馈：中英文、构念、出处与分析规则
A3: 层级 | B3: Item_ID | C3: 构念（中文） | D3: Construct (EN) | E3: 对应阶段 | F3: 中文题目 | G3: English item | H3: 量尺 | I3: 方向 | J3: 来源类型 | K3: 来源/改编说明 | L3: Source URL 1 | M3: Source URL 2 | N3: 分析单位 | O3: 禁止处理 | P3: 论文解释边界
A4: 条件–物体 | B4: Q1_STATIC_STABILITY | C4: 静止稳定性 | D4: Perceived static stability | E4: T1 静止观察 | F4: 在静止观察阶段，虚拟内容在真实物体上的位置保持稳定。 | G4: During static observation, the virtual content remained stable relative to the physical object. | H4: 七点同意度 | I4: 高分更好 | J4: 本研究自编 | K4: 依据 EgoAnchor 的世界一致性、StaticLock 与静止抖动评价构念设计。 | N4: 逐项；Method×Object | O4: 不得与其他题目合并；不得报 alpha | P4: 仅表示主观稳定感，不等于毫米级抖动或绝对配准精度。
A5: 条件–物体 | B5: Q2_MOTION_ATTACHMENT | C5: 运动附着感 | D5: Perceived motion attachment | E5: T2 拿起–移动–放下 | F5: 在拿起、移动和旋转物体时，虚拟内容与真实物体保持一致运动。 | G5: While I picked up, moved, and rotated the object, the virtual content moved consistently with the physical object. | H5: 七点同意度 | I5: 高分更好 | J5: 本研究自编 | K5: 依据运动连续性、响应滞后与虚拟内容相对物体滑动的感知后果设计。 | N5: 逐项；Method×Object | O5: 不得与其他题目合并；不得报 alpha | P5: 不等同于客观轨迹误差或任务完成速度。
A6: 条件–物体 | B6: Q3_RECOVERY_CONSISTENCY | C6: 遮挡恢复一致性 | D6: Perceived recovery consistency | E6: T3 遮挡–恢复 | F6: 遮挡移除后，虚拟内容恢复到了与真实物体一致的位置。 | G6: After the occlusion was removed, the virtual content recovered to a position consistent with the physical object. | H6: 七点同意度 | I6: 高分更好 | J6: 本研究自编 | K6: 依据候选接纳、冻结保护、生命周期与重新获取的用户可感知结果设计。 | N6: 逐项；Method×Object | O6: 不得与其他题目合并；不得报 alpha | P6: 评价恢复结果的主观一致性，不测量恢复时间。
A7: 条件–物体 | B7: Q4_PLAUSIBILITY | C7: 合理可信度 | D7: Perceived plausibility | E7: 综合 T1–T3 | F7: 这种虚实交互体验在多大程度上让你觉得合理可信？ | G7: To what extent did this physical–virtual interaction experience feel plausible and credible to you? | H7: 七点强度 | I7: 高分更好 | J7: 改编自既有跨现实交互提问的单项 | K7: 措辞参考 SelfBlending 报告的 plausibility 提问，并追溯至 Gottsacker 等人的跨现实中断研究；仅作为改编单项，不称量表或子量表。 | L7: https://doi.org/10.1109/TVCG.2026.3690947 | M7: https://doi.org/10.1109/ISMAR52148.2021.00047 | N7: 逐项；Method×Object | O7: 不得称 CRIQ；不得与 Q5 或其他题目合并；不得报 alpha | P7: 仅说明该条件–物体体验是否显得合理可信。
A8: 条件–物体 | B8: Q5_SYNCHRONY | C8: 虚实同步性 | D8: Perceived synchrony | E8: 综合 T1–T3 | F8: 你在多大程度上感觉真实物体与虚拟内容之间的交互是同步的？ | G8: To what extent did the interaction between the physical object and virtual content feel synchronized? | H8: 七点强度 | I8: 高分更好 | J8: 改编自既有跨现实交互提问的单项 | K8: 将原文中的物理/虚拟环境具体化为真实物体/附着虚拟内容；仅作为改编单项。 | L8: https://doi.org/10.1109/TVCG.2026.3690947 | M8: https://doi.org/10.1109/ISMAR52148.2021.00047 | N8: 逐项；Method×Object | O8: 不得称 CRIQ；不得与 Q4 或其他题目合并；不得报 alpha | P8: 同步性是整体主观判断，不等同于测得的系统时延。
A9: 条件–物体 | B9: Q6_RELIANCE | C9: 依赖意愿 | D9: Willingness to rely | E9: 综合 T1–T3 | F9: 在需要虚拟内容准确附着于真实物体的混合现实应用中，我愿意依赖这种锚定方法。 | G9: I would be willing to rely on this anchoring method in an MR application that requires virtual content to be accurately attached to a physical object. | H9: 七点同意度 | I9: 高分更好 | J9: 本研究自编 | K9: 面向对象锚定应用的应用层依赖意愿；是最直接的应用侧条目。 | N9: 逐项；Method×Object | O9: 不得命名为已验证信任量表；不得与其他题目合并；不得报 alpha | P9: 只能支持主观依赖意愿，不支持实际使用行为或任务绩效。
A10: 条件–物体 | B10: Q7_STABILITY_RESPONSE_BALANCE | C10: 稳定性–响应性平衡 | D10: Perceived stability–responsiveness balance | E10: 综合 T1–T3 | F10: 总体而言，该方法在锚点稳定性与响应及时性之间取得了合适的平衡。 | G10: Overall, this method achieved an appropriate balance between anchor stability and responsiveness. | H10: 七点同意度 | I10: 高分更好 | J10: 本研究自编 | K10: 直接对应论文中静止稳定、运动响应、起停转换与恢复之间的系统权衡。 | N10: 逐项；Method×Object | O10: 不得加入任何总分；不得报 alpha | P10: 高分表示参与者接受整体工作点，不表示稳定性和响应性均单独最优。
A11: 最终 | B11: F1_FINAL_CHOICE | C11: 最终方法选择 | D11: Final method choice | E11: 全部六个条件后 | F11: 如果需要在实际混合现实应用中使用一个对象锚定方法，你会选择哪一种？ | G11: If you had to use one object-anchoring method in an actual mixed-reality application, which method would you choose? | H11: EgoAnchor / One-Euro / 无明显偏好 | I11: 分类 | J11: 本研究自编 | K11: 总体偏好；不计入 42 个七点评分。 | N11: 人数与比例 | O11: 不得计算平均值 | P11: 偏好不能替代各条目的条件效应。
A12: 最终 | B12: F2_OPEN_DIFFERENCE | C12: 最明显差异 | D12: Most noticeable difference | E12: 全部六个条件后 | F12: 你认为两种锚定方法之间最明显的区别是什么？ | G12: What was the most noticeable difference between the two anchoring methods? | H12: 开放文本 | I12: 不适用 | J12: 本研究自编 | K12: 用于解释定量差异。 | N12: 轻量主题分析 | O12: 不得量化成未经预设的总分 | P12: 主题编码作为解释性证据。
A13: 最终 | B13: F3_OPEN_DISTRUST | C13: 信任破坏因素 | D13: Anchor distrust factor | E13: 全部六个条件后 | F13: 在使用附着于真实物体的虚拟内容时，什么现象最容易使你不再信任这个锚点？ | G13: When using virtual content attached to a physical object, what behavior would most easily make you distrust the anchor? | H13: 开放文本 | I13: 不适用 | J13: 本研究自编 | K13: 重点关注抖动、漂移、运动滑动、滞后、恢复跳变与不可预测性。 | N13: 轻量主题分析 | O13: 不得将事后主题当作预注册量化结局 | P13: 用于形成设计启示和失败模式分类。
A14: 安全 | B14: S1_DISCOMFORT | C14: 结束时不适 | D14: End-of-study discomfort | E14: 实验结束 | F14: 与实验开始前相比，你目前是否感到任何额外的不适？ | G14: Compared with before the experiment, are you currently experiencing any additional discomfort? | H14: 无 / 轻微 / 中等 / 明显或中止 | I14: 分类 | J14: 安全审计自编项 | K14: 安全监测，不作为两方法主要结局。 | N14: 描述性记录 | O14: 不得解释为 SSQ | P14: 仅用于安全与退出审计。

Sheet ScaleAnchors
A1: 评分锚点与界面呈现规则
A3: 量尺 | B3: 分值 | C3: 中文锚点 | D3: English anchor | E3: 适用条目
A4: 七点同意度 | B4: 1 | C4: 完全不同意 | D4: Strongly disagree | E4: Q1, Q2, Q3, Q6, Q7
A5: 七点同意度 | B5: 2 | C5: 不同意 | D5: Disagree | E5: Q1, Q2, Q3, Q6, Q7
A6: 七点同意度 | B6: 3 | C6: 比较不同意 | D6: Somewhat disagree | E6: Q1, Q2, Q3, Q6, Q7
A7: 七点同意度 | B7: 4 | C7: 既不同意也不赞同 | D7: Neither agree nor disagree | E7: Q1, Q2, Q3, Q6, Q7
A8: 七点同意度 | B8: 5 | C8: 比较同意 | D8: Somewhat agree | E8: Q1, Q2, Q3, Q6, Q7
A9: 七点同意度 | B9: 6 | C9: 同意 | D9: Agree | E9: Q1, Q2, Q3, Q6, Q7
A10: 七点同意度 | B10: 7 | C10: 完全同意 | D10: Strongly agree | E10: Q1, Q2, Q3, Q6, Q7
A11: 七点强度 | B11: 1 | C11: 完全没有 | D11: Not at all | E11: Q4, Q5
A12: 七点强度 | B12: 2 | C12: 非常少 | D12: Very little | E12: Q4, Q5
A13: 七点强度 | B13: 3 | C13: 比较少 | D13: Slightly | E13: Q4, Q5
A14: 七点强度 | B14: 4 | C14: 中等程度 | D14: Moderately | E14: Q4, Q5
A15: 七点强度 | B15: 5 | C15: 比较强 | D15: Quite strongly | E15: Q4, Q5
... A17: 七点强度 | B17: 7 | C17: 非常强烈 | D17: Extremely | E17: Q4, Q5
A20: 界面规则 | B20: 要求 | C20: 原因 | D20: 冻结状态 | E20: 检查
A21: 每屏一题 | B21: 必须 | C21: 减少遗漏和跨题比较 | D21: 冻结 | E21: pilot 检查
A22: 头锁 UI | B22: 必须 | C22: 避免问卷自身附着于被评价物体 | D22: 冻结 | E22: pilot 检查
A23: 条件匿名 A/B | B23: 必须 | C23: 降低需求特征 | D23: 冻结 | E23: 实验员核对排程
A24: 不显示前次答案 | B24: 必须 | C24: 避免锚定效应 | D24: 冻结 | E24: 软件检查
A25: Q4–Q5 单独显示强度锚点 | B25: 必须 | C25: 避免和同意度混淆 | D25: 冻结 | E25: 软件检查
A26: 正式采集后不得改题 | B26: 必须 | C26: 保持测量一致 | D26: 冻结 | E26: 版本控制

Sheet BalanceSchedule
A1: 24 人平衡排程：六种物体顺序 × 两种互补方法序列
A3: Participant_ID | B3: Object_Order_ID | C3: Method_Sequence | D3: Block1_Object | E3: B1_Period1 | F3: B1_Period2 | G3: Block2_Object | H3: B2_Period1 | I3: B2_Period2 | J3: Block3_Object | K3: B3_Period1 | L3: B3_Period2 | M3: Ego_First_Count | N3: OneEuro_First_Count | O3: Planned_Ratings | P3: Balance_Cell | Q3: Notes
A4: P001 | B4: 1 | C4: S1 | D4: 无线鼠标 | E4: EgoAnchor | F4: One-Euro | G4: 固定闭合订书机 | H4: One-Euro | I4: EgoAnchor | J4: 游戏手柄 | K4: EgoAnchor | L4: One-Euro | M4: 2 | N4: 1 | O4: 42 | P4: O1-S1
A5: P002 | B5: 1 | C5: S1 | D5: 无线鼠标 | E5: EgoAnchor | F5: One-Euro | G5: 固定闭合订书机 | H5: One-Euro | I5: EgoAnchor | J5: 游戏手柄 | K5: EgoAnchor | L5: One-Euro | M5: 2 | N5: 1 | O5: 42 | P5: O1-S1
A6: P003 | B6: 1 | C6: S2 | D6: 无线鼠标 | E6: One-Euro | F6: EgoAnchor | G6: 固定闭合订书机 | H6: EgoAnchor | I6: One-Euro | J6: 游戏手柄 | K6: One-Euro | L6: EgoAnchor | M6: 1 | N6: 2 | O6: 42 | P6: O1-S2
A7: P004 | B7: 1 | C7: S2 | D7: 无线鼠标 | E7: One-Euro | F7: EgoAnchor | G7: 固定闭合订书机 | H7: EgoAnchor | I7: One-Euro | J7: 游戏手柄 | K7: One-Euro | L7: EgoAnchor | M7: 1 | N7: 2 | O7: 42 | P7: O1-S2
A8: P005 | B8: 2 | C8: S1 | D8: 无线鼠标 | E8: EgoAnchor | F8: One-Euro | G8: 游戏手柄 | H8: One-Euro | I8: EgoAnchor | J8: 固定闭合订书机 | K8: EgoAnchor | L8: One-Euro | M8: 2 | N8: 1 | O8: 42 | P8: O2-S1
A9: P006 | B9: 2 | C9: S1 | D9: 无线鼠标 | E9: EgoAnchor | F9: One-Euro | G9: 游戏手柄 | H9: One-Euro | I9: EgoAnchor | J9: 固定闭合订书机 | K9: EgoAnchor | L9: One-Euro | M9: 2 | N9: 1 | O9: 42 | P9: O2-S1
A10: P007 | B10: 2 | C10: S2 | D10: 无线鼠标 | E10: One-Euro | F10: EgoAnchor | G10: 游戏手柄 | H10: EgoAnchor | I10: One-Euro | J10: 固定闭合订书机 | K10: One-Euro | L10: EgoAnchor | M10: 1 | N10: 2 | O10: 42 | P10: O2-S2
A11: P008 | B11: 2 | C11: S2 | D11: 无线鼠标 | E11: One-Euro | F11: EgoAnchor | G11: 游戏手柄 | H11: EgoAnchor | I11: One-Euro | J11: 固定闭合订书机 | K11: One-Euro | L11: EgoAnchor | M11: 1 | N11: 2 | O11: 42 | P11: O2-S2
A12: P009 | B12: 3 | C12: S1 | D12: 固定闭合订书机 | E12: EgoAnchor | F12: One-Euro | G12: 无线鼠标 | H12: One-Euro | I12: EgoAnchor | J12: 游戏手柄 | K12: EgoAnchor | L12: One-Euro | M12: 2 | N12: 1 | O12: 42 | P12: O3-S1
A13: P010 | B13: 3 | C13: S1 | D13: 固定闭合订书机 | E13: EgoAnchor | F13: One-Euro | G13: 无线鼠标 | H13: One-Euro | I13: EgoAnchor | J13: 游戏手柄 | K13: EgoAnchor | L13: One-Euro | M13: 2 | N13: 1 | O13: 42 | P13: O3-S1
A14: P011 | B14: 3 | C14: S2 | D14: 固定闭合订书机 | E14: One-Euro | F14: EgoAnchor | G14: 无线鼠标 | H14: EgoAnchor | I14: One-Euro | J14: 游戏手柄 | K14: One-Euro | L14: EgoAnchor | M14: 1 | N14: 2 | O14: 42 | P14: O3-S2
A15: P012 | B15: 3 | C15: S2 | D15: 固定闭合订书机 | E15: One-Euro | F15: EgoAnchor | G15: 无线鼠标 | H15: EgoAnchor | I15: One-Euro | J15: 游戏手柄 | K15: One-Euro | L15: EgoAnchor | M15: 1 | N15: 2 | O15: 42 | P15: O3-S2
... A27: P024 | B27: 6 | C27: S2 | D27: 游戏手柄 | E27: One-Euro | F27: EgoAnchor | G27: 固定闭合订书机 | H27: EgoAnchor | I27: One-Euro | J27: 无线鼠标 | K27: One-Euro | L27: EgoAnchor | M27: 1 | N27: 2 | O27: 42 | P27: O6-S2

Sheet Participants
A1: 参与者信息与纳入记录
A3: Participant_ID | B3: Include | C3: Age | D3: Gender | E3: Handedness | F3: Vision | G3: VRMR_Experience | H3: Object_Order_ID | I3: Method_Sequence | J3: Object1 | K3: Object2 | L3: Object3 | M3: Consent | N3: Completed | O3: Withdrawal_Reason | P3: Notes
A4: P001 | B4: Yes | H4: 1 | I4: S1 | J4: 无线鼠标 | K4: 固定闭合订书机 | L4: 游戏手柄 | M4: Pending | N4: No
A5: P002 | B5: Yes | H5: 1 | I5: S1 | J5: 无线鼠标 | K5: 固定闭合订书机 | L5: 游戏手柄 | M5: Pending | N5: No
A6: P003 | B6: Yes | H6: 1 | I6: S2 | J6: 无线鼠标 | K6: 固定闭合订书机 | L6: 游戏手柄 | M6: Pending | N6: No
A7: P004 | B7: Yes | H7: 1 | I7: S2 | J7: 无线鼠标 | K7: 固定闭合订书机 | L7: 游戏手柄 | M7: Pending | N7: No
A8: P005 | B8: Yes | H8: 2 | I8: S1 | J8: 无线鼠标 | K8: 游戏手柄 | L8: 固定闭合订书机 | M8: Pending | N8: No
A9: P006 | B9: Yes | H9: 2 | I9: S1 | J9: 无线鼠标 | K9: 游戏手柄 | L9: 固定闭合订书机 | M9: Pending | N9: No
A10: P007 | B10: Yes | H10: 2 | I10: S2 | J10: 无线鼠标 | K10: 游戏手柄 | L10: 固定闭合订书机 | M10: Pending | N10: No
A11: P008 | B11: Yes | H11: 2 | I11: S2 | J11: 无线鼠标 | K11: 游戏手柄 | L11: 固定闭合订书机 | M11: Pending | N11: No
A12: P009 | B12: Yes | H12: 3 | I12: S1 | J12: 固定闭合订书机 | K12: 无线鼠标 | L12: 游戏手柄 | M12: Pending | N12: No
A13: P010 | B13: Yes | H13: 3 | I13: S1 | J13: 固定闭合订书机 | K13: 无线鼠标 | L13: 游戏手柄 | M13: Pending | N13: No
A14: P011 | B14: Yes | H14: 3 | I14: S2 | J14: 固定闭合订书机 | K14: 无线鼠标 | L14: 游戏手柄 | M14: Pending | N14: No
A15: P012 | B15: Yes | H15: 3 | I15: S2 | J15: 固定闭合订书机 | K15: 无线鼠标 | L15: 游戏手柄 | M15: Pending | N15: No
... A27: P024 | B27: Yes | H27: 6 | I27: S2 | J27: 游戏手柄 | K27: 固定闭合订书机 | L27: 无线鼠标 | M27: Pending | N27: No

Sheet ConditionRatings
A1: 正式评分录入：每位参与者 6 行，每行一个方法–物体条件，填写 Q1–Q7
A2: 黄色列由实验员填写；绿色列为冻结排程。评分必须为 1–7。每个条件完成 T1–T3 后一次性填写七项。
A3: Participant_ID | B3: Object_Order_ID | C3: Object_Block_Position | D3: Object | E3: Method_Sequence | F3: WithinObject_Period | G3: Display_Label | H3: Method | I3: Python_Session_ID | J3: Condition_Start | K3: Condition_End | L3: T1_Completed | M3: T2_Completed | N3: T3_Completed | O3: Runtime_Reset_Confirmed | P3: Questionnaire_Completed | Q3: Condition_Valid | R3: Technical_Issue | S3: Q1_Static_Stability | T3: Q2_Motion_Attachment | U3: Q3_Recovery_Consistency | V3: Q4_Plausibility | W3: Q5_Synchrony | X3: Q6_Reliance | Y3: Q7_Stability_Response_Balance | Z3: Notes
A4: P001 | B4: 1 | C4: 1 | D4: 无线鼠标 | E4: S1 | F4: 1 | G4: A | H4: EgoAnchor | I4: P001_Mouse_S1 | L4: No | M4: No | N4: No | O4: N/A | P4: No | Q4: Pending | R4: None
A5: P001 | B5: 1 | C5: 1 | D5: 无线鼠标 | E5: S1 | F5: 2 | G5: B | H5: One-Euro | I5: P001_Mouse_S1 | L5: No | M5: No | N5: No | O5: Pending | P5: No | Q5: Pending | R5: None
A6: P001 | B6: 1 | C6: 2 | D6: 固定闭合订书机 | E6: S1 | F6: 1 | G6: A | H6: One-Euro | I6: P001_Stapler_S1 | L6: No | M6: No | N6: No | O6: N/A | P6: No | Q6: Pending | R6: None
A7: P001 | B7: 1 | C7: 2 | D7: 固定闭合订书机 | E7: S1 | F7: 2 | G7: B | H7: EgoAnchor | I7: P001_Stapler_S1 | L7: No | M7: No | N7: No | O7: Pending | P7: No | Q7: Pending | R7: None
A8: P001 | B8: 1 | C8: 3 | D8: 游戏手柄 | E8: S1 | F8: 1 | G8: A | H8: EgoAnchor | I8: P001_Gamepad_S1 | L8: No | M8: No | N8: No | O8: N/A | P8: No | Q8: Pending | R8: None
A9: P001 | B9: 1 | C9: 3 | D9: 游戏手柄 | E9: S1 | F9: 2 | G9: B | H9: One-Euro | I9: P001_Gamepad_S1 | L9: No | M9: No | N9: No | O9: Pending | P9: No | Q9: Pending | R9: None
A10: P002 | B10: 1 | C10: 1 | D10: 无线鼠标 | E10: S1 | F10: 1 | G10: A | H10: EgoAnchor | I10: P002_Mouse_S1 | L10: No | M10: No | N10: No | O10: N/A | P10: No | Q10: Pending | R10: None
A11: P002 | B11: 1 | C11: 1 | D11: 无线鼠标 | E11: S1 | F11: 2 | G11: B | H11: One-Euro | I11: P002_Mouse_S1 | L11: No | M11: No | N11: No | O11: Pending | P11: No | Q11: Pending | R11: None
A12: P002 | B12: 1 | C12: 2 | D12: 固定闭合订书机 | E12: S1 | F12: 1 | G12: A | H12: One-Euro | I12: P002_Stapler_S1 | L12: No | M12: No | N12: No | O12: N/A | P12: No | Q12: Pending | R12: None
A13: P002 | B13: 1 | C13: 2 | D13: 固定闭合订书机 | E13: S1 | F13: 2 | G13: B | H13: EgoAnchor | I13: P002_Stapler_S1 | L13: No | M13: No | N13: No | O13: Pending | P13: No | Q13: Pending | R13: None
A14: P002 | B14: 1 | C14: 3 | D14: 游戏手柄 | E14: S1 | F14: 1 | G14: A | H14: EgoAnchor | I14: P002_Gamepad_S1 | L14: No | M14: No | N14: No | O14: N/A | P14: No | Q14: Pending | R14: None
A15: P002 | B15: 1 | C15: 3 | D15: 游戏手柄 | E15: S1 | F15: 2 | G15: B | H15: One-Euro | I15: P002_Gamepad_S1 | L15: No | M15: No | N15: No | O15: Pending | P15: No | Q15: Pending | R15: None
... A147: P024 | B147: 6 | C147: 3 | D147: 无线鼠标 | E147: S2 | F147: 2 | G147: B | H147: EgoAnchor | I147: P024_Mouse_S1 | L147: No | M147: No | N147: No | O147: Pending | P147: No | Q147: Pending | R147: None

Sheet FinalFeedback
A1: 最终偏好、开放反馈与安全检查
A3: Participant_ID | B3: Final_Choice | C3: Most_Noticeable_Difference | D3: Primary_Distrust_Factor | E3: End_Discomfort | F3: Participant_Included | G3: Completed | H3: Notes
A4: P001 | F4: Yes | G4: No
A5: P002 | F5: Yes | G5: No
A6: P003 | F6: Yes | G6: No
A7: P004 | F7: Yes | G7: No
A8: P005 | F8: Yes | G8: No
A9: P006 | F9: Yes | G9: No
A10: P007 | F10: Yes | G10: No
A11: P008 | F11: Yes | G11: No
A12: P009 | F12: Yes | G12: No
A13: P010 | F13: Yes | G13: No
A14: P011 | F14: Yes | G14: No
A15: P012 | F15: Yes | G15: No
... A27: P024 | F27: Yes | G27: No

Sheet AuditLog
A1: 操纵检查与运行时审计（不作为客观绩效因变量）
A3: Participant_ID | B3: Object_Block_Position | C3: Object | D3: WithinObject_Period | E3: Method | F3: Python_Session_ID | G3: Launch_Time | H3: Ready_Time | I3: Calibration_OK | J3: Object_Reset_OK | K3: Anchor_State_Cleared | L3: Runtime_Crash | M3: Reinitialization_Count | N3: Tracking_Long_Failure | O3: Protocol_Deviation | P3: Occlusion_Duration_s | Q3: Questionnaire_UI_OK | R3: Condition_Valid | S3: Issue_Category | T3: Notes
A4: P001 | B4: 1 | C4: 无线鼠标 | D4: 1 | E4: EgoAnchor | F4: P001_Mouse_S1 | I4: Pending | J4: Pending | K4: N/A | L4: No | M4: 0 | N4: No | O4: None | Q4: Pending | R4: Pending | S4: None
A5: P001 | B5: 1 | C5: 无线鼠标 | D5: 2 | E5: One-Euro | F5: P001_Mouse_S1 | I5: Pending | J5: Pending | K5: Pending | L5: No | M5: 0 | N5: No | O5: None | Q5: Pending | R5: Pending | S5: None
A6: P001 | B6: 2 | C6: 固定闭合订书机 | D6: 1 | E6: One-Euro | F6: P001_Stapler_S1 | I6: Pending | J6: Pending | K6: N/A | L6: No | M6: 0 | N6: No | O6: None | Q6: Pending | R6: Pending | S6: None
A7: P001 | B7: 2 | C7: 固定闭合订书机 | D7: 2 | E7: EgoAnchor | F7: P001_Stapler_S1 | I7: Pending | J7: Pending | K7: Pending | L7: No | M7: 0 | N7: No | O7: None | Q7: Pending | R7: Pending | S7: None
A8: P001 | B8: 3 | C8: 游戏手柄 | D8: 1 | E8: EgoAnchor | F8: P001_Gamepad_S1 | I8: Pending | J8: Pending | K8: N/A | L8: No | M8: 0 | N8: No | O8: None | Q8: Pending | R8: Pending | S8: None
A9: P001 | B9: 3 | C9: 游戏手柄 | D9: 2 | E9: One-Euro | F9: P001_Gamepad_S1 | I9: Pending | J9: Pending | K9: Pending | L9: No | M9: 0 | N9: No | O9: None | Q9: Pending | R9: Pending | S9: None
A10: P002 | B10: 1 | C10: 无线鼠标 | D10: 1 | E10: EgoAnchor | F10: P002_Mouse_S1 | I10: Pending | J10: Pending | K10: N/A | L10: No | M10: 0 | N10: No | O10: None | Q10: Pending | R10: Pending | S10: None
A11: P002 | B11: 1 | C11: 无线鼠标 | D11: 2 | E11: One-Euro | F11: P002_Mouse_S1 | I11: Pending | J11: Pending | K11: Pending | L11: No | M11: 0 | N11: No | O11: None | Q11: Pending | R11: Pending | S11: None
A12: P002 | B12: 2 | C12: 固定闭合订书机 | D12: 1 | E12: One-Euro | F12: P002_Stapler_S1 | I12: Pending | J12: Pending | K12: N/A | L12: No | M12: 0 | N12: No | O12: None | Q12: Pending | R12: Pending | S12: None
A13: P002 | B13: 2 | C13: 固定闭合订书机 | D13: 2 | E13: EgoAnchor | F13: P002_Stapler_S1 | I13: Pending | J13: Pending | K13: Pending | L13: No | M13: 0 | N13: No | O13: None | Q13: Pending | R13: Pending | S13: None
A14: P002 | B14: 3 | C14: 游戏手柄 | D14: 1 | E14: EgoAnchor | F14: P002_Gamepad_S1 | I14: Pending | J14: Pending | K14: N/A | L14: No | M14: 0 | N14: No | O14: None | Q14: Pending | R14: Pending | S14: None
A15: P002 | B15: 3 | C15: 游戏手柄 | D15: 2 | E15: One-Euro | F15: P002_Gamepad_S1 | I15: Pending | J15: Pending | K15: Pending | L15: No | M15: 0 | N15: No | O15: None | Q15: Pending | R15: Pending | S15: None
... A147: P024 | B147: 3 | C147: 无线鼠标 | D147: 2 | E147: EgoAnchor | F147: P024_Mouse_S1 | I147: Pending | J147: Pending | K147: Pending | L147: No | M147: 0 | N147: No | O147: None | Q147: Pending | R147: Pending | S147: None

Sheet DataChecks
A1: 自动质量检查：完整性、评分范围与平衡
A3: 全局检查 | B3: 值 | C3: 判定 | E3: 平衡检查 | F3: 目标 | G3: 实际 | H3: 判定
A4: 计划参与者 | B4: 24 | C4: 冻结 | E4: Object order 1 | F4: 4 | G4: =COUNTIF(Participants!H4:H27,1) -> 4 | H4: =IF(G4=F4,"OK","CHECK") -> OK
A5: 参与者行数 | B5: =COUNTA(Participants!A4:A27) -> 24 | C5: =IF(B5=24,"OK","CHECK") -> OK | E5: Object order 2 | F5: 4 | G5: =COUNTIF(Participants!H4:H27,2) -> 4 | H5: =IF(G5=F5,"OK","CHECK") -> OK
A6: 纳入参与者 | B6: =COUNTIF(Participants!B4:B27,"Yes") -> 24 | C6: 采集后确认 | E6: Object order 3 | F6: 4 | G6: =COUNTIF(Participants!H4:H27,3) -> 4 | H6: =IF(G6=F6,"OK","CHECK") -> OK
A7: 计划条件行数 | B7: 144 | C7: 冻结 | E7: Object order 4 | F7: 4 | G7: =COUNTIF(Participants!H4:H27,4) -> 4 | H7: =IF(G7=F7,"OK","CHECK") -> OK
A8: 条件行数 | B8: =COUNTA(ConditionRatings!A4:A147) -> 144 | C8: =IF(B8=144,"OK","CHECK") -> OK | E8: Object order 5 | F8: 4 | G8: =COUNTIF(Participants!H4:H27,5) -> 4 | H8: =IF(G8=F8,"OK","CHECK") -> OK
A9: 有效条件行数 | B9: =COUNTIF(ConditionRatings!Q4:Q147,"Yes") -> 0 | C9: 完成并审核后应为 144 | E9: Object order 6 | F9: 4 | G9: =COUNTIF(Participants!H4:H27,6) -> 4 | H9: =IF(G9=F9,"OK","CHECK") -> OK
A10: 计划七点评分 | B10: 1008 | C10: 24×6×7 | E10: Method sequence S1 | F10: 12 | G10: =COUNTIF(Participants!I4:I27,"S1") -> 12 | H10: =IF(G10=F10,"OK","CHECK") -> OK
A11: 已完成问卷条件 | B11: =COUNTIF(ConditionRatings!P4:P147,"Yes") -> 0 | C11: 目标 144 | E11: Method sequence S2 | F11: 12 | G11: =COUNTIF(Participants!I4:I27,"S2") -> 12 | H11: =IF(G11=F11,"OK","CHECK") -> OK
A12: 已填写评分总数 | B12: =COUNT(ConditionRatings!S4:S147)+COUNT(ConditionRatings!T4:T147)+COUNT(ConditionRatings!U4:U147)+COUNT(ConditionRatings!V4:V147)+COUNT(ConditionRatings!W4:W147)+COUNT(ConditionRatings!X4:X147)+COUNT(ConditionRatings!Y4:Y147) -> 0 | C12: =IF(B12=0,"NOT STARTED",IF(B12=B10,"COMPLETE","IN PROGRESS")) -> NOT STARTED | E12: 无线鼠标: first = EgoAnchor | F12: 12 | G12: =COUNTIFS(ConditionRatings!D4:D147,"无线鼠标",ConditionRatings!F4:F147,1,ConditionRatings!H4:H147,"EgoAnchor") -> 12 | H12: =IF(G12=F12,"OK","CHECK") -> OK
A13: 剩余计划评分 | B13: =B10-B12 -> 1008 | C13: =IF(B13=0,"OK","IN PROGRESS") -> IN PROGRESS | E13: 无线鼠标: first = One-Euro | F13: 12 | G13: =COUNTIFS(ConditionRatings!D4:D147,"无线鼠标",ConditionRatings!F4:F147,1,ConditionRatings!H4:H147,"One-Euro") -> 12 | H13: =IF(G13=F13,"OK","CHECK") -> OK
A14: 已完成且有效条件内的缺失评分 | B14: =COUNTIFS(ConditionRatings!P4:P147,"Yes",ConditionRatings!Q4:Q147,"Yes")*7-(COUNTIFS(ConditionRatings!P4:P147,"Yes",ConditionRatings!Q4:Q147,"Yes",ConditionRatings!S4:S147,">=1")+COUNTIFS(ConditionRatings!P4:P147,"Yes",ConditionRatings!Q4:Q147,"Yes",ConditionRatings!T4:T147,">=1")+COUNTIFS(ConditionRatings!P4:P147,"Yes",ConditionRatings!Q4:Q147,"Yes",ConditionRatings!U4:U147,">=1")+COUNTIFS(ConditionRatings!P4:P147,"Yes",ConditionRatings!Q4:Q147,"Yes",ConditionRatings!V4:V147,">=1")+COUNTIFS(ConditionRatings!P4:P147,"Yes",ConditionRatings!Q4:Q147,"Yes",ConditionRatings!W4:W147,">=1")+COUNTIFS(ConditionRatings!P4:P147,"Yes",ConditionRatings!Q4:Q147,"Yes",ConditionRatings!X4:X147,">=1")+COUNTIFS(ConditionRatings!P4:P147,"Yes",ConditionRatings!Q4:Q147,"Yes",ConditionRatings!Y4:Y147,">=1")) -> 0 | C14: =IF(B14=0,"OK","CHECK") -> OK | E14: 固定闭合订书机: first = EgoAnchor | F14: 12 | G14: =COUNTIFS(ConditionRatings!D4:D147,"固定闭合订书机",ConditionRatings!F4:F147,1,ConditionRatings!H4:H147,"EgoAnchor") -> 12 | H14: =IF(G14=F14,"OK","CHECK") -> OK
A15: 越界或非 1–7 数值 | B15: =COUNT(ConditionRatings!S4:Y147)-(COUNTIF(ConditionRatings!S4:Y147,1)+COUNTIF(ConditionRatings!S4:Y147,2)+COUNTIF(ConditionRatings!S4:Y147,3)+COUNTIF(ConditionRatings!S4:Y147,4)+COUNTIF(ConditionRatings!S4:Y147,5)+COUNTIF(ConditionRatings!S4:Y147,6)+COUNTIF(ConditionRatings!S4:Y147,7)) -> 0 | C15: =IF(B15=0,"OK","CHECK") -> OK | E15: 固定闭合订书机: first = One-Euro | F15: 12 | G15: =COUNTIFS(ConditionRatings!D4:D147,"固定闭合订书机",ConditionRatings!F4:F147,1,ConditionRatings!H4:H147,"One-Euro") -> 12 | H15: =IF(G15=F15,"OK","CHECK") -> OK
A16: 无技术异常条件 | B16: =COUNTIF(ConditionRatings!R4:R147,"None") -> 144 | C16: 描述性 | E16: 游戏手柄: first = EgoAnchor | F16: 12 | G16: =COUNTIFS(ConditionRatings!D4:D147,"游戏手柄",ConditionRatings!F4:F147,1,ConditionRatings!H4:H147,"EgoAnchor") -> 12 | H16: =IF(G16=F16,"OK","CHECK") -> OK
A17: 待审核条件 | B17: =COUNTIF(ConditionRatings!Q4:Q147,"Pending") -> 144 | C17: =IF(B17=0,"OK","IN PROGRESS") -> IN PROGRESS | E17: 游戏手柄: first = One-Euro | F17: 12 | G17: =COUNTIFS(ConditionRatings!D4:D147,"游戏手柄",ConditionRatings!F4:F147,1,ConditionRatings!H4:H147,"One-Euro") -> 12 | H17: =IF(G17=F17,"OK","CHECK") -> OK
A22: Participant_ID | B22: Condition_Rows | C22: Ratings_Filled | D22: Expected_Ratings | E22: Questionnaire_Completed_Rows | F22: Status
A23: P001 | B23: =COUNTIF(ConditionRatings!A4:A147,A23) -> 6 | C23: =COUNTIFS(ConditionRatings!A4:A147,A23,ConditionRatings!S4:S147,">=1")+COUNTIFS(ConditionRatings!A4:A147,A23,ConditionRatings!T4:T147,">=1")+COUNTIFS(ConditionRatings!A4:A147,A23,ConditionRatings!U4:U147,">=1")+COUNTIFS(ConditionRatings!A4:A147,A23,ConditionRatings!V4:V147,">=1")+COUNTIFS(ConditionRatings!A4:A147,A23,ConditionRatings!W4:W147,">=1")+COUNTIFS(ConditionRatings!A4:A147,A23,ConditionRatings!X4:X147,">=1")+COUNTIFS(ConditionRatings!A4:A147,A23,ConditionRatings!Y4:Y147,">=1") -> 0 | D23: 42 | E23: =COUNTIFS(ConditionRatings!A4:A147,A23,ConditionRatings!P4:P147,"Yes") -> 0 | F23: =IF(AND(B23=6,C23=0,E23=0),"NOT STARTED",IF(AND(B23=6,C23=D23,E23=6),"OK","IN PROGRESS")) -> NOT STARTED
A24: P002 | B24: =COUNTIF(ConditionRatings!A4:A147,A24) -> 6 | C24: =COUNTIFS(ConditionRatings!A4:A147,A24,ConditionRatings!S4:S147,">=1")+COUNTIFS(ConditionRatings!A4:A147,A24,ConditionRatings!T4:T147,">=1")+COUNTIFS(ConditionRatings!A4:A147,A24,ConditionRatings!U4:U147,">=1")+COUNTIFS(ConditionRatings!A4:A147,A24,ConditionRatings!V4:V147,">=1")+COUNTIFS(ConditionRatings!A4:A147,A24,ConditionRatings!W4:W147,">=1")+COUNTIFS(ConditionRatings!A4:A147,A24,ConditionRatings!X4:X147,">=1")+COUNTIFS(ConditionRatings!A4:A147,A24,ConditionRatings!Y4:Y147,">=1") -> 0 | D24: 42 | E24: =COUNTIFS(ConditionRatings!A4:A147,A24,ConditionRatings!P4:P147,"Yes") -> 0 | F24: =IF(AND(B24=6,C24=0,E24=0),"NOT STARTED",IF(AND(B24=6,C24=D24,E24=6),"OK","IN PROGRESS")) -> NOT STARTED
A25: P003 | B25: =COUNTIF(ConditionRatings!A4:A147,A25) -> 6 | C25: =COUNTIFS(ConditionRatings!A4:A147,A25,ConditionRatings!S4:S147,">=1")+COUNTIFS(ConditionRatings!A4:A147,A25,ConditionRatings!T4:T147,">=1")+COUNTIFS(ConditionRatings!A4:A147,A25,ConditionRatings!U4:U147,">=1")+COUNTIFS(ConditionRatings!A4:A147,A25,ConditionRatings!V4:V147,">=1")+COUNTIFS(ConditionRatings!A4:A147,A25,ConditionRatings!W4:W147,">=1")+COUNTIFS(ConditionRatings!A4:A147,A25,ConditionRatings!X4:X147,">=1")+COUNTIFS(ConditionRatings!A4:A147,A25,ConditionRatings!Y4:Y147,">=1") -> 0 | D25: 42 | E25: =COUNTIFS(ConditionRatings!A4:A147,A25,ConditionRatings!P4:P147,"Yes") -> 0 | F25: =IF(AND(B25=6,C25=0,E25=0),"NOT STARTED",IF(AND(B25=6,C25=D25,E25=6),"OK","IN PROGRESS")) -> NOT STARTED
A26: P004 | B26: =COUNTIF(ConditionRatings!A4:A147,A26) -> 6 | C26: =COUNTIFS(ConditionRatings!A4:A147,A26,ConditionRatings!S4:S147,">=1")+COUNTIFS(ConditionRatings!A4:A147,A26,ConditionRatings!T4:T147,">=1")+COUNTIFS(ConditionRatings!A4:A147,A26,ConditionRatings!U4:U147,">=1")+COUNTIFS(ConditionRatings!A4:A147,A26,ConditionRatings!V4:V147,">=1")+COUNTIFS(ConditionRatings!A4:A147,A26,ConditionRatings!W4:W147,">=1")+COUNTIFS(ConditionRatings!A4:A147,A26,ConditionRatings!X4:X147,">=1")+COUNTIFS(ConditionRatings!A4:A147,A26,ConditionRatings!Y4:Y147,">=1") -> 0 | D26: 42 | E26: =COUNTIFS(ConditionRatings!A4:A147,A26,ConditionRatings!P4:P147,"Yes") -> 0 | F26: =IF(AND(B26=6,C26=0,E26=0),"NOT STARTED",IF(AND(B26=6,C26=D26,E26=6),"OK","IN PROGRESS")) -> NOT STARTED
A27: P005 | B27: =COUNTIF(ConditionRatings!A4:A147,A27) -> 6 | C27: =COUNTIFS(ConditionRatings!A4:A147,A27,ConditionRatings!S4:S147,">=1")+COUNTIFS(ConditionRatings!A4:A147,A27,ConditionRatings!T4:T147,">=1")+COUNTIFS(ConditionRatings!A4:A147,A27,ConditionRatings!U4:U147,">=1")+COUNTIFS(ConditionRatings!A4:A147,A27,ConditionRatings!V4:V147,">=1")+COUNTIFS(ConditionRatings!A4:A147,A27,ConditionRatings!W4:W147,">=1")+COUNTIFS(ConditionRatings!A4:A147,A27,ConditionRatings!X4:X147,">=1")+COUNTIFS(ConditionRatings!A4:A147,A27,ConditionRatings!Y4:Y147,">=1") -> 0 | D27: 42 | E27: =COUNTIFS(ConditionRatings!A4:A147,A27,ConditionRatings!P4:P147,"Yes") -> 0 | F27: =IF(AND(B27=6,C27=0,E27=0),"NOT STARTED",IF(AND(B27=6,C27=D27,E27=6),"OK","IN PROGRESS")) -> NOT STARTED
A28: P006 | B28: =COUNTIF(ConditionRatings!A4:A147,A28) -> 6 | C28: =COUNTIFS(ConditionRatings!A4:A147,A28,ConditionRatings!S4:S147,">=1")+COUNTIFS(ConditionRatings!A4:A147,A28,ConditionRatings!T4:T147,">=1")+COUNTIFS(ConditionRatings!A4:A147,A28,ConditionRatings!U4:U147,">=1")+COUNTIFS(ConditionRatings!A4:A147,A28,ConditionRatings!V4:V147,">=1")+COUNTIFS(ConditionRatings!A4:A147,A28,ConditionRatings!W4:W147,">=1")+COUNTIFS(ConditionRatings!A4:A147,A28,ConditionRatings!X4:X147,">=1")+COUNTIFS(ConditionRatings!A4:A147,A28,ConditionRatings!Y4:Y147,">=1") -> 0 | D28: 42 | E28: =COUNTIFS(ConditionRatings!A4:A147,A28,ConditionRatings!P4:P147,"Yes") -> 0 | F28: =IF(AND(B28=6,C28=0,E28=0),"NOT STARTED",IF(AND(B28=6,C28=D28,E28=6),"OK","IN PROGRESS")) -> NOT STARTED
A29: P007 | B29: =COUNTIF(ConditionRatings!A4:A147,A29) -> 6 | C29: =COUNTIFS(ConditionRatings!A4:A147,A29,ConditionRatings!S4:S147,">=1")+COUNTIFS(ConditionRatings!A4:A147,A29,ConditionRatings!T4:T147,">=1")+COUNTIFS(ConditionRatings!A4:A147,A29,ConditionRatings!U4:U147,">=1")+COUNTIFS(ConditionRatings!A4:A147,A29,ConditionRatings!V4:V147,">=1")+COUNTIFS(ConditionRatings!A4:A147,A29,ConditionRatings!W4:W147,">=1")+COUNTIFS(ConditionRatings!A4:A147,A29,ConditionRatings!X4:X147,">=1")+COUNTIFS(ConditionRatings!A4:A147,A29,ConditionRatings!Y4:Y147,">=1") -> 0 | D29: 42 | E29: =COUNTIFS(ConditionRatings!A4:A147,A29,ConditionRatings!P4:P147,"Yes") -> 0 | F29: =IF(AND(B29=6,C29=0,E29=0),"NOT STARTED",IF(AND(B29=6,C29=D29,E29=6),"OK","IN PROGRESS")) -> NOT STARTED
A30: P008 | B30: =COUNTIF(ConditionRatings!A4:A147,A30) -> 6 | C30: =COUNTIFS(ConditionRatings!A4:A147,A30,ConditionRatings!S4:S147,">=1")+COUNTIFS(ConditionRatings!A4:A147,A30,ConditionRatings!T4:T147,">=1")+COUNTIFS(ConditionRatings!A4:A147,A30,ConditionRatings!U4:U147,">=1")+COUNTIFS(ConditionRatings!A4:A147,A30,ConditionRatings!V4:V147,">=1")+COUNTIFS(ConditionRatings!A4:A147,A30,ConditionRatings!W4:W147,">=1")+COUNTIFS(ConditionRatings!A4:A147,A30,ConditionRatings!X4:X147,">=1")+COUNTIFS(ConditionRatings!A4:A147,A30,ConditionRatings!Y4:Y147,">=1") -> 0 | D30: 42 | E30: =COUNTIFS(ConditionRatings!A4:A147,A30,ConditionRatings!P4:P147,"Yes") -> 0 | F30: =IF(AND(B30=6,C30=0,E30=0),"NOT STARTED",IF(AND(B30=6,C30=D30,E30=6),"OK","IN PROGRESS")) -> NOT STARTED
A31: P009 | B31: =COUNTIF(ConditionRatings!A4:A147,A31) -> 6 | C31: =COUNTIFS(ConditionRatings!A4:A147,A31,ConditionRatings!S4:S147,">=1")+COUNTIFS(ConditionRatings!A4:A147,A31,ConditionRatings!T4:T147,">=1")+COUNTIFS(ConditionRatings!A4:A147,A31,ConditionRatings!U4:U147,">=1")+COUNTIFS(ConditionRatings!A4:A147,A31,ConditionRatings!V4:V147,">=1")+COUNTIFS(ConditionRatings!A4:A147,A31,ConditionRatings!W4:W147,">=1")+COUNTIFS(ConditionRatings!A4:A147,A31,ConditionRatings!X4:X147,">=1")+COUNTIFS(ConditionRatings!A4:A147,A31,ConditionRatings!Y4:Y147,">=1") -> 0 | D31: 42 | E31: =COUNTIFS(ConditionRatings!A4:A147,A31,ConditionRatings!P4:P147,"Yes") -> 0 | F31: =IF(AND(B31=6,C31=0,E31=0),"NOT STARTED",IF(AND(B31=6,C31=D31,E31=6),"OK","IN PROGRESS")) -> NOT STARTED
A32: P010 | B32: =COUNTIF(ConditionRatings!A4:A147,A32) -> 6 | C32: =COUNTIFS(ConditionRatings!A4:A147,A32,ConditionRatings!S4:S147,">=1")+COUNTIFS(ConditionRatings!A4:A147,A32,ConditionRatings!T4:T147,">=1")+COUNTIFS(ConditionRatings!A4:A147,A32,ConditionRatings!U4:U147,">=1")+COUNTIFS(ConditionRatings!A4:A147,A32,ConditionRatings!V4:V147,">=1")+COUNTIFS(ConditionRatings!A4:A147,A32,ConditionRatings!W4:W147,">=1")+COUNTIFS(ConditionRatings!A4:A147,A32,ConditionRatings!X4:X147,">=1")+COUNTIFS(ConditionRatings!A4:A147,A32,ConditionRatings!Y4:Y147,">=1") -> 0 | D32: 42 | E32: =COUNTIFS(ConditionRatings!A4:A147,A32,ConditionRatings!P4:P147,"Yes") -> 0 | F32: =IF(AND(B32=6,C32=0,E32=0),"NOT STARTED",IF(AND(B32=6,C32=D32,E32=6),"OK","IN PROGRESS")) -> NOT STARTED
A33: P011 | B33: =COUNTIF(ConditionRatings!A4:A147,A33) -> 6 | C33: =COUNTIFS(ConditionRatings!A4:A147,A33,ConditionRatings!S4:S147,">=1")+COUNTIFS(ConditionRatings!A4:A147,A33,ConditionRatings!T4:T147,">=1")+COUNTIFS(ConditionRatings!A4:A147,A33,ConditionRatings!U4:U147,">=1")+COUNTIFS(ConditionRatings!A4:A147,A33,ConditionRatings!V4:V147,">=1")+COUNTIFS(ConditionRatings!A4:A147,A33,ConditionRatings!W4:W147,">=1")+COUNTIFS(ConditionRatings!A4:A147,A33,ConditionRatings!X4:X147,">=1")+COUNTIFS(ConditionRatings!A4:A147,A33,ConditionRatings!Y4:Y147,">=1") -> 0 | D33: 42 | E33: =COUNTIFS(ConditionRatings!A4:A147,A33,ConditionRatings!P4:P147,"Yes") -> 0 | F33: =IF(AND(B33=6,C33=0,E33=0),"NOT STARTED",IF(AND(B33=6,C33=D33,E33=6),"OK","IN PROGRESS")) -> NOT STARTED
A34: P012 | B34: =COUNTIF(ConditionRatings!A4:A147,A34) -> 6 | C34: =COUNTIFS(ConditionRatings!A4:A147,A34,ConditionRatings!S4:S147,">=1")+COUNTIFS(ConditionRatings!A4:A147,A34,ConditionRatings!T4:T147,">=1")+COUNTIFS(ConditionRatings!A4:A147,A34,ConditionRatings!U4:U147,">=1")+COUNTIFS(ConditionRatings!A4:A147,A34,ConditionRatings!V4:V147,">=1")+COUNTIFS(ConditionRatings!A4:A147,A34,ConditionRatings!W4:W147,">=1")+COUNTIFS(ConditionRatings!A4:A147,A34,ConditionRatings!X4:X147,">=1")+COUNTIFS(ConditionRatings!A4:A147,A34,ConditionRatings!Y4:Y147,">=1") -> 0 | D34: 42 | E34: =COUNTIFS(ConditionRatings!A4:A147,A34,ConditionRatings!P4:P147,"Yes") -> 0 | F34: =IF(AND(B34=6,C34=0,E34=0),"NOT STARTED",IF(AND(B34=6,C34=D34,E34=6),"OK","IN PROGRESS")) -> NOT STARTED
A35: P013 | B35: =COUNTIF(ConditionRatings!A4:A147,A35) -> 6 | C35: =COUNTIFS(ConditionRatings!A4:A147,A35,ConditionRatings!S4:S147,">=1")+COUNTIFS(ConditionRatings!A4:A147,A35,ConditionRatings!T4:T147,">=1")+COUNTIFS(ConditionRatings!A4:A147,A35,ConditionRatings!U4:U147,">=1")+COUNTIFS(ConditionRatings!A4:A147,A35,ConditionRatings!V4:V147,">=1")+COUNTIFS(ConditionRatings!A4:A147,A35,ConditionRatings!W4:W147,">=1")+COUNTIFS(ConditionRatings!A4:A147,A35,ConditionRatings!X4:X147,">=1")+COUNTIFS(ConditionRatings!A4:A147,A35,ConditionRatings!Y4:Y147,">=1") -> 0 | D35: 42 | E35: =COUNTIFS(ConditionRatings!A4:A147,A35,ConditionRatings!P4:P147,"Yes") -> 0 | F35: =IF(AND(B35=6,C35=0,E35=0),"NOT STARTED",IF(AND(B35=6,C35=D35,E35=6),"OK","IN PROGRESS")) -> NOT STARTED
A36: P014 | B36: =COUNTIF(ConditionRatings!A4:A147,A36) -> 6 | C36: =COUNTIFS(ConditionRatings!A4:A147,A36,ConditionRatings!S4:S147,">=1")+COUNTIFS(ConditionRatings!A4:A147,A36,ConditionRatings!T4:T147,">=1")+COUNTIFS(ConditionRatings!A4:A147,A36,ConditionRatings!U4:U147,">=1")+COUNTIFS(ConditionRatings!A4:A147,A36,ConditionRatings!V4:V147,">=1")+COUNTIFS(ConditionRatings!A4:A147,A36,ConditionRatings!W4:W147,">=1")+COUNTIFS(ConditionRatings!A4:A147,A36,ConditionRatings!X4:X147,">=1")+COUNTIFS(ConditionRatings!A4:A147,A36,ConditionRatings!Y4:Y147,">=1") -> 0 | D36: 42 | E36: =COUNTIFS(ConditionRatings!A4:A147,A36,ConditionRatings!P4:P147,"Yes") -> 0 | F36: =IF(AND(B36=6,C36=0,E36=0),"NOT STARTED",IF(AND(B36=6,C36=D36,E36=6),"OK","IN PROGRESS")) -> NOT STARTED
A37: P015 | B37: =COUNTIF(ConditionRatings!A4:A147,A37) -> 6 | C37: =COUNTIFS(ConditionRatings!A4:A147,A37,ConditionRatings!S4:S147,">=1")+COUNTIFS(ConditionRatings!A4:A147,A37,ConditionRatings!T4:T147,">=1")+COUNTIFS(ConditionRatings!A4:A147,A37,ConditionRatings!U4:U147,">=1")+COUNTIFS(ConditionRatings!A4:A147,A37,ConditionRatings!V4:V147,">=1")+COUNTIFS(ConditionRatings!A4:A147,A37,ConditionRatings!W4:W147,">=1")+COUNTIFS(ConditionRatings!A4:A147,A37,ConditionRatings!X4:X147,">=1")+COUNTIFS(ConditionRatings!A4:A147,A37,ConditionRatings!Y4:Y147,">=1") -> 0 | D37: 42 | E37: =COUNTIFS(ConditionRatings!A4:A147,A37,ConditionRatings!P4:P147,"Yes") -> 0 | F37: =IF(AND(B37=6,C37=0,E37=0),"NOT STARTED",IF(AND(B37=6,C37=D37,E37=6),"OK","IN PROGRESS")) -> NOT STARTED
A38: P016 | B38: =COUNTIF(ConditionRatings!A4:A147,A38) -> 6 | C38: =COUNTIFS(ConditionRatings!A4:A147,A38,ConditionRatings!S4:S147,">=1")+COUNTIFS(ConditionRatings!A4:A147,A38,ConditionRatings!T4:T147,">=1")+COUNTIFS(ConditionRatings!A4:A147,A38,ConditionRatings!U4:U147,">=1")+COUNTIFS(ConditionRatings!A4:A147,A38,ConditionRatings!V4:V147,">=1")+COUNTIFS(ConditionRatings!A4:A147,A38,ConditionRatings!W4:W147,">=1")+COUNTIFS(ConditionRatings!A4:A147,A38,ConditionRatings!X4:X147,">=1")+COUNTIFS(ConditionRatings!A4:A147,A38,ConditionRatings!Y4:Y147,">=1") -> 0 | D38: 42 | E38: =COUNTIFS(ConditionRatings!A4:A147,A38,ConditionRatings!P4:P147,"Yes") -> 0 | F38: =IF(AND(B38=6,C38=0,E38=0),"NOT STARTED",IF(AND(B38=6,C38=D38,E38=6),"OK","IN PROGRESS")) -> NOT STARTED
A39: P017 | B39: =COUNTIF(ConditionRatings!A4:A147,A39) -> 6 | C39: =COUNTIFS(ConditionRatings!A4:A147,A39,ConditionRatings!S4:S147,">=1")+COUNTIFS(ConditionRatings!A4:A147,A39,ConditionRatings!T4:T147,">=1")+COUNTIFS(ConditionRatings!A4:A147,A39,ConditionRatings!U4:U147,">=1")+COUNTIFS(ConditionRatings!A4:A147,A39,ConditionRatings!V4:V147,">=1")+COUNTIFS(ConditionRatings!A4:A147,A39,ConditionRatings!W4:W147,">=1")+COUNTIFS(ConditionRatings!A4:A147,A39,ConditionRatings!X4:X147,">=1")+COUNTIFS(ConditionRatings!A4:A147,A39,ConditionRatings!Y4:Y147,">=1") -> 0 | D39: 42 | E39: =COUNTIFS(ConditionRatings!A4:A147,A39,ConditionRatings!P4:P147,"Yes") -> 0 | F39: =IF(AND(B39=6,C39=0,E39=0),"NOT STARTED",IF(AND(B39=6,C39=D39,E39=6),"OK","IN PROGRESS")) -> NOT STARTED
A40: P018 | B40: =COUNTIF(ConditionRatings!A4:A147,A40) -> 6 | C40: =COUNTIFS(ConditionRatings!A4:A147,A40,ConditionRatings!S4:S147,">=1")+COUNTIFS(ConditionRatings!A4:A147,A40,ConditionRatings!T4:T147,">=1")+COUNTIFS(ConditionRatings!A4:A147,A40,ConditionRatings!U4:U147,">=1")+COUNTIFS(ConditionRatings!A4:A147,A40,ConditionRatings!V4:V147,">=1")+COUNTIFS(ConditionRatings!A4:A147,A40,ConditionRatings!W4:W147,">=1")+COUNTIFS(ConditionRatings!A4:A147,A40,ConditionRatings!X4:X147,">=1")+COUNTIFS(ConditionRatings!A4:A147,A40,ConditionRatings!Y4:Y147,">=1") -> 0 | D40: 42 | E40: =COUNTIFS(ConditionRatings!A4:A147,A40,ConditionRatings!P4:P147,"Yes") -> 0 | F40: =IF(AND(B40=6,C40=0,E40=0),"NOT STARTED",IF(AND(B40=6,C40=D40,E40=6),"OK","IN PROGRESS")) -> NOT STARTED
A41: P019 | B41: =COUNTIF(ConditionRatings!A4:A147,A41) -> 6 | C41: =COUNTIFS(ConditionRatings!A4:A147,A41,ConditionRatings!S4:S147,">=1")+COUNTIFS(ConditionRatings!A4:A147,A41,ConditionRatings!T4:T147,">=1")+COUNTIFS(ConditionRatings!A4:A147,A41,ConditionRatings!U4:U147,">=1")+COUNTIFS(ConditionRatings!A4:A147,A41,ConditionRatings!V4:V147,">=1")+COUNTIFS(ConditionRatings!A4:A147,A41,ConditionRatings!W4:W147,">=1")+COUNTIFS(ConditionRatings!A4:A147,A41,ConditionRatings!X4:X147,">=1")+COUNTIFS(ConditionRatings!A4:A147,A41,ConditionRatings!Y4:Y147,">=1") -> 0 | D41: 42 | E41: =COUNTIFS(ConditionRatings!A4:A147,A41,ConditionRatings!P4:P147,"Yes") -> 0 | F41: =IF(AND(B41=6,C41=0,E41=0),"NOT STARTED",IF(AND(B41=6,C41=D41,E41=6),"OK","IN PROGRESS")) -> NOT STARTED
A42: P020 | B42: =COUNTIF(ConditionRatings!A4:A147,A42) -> 6 | C42: =COUNTIFS(ConditionRatings!A4:A147,A42,ConditionRatings!S4:S147,">=1")+COUNTIFS(ConditionRatings!A4:A147,A42,ConditionRatings!T4:T147,">=1")+COUNTIFS(ConditionRatings!A4:A147,A42,ConditionRatings!U4:U147,">=1")+COUNTIFS(ConditionRatings!A4:A147,A42,ConditionRatings!V4:V147,">=1")+COUNTIFS(ConditionRatings!A4:A147,A42,ConditionRatings!W4:W147,">=1")+COUNTIFS(ConditionRatings!A4:A147,A42,ConditionRatings!X4:X147,">=1")+COUNTIFS(ConditionRatings!A4:A147,A42,ConditionRatings!Y4:Y147,">=1") -> 0 | D42: 42 | E42: =COUNTIFS(ConditionRatings!A4:A147,A42,ConditionRatings!P4:P147,"Yes") -> 0 | F42: =IF(AND(B42=6,C42=0,E42=0),"NOT STARTED",IF(AND(B42=6,C42=D42,E42=6),"OK","IN PROGRESS")) -> NOT STARTED
A43: P021 | B43: =COUNTIF(ConditionRatings!A4:A147,A43) -> 6 | C43: =COUNTIFS(ConditionRatings!A4:A147,A43,ConditionRatings!S4:S147,">=1")+COUNTIFS(ConditionRatings!A4:A147,A43,ConditionRatings!T4:T147,">=1")+COUNTIFS(ConditionRatings!A4:A147,A43,ConditionRatings!U4:U147,">=1")+COUNTIFS(ConditionRatings!A4:A147,A43,ConditionRatings!V4:V147,">=1")+COUNTIFS(ConditionRatings!A4:A147,A43,ConditionRatings!W4:W147,">=1")+COUNTIFS(ConditionRatings!A4:A147,A43,ConditionRatings!X4:X147,">=1")+COUNTIFS(ConditionRatings!A4:A147,A43,ConditionRatings!Y4:Y147,">=1") -> 0 | D43: 42 | E43: =COUNTIFS(ConditionRatings!A4:A147,A43,ConditionRatings!P4:P147,"Yes") -> 0 | F43: =IF(AND(B43=6,C43=0,E43=0),"NOT STARTED",IF(AND(B43=6,C43=D43,E43=6),"OK","IN PROGRESS")) -> NOT STARTED
A44: P022 | B44: =COUNTIF(ConditionRatings!A4:A147,A44) -> 6 | C44: =COUNTIFS(ConditionRatings!A4:A147,A44,ConditionRatings!S4:S147,">=1")+COUNTIFS(ConditionRatings!A4:A147,A44,ConditionRatings!T4:T147,">=1")+COUNTIFS(ConditionRatings!A4:A147,A44,ConditionRatings!U4:U147,">=1")+COUNTIFS(ConditionRatings!A4:A147,A44,ConditionRatings!V4:V147,">=1")+COUNTIFS(ConditionRatings!A4:A147,A44,ConditionRatings!W4:W147,">=1")+COUNTIFS(ConditionRatings!A4:A147,A44,ConditionRatings!X4:X147,">=1")+COUNTIFS(ConditionRatings!A4:A147,A44,ConditionRatings!Y4:Y147,">=1") -> 0 | D44: 42 | E44: =COUNTIFS(ConditionRatings!A4:A147,A44,ConditionRatings!P4:P147,"Yes") -> 0 | F44: =IF(AND(B44=6,C44=0,E44=0),"NOT STARTED",IF(AND(B44=6,C44=D44,E44=6),"OK","IN PROGRESS")) -> NOT STARTED
A45: P023 | B45: =COUNTIF(ConditionRatings!A4:A147,A45) -> 6 | C45: =COUNTIFS(ConditionRatings!A4:A147,A45,ConditionRatings!S4:S147,">=1")+COUNTIFS(ConditionRatings!A4:A147,A45,ConditionRatings!T4:T147,">=1")+COUNTIFS(ConditionRatings!A4:A147,A45,ConditionRatings!U4:U147,">=1")+COUNTIFS(ConditionRatings!A4:A147,A45,ConditionRatings!V4:V147,">=1")+COUNTIFS(ConditionRatings!A4:A147,A45,ConditionRatings!W4:W147,">=1")+COUNTIFS(ConditionRatings!A4:A147,A45,ConditionRatings!X4:X147,">=1")+COUNTIFS(ConditionRatings!A4:A147,A45,ConditionRatings!Y4:Y147,">=1") -> 0 | D45: 42 | E45: =COUNTIFS(ConditionRatings!A4:A147,A45,ConditionRatings!P4:P147,"Yes") -> 0 | F45: =IF(AND(B45=6,C45=0,E45=0),"NOT STARTED",IF(AND(B45=6,C45=D45,E45=6),"OK","IN PROGRESS")) -> NOT STARTED
...

Sheet Descriptives
A1: 逐项描述性统计：自动 N/Mean；Median 与 IQR 从 R 输出回填
A3: Item_ID | B3: Construct | C3: Method | D3: Object | E3: N | F3: Mean_Monitoring | G3: Median_R | H3: Q1_R | I3: Q3_R | J3: Median_[Q1,Q3] | K3: Notes
A4: Q1_STATIC_STABILITY | B4: 静止稳定性 | C4: EgoAnchor | D4: 无线鼠标 | E4: =COUNTIFS(ConditionRatings!$H$4:$H$147,$C4,ConditionRatings!$D$4:$D$147,$D4,ConditionRatings!$Q$4:$Q$147,"Yes",ConditionRatings!$S$4:$S$147,">=1") -> 0 | F4: =IF(E4=0,"",SUMIFS(ConditionRatings!$S$4:$S$147,ConditionRatings!$H$4:$H$147,$C4,ConditionRatings!$D$4:$D$147,$D4,ConditionRatings!$Q$4:$Q$147,"Yes")/E4) | J4: =IF(COUNT(G4:I4)=3,TEXT(G4,"0.00")&" ["&TEXT(H4,"0.00")&", "&TEXT(I4,"0.00")&"]","")
A5: Q1_STATIC_STABILITY | B5: 静止稳定性 | C5: EgoAnchor | D5: 固定闭合订书机 | E5: =COUNTIFS(ConditionRatings!$H$4:$H$147,$C5,ConditionRatings!$D$4:$D$147,$D5,ConditionRatings!$Q$4:$Q$147,"Yes",ConditionRatings!$S$4:$S$147,">=1") -> 0 | F5: =IF(E5=0,"",SUMIFS(ConditionRatings!$S$4:$S$147,ConditionRatings!$H$4:$H$147,$C5,ConditionRatings!$D$4:$D$147,$D5,ConditionRatings!$Q$4:$Q$147,"Yes")/E5) | J5: =IF(COUNT(G5:I5)=3,TEXT(G5,"0.00")&" ["&TEXT(H5,"0.00")&", "&TEXT(I5,"0.00")&"]","")
A6: Q1_STATIC_STABILITY | B6: 静止稳定性 | C6: EgoAnchor | D6: 游戏手柄 | E6: =COUNTIFS(ConditionRatings!$H$4:$H$147,$C6,ConditionRatings!$D$4:$D$147,$D6,ConditionRatings!$Q$4:$Q$147,"Yes",ConditionRatings!$S$4:$S$147,">=1") -> 0 | F6: =IF(E6=0,"",SUMIFS(ConditionRatings!$S$4:$S$147,ConditionRatings!$H$4:$H$147,$C6,ConditionRatings!$D$4:$D$147,$D6,ConditionRatings!$Q$4:$Q$147,"Yes")/E6) | J6: =IF(COUNT(G6:I6)=3,TEXT(G6,"0.00")&" ["&TEXT(H6,"0.00")&", "&TEXT(I6,"0.00")&"]","")
A7: Q1_STATIC_STABILITY | B7: 静止稳定性 | C7: One-Euro | D7: 无线鼠标 | E7: =COUNTIFS(ConditionRatings!$H$4:$H$147,$C7,ConditionRatings!$D$4:$D$147,$D7,ConditionRatings!$Q$4:$Q$147,"Yes",ConditionRatings!$S$4:$S$147,">=1") -> 0 | F7: =IF(E7=0,"",SUMIFS(ConditionRatings!$S$4:$S$147,ConditionRatings!$H$4:$H$147,$C7,ConditionRatings!$D$4:$D$147,$D7,ConditionRatings!$Q$4:$Q$147,"Yes")/E7) | J7: =IF(COUNT(G7:I7)=3,TEXT(G7,"0.00")&" ["&TEXT(H7,"0.00")&", "&TEXT(I7,"0.00")&"]","")
A8: Q1_STATIC_STABILITY | B8: 静止稳定性 | C8: One-Euro | D8: 固定闭合订书机 | E8: =COUNTIFS(ConditionRatings!$H$4:$H$147,$C8,ConditionRatings!$D$4:$D$147,$D8,ConditionRatings!$Q$4:$Q$147,"Yes",ConditionRatings!$S$4:$S$147,">=1") -> 0 | F8: =IF(E8=0,"",SUMIFS(ConditionRatings!$S$4:$S$147,ConditionRatings!$H$4:$H$147,$C8,ConditionRatings!$D$4:$D$147,$D8,ConditionRatings!$Q$4:$Q$147,"Yes")/E8) | J8: =IF(COUNT(G8:I8)=3,TEXT(G8,"0.00")&" ["&TEXT(H8,"0.00")&", "&TEXT(I8,"0.00")&"]","")
A9: Q1_STATIC_STABILITY | B9: 静止稳定性 | C9: One-Euro | D9: 游戏手柄 | E9: =COUNTIFS(ConditionRatings!$H$4:$H$147,$C9,ConditionRatings!$D$4:$D$147,$D9,ConditionRatings!$Q$4:$Q$147,"Yes",ConditionRatings!$S$4:$S$147,">=1") -> 0 | F9: =IF(E9=0,"",SUMIFS(ConditionRatings!$S$4:$S$147,ConditionRatings!$H$4:$H$147,$C9,ConditionRatings!$D$4:$D$147,$D9,ConditionRatings!$Q$4:$Q$147,"Yes")/E9) | J9: =IF(COUNT(G9:I9)=3,TEXT(G9,"0.00")&" ["&TEXT(H9,"0.00")&", "&TEXT(I9,"0.00")&"]","")
A10: Q2_MOTION_ATTACHMENT | B10: 运动附着感 | C10: EgoAnchor | D10: 无线鼠标 | E10: =COUNTIFS(ConditionRatings!$H$4:$H$147,$C10,ConditionRatings!$D$4:$D$147,$D10,ConditionRatings!$Q$4:$Q$147,"Yes",ConditionRatings!$T$4:$T$147,">=1") -> 0 | F10: =IF(E10=0,"",SUMIFS(ConditionRatings!$T$4:$T$147,ConditionRatings!$H$4:$H$147,$C10,ConditionRatings!$D$4:$D$147,$D10,ConditionRatings!$Q$4:$Q$147,"Yes")/E10) | J10: =IF(COUNT(G10:I10)=3,TEXT(G10,"0.00")&" ["&TEXT(H10,"0.00")&", "&TEXT(I10,"0.00")&"]","")
A11: Q2_MOTION_ATTACHMENT | B11: 运动附着感 | C11: EgoAnchor | D11: 固定闭合订书机 | E11: =COUNTIFS(ConditionRatings!$H$4:$H$147,$C11,ConditionRatings!$D$4:$D$147,$D11,ConditionRatings!$Q$4:$Q$147,"Yes",ConditionRatings!$T$4:$T$147,">=1") -> 0 | F11: =IF(E11=0,"",SUMIFS(ConditionRatings!$T$4:$T$147,ConditionRatings!$H$4:$H$147,$C11,ConditionRatings!$D$4:$D$147,$D11,ConditionRatings!$Q$4:$Q$147,"Yes")/E11) | J11: =IF(COUNT(G11:I11)=3,TEXT(G11,"0.00")&" ["&TEXT(H11,"0.00")&", "&TEXT(I11,"0.00")&"]","")
A12: Q2_MOTION_ATTACHMENT | B12: 运动附着感 | C12: EgoAnchor | D12: 游戏手柄 | E12: =COUNTIFS(ConditionRatings!$H$4:$H$147,$C12,ConditionRatings!$D$4:$D$147,$D12,ConditionRatings!$Q$4:$Q$147,"Yes",ConditionRatings!$T$4:$T$147,">=1") -> 0 | F12: =IF(E12=0,"",SUMIFS(ConditionRatings!$T$4:$T$147,ConditionRatings!$H$4:$H$147,$C12,ConditionRatings!$D$4:$D$147,$D12,ConditionRatings!$Q$4:$Q$147,"Yes")/E12) | J12: =IF(COUNT(G12:I12)=3,TEXT(G12,"0.00")&" ["&TEXT(H12,"0.00")&", "&TEXT(I12,"0.00")&"]","")
A13: Q2_MOTION_ATTACHMENT | B13: 运动附着感 | C13: One-Euro | D13: 无线鼠标 | E13: =COUNTIFS(ConditionRatings!$H$4:$H$147,$C13,ConditionRatings!$D$4:$D$147,$D13,ConditionRatings!$Q$4:$Q$147,"Yes",ConditionRatings!$T$4:$T$147,">=1") -> 0 | F13: =IF(E13=0,"",SUMIFS(ConditionRatings!$T$4:$T$147,ConditionRatings!$H$4:$H$147,$C13,ConditionRatings!$D$4:$D$147,$D13,ConditionRatings!$Q$4:$Q$147,"Yes")/E13) | J13: =IF(COUNT(G13:I13)=3,TEXT(G13,"0.00")&" ["&TEXT(H13,"0.00")&", "&TEXT(I13,"0.00")&"]","")
A14: Q2_MOTION_ATTACHMENT | B14: 运动附着感 | C14: One-Euro | D14: 固定闭合订书机 | E14: =COUNTIFS(ConditionRatings!$H$4:$H$147,$C14,ConditionRatings!$D$4:$D$147,$D14,ConditionRatings!$Q$4:$Q$147,"Yes",ConditionRatings!$T$4:$T$147,">=1") -> 0 | F14: =IF(E14=0,"",SUMIFS(ConditionRatings!$T$4:$T$147,ConditionRatings!$H$4:$H$147,$C14,ConditionRatings!$D$4:$D$147,$D14,ConditionRatings!$Q$4:$Q$147,"Yes")/E14) | J14: =IF(COUNT(G14:I14)=3,TEXT(G14,"0.00")&" ["&TEXT(H14,"0.00")&", "&TEXT(I14,"0.00")&"]","")
A15: Q2_MOTION_ATTACHMENT | B15: 运动附着感 | C15: One-Euro | D15: 游戏手柄 | E15: =COUNTIFS(ConditionRatings!$H$4:$H$147,$C15,ConditionRatings!$D$4:$D$147,$D15,ConditionRatings!$Q$4:$Q$147,"Yes",ConditionRatings!$T$4:$T$147,">=1") -> 0 | F15: =IF(E15=0,"",SUMIFS(ConditionRatings!$T$4:$T$147,ConditionRatings!$H$4:$H$147,$C15,ConditionRatings!$D$4:$D$147,$D15,ConditionRatings!$Q$4:$Q$147,"Yes")/E15) | J15: =IF(COUNT(G15:I15)=3,TEXT(G15,"0.00")&" ["&TEXT(H15,"0.00")&", "&TEXT(I15,"0.00")&"]","")
A16: Q3_RECOVERY_CONSISTENCY | B16: 遮挡恢复一致性 | C16: EgoAnchor | D16: 无线鼠标 | E16: =COUNTIFS(ConditionRatings!$H$4:$H$147,$C16,ConditionRatings!$D$4:$D$147,$D16,ConditionRatings!$Q$4:$Q$147,"Yes",ConditionRatings!$U$4:$U$147,">=1") -> 0 | F16: =IF(E16=0,"",SUMIFS(ConditionRatings!$U$4:$U$147,ConditionRatings!$H$4:$H$147,$C16,ConditionRatings!$D$4:$D$147,$D16,ConditionRatings!$Q$4:$Q$147,"Yes")/E16) | J16: =IF(COUNT(G16:I16)=3,TEXT(G16,"0.00")&" ["&TEXT(H16,"0.00")&", "&TEXT(I16,"0.00")&"]","")
A17: Q3_RECOVERY_CONSISTENCY | B17: 遮挡恢复一致性 | C17: EgoAnchor | D17: 固定闭合订书机 | E17: =COUNTIFS(ConditionRatings!$H$4:$H$147,$C17,ConditionRatings!$D$4:$D$147,$D17,ConditionRatings!$Q$4:$Q$147,"Yes",ConditionRatings!$U$4:$U$147,">=1") -> 0 | F17: =IF(E17=0,"",SUMIFS(ConditionRatings!$U$4:$U$147,ConditionRatings!$H$4:$H$147,$C17,ConditionRatings!$D$4:$D$147,$D17,ConditionRatings!$Q$4:$Q$147,"Yes")/E17) | J17: =IF(COUNT(G17:I17)=3,TEXT(G17,"0.00")&" ["&TEXT(H17,"0.00")&", "&TEXT(I17,"0.00")&"]","")
A18: Q3_RECOVERY_CONSISTENCY | B18: 遮挡恢复一致性 | C18: EgoAnchor | D18: 游戏手柄 | E18: =COUNTIFS(ConditionRatings!$H$4:$H$147,$C18,ConditionRatings!$D$4:$D$147,$D18,ConditionRatings!$Q$4:$Q$147,"Yes",ConditionRatings!$U$4:$U$147,">=1") -> 0 | F18: =IF(E18=0,"",SUMIFS(ConditionRatings!$U$4:$U$147,ConditionRatings!$H$4:$H$147,$C18,ConditionRatings!$D$4:$D$147,$D18,ConditionRatings!$Q$4:$Q$147,"Yes")/E18) | J18: =IF(COUNT(G18:I18)=3,TEXT(G18,"0.00")&" ["&TEXT(H18,"0.00")&", "&TEXT(I18,"0.00")&"]","")
A19: Q3_RECOVERY_CONSISTENCY | B19: 遮挡恢复一致性 | C19: One-Euro | D19: 无线鼠标 | E19: =COUNTIFS(ConditionRatings!$H$4:$H$147,$C19,ConditionRatings!$D$4:$D$147,$D19,ConditionRatings!$Q$4:$Q$147,"Yes",ConditionRatings!$U$4:$U$147,">=1") -> 0 | F19: =IF(E19=0,"",SUMIFS(ConditionRatings!$U$4:$U$147,ConditionRatings!$H$4:$H$147,$C19,ConditionRatings!$D$4:$D$147,$D19,ConditionRatings!$Q$4:$Q$147,"Yes")/E19) | J19: =IF(COUNT(G19:I19)=3,TEXT(G19,"0.00")&" ["&TEXT(H19,"0.00")&", "&TEXT(I19,"0.00")&"]","")
A20: Q3_RECOVERY_CONSISTENCY | B20: 遮挡恢复一致性 | C20: One-Euro | D20: 固定闭合订书机 | E20: =COUNTIFS(ConditionRatings!$H$4:$H$147,$C20,ConditionRatings!$D$4:$D$147,$D20,ConditionRatings!$Q$4:$Q$147,"Yes",ConditionRatings!$U$4:$U$147,">=1") -> 0 | F20: =IF(E20=0,"",SUMIFS(ConditionRatings!$U$4:$U$147,ConditionRatings!$H$4:$H$147,$C20,ConditionRatings!$D$4:$D$147,$D20,ConditionRatings!$Q$4:$Q$147,"Yes")/E20) | J20: =IF(COUNT(G20:I20)=3,TEXT(G20,"0.00")&" ["&TEXT(H20,"0.00")&", "&TEXT(I20,"0.00")&"]","")
A21: Q3_RECOVERY_CONSISTENCY | B21: 遮挡恢复一致性 | C21: One-Euro | D21: 游戏手柄 | E21: =COUNTIFS(ConditionRatings!$H$4:$H$147,$C21,ConditionRatings!$D$4:$D$147,$D21,ConditionRatings!$Q$4:$Q$147,"Yes",ConditionRatings!$U$4:$U$147,">=1") -> 0 | F21: =IF(E21=0,"",SUMIFS(ConditionRatings!$U$4:$U$147,ConditionRatings!$H$4:$H$147,$C21,ConditionRatings!$D$4:$D$147,$D21,ConditionRatings!$Q$4:$Q$147,"Yes")/E21) | J21: =IF(COUNT(G21:I21)=3,TEXT(G21,"0.00")&" ["&TEXT(H21,"0.00")&", "&TEXT(I21,"0.00")&"]","")
A22: Q4_PLAUSIBILITY | B22: 合理可信度 | C22: EgoAnchor | D22: 无线鼠标 | E22: =COUNTIFS(ConditionRatings!$H$4:$H$147,$C22,ConditionRatings!$D$4:$D$147,$D22,ConditionRatings!$Q$4:$Q$147,"Yes",ConditionRatings!$V$4:$V$147,">=1") -> 0 | F22: =IF(E22=0,"",SUMIFS(ConditionRatings!$V$4:$V$147,ConditionRatings!$H$4:$H$147,$C22,ConditionRatings!$D$4:$D$147,$D22,ConditionRatings!$Q$4:$Q$147,"Yes")/E22) | J22: =IF(COUNT(G22:I22)=3,TEXT(G22,"0.00")&" ["&TEXT(H22,"0.00")&", "&TEXT(I22,"0.00")&"]","")
A23: Q4_PLAUSIBILITY | B23: 合理可信度 | C23: EgoAnchor | D23: 固定闭合订书机 | E23: =COUNTIFS(ConditionRatings!$H$4:$H$147,$C23,ConditionRatings!$D$4:$D$147,$D23,ConditionRatings!$Q$4:$Q$147,"Yes",ConditionRatings!$V$4:$V$147,">=1") -> 0 | F23: =IF(E23=0,"",SUMIFS(ConditionRatings!$V$4:$V$147,ConditionRatings!$H$4:$H$147,$C23,ConditionRatings!$D$4:$D$147,$D23,ConditionRatings!$Q$4:$Q$147,"Yes")/E23) | J23: =IF(COUNT(G23:I23)=3,TEXT(G23,"0.00")&" ["&TEXT(H23,"0.00")&", "&TEXT(I23,"0.00")&"]","")
A24: Q4_PLAUSIBILITY | B24: 合理可信度 | C24: EgoAnchor | D24: 游戏手柄 | E24: =COUNTIFS(ConditionRatings!$H$4:$H$147,$C24,ConditionRatings!$D$4:$D$147,$D24,ConditionRatings!$Q$4:$Q$147,"Yes",ConditionRatings!$V$4:$V$147,">=1") -> 0 | F24: =IF(E24=0,"",SUMIFS(ConditionRatings!$V$4:$V$147,ConditionRatings!$H$4:$H$147,$C24,ConditionRatings!$D$4:$D$147,$D24,ConditionRatings!$Q$4:$Q$147,"Yes")/E24) | J24: =IF(COUNT(G24:I24)=3,TEXT(G24,"0.00")&" ["&TEXT(H24,"0.00")&", "&TEXT(I24,"0.00")&"]","")
A25: Q4_PLAUSIBILITY | B25: 合理可信度 | C25: One-Euro | D25: 无线鼠标 | E25: =COUNTIFS(ConditionRatings!$H$4:$H$147,$C25,ConditionRatings!$D$4:$D$147,$D25,ConditionRatings!$Q$4:$Q$147,"Yes",ConditionRatings!$V$4:$V$147,">=1") -> 0 | F25: =IF(E25=0,"",SUMIFS(ConditionRatings!$V$4:$V$147,ConditionRatings!$H$4:$H$147,$C25,ConditionRatings!$D$4:$D$147,$D25,ConditionRatings!$Q$4:$Q$147,"Yes")/E25) | J25: =IF(COUNT(G25:I25)=3,TEXT(G25,"0.00")&" ["&TEXT(H25,"0.00")&", "&TEXT(I25,"0.00")&"]","")
A26: Q4_PLAUSIBILITY | B26: 合理可信度 | C26: One-Euro | D26: 固定闭合订书机 | E26: =COUNTIFS(ConditionRatings!$H$4:$H$147,$C26,ConditionRatings!$D$4:$D$147,$D26,ConditionRatings!$Q$4:$Q$147,"Yes",ConditionRatings!$V$4:$V$147,">=1") -> 0 | F26: =IF(E26=0,"",SUMIFS(ConditionRatings!$V$4:$V$147,ConditionRatings!$H$4:$H$147,$C26,ConditionRatings!$D$4:$D$147,$D26,ConditionRatings!$Q$4:$Q$147,"Yes")/E26) | J26: =IF(COUNT(G26:I26)=3,TEXT(G26,"0.00")&" ["&TEXT(H26,"0.00")&", "&TEXT(I26,"0.00")&"]","")
A27: Q4_PLAUSIBILITY | B27: 合理可信度 | C27: One-Euro | D27: 游戏手柄 | E27: =COUNTIFS(ConditionRatings!$H$4:$H$147,$C27,ConditionRatings!$D$4:$D$147,$D27,ConditionRatings!$Q$4:$Q$147,"Yes",ConditionRatings!$V$4:$V$147,">=1") -> 0 | F27: =IF(E27=0,"",SUMIFS(ConditionRatings!$V$4:$V$147,ConditionRatings!$H$4:$H$147,$C27,ConditionRatings!$D$4:$D$147,$D27,ConditionRatings!$Q$4:$Q$147,"Yes")/E27) | J27: =IF(COUNT(G27:I27)=3,TEXT(G27,"0.00")&" ["&TEXT(H27,"0.00")&", "&TEXT(I27,"0.00")&"]","")
A28: Q5_SYNCHRONY | B28: 虚实同步性 | C28: EgoAnchor | D28: 无线鼠标 | E28: =COUNTIFS(ConditionRatings!$H$4:$H$147,$C28,ConditionRatings!$D$4:$D$147,$D28,ConditionRatings!$Q$4:$Q$147,"Yes",ConditionRatings!$W$4:$W$147,">=1") -> 0 | F28: =IF(E28=0,"",SUMIFS(ConditionRatings!$W$4:$W$147,ConditionRatings!$H$4:$H$147,$C28,ConditionRatings!$D$4:$D$147,$D28,ConditionRatings!$Q$4:$Q$147,"Yes")/E28) | J28: =IF(COUNT(G28:I28)=3,TEXT(G28,"0.00")&" ["&TEXT(H28,"0.00")&", "&TEXT(I28,"0.00")&"]","")
A29: Q5_SYNCHRONY | B29: 虚实同步性 | C29: EgoAnchor | D29: 固定闭合订书机 | E29: =COUNTIFS(ConditionRatings!$H$4:$H$147,$C29,ConditionRatings!$D$4:$D$147,$D29,ConditionRatings!$Q$4:$Q$147,"Yes",ConditionRatings!$W$4:$W$147,">=1") -> 0 | F29: =IF(E29=0,"",SUMIFS(ConditionRatings!$W$4:$W$147,ConditionRatings!$H$4:$H$147,$C29,ConditionRatings!$D$4:$D$147,$D29,ConditionRatings!$Q$4:$Q$147,"Yes")/E29) | J29: =IF(COUNT(G29:I29)=3,TEXT(G29,"0.00")&" ["&TEXT(H29,"0.00")&", "&TEXT(I29,"0.00")&"]","")
A30: Q5_SYNCHRONY | B30: 虚实同步性 | C30: EgoAnchor | D30: 游戏手柄 | E30: =COUNTIFS(ConditionRatings!$H$4:$H$147,$C30,ConditionRatings!$D$4:$D$147,$D30,ConditionRatings!$Q$4:$Q$147,"Yes",ConditionRatings!$W$4:$W$147,">=1") -> 0 | F30: =IF(E30=0,"",SUMIFS(ConditionRatings!$W$4:$W$147,ConditionRatings!$H$4:$H$147,$C30,ConditionRatings!$D$4:$D$147,$D30,ConditionRatings!$Q$4:$Q$147,"Yes")/E30) | J30: =IF(COUNT(G30:I30)=3,TEXT(G30,"0.00")&" ["&TEXT(H30,"0.00")&", "&TEXT(I30,"0.00")&"]","")
A31: Q5_SYNCHRONY | B31: 虚实同步性 | C31: One-Euro | D31: 无线鼠标 | E31: =COUNTIFS(ConditionRatings!$H$4:$H$147,$C31,ConditionRatings!$D$4:$D$147,$D31,ConditionRatings!$Q$4:$Q$147,"Yes",ConditionRatings!$W$4:$W$147,">=1") -> 0 | F31: =IF(E31=0,"",SUMIFS(ConditionRatings!$W$4:$W$147,ConditionRatings!$H$4:$H$147,$C31,ConditionRatings!$D$4:$D$147,$D31,ConditionRatings!$Q$4:$Q$147,"Yes")/E31) | J31: =IF(COUNT(G31:I31)=3,TEXT(G31,"0.00")&" ["&TEXT(H31,"0.00")&", "&TEXT(I31,"0.00")&"]","")
A32: Q5_SYNCHRONY | B32: 虚实同步性 | C32: One-Euro | D32: 固定闭合订书机 | E32: =COUNTIFS(ConditionRatings!$H$4:$H$147,$C32,ConditionRatings!$D$4:$D$147,$D32,ConditionRatings!$Q$4:$Q$147,"Yes",ConditionRatings!$W$4:$W$147,">=1") -> 0 | F32: =IF(E32=0,"",SUMIFS(ConditionRatings!$W$4:$W$147,ConditionRatings!$H$4:$H$147,$C32,ConditionRatings!$D$4:$D$147,$D32,ConditionRatings!$Q$4:$Q$147,"Yes")/E32) | J32: =IF(COUNT(G32:I32)=3,TEXT(G32,"0.00")&" ["&TEXT(H32,"0.00")&", "&TEXT(I32,"0.00")&"]","")
A33: Q5_SYNCHRONY | B33: 虚实同步性 | C33: One-Euro | D33: 游戏手柄 | E33: =COUNTIFS(ConditionRatings!$H$4:$H$147,$C33,ConditionRatings!$D$4:$D$147,$D33,ConditionRatings!$Q$4:$Q$147,"Yes",ConditionRatings!$W$4:$W$147,">=1") -> 0 | F33: =IF(E33=0,"",SUMIFS(ConditionRatings!$W$4:$W$147,ConditionRatings!$H$4:$H$147,$C33,ConditionRatings!$D$4:$D$147,$D33,ConditionRatings!$Q$4:$Q$147,"Yes")/E33) | J33: =IF(COUNT(G33:I33)=3,TEXT(G33,"0.00")&" ["&TEXT(H33,"0.00")&", "&TEXT(I33,"0.00")&"]","")
A34: Q6_RELIANCE | B34: 依赖意愿 | C34: EgoAnchor | D34: 无线鼠标 | E34: =COUNTIFS(ConditionRatings!$H$4:$H$147,$C34,ConditionRatings!$D$4:$D$147,$D34,ConditionRatings!$Q$4:$Q$147,"Yes",ConditionRatings!$X$4:$X$147,">=1") -> 0 | F34: =IF(E34=0,"",SUMIFS(ConditionRatings!$X$4:$X$147,ConditionRatings!$H$4:$H$147,$C34,ConditionRatings!$D$4:$D$147,$D34,ConditionRatings!$Q$4:$Q$147,"Yes")/E34) | J34: =IF(COUNT(G34:I34)=3,TEXT(G34,"0.00")&" ["&TEXT(H34,"0.00")&", "&TEXT(I34,"0.00")&"]","")
A35: Q6_RELIANCE | B35: 依赖意愿 | C35: EgoAnchor | D35: 固定闭合订书机 | E35: =COUNTIFS(ConditionRatings!$H$4:$H$147,$C35,ConditionRatings!$D$4:$D$147,$D35,ConditionRatings!$Q$4:$Q$147,"Yes",ConditionRatings!$X$4:$X$147,">=1") -> 0 | F35: =IF(E35=0,"",SUMIFS(ConditionRatings!$X$4:$X$147,ConditionRatings!$H$4:$H$147,$C35,ConditionRatings!$D$4:$D$147,$D35,ConditionRatings!$Q$4:$Q$147,"Yes")/E35) | J35: =IF(COUNT(G35:I35)=3,TEXT(G35,"0.00")&" ["&TEXT(H35,"0.00")&", "&TEXT(I35,"0.00")&"]","")
A36: Q6_RELIANCE | B36: 依赖意愿 | C36: EgoAnchor | D36: 游戏手柄 | E36: =COUNTIFS(ConditionRatings!$H$4:$H$147,$C36,ConditionRatings!$D$4:$D$147,$D36,ConditionRatings!$Q$4:$Q$147,"Yes",ConditionRatings!$X$4:$X$147,">=1") -> 0 | F36: =IF(E36=0,"",SUMIFS(ConditionRatings!$X$4:$X$147,ConditionRatings!$H$4:$H$147,$C36,ConditionRatings!$D$4:$D$147,$D36,ConditionRatings!$Q$4:$Q$147,"Yes")/E36) | J36: =IF(COUNT(G36:I36)=3,TEXT(G36,"0.00")&" ["&TEXT(H36,"0.00")&", "&TEXT(I36,"0.00")&"]","")
A37: Q6_RELIANCE | B37: 依赖意愿 | C37: One-Euro | D37: 无线鼠标 | E37: =COUNTIFS(ConditionRatings!$H$4:$H$147,$C37,ConditionRatings!$D$4:$D$147,$D37,ConditionRatings!$Q$4:$Q$147,"Yes",ConditionRatings!$X$4:$X$147,">=1") -> 0 | F37: =IF(E37=0,"",SUMIFS(ConditionRatings!$X$4:$X$147,ConditionRatings!$H$4:$H$147,$C37,ConditionRatings!$D$4:$D$147,$D37,ConditionRatings!$Q$4:$Q$147,"Yes")/E37) | J37: =IF(COUNT(G37:I37)=3,TEXT(G37,"0.00")&" ["&TEXT(H37,"0.00")&", "&TEXT(I37,"0.00")&"]","")
