Workbook

Sheet README
A1: EgoAnchor 实验3正式采集与分析工作簿（v5：30题分层问卷，24名参与者）
A3: 本工作簿对应当前实验流程：3个物体 × 2种匿名方法 × 3个任务。问卷采用“验证子量表 + EgoAnchor特异诊断题 + 方法级信任/体验 + 最终偏好与开放反馈”的分层设计。黄色单元格为人工填写；绿色为预设信息；灰色为公式。正式采集开始后不要改变题目、评分端点、顺序平衡或主要分析家族。
A8: 步骤 | B8: 实验时点 | C8: 填写工作表 | D8: 填写内容 | E8: 每名参与者产生的数据 | F8: 备注
A9: 0 | B9: 参与者到达 | C9: Participants | D9: 同意书、人口学、经验、基线不适 | E9: 6个背景题 + 安全基线 | F9: 基线安全项不计入30个核心题干
A10: 1 | B10: 每个区块：静止任务后 | C10: TaskRatings | D10: T1 静止稳定性 | E10: 6个评分 | F10: 任务后立即填写
A11: 2 | B11: 每个区块：移动任务后 | C11: TaskRatings | D11: T2 运动附着一致性 | E11: 6个评分 | F11: 任务后立即填写
A12: 3 | B12: 每个区块：遮挡任务后 | C12: TaskRatings | D12: T3 遮挡恢复一致性 | E12: 6个评分 | F12: 任务后立即填写
A13: 4 | B13: 每个方法×物体区块结束 | C13: BlockRatings_AQ | D13: Embedding Quality 3项 + Interaction Quality 3项 | E13: 36个评分 | F13: 每区块6项
A14: 5 | B14: 全部6个区块结束 | C14: MethodRatings | D14: S-TIAS 3项 + CRIQ 3项 + CIQ 2项 + SB1 | E14: 18个评分 | F14: 按预设A/B顺序分别评价两种方法
A15: 6 | B15: 摘下头显后 | C15: FinalFeedback | D15: 方法选择、偏好强度、区分信心、2个开放题、安全审计 | E15: 6个回答 | F15: 标签解码在参与者离场后完成
A18: 计分和分析冻结规则
A19: 1 | B19: 主要结局 | C19: Embedding Quality、Interaction Quality、adapted S-TIAS 三个完整3项结构。
A20: 2 | B20: 机制诊断 | C20: T1静止稳定、T2运动附着、T3恢复一致分别分析，不构造“锚定质量总分”。
A21: 3 | B21: 次要结局 | C21: CR1–CR3、CI1–CI2、SB1分别报告；CRIQ三项均值仅在内部一致性可接受时作补充。
A22: 4 | B22: 内部一致性 | C22: 只对EQ、IQ、S-TIAS以及探索性CRIQ三项报告当前样本α/ω；N=24不构成中文版量表验证。
A23: 5 | B23: 统计模型 | C23: EQ/IQ和任务单项优先采用 Method × Object 混合模型；S-TIAS和方法级题采用配对分析。
A24: 6 | B24: 安全边界 | C24: ARSQ/SSQ未作为主要结局；结束不适和运行时日志仅作安全、审计与操纵检验。
A25: 7 | B25: 禁止主张 | C25: 不报告任务时间/成功率改善，不声称绝对配准精度，不从实验3推出中介效应。
A28: 工作表导航
A29: Dashboard | B29: 完成度、平衡、缺失值和核心描述统计
A30: Questionnaire_Items | B30: 30个核心题目的中英文、来源、量尺、计分与重复次数
A31: Participants | B31: 人口学、纳入状态、平衡单元、方法映射和会话时间
A32: BlockSchedule | B32: 144个正式区块的物体、标签、条件和阶段时间记录
A33: TaskRatings / BlockRatings_AQ / MethodRatings | B33: 三层量化原始数据
A34: ParticipantConditionSummary / PairedDifferences | B34: 自动计算的子量表分、参与者条件均值和配对差
A35: Reliability / Analysis_Results / Analysis_ByObject | B35: 信度、推断分析和逐物体结果回填
A36: QualitativeCoding / Report_Tables | B36: 开放反馈编码和论文汇报表

Sheet Dashboard
A1: 实验3数据完成度与质量控制面板
A3: 采集完成度 | B3: 目标 | C3: 当前 | D3: 状态 | F3: 顺序平衡检查 | G3: 计数 | H3: 期望
A4: 计划参与者 | B4: 24 | C4: =COUNTA(Participants!A5:A28) -> 24 | D4: =IF(C4=B4,"完成","进行中") -> 完成 | F4: 首个实际方法：EgoAnchor | G4: =COUNTIF(Participants!X5:X28,"EgoAnchor") -> 12 | H4: 12
A5: 纳入分析参与者 | B5: 24 | C5: =COUNTIF(Participants!B5:B28,"是") -> 24 | D5: =IF(C5=B5,"完成","检查排除") -> 完成 | F5: 首个实际方法：One-Euro | G5: =COUNTIF(Participants!X5:X28,"One-Euro") -> 12 | H5: 12
A6: 签署同意 | B6: 24 | C6: =COUNTIF(Participants!C5:C28,"是") -> 0 | D6: =IF(C6=B6,"完成","缺失") -> 缺失 | F6: 方法A映射：EgoAnchor | G6: =COUNTIF(Participants!V5:V28,"EgoAnchor") -> 12 | H6: 12
A7: 任务评分完整区块 | B7: 144 | C7: =COUNTIF(TaskRatings!N5:N148,"完整") -> 0 | D7: =IF(C7=B7,"完成","缺失") -> 缺失 | F7: 方法A映射：One-Euro | G7: =COUNTIF(Participants!V5:V28,"One-Euro") -> 12 | H7: 12
A8: AQ评分完整区块 | B8: 144 | C8: =COUNTIF(BlockRatings_AQ!Q5:Q148,"完整") -> 0 | D8: =IF(C8=B8,"完成","缺失") -> 缺失 | F8: 标签序列S1 | G8: =COUNTIF(Participants!Q5:Q28,"S1") -> 12 | H8: 12
A9: 方法级问卷完整 | B9: 48 | C9: =COUNTIF(MethodRatings!Q5:Q52,"完整") -> 0 | D9: =IF(C9=B9,"完成","缺失") -> 缺失 | F9: 标签序列S2 | G9: =COUNTIF(Participants!Q5:Q28,"S2") -> 12 | H9: 12
A10: 最终反馈完整 | B10: 24 | C10: =COUNTIF(FinalFeedback!K5:K28,"完整") -> 0 | D10: =IF(C10=B10,"完成","缺失") -> 缺失
A13: 数据质量检查 | B13: 当前值 | C13: 可接受标准 | D13: 处理 | F13: 核心描述统计 | G13: One-Euro均值 | H13: EgoAnchor均值
A14: 任务评分超出1–7范围 | B14: =COUNT(TaskRatings!H5:H148)-COUNTIFS(TaskRatings!H5:H148,">=1",TaskRatings!H5:H148,"<=7")+COUNT(TaskRatings!J5:J148)-COUNTIFS(TaskRatings!J5:J148,">=1",TaskRatings!J5:J148,"<=7")+COUNT(TaskRatings!L5:L148)-COUNTIFS(TaskRatings!L5:L148,">=1",TaskRatings!L5:L148,"<=7") -> 0 | C14: 0 | D14: 修正录入 | F14: Embedding Quality | G14: =IF(Analysis_Results!H5="","",Analysis_Results!H5) | H14: =IF(Analysis_Results!L5="","",Analysis_Results!L5)
A15: AQ评分超出1–7范围 | B15: =COUNT(BlockRatings_AQ!H5:J148)-COUNTIFS(BlockRatings_AQ!H5:J148,">=1",BlockRatings_AQ!H5:J148,"<=7")+COUNT(BlockRatings_AQ!L5:N148)-COUNTIFS(BlockRatings_AQ!L5:N148,">=1",BlockRatings_AQ!L5:N148,"<=7") -> 0 | C15: 0 | D15: 修正录入 | F15: Interaction Quality | G15: =IF(Analysis_Results!H6="","",Analysis_Results!H6) | H15: =IF(Analysis_Results!L6="","",Analysis_Results!L6)
A16: 方法级评分超出1–7范围 | B16: =COUNT(MethodRatings!E5:G52)-COUNTIFS(MethodRatings!E5:G52,">=1",MethodRatings!E5:G52,"<=7")+COUNT(MethodRatings!I5:O52)-COUNTIFS(MethodRatings!I5:O52,">=1",MethodRatings!I5:O52,"<=7") -> 0 | C16: 0 | D16: 修正录入 | F16: S-TIAS Trust | G16: =IF(Analysis_Results!H7="","",Analysis_Results!H7) | H16: =IF(Analysis_Results!L7="","",Analysis_Results!L7)
A17: 无效任务区块 | B17: =COUNTIF(TaskRatings!O5:O148,"否") -> 0 | C17: 0 | D17: 检查技术事件 | F17: T1 静止稳定 | G17: =IF(Analysis_Results!H8="","",Analysis_Results!H8) | H17: =IF(Analysis_Results!L8="","",Analysis_Results!L8)
A18: 无效AQ区块 | B18: =COUNTIF(BlockRatings_AQ!R5:R148,"否") -> 0 | C18: 0 | D18: 检查技术事件 | F18: T2 运动附着 | G18: =IF(Analysis_Results!H9="","",Analysis_Results!H9) | H18: =IF(Analysis_Results!L9="","",Analysis_Results!L9)
A19: 运行时技术问题 | B19: =COUNTIF(RuntimeAudit!U5:U148,"<>无") -> 0 | C19: 0 | D19: 审计并决定排除 | F19: T3 恢复一致 | G19: =IF(Analysis_Results!H10="","",Analysis_Results!H10) | H19: =IF(Analysis_Results!L10="","",Analysis_Results!L10)
A22: 提示：Dashboard 中的均值来自每位参与者在三个物体上的方法级平均。正式推断仍按 Analysis_Results 中的预注册模型执行：区块级量表与任务单项使用 Method × Object 混合模型；方法级量表使用配对分析。

Sheet Questionnaire_Items
A1: 30个核心题干：呈现时点、双语措辞、来源、计分与分析地位
A2: 正式施测前应完成英文原文核对、正向翻译、独立回译和6–8人认知访谈。Augmentation Quality、S-TIAS、CRIQ和CIQ条目均为对象锚定情境适配版本，不能称为未经修改的官方中文版。
A5: Item_ID | B5: 层级 | C5: 呈现时点 | D5: 简称 | E5: 中文题目 | F5: English item | G5: 量尺 | H5: 每人重复次数 | I5: 分析地位 | J5: 来源/属性 | K5: 计分 | L5: 备注/来源URL
A6: B1 | B6: 背景 | C6: 实验前 | D6: 年龄 | E6: 你的年龄是？ | F6: What is your age? | G6: 整数 | H6: 1次 | I6: 背景变量 | J6: 研究定制 | K6: 不计分 | L6: 年龄（岁）
A7: B2 | B7: 背景 | C7: 实验前 | D7: 性别 | E7: 你的性别是？ | F7: What is your gender? | G7: 分类 | H7: 1次 | I7: 背景变量 | J7: 研究定制 | K7: 不计分 | L7: 女/男/非二元或其他/不愿透露
A8: B3 | B8: 背景 | C8: 实验前 | D8: 主手 | E8: 你通常使用哪只手进行精细操作？ | F8: Which hand do you normally use for precise manipulation? | G8: 分类 | H8: 1次 | I8: 背景变量 | J8: 研究定制 | K8: 不计分 | L8: 右手/左手/双手均可
A9: B4 | B9: 背景 | C9: 实验前 | D9: 视力 | E9: 你的视力情况是？ | F9: What is your current vision status? | G9: 分类 | H9: 1次 | I9: 背景变量 | J9: 研究定制 | K9: 不计分 | L9: 正常/矫正后正常/其他
A10: B5 | B10: 背景 | C10: 实验前 | D10: VR/MR经验 | E10: 你此前使用 VR 或 MR 设备的频率如何？ | F10: How frequently have you previously used VR or MR devices? | G10: 有序分类 | H10: 1次 | I10: 背景变量 | J10: 研究定制 | K10: 不计分 | L10: 从未/1–5次/6–20次/超过20次/经常使用
A11: B6 | B11: 背景 | C11: 实验前 | D11: 真实物体MR经验 | E11: 你此前是否使用过需要操作真实物体的 AR/MR 应用？ | F11: Have you previously used an AR/MR application that required manipulating physical objects? | G11: 有序分类 | H11: 1次 | I11: 背景变量 | J11: 研究定制 | K11: 不计分 | L11: 从未/1–2次/数次/经常使用
A12: T1 | B12: 任务即时 | C12: 静止任务后 | D12: 静止稳定性 | E12: 在刚才的静止观察过程中，虚拟内容在真实物体上的位置保持稳定。 | F12: During the static observation, the virtual content remained stable relative to the physical object. | G12: 7点同意度 | H12: 6次 | I12: 机制诊断 | J12: EgoAnchor研究定制 | K12: 单项，不合成 | L12: 1=完全不同意；7=完全同意
A13: T2 | B13: 任务即时 | C13: 移动任务后 | D13: 运动附着一致性 | E13: 在拿起、移动和旋转物体时，虚拟内容始终附着在真实物体上的同一位置。 | F13: While I picked up, moved, and rotated the object, the virtual content remained attached to the same location on the physical object. | G13: 7点同意度 | H13: 6次 | I13: 机制诊断 | J13: EgoAnchor研究定制 | K13: 单项，不合成 | L13: 避免与“运动平滑”混淆
A14: T3 | B14: 任务即时 | C14: 遮挡任务后 | D14: 遮挡恢复一致性 | E14: 遮挡移除后，虚拟内容恢复到了与真实物体一致的位置。 | F14: After the occlusion was removed, the virtual content recovered to a position consistent with the physical object. | G14: 7点同意度 | H14: 6次 | I14: 机制诊断 | J14: EgoAnchor研究定制 | K14: 单项，不合成 | L14: 1=完全不同意；7=完全同意
A15: EQ1 | B15: 区块量表 | C15: 每个方法×物体区块后 | D15: 虚实融合 | E15: 虚拟内容与真实物体及周围现实元素自然地融合在一起。 | F15: The virtual content blended naturally with the physical object and surrounding real-world elements. | G15: 7点同意度 | H15: 6次 | I15: 主要结局 | J15: 改编自 Augmentation Quality: Embedding Quality | K15: EQ1–EQ3均值 | L15: https://doi.org/10.1007/s11747-025-01108-2
A16: EQ2 | B16: 区块量表 | C16: 每个方法×物体区块后 | D16: 空间嵌入 | E16: 虚拟内容看起来被恰当地嵌入在真实物体上。 | F16: The virtual content appeared to be appropriately embedded in the physical object. | G16: 7点同意度 | H16: 6次 | I16: 主要结局 | J16: 改编自 Augmentation Quality: Embedding Quality | K16: EQ1–EQ3均值 | L16: 最小语境替换
... A35: F6 | B35: 最终比较 | C35: 实验结束 | D35: 结束不适 | E35: 与实验开始前相比，你目前是否感到额外的不适？ | F35: Compared with before the experiment, are you currently experiencing any additional discomfort? | G35: 分类 | H35: 1次 | I35: 安全审计 | J35: 研究定制 | K35: 不作条件比较 | L35: 无/轻微/中等/明显/中止

Sheet Participants
A1: 参与者信息、会话记录与平衡分配（24名）
A2: 黄色列由实验员填写；绿色列为预设平衡信息；灰色列为公式。方法A/B映射仅供实验员使用，不能向参与者展示。方法级问卷顺序由标签序列平衡：S1为A→B，S2为B→A。
A4: Participant_ID | B4: 纳入分析 | C4: 签署同意 | D4: 年龄 | E4: 性别 | F4: 主手 | G4: 视力情况 | H4: VR/MR经验 | I4: 真实物体MR经验 | J4: 基线不适 | K4: 基线备注 | L4: 会话开始 | M4: 会话结束 | N4: 会话时长_min | O4: 平衡单元 | P4: 物体排列ID | Q4: 标签序列 | R4: 物体1 | S4: 物体2 | T4: 物体3 | U4: 区块内标签顺序 | V4: 方法A=（保密） | W4: 方法B=（保密） | X4: 首个实际方法 | Y4: 方法级问卷顺序 | Z4: 退出/技术问题 | AA4: 备注
A5: P001 | B5: 是 | N5: =IF(AND(L5<>"",M5<>""),(M5-L5)*1440,"") | O5: P1-S1-EA | P5: 1 | Q5: S1 | R5: 鼠标 | S5: 固定订书机 | T5: 游戏手柄 | U5: A-B / B-A / A-B | V5: EgoAnchor | W5: One-Euro | X5: EgoAnchor | Y5: 方法A → 方法B | Z5: 无
A6: P002 | B6: 是 | N6: =IF(AND(L6<>"",M6<>""),(M6-L6)*1440,"") | O6: P2-S1-EA | P6: 2 | Q6: S1 | R6: 鼠标 | S6: 游戏手柄 | T6: 固定订书机 | U6: A-B / B-A / A-B | V6: EgoAnchor | W6: One-Euro | X6: EgoAnchor | Y6: 方法A → 方法B | Z6: 无
A7: P003 | B7: 是 | N7: =IF(AND(L7<>"",M7<>""),(M7-L7)*1440,"") | O7: P3-S1-EA | P7: 3 | Q7: S1 | R7: 固定订书机 | S7: 鼠标 | T7: 游戏手柄 | U7: A-B / B-A / A-B | V7: EgoAnchor | W7: One-Euro | X7: EgoAnchor | Y7: 方法A → 方法B | Z7: 无
A8: P004 | B8: 是 | N8: =IF(AND(L8<>"",M8<>""),(M8-L8)*1440,"") | O8: P4-S1-EA | P8: 4 | Q8: S1 | R8: 固定订书机 | S8: 游戏手柄 | T8: 鼠标 | U8: A-B / B-A / A-B | V8: EgoAnchor | W8: One-Euro | X8: EgoAnchor | Y8: 方法A → 方法B | Z8: 无
A9: P005 | B9: 是 | N9: =IF(AND(L9<>"",M9<>""),(M9-L9)*1440,"") | O9: P5-S1-EA | P9: 5 | Q9: S1 | R9: 游戏手柄 | S9: 鼠标 | T9: 固定订书机 | U9: A-B / B-A / A-B | V9: EgoAnchor | W9: One-Euro | X9: EgoAnchor | Y9: 方法A → 方法B | Z9: 无
A10: P006 | B10: 是 | N10: =IF(AND(L10<>"",M10<>""),(M10-L10)*1440,"") | O10: P6-S1-EA | P10: 6 | Q10: S1 | R10: 游戏手柄 | S10: 固定订书机 | T10: 鼠标 | U10: A-B / B-A / A-B | V10: EgoAnchor | W10: One-Euro | X10: EgoAnchor | Y10: 方法A → 方法B | Z10: 无
A11: P007 | B11: 是 | N11: =IF(AND(L11<>"",M11<>""),(M11-L11)*1440,"") | O11: P1-S2-EA | P11: 1 | Q11: S2 | R11: 鼠标 | S11: 固定订书机 | T11: 游戏手柄 | U11: B-A / A-B / B-A | V11: EgoAnchor | W11: One-Euro | X11: One-Euro | Y11: 方法B → 方法A | Z11: 无
A12: P008 | B12: 是 | N12: =IF(AND(L12<>"",M12<>""),(M12-L12)*1440,"") | O12: P2-S2-EA | P12: 2 | Q12: S2 | R12: 鼠标 | S12: 游戏手柄 | T12: 固定订书机 | U12: B-A / A-B / B-A | V12: EgoAnchor | W12: One-Euro | X12: One-Euro | Y12: 方法B → 方法A | Z12: 无
A13: P009 | B13: 是 | N13: =IF(AND(L13<>"",M13<>""),(M13-L13)*1440,"") | O13: P3-S2-EA | P13: 3 | Q13: S2 | R13: 固定订书机 | S13: 鼠标 | T13: 游戏手柄 | U13: B-A / A-B / B-A | V13: EgoAnchor | W13: One-Euro | X13: One-Euro | Y13: 方法B → 方法A | Z13: 无
A14: P010 | B14: 是 | N14: =IF(AND(L14<>"",M14<>""),(M14-L14)*1440,"") | O14: P4-S2-EA | P14: 4 | Q14: S2 | R14: 固定订书机 | S14: 游戏手柄 | T14: 鼠标 | U14: B-A / A-B / B-A | V14: EgoAnchor | W14: One-Euro | X14: One-Euro | Y14: 方法B → 方法A | Z14: 无
A15: P011 | B15: 是 | N15: =IF(AND(L15<>"",M15<>""),(M15-L15)*1440,"") | O15: P5-S2-EA | P15: 5 | Q15: S2 | R15: 游戏手柄 | S15: 鼠标 | T15: 固定订书机 | U15: B-A / A-B / B-A | V15: EgoAnchor | W15: One-Euro | X15: One-Euro | Y15: 方法B → 方法A | Z15: 无
A16: P012 | B16: 是 | N16: =IF(AND(L16<>"",M16<>""),(M16-L16)*1440,"") | O16: P6-S2-EA | P16: 6 | Q16: S2 | R16: 游戏手柄 | S16: 固定订书机 | T16: 鼠标 | U16: B-A / A-B / B-A | V16: EgoAnchor | W16: One-Euro | X16: One-Euro | Y16: 方法B → 方法A | Z16: 无
... A28: P024 | B28: 是 | N28: =IF(AND(L28<>"",M28<>""),(M28-L28)*1440,"") | O28: P6-S2-OE | P28: 6 | Q28: S2 | R28: 游戏手柄 | S28: 固定订书机 | T28: 鼠标 | U28: B-A / A-B / B-A | V28: One-Euro | W28: EgoAnchor | X28: EgoAnchor | Y28: 方法B → 方法A | Z28: 无

Sheet BlockSchedule
A1: 正式区块顺序与阶段时间记录（144个区块）
A2: 每个区块依次完成：静止观察 → T1 → 拿起/移动/旋转/放置 → T2 → 遮挡/恢复 → T3 → AQ六项。Block_Complete 由 TaskRatings 和 BlockRatings_AQ 的完成标记自动生成。
A4: Participant_ID | B4: Block_Index | C4: 平衡单元 | D4: Object_Position | E4: Object | F4: Object_Key | G4: Shown_Label | H4: Condition | I4: Cond_Pos_In_Object | J4: Method_Exposure_No | K4: Static_Start | L4: Static_End | M4: Move_Start | N4: Move_End | O4: Occlusion_Start | P4: Occlusion_End | Q4: AQ_Start | R4: AQ_End | S4: Block_End | T4: Operator | U4: Block_Complete | V4: Notes
A5: P001 | B5: 1 | C5: P1-S1-EA | D5: 1 | E5: 鼠标 | F5: blue_mouse | G5: 方法A | H5: EgoAnchor | I5: 1 | J5: 1 | U5: =IF(AND(TaskRatings!N5="完整",BlockRatings_AQ!Q5="完整"),"完整","未完成") -> 未完成
A6: P001 | B6: 2 | C6: P1-S1-EA | D6: 1 | E6: 鼠标 | F6: blue_mouse | G6: 方法B | H6: One-Euro | I6: 2 | J6: 1 | U6: =IF(AND(TaskRatings!N6="完整",BlockRatings_AQ!Q6="完整"),"完整","未完成") -> 未完成
A7: P001 | B7: 3 | C7: P1-S1-EA | D7: 2 | E7: 固定订书机 | F7: stapler | G7: 方法B | H7: One-Euro | I7: 1 | J7: 2 | U7: =IF(AND(TaskRatings!N7="完整",BlockRatings_AQ!Q7="完整"),"完整","未完成") -> 未完成
A8: P001 | B8: 4 | C8: P1-S1-EA | D8: 2 | E8: 固定订书机 | F8: stapler | G8: 方法A | H8: EgoAnchor | I8: 2 | J8: 2 | U8: =IF(AND(TaskRatings!N8="完整",BlockRatings_AQ!Q8="完整"),"完整","未完成") -> 未完成
A9: P001 | B9: 5 | C9: P1-S1-EA | D9: 3 | E9: 游戏手柄 | F9: gamepad | G9: 方法A | H9: EgoAnchor | I9: 1 | J9: 3 | U9: =IF(AND(TaskRatings!N9="完整",BlockRatings_AQ!Q9="完整"),"完整","未完成") -> 未完成
A10: P001 | B10: 6 | C10: P1-S1-EA | D10: 3 | E10: 游戏手柄 | F10: gamepad | G10: 方法B | H10: One-Euro | I10: 2 | J10: 3 | U10: =IF(AND(TaskRatings!N10="完整",BlockRatings_AQ!Q10="完整"),"完整","未完成") -> 未完成
A11: P002 | B11: 1 | C11: P2-S1-EA | D11: 1 | E11: 鼠标 | F11: blue_mouse | G11: 方法A | H11: EgoAnchor | I11: 1 | J11: 1 | U11: =IF(AND(TaskRatings!N11="完整",BlockRatings_AQ!Q11="完整"),"完整","未完成") -> 未完成
A12: P002 | B12: 2 | C12: P2-S1-EA | D12: 1 | E12: 鼠标 | F12: blue_mouse | G12: 方法B | H12: One-Euro | I12: 2 | J12: 1 | U12: =IF(AND(TaskRatings!N12="完整",BlockRatings_AQ!Q12="完整"),"完整","未完成") -> 未完成
A13: P002 | B13: 3 | C13: P2-S1-EA | D13: 2 | E13: 游戏手柄 | F13: gamepad | G13: 方法B | H13: One-Euro | I13: 1 | J13: 2 | U13: =IF(AND(TaskRatings!N13="完整",BlockRatings_AQ!Q13="完整"),"完整","未完成") -> 未完成
A14: P002 | B14: 4 | C14: P2-S1-EA | D14: 2 | E14: 游戏手柄 | F14: gamepad | G14: 方法A | H14: EgoAnchor | I14: 2 | J14: 2 | U14: =IF(AND(TaskRatings!N14="完整",BlockRatings_AQ!Q14="完整"),"完整","未完成") -> 未完成
A15: P002 | B15: 5 | C15: P2-S1-EA | D15: 3 | E15: 固定订书机 | F15: stapler | G15: 方法A | H15: EgoAnchor | I15: 1 | J15: 3 | U15: =IF(AND(TaskRatings!N15="完整",BlockRatings_AQ!Q15="完整"),"完整","未完成") -> 未完成
A16: P002 | B16: 6 | C16: P2-S1-EA | D16: 3 | E16: 固定订书机 | F16: stapler | G16: 方法B | H16: One-Euro | I16: 2 | J16: 3 | U16: =IF(AND(TaskRatings!N16="完整",BlockRatings_AQ!Q16="完整"),"完整","未完成") -> 未完成
... A148: P024 | B148: 6 | C148: P6-S2-OE | D148: 3 | E148: 鼠标 | F148: blue_mouse | G148: 方法A | H148: One-Euro | I148: 2 | J148: 3 | U148: =IF(AND(TaskRatings!N148="完整",BlockRatings_AQ!Q148="完整"),"完整","未完成") -> 未完成

Sheet TaskRatings
A1: 任务后即时评分：静止、运动附着与遮挡恢复（每位参与者6行）
A2: T1、T2、T3分别在对应任务结束后立即填写，取1–7整数。T2测量虚拟内容相对于真实物体的附着位置是否一致，不等同于AQ中的运动平滑性。
A4: Participant_ID | B4: Block_Index | C4: Object_Position | D4: Object | E4: Shown_Label | F4: Condition | G4: Cond_Pos | H4: T1_Static_Stability | I4: T1_Answer_Time | J4: T2_Motion_Attachment | K4: T2_Answer_Time | L4: T3_Recovery_Consistency | M4: T3_Answer_Time | N4: Rating_Complete | O4: Block_Valid | P4: Participant_Included | Q4: Technical_Issue | R4: Notes
A5: P001 | B5: 1 | C5: 1 | D5: 鼠标 | E5: 方法A | F5: EgoAnchor | G5: 1 | N5: =IF(COUNT(H5,J5,L5)=3,"完整","缺失") -> 缺失 | O5: 是 | P5: 是 | Q5: 无
A6: P001 | B6: 2 | C6: 1 | D6: 鼠标 | E6: 方法B | F6: One-Euro | G6: 2 | N6: =IF(COUNT(H6,J6,L6)=3,"完整","缺失") -> 缺失 | O6: 是 | P6: 是 | Q6: 无
A7: P001 | B7: 3 | C7: 2 | D7: 固定订书机 | E7: 方法B | F7: One-Euro | G7: 1 | N7: =IF(COUNT(H7,J7,L7)=3,"完整","缺失") -> 缺失 | O7: 是 | P7: 是 | Q7: 无
A8: P001 | B8: 4 | C8: 2 | D8: 固定订书机 | E8: 方法A | F8: EgoAnchor | G8: 2 | N8: =IF(COUNT(H8,J8,L8)=3,"完整","缺失") -> 缺失 | O8: 是 | P8: 是 | Q8: 无
A9: P001 | B9: 5 | C9: 3 | D9: 游戏手柄 | E9: 方法A | F9: EgoAnchor | G9: 1 | N9: =IF(COUNT(H9,J9,L9)=3,"完整","缺失") -> 缺失 | O9: 是 | P9: 是 | Q9: 无
A10: P001 | B10: 6 | C10: 3 | D10: 游戏手柄 | E10: 方法B | F10: One-Euro | G10: 2 | N10: =IF(COUNT(H10,J10,L10)=3,"完整","缺失") -> 缺失 | O10: 是 | P10: 是 | Q10: 无
A11: P002 | B11: 1 | C11: 1 | D11: 鼠标 | E11: 方法A | F11: EgoAnchor | G11: 1 | N11: =IF(COUNT(H11,J11,L11)=3,"完整","缺失") -> 缺失 | O11: 是 | P11: 是 | Q11: 无
A12: P002 | B12: 2 | C12: 1 | D12: 鼠标 | E12: 方法B | F12: One-Euro | G12: 2 | N12: =IF(COUNT(H12,J12,L12)=3,"完整","缺失") -> 缺失 | O12: 是 | P12: 是 | Q12: 无
A13: P002 | B13: 3 | C13: 2 | D13: 游戏手柄 | E13: 方法B | F13: One-Euro | G13: 1 | N13: =IF(COUNT(H13,J13,L13)=3,"完整","缺失") -> 缺失 | O13: 是 | P13: 是 | Q13: 无
A14: P002 | B14: 4 | C14: 2 | D14: 游戏手柄 | E14: 方法A | F14: EgoAnchor | G14: 2 | N14: =IF(COUNT(H14,J14,L14)=3,"完整","缺失") -> 缺失 | O14: 是 | P14: 是 | Q14: 无
A15: P002 | B15: 5 | C15: 3 | D15: 固定订书机 | E15: 方法A | F15: EgoAnchor | G15: 1 | N15: =IF(COUNT(H15,J15,L15)=3,"完整","缺失") -> 缺失 | O15: 是 | P15: 是 | Q15: 无
A16: P002 | B16: 6 | C16: 3 | D16: 固定订书机 | E16: 方法B | F16: One-Euro | G16: 2 | N16: =IF(COUNT(H16,J16,L16)=3,"完整","缺失") -> 缺失 | O16: 是 | P16: 是 | Q16: 无
... A148: P024 | B148: 6 | C148: 3 | D148: 鼠标 | E148: 方法A | F148: One-Euro | G148: 2 | N148: =IF(COUNT(H148,J148,L148)=3,"完整","缺失") -> 缺失 | O148: 是 | P148: 是 | Q148: 无

Sheet BlockRatings_AQ
A1: 区块级 Augmentation Quality 评分：Embedding 与 Interaction（144行）
A2: 每个方法×物体区块的三个任务完成后填写6项。K列和O列自动计算完整三项均值；若任一项目缺失则子量表分为空。正式分析保留单项，并以子量表均值作为主要结局。
A4: Participant_ID | B4: Block_Index | C4: Object_Position | D4: Object | E4: Shown_Label | F4: Condition | G4: Cond_Pos | H4: EQ1_Fusion | I4: EQ2_Embedded | J4: EQ3_Scale_Spatial | K4: EmbeddingQuality_Mean | L4: IQ1_Intuitive | M4: IQ2_Prompt_Response | N4: IQ3_Smooth_Motion | O4: InteractionQuality_Mean | P4: Missing_Item_Count | Q4: Rating_Complete | R4: Block_Valid | S4: Participant_Included | T4: Technical_Issue | U4: Notes
A5: P001 | B5: 1 | C5: 1 | D5: 鼠标 | E5: 方法A | F5: EgoAnchor | G5: 1 | K5: =IF(COUNT(H5:J5)=3,AVERAGE(H5:J5),"") | O5: =IF(COUNT(L5:N5)=3,AVERAGE(L5:N5),"") | P5: =6-COUNT(H5:J5,L5:N5) -> 6 | Q5: =IF(P5=0,"完整","缺失") -> 缺失 | R5: 是 | S5: 是 | T5: 无
A6: P001 | B6: 2 | C6: 1 | D6: 鼠标 | E6: 方法B | F6: One-Euro | G6: 2 | K6: =IF(COUNT(H6:J6)=3,AVERAGE(H6:J6),"") | O6: =IF(COUNT(L6:N6)=3,AVERAGE(L6:N6),"") | P6: =6-COUNT(H6:J6,L6:N6) -> 6 | Q6: =IF(P6=0,"完整","缺失") -> 缺失 | R6: 是 | S6: 是 | T6: 无
A7: P001 | B7: 3 | C7: 2 | D7: 固定订书机 | E7: 方法B | F7: One-Euro | G7: 1 | K7: =IF(COUNT(H7:J7)=3,AVERAGE(H7:J7),"") | O7: =IF(COUNT(L7:N7)=3,AVERAGE(L7:N7),"") | P7: =6-COUNT(H7:J7,L7:N7) -> 6 | Q7: =IF(P7=0,"完整","缺失") -> 缺失 | R7: 是 | S7: 是 | T7: 无
A8: P001 | B8: 4 | C8: 2 | D8: 固定订书机 | E8: 方法A | F8: EgoAnchor | G8: 2 | K8: =IF(COUNT(H8:J8)=3,AVERAGE(H8:J8),"") | O8: =IF(COUNT(L8:N8)=3,AVERAGE(L8:N8),"") | P8: =6-COUNT(H8:J8,L8:N8) -> 6 | Q8: =IF(P8=0,"完整","缺失") -> 缺失 | R8: 是 | S8: 是 | T8: 无
A9: P001 | B9: 5 | C9: 3 | D9: 游戏手柄 | E9: 方法A | F9: EgoAnchor | G9: 1 | K9: =IF(COUNT(H9:J9)=3,AVERAGE(H9:J9),"") | O9: =IF(COUNT(L9:N9)=3,AVERAGE(L9:N9),"") | P9: =6-COUNT(H9:J9,L9:N9) -> 6 | Q9: =IF(P9=0,"完整","缺失") -> 缺失 | R9: 是 | S9: 是 | T9: 无
A10: P001 | B10: 6 | C10: 3 | D10: 游戏手柄 | E10: 方法B | F10: One-Euro | G10: 2 | K10: =IF(COUNT(H10:J10)=3,AVERAGE(H10:J10),"") | O10: =IF(COUNT(L10:N10)=3,AVERAGE(L10:N10),"") | P10: =6-COUNT(H10:J10,L10:N10) -> 6 | Q10: =IF(P10=0,"完整","缺失") -> 缺失 | R10: 是 | S10: 是 | T10: 无
A11: P002 | B11: 1 | C11: 1 | D11: 鼠标 | E11: 方法A | F11: EgoAnchor | G11: 1 | K11: =IF(COUNT(H11:J11)=3,AVERAGE(H11:J11),"") | O11: =IF(COUNT(L11:N11)=3,AVERAGE(L11:N11),"") | P11: =6-COUNT(H11:J11,L11:N11) -> 6 | Q11: =IF(P11=0,"完整","缺失") -> 缺失 | R11: 是 | S11: 是 | T11: 无
A12: P002 | B12: 2 | C12: 1 | D12: 鼠标 | E12: 方法B | F12: One-Euro | G12: 2 | K12: =IF(COUNT(H12:J12)=3,AVERAGE(H12:J12),"") | O12: =IF(COUNT(L12:N12)=3,AVERAGE(L12:N12),"") | P12: =6-COUNT(H12:J12,L12:N12) -> 6 | Q12: =IF(P12=0,"完整","缺失") -> 缺失 | R12: 是 | S12: 是 | T12: 无
A13: P002 | B13: 3 | C13: 2 | D13: 游戏手柄 | E13: 方法B | F13: One-Euro | G13: 1 | K13: =IF(COUNT(H13:J13)=3,AVERAGE(H13:J13),"") | O13: =IF(COUNT(L13:N13)=3,AVERAGE(L13:N13),"") | P13: =6-COUNT(H13:J13,L13:N13) -> 6 | Q13: =IF(P13=0,"完整","缺失") -> 缺失 | R13: 是 | S13: 是 | T13: 无
A14: P002 | B14: 4 | C14: 2 | D14: 游戏手柄 | E14: 方法A | F14: EgoAnchor | G14: 2 | K14: =IF(COUNT(H14:J14)=3,AVERAGE(H14:J14),"") | O14: =IF(COUNT(L14:N14)=3,AVERAGE(L14:N14),"") | P14: =6-COUNT(H14:J14,L14:N14) -> 6 | Q14: =IF(P14=0,"完整","缺失") -> 缺失 | R14: 是 | S14: 是 | T14: 无
A15: P002 | B15: 5 | C15: 3 | D15: 固定订书机 | E15: 方法A | F15: EgoAnchor | G15: 1 | K15: =IF(COUNT(H15:J15)=3,AVERAGE(H15:J15),"") | O15: =IF(COUNT(L15:N15)=3,AVERAGE(L15:N15),"") | P15: =6-COUNT(H15:J15,L15:N15) -> 6 | Q15: =IF(P15=0,"完整","缺失") -> 缺失 | R15: 是 | S15: 是 | T15: 无
A16: P002 | B16: 6 | C16: 3 | D16: 固定订书机 | E16: 方法B | F16: One-Euro | G16: 2 | K16: =IF(COUNT(H16:J16)=3,AVERAGE(H16:J16),"") | O16: =IF(COUNT(L16:N16)=3,AVERAGE(L16:N16),"") | P16: =6-COUNT(H16:J16,L16:N16) -> 6 | Q16: =IF(P16=0,"完整","缺失") -> 缺失 | R16: 是 | S16: 是 | T16: 无
... A148: P024 | B148: 6 | C148: 3 | D148: 鼠标 | E148: 方法A | F148: One-Euro | G148: 2 | K148: =IF(COUNT(H148:J148)=3,AVERAGE(H148:J148),"") | O148: =IF(COUNT(L148:N148)=3,AVERAGE(L148:N148),"") | P148: =6-COUNT(H148:J148,L148:N148) -> 6 | Q148: =IF(P148=0,"完整","缺失") -> 缺失 | R148: 是 | S148: 是 | T148: 无

Sheet MethodRatings
A1: 方法级总结问卷：S-TIAS、CRIQ、CIQ与稳定—响应平衡（48行）
A2: 全部6个区块完成后，按照 Participants 中的“方法级问卷顺序”分别评价方法A和B。S-TIAS均值是主要结局；CRIQ三项均值是探索性补充分，仅在内部一致性可接受时汇报。
A4: Participant_ID | B4: Rating_Order | C4: Shown_Label | D4: Condition | E4: ST1_Confidence | F4: ST2_Reliability | G4: ST3_Trust | H4: STIAS_Mean | I4: CR1_Plausibility | J4: CR2_Synchrony | K4: CR3_Responsiveness | L4: CRIQ_Exploratory_Mean | M4: CI1_RealWorld_Consistency | N4: CI2_Behaved_As_Expected | O4: SB1_Stability_Response_Balance | P4: Missing_Item_Count | Q4: Rating_Complete | R4: Participant_Included | S4: Technical_Issue | T4: Notes | U4: Questionnaire_Start | V4: Questionnaire_End | W4: Duration_s
A5: P001 | B5: 1 | C5: 方法A | D5: EgoAnchor | H5: =IF(COUNT(E5:G5)=3,AVERAGE(E5:G5),"") | L5: =IF(COUNT(I5:K5)=3,AVERAGE(I5:K5),"") | P5: =9-COUNT(E5:G5,I5:O5) -> 9 | Q5: =IF(P5=0,"完整","缺失") -> 缺失 | R5: 是 | S5: 无 | W5: =IF(AND(U5<>"",V5<>""),(V5-U5)*86400,"")
A6: P001 | B6: 2 | C6: 方法B | D6: One-Euro | H6: =IF(COUNT(E6:G6)=3,AVERAGE(E6:G6),"") | L6: =IF(COUNT(I6:K6)=3,AVERAGE(I6:K6),"") | P6: =9-COUNT(E6:G6,I6:O6) -> 9 | Q6: =IF(P6=0,"完整","缺失") -> 缺失 | R6: 是 | S6: 无 | W6: =IF(AND(U6<>"",V6<>""),(V6-U6)*86400,"")
A7: P002 | B7: 1 | C7: 方法A | D7: EgoAnchor | H7: =IF(COUNT(E7:G7)=3,AVERAGE(E7:G7),"") | L7: =IF(COUNT(I7:K7)=3,AVERAGE(I7:K7),"") | P7: =9-COUNT(E7:G7,I7:O7) -> 9 | Q7: =IF(P7=0,"完整","缺失") -> 缺失 | R7: 是 | S7: 无 | W7: =IF(AND(U7<>"",V7<>""),(V7-U7)*86400,"")
A8: P002 | B8: 2 | C8: 方法B | D8: One-Euro | H8: =IF(COUNT(E8:G8)=3,AVERAGE(E8:G8),"") | L8: =IF(COUNT(I8:K8)=3,AVERAGE(I8:K8),"") | P8: =9-COUNT(E8:G8,I8:O8) -> 9 | Q8: =IF(P8=0,"完整","缺失") -> 缺失 | R8: 是 | S8: 无 | W8: =IF(AND(U8<>"",V8<>""),(V8-U8)*86400,"")
A9: P003 | B9: 1 | C9: 方法A | D9: EgoAnchor | H9: =IF(COUNT(E9:G9)=3,AVERAGE(E9:G9),"") | L9: =IF(COUNT(I9:K9)=3,AVERAGE(I9:K9),"") | P9: =9-COUNT(E9:G9,I9:O9) -> 9 | Q9: =IF(P9=0,"完整","缺失") -> 缺失 | R9: 是 | S9: 无 | W9: =IF(AND(U9<>"",V9<>""),(V9-U9)*86400,"")
A10: P003 | B10: 2 | C10: 方法B | D10: One-Euro | H10: =IF(COUNT(E10:G10)=3,AVERAGE(E10:G10),"") | L10: =IF(COUNT(I10:K10)=3,AVERAGE(I10:K10),"") | P10: =9-COUNT(E10:G10,I10:O10) -> 9 | Q10: =IF(P10=0,"完整","缺失") -> 缺失 | R10: 是 | S10: 无 | W10: =IF(AND(U10<>"",V10<>""),(V10-U10)*86400,"")
A11: P004 | B11: 1 | C11: 方法A | D11: EgoAnchor | H11: =IF(COUNT(E11:G11)=3,AVERAGE(E11:G11),"") | L11: =IF(COUNT(I11:K11)=3,AVERAGE(I11:K11),"") | P11: =9-COUNT(E11:G11,I11:O11) -> 9 | Q11: =IF(P11=0,"完整","缺失") -> 缺失 | R11: 是 | S11: 无 | W11: =IF(AND(U11<>"",V11<>""),(V11-U11)*86400,"")
A12: P004 | B12: 2 | C12: 方法B | D12: One-Euro | H12: =IF(COUNT(E12:G12)=3,AVERAGE(E12:G12),"") | L12: =IF(COUNT(I12:K12)=3,AVERAGE(I12:K12),"") | P12: =9-COUNT(E12:G12,I12:O12) -> 9 | Q12: =IF(P12=0,"完整","缺失") -> 缺失 | R12: 是 | S12: 无 | W12: =IF(AND(U12<>"",V12<>""),(V12-U12)*86400,"")
A13: P005 | B13: 1 | C13: 方法A | D13: EgoAnchor | H13: =IF(COUNT(E13:G13)=3,AVERAGE(E13:G13),"") | L13: =IF(COUNT(I13:K13)=3,AVERAGE(I13:K13),"") | P13: =9-COUNT(E13:G13,I13:O13) -> 9 | Q13: =IF(P13=0,"完整","缺失") -> 缺失 | R13: 是 | S13: 无 | W13: =IF(AND(U13<>"",V13<>""),(V13-U13)*86400,"")
A14: P005 | B14: 2 | C14: 方法B | D14: One-Euro | H14: =IF(COUNT(E14:G14)=3,AVERAGE(E14:G14),"") | L14: =IF(COUNT(I14:K14)=3,AVERAGE(I14:K14),"") | P14: =9-COUNT(E14:G14,I14:O14) -> 9 | Q14: =IF(P14=0,"完整","缺失") -> 缺失 | R14: 是 | S14: 无 | W14: =IF(AND(U14<>"",V14<>""),(V14-U14)*86400,"")
A15: P006 | B15: 1 | C15: 方法A | D15: EgoAnchor | H15: =IF(COUNT(E15:G15)=3,AVERAGE(E15:G15),"") | L15: =IF(COUNT(I15:K15)=3,AVERAGE(I15:K15),"") | P15: =9-COUNT(E15:G15,I15:O15) -> 9 | Q15: =IF(P15=0,"完整","缺失") -> 缺失 | R15: 是 | S15: 无 | W15: =IF(AND(U15<>"",V15<>""),(V15-U15)*86400,"")
A16: P006 | B16: 2 | C16: 方法B | D16: One-Euro | H16: =IF(COUNT(E16:G16)=3,AVERAGE(E16:G16),"") | L16: =IF(COUNT(I16:K16)=3,AVERAGE(I16:K16),"") | P16: =9-COUNT(E16:G16,I16:O16) -> 9 | Q16: =IF(P16=0,"完整","缺失") -> 缺失 | R16: 是 | S16: 无 | W16: =IF(AND(U16<>"",V16<>""),(V16-U16)*86400,"")
... A52: P024 | B52: 2 | C52: 方法A | D52: One-Euro | H52: =IF(COUNT(E52:G52)=3,AVERAGE(E52:G52),"") | L52: =IF(COUNT(I52:K52)=3,AVERAGE(I52:K52),"") | P52: =9-COUNT(E52:G52,I52:O52) -> 9 | Q52: =IF(P52=0,"完整","缺失") -> 缺失 | R52: 是 | S52: 无 | W52: =IF(AND(U52<>"",V52<>""),(V52-U52)*86400,"")

Sheet FinalFeedback
A1: 最终方法选择、偏好强度、开放反馈与安全审计（24行）
A2: 参与者只看到方法A/B。Decoded_Choice在回答后自动依据Participants映射解码。开放反馈建议采用双编码；结束不适只作安全审计。
A4: Participant_ID | B4: Final_Choice_Label | C4: Decoded_Choice | D4: Preference_Strength_1_7 | E4: Difference_Confidence_1_7 | F4: Most_Noticeable_Difference | G4: Primary_Distrust_Factor | H4: End_Discomfort | I4: Participant_Included | J4: Interviewer_Notes | K4: Response_Complete
A5: P001 | C5: =IF(B5="方法A",VLOOKUP(A5,Participants!$A$5:$W$28,22,FALSE),IF(B5="方法B",VLOOKUP(A5,Participants!$A$5:$W$28,23,FALSE),IF(B5="无明显偏好","无明显偏好",""))) | I5: 是 | K5: =IF(AND(B5<>"",D5<>"",E5<>"",F5<>"",G5<>"",H5<>""),"完整","缺失") -> 缺失
A6: P002 | C6: =IF(B6="方法A",VLOOKUP(A6,Participants!$A$5:$W$28,22,FALSE),IF(B6="方法B",VLOOKUP(A6,Participants!$A$5:$W$28,23,FALSE),IF(B6="无明显偏好","无明显偏好",""))) | I6: 是 | K6: =IF(AND(B6<>"",D6<>"",E6<>"",F6<>"",G6<>"",H6<>""),"完整","缺失") -> 缺失
A7: P003 | C7: =IF(B7="方法A",VLOOKUP(A7,Participants!$A$5:$W$28,22,FALSE),IF(B7="方法B",VLOOKUP(A7,Participants!$A$5:$W$28,23,FALSE),IF(B7="无明显偏好","无明显偏好",""))) | I7: 是 | K7: =IF(AND(B7<>"",D7<>"",E7<>"",F7<>"",G7<>"",H7<>""),"完整","缺失") -> 缺失
A8: P004 | C8: =IF(B8="方法A",VLOOKUP(A8,Participants!$A$5:$W$28,22,FALSE),IF(B8="方法B",VLOOKUP(A8,Participants!$A$5:$W$28,23,FALSE),IF(B8="无明显偏好","无明显偏好",""))) | I8: 是 | K8: =IF(AND(B8<>"",D8<>"",E8<>"",F8<>"",G8<>"",H8<>""),"完整","缺失") -> 缺失
A9: P005 | C9: =IF(B9="方法A",VLOOKUP(A9,Participants!$A$5:$W$28,22,FALSE),IF(B9="方法B",VLOOKUP(A9,Participants!$A$5:$W$28,23,FALSE),IF(B9="无明显偏好","无明显偏好",""))) | I9: 是 | K9: =IF(AND(B9<>"",D9<>"",E9<>"",F9<>"",G9<>"",H9<>""),"完整","缺失") -> 缺失
A10: P006 | C10: =IF(B10="方法A",VLOOKUP(A10,Participants!$A$5:$W$28,22,FALSE),IF(B10="方法B",VLOOKUP(A10,Participants!$A$5:$W$28,23,FALSE),IF(B10="无明显偏好","无明显偏好",""))) | I10: 是 | K10: =IF(AND(B10<>"",D10<>"",E10<>"",F10<>"",G10<>"",H10<>""),"完整","缺失") -> 缺失
A11: P007 | C11: =IF(B11="方法A",VLOOKUP(A11,Participants!$A$5:$W$28,22,FALSE),IF(B11="方法B",VLOOKUP(A11,Participants!$A$5:$W$28,23,FALSE),IF(B11="无明显偏好","无明显偏好",""))) | I11: 是 | K11: =IF(AND(B11<>"",D11<>"",E11<>"",F11<>"",G11<>"",H11<>""),"完整","缺失") -> 缺失
A12: P008 | C12: =IF(B12="方法A",VLOOKUP(A12,Participants!$A$5:$W$28,22,FALSE),IF(B12="方法B",VLOOKUP(A12,Participants!$A$5:$W$28,23,FALSE),IF(B12="无明显偏好","无明显偏好",""))) | I12: 是 | K12: =IF(AND(B12<>"",D12<>"",E12<>"",F12<>"",G12<>"",H12<>""),"完整","缺失") -> 缺失
A13: P009 | C13: =IF(B13="方法A",VLOOKUP(A13,Participants!$A$5:$W$28,22,FALSE),IF(B13="方法B",VLOOKUP(A13,Participants!$A$5:$W$28,23,FALSE),IF(B13="无明显偏好","无明显偏好",""))) | I13: 是 | K13: =IF(AND(B13<>"",D13<>"",E13<>"",F13<>"",G13<>"",H13<>""),"完整","缺失") -> 缺失
A14: P010 | C14: =IF(B14="方法A",VLOOKUP(A14,Participants!$A$5:$W$28,22,FALSE),IF(B14="方法B",VLOOKUP(A14,Participants!$A$5:$W$28,23,FALSE),IF(B14="无明显偏好","无明显偏好",""))) | I14: 是 | K14: =IF(AND(B14<>"",D14<>"",E14<>"",F14<>"",G14<>"",H14<>""),"完整","缺失") -> 缺失
A15: P011 | C15: =IF(B15="方法A",VLOOKUP(A15,Participants!$A$5:$W$28,22,FALSE),IF(B15="方法B",VLOOKUP(A15,Participants!$A$5:$W$28,23,FALSE),IF(B15="无明显偏好","无明显偏好",""))) | I15: 是 | K15: =IF(AND(B15<>"",D15<>"",E15<>"",F15<>"",G15<>"",H15<>""),"完整","缺失") -> 缺失
A16: P012 | C16: =IF(B16="方法A",VLOOKUP(A16,Participants!$A$5:$W$28,22,FALSE),IF(B16="方法B",VLOOKUP(A16,Participants!$A$5:$W$28,23,FALSE),IF(B16="无明显偏好","无明显偏好",""))) | I16: 是 | K16: =IF(AND(B16<>"",D16<>"",E16<>"",F16<>"",G16<>"",H16<>""),"完整","缺失") -> 缺失
... A28: P024 | C28: =IF(B28="方法A",VLOOKUP(A28,Participants!$A$5:$W$28,22,FALSE),IF(B28="方法B",VLOOKUP(A28,Participants!$A$5:$W$28,23,FALSE),IF(B28="无明显偏好","无明显偏好",""))) | I28: 是 | K28: =IF(AND(B28<>"",D28<>"",E28<>"",F28<>"",G28<>"",H28<>""),"完整","缺失") -> 缺失

Sheet RuntimeAudit
A1: 运行时日志与技术审计（不作为用户体验因变量）
A2: 全部指标为自参考运行时日志，不是绝对配准误差。可用于检查两条件是否接收到可比的候选观测、遮挡是否进入预期生命周期状态，以及技术问题是否影响某个区块。
A4: Participant_ID | B4: Block_Index | C4: Object | D4: Shown_Label | E4: Condition | F4: Candidate_Rate_Hz | G4: VCD_Score_Median | H4: VCD_Admission_Rate | I4: Output_Availability | J4: Occlusion_Events | K4: Occlusion_Duration_s | L4: Occlusion_Lifecycle_State | M4: Server_Reacquire_Count | N4: StaticLock_Enter_Count | O4: Display_Frame_Increment_P95_mm | P4: Block_Duration_s | Q4: Static_Phase_Duration_s | R4: Move_Phase_Duration_s | S4: Occlusion_Phase_Duration_s | T4: AQ_Duration_s | U4: Technical_Issue | V4: Block_Valid | W4: Notes
A5: P001 | B5: 1 | C5: 鼠标 | D5: 方法A | E5: EgoAnchor | U5: 无 | V5: 是
A6: P001 | B6: 2 | C6: 鼠标 | D6: 方法B | E6: One-Euro | U6: 无 | V6: 是
A7: P001 | B7: 3 | C7: 固定订书机 | D7: 方法B | E7: One-Euro | U7: 无 | V7: 是
A8: P001 | B8: 4 | C8: 固定订书机 | D8: 方法A | E8: EgoAnchor | U8: 无 | V8: 是
A9: P001 | B9: 5 | C9: 游戏手柄 | D9: 方法A | E9: EgoAnchor | U9: 无 | V9: 是
A10: P001 | B10: 6 | C10: 游戏手柄 | D10: 方法B | E10: One-Euro | U10: 无 | V10: 是
A11: P002 | B11: 1 | C11: 鼠标 | D11: 方法A | E11: EgoAnchor | U11: 无 | V11: 是
A12: P002 | B12: 2 | C12: 鼠标 | D12: 方法B | E12: One-Euro | U12: 无 | V12: 是
A13: P002 | B13: 3 | C13: 游戏手柄 | D13: 方法B | E13: One-Euro | U13: 无 | V13: 是
A14: P002 | B14: 4 | C14: 游戏手柄 | D14: 方法A | E14: EgoAnchor | U14: 无 | V14: 是
A15: P002 | B15: 5 | C15: 固定订书机 | D15: 方法A | E15: EgoAnchor | U15: 无 | V15: 是
A16: P002 | B16: 6 | C16: 固定订书机 | D16: 方法B | E16: One-Euro | U16: 无 | V16: 是
... A148: P024 | B148: 6 | C148: 鼠标 | D148: 方法A | E148: One-Euro | U148: 无 | V148: 是

Sheet ParticipantConditionSummary
A1: 参与者×方法汇总分（自动计算；48行）
A2: 每名参与者先列EgoAnchor、再列One-Euro。任务和AQ项目在三个物体上取有效区块平均；方法级项目直接从MethodRatings提取。AB–AE为信度计算辅助总分。
A4: Participant_ID | B4: Condition | C4: Shown_Label | D4: Participant_Included | E4: Valid_Block_Count | F4: T1_Static_Mean | G4: T2_Motion_Mean | H4: T3_Recovery_Mean | I4: EQ1_Mean | J4: EQ2_Mean | K4: EQ3_Mean | L4: EmbeddingQuality_Mean | M4: IQ1_Mean | N4: IQ2_Mean | O4: IQ3_Mean | P4: InteractionQuality_Mean | Q4: ST1 | R4: ST2 | S4: ST3 | T4: STIAS_Mean | U4: CR1 | V4: CR2 | W4: CR3 | X4: CRIQ_Exploratory_Mean | Y4: CI1 | Z4: CI2 | AA4: SB1 | AB4: EQ_Item_Total | AC4: IQ_Item_Total | AD4: STIAS_Item_Total | AE4: CRIQ_Item_Total | AF4: Data_Complete
A5: P001 | B5: EgoAnchor | C5: =IF(B5=VLOOKUP(A5,Participants!$A$5:$W$28,22,FALSE),"方法A","方法B") -> 方法A | D5: =VLOOKUP(A5,Participants!$A$5:$B$28,2,FALSE) -> 是 | E5: =COUNTIFS(TaskRatings!$A$5:$A$148,A5,TaskRatings!$F$5:$F$148,B5,TaskRatings!$O$5:$O$148,"是") -> 3 | F5: =IFERROR(SUMIFS(TaskRatings!$H$5:$H$148,TaskRatings!$A$5:$A$148,A5,TaskRatings!$F$5:$F$148,B5,TaskRatings!$O$5:$O$148,"是",TaskRatings!$H$5:$H$148,">0")/COUNTIFS(TaskRatings!$A$5:$A$148,A5,TaskRatings!$F$5:$F$148,B5,TaskRatings!$O$5:$O$148,"是",TaskRatings!$H$5:$H$148,">0"),"") | G5: =IFERROR(SUMIFS(TaskRatings!$J$5:$J$148,TaskRatings!$A$5:$A$148,A5,TaskRatings!$F$5:$F$148,B5,TaskRatings!$O$5:$O$148,"是",TaskRatings!$J$5:$J$148,">0")/COUNTIFS(TaskRatings!$A$5:$A$148,A5,TaskRatings!$F$5:$F$148,B5,TaskRatings!$O$5:$O$148,"是",TaskRatings!$J$5:$J$148,">0"),"") | H5: =IFERROR(SUMIFS(TaskRatings!$L$5:$L$148,TaskRatings!$A$5:$A$148,A5,TaskRatings!$F$5:$F$148,B5,TaskRatings!$O$5:$O$148,"是",TaskRatings!$L$5:$L$148,">0")/COUNTIFS(TaskRatings!$A$5:$A$148,A5,TaskRatings!$F$5:$F$148,B5,TaskRatings!$O$5:$O$148,"是",TaskRatings!$L$5:$L$148,">0"),"") | I5: =IFERROR(SUMIFS(BlockRatings_AQ!$H$5:$H$148,BlockRatings_AQ!$A$5:$A$148,A5,BlockRatings_AQ!$F$5:$F$148,B5,BlockRatings_AQ!$R$5:$R$148,"是",BlockRatings_AQ!$H$5:$H$148,">0")/COUNTIFS(BlockRatings_AQ!$A$5:$A$148,A5,BlockRatings_AQ!$F$5:$F$148,B5,BlockRatings_AQ!$R$5:$R$148,"是",BlockRatings_AQ!$H$5:$H$148,">0"),"") | J5: =IFERROR(SUMIFS(BlockRatings_AQ!$I$5:$I$148,BlockRatings_AQ!$A$5:$A$148,A5,BlockRatings_AQ!$F$5:$F$148,B5,BlockRatings_AQ!$R$5:$R$148,"是",BlockRatings_AQ!$I$5:$I$148,">0")/COUNTIFS(BlockRatings_AQ!$A$5:$A$148,A5,BlockRatings_AQ!$F$5:$F$148,B5,BlockRatings_AQ!$R$5:$R$148,"是",BlockRatings_AQ!$I$5:$I$148,">0"),"") | K5: =IFERROR(SUMIFS(BlockRatings_AQ!$J$5:$J$148,BlockRatings_AQ!$A$5:$A$148,A5,BlockRatings_AQ!$F$5:$F$148,B5,BlockRatings_AQ!$R$5:$R$148,"是",BlockRatings_AQ!$J$5:$J$148,">0")/COUNTIFS(BlockRatings_AQ!$A$5:$A$148,A5,BlockRatings_AQ!$F$5:$F$148,B5,BlockRatings_AQ!$R$5:$R$148,"是",BlockRatings_AQ!$J$5:$J$148,">0"),"") | L5: =IF(COUNT(I5:K5)=3,AVERAGE(I5:K5),"") | M5: =IFERROR(SUMIFS(BlockRatings_AQ!$L$5:$L$148,BlockRatings_AQ!$A$5:$A$148,A5,BlockRatings_AQ!$F$5:$F$148,B5,BlockRatings_AQ!$R$5:$R$148,"是",BlockRatings_AQ!$L$5:$L$148,">0")/COUNTIFS(BlockRatings_AQ!$A$5:$A$148,A5,BlockRatings_AQ!$F$5:$F$148,B5,BlockRatings_AQ!$R$5:$R$148,"是",BlockRatings_AQ!$L$5:$L$148,">0"),"") | N5: =IFERROR(SUMIFS(BlockRatings_AQ!$M$5:$M$148,BlockRatings_AQ!$A$5:$A$148,A5,BlockRatings_AQ!$F$5:$F$148,B5,BlockRatings_AQ!$R$5:$R$148,"是",BlockRatings_AQ!$M$5:$M$148,">0")/COUNTIFS(BlockRatings_AQ!$A$5:$A$148,A5,BlockRatings_AQ!$F$5:$F$148,B5,BlockRatings_AQ!$R$5:$R$148,"是",BlockRatings_AQ!$M$5:$M$148,">0"),"") | O5: =IFERROR(SUMIFS(BlockRatings_AQ!$N$5:$N$148,BlockRatings_AQ!$A$5:$A$148,A5,BlockRatings_AQ!$F$5:$F$148,B5,BlockRatings_AQ!$R$5:$R$148,"是",BlockRatings_AQ!$N$5:$N$148,">0")/COUNTIFS(BlockRatings_AQ!$A$5:$A$148,A5,BlockRatings_AQ!$F$5:$F$148,B5,BlockRatings_AQ!$R$5:$R$148,"是",BlockRatings_AQ!$N$5:$N$148,">0"),"") | P5: =IF(COUNT(M5:O5)=3,AVERAGE(M5:O5),"") | Q5: =IFERROR(SUMIFS(MethodRatings!$E$5:$E$52,MethodRatings!$A$5:$A$52,A5,MethodRatings!$D$5:$D$52,B5,MethodRatings!$E$5:$E$52,">0")/COUNTIFS(MethodRatings!$A$5:$A$52,A5,MethodRatings!$D$5:$D$52,B5,MethodRatings!$E$5:$E$52,">0"),"") | R5: =IFERROR(SUMIFS(MethodRatings!$F$5:$F$52,MethodRatings!$A$5:$A$52,A5,MethodRatings!$D$5:$D$52,B5,MethodRatings!$F$5:$F$52,">0")/COUNTIFS(MethodRatings!$A$5:$A$52,A5,MethodRatings!$D$5:$D$52,B5,MethodRatings!$F$5:$F$52,">0"),"") | S5: =IFERROR(SUMIFS(MethodRatings!$G$5:$G$52,MethodRatings!$A$5:$A$52,A5,MethodRatings!$D$5:$D$52,B5,MethodRatings!$G$5:$G$52,">0")/COUNTIFS(MethodRatings!$A$5:$A$52,A5,MethodRatings!$D$5:$D$52,B5,MethodRatings!$G$5:$G$52,">0"),"") | T5: =IF(COUNT(Q5:S5)=3,AVERAGE(Q5:S5),"") | U5: =IFERROR(SUMIFS(MethodRatings!$I$5:$I$52,MethodRatings!$A$5:$A$52,A5,MethodRatings!$D$5:$D$52,B5,MethodRatings!$I$5:$I$52,">0")/COUNTIFS(MethodRatings!$A$5:$A$52,A5,MethodRatings!$D$5:$D$52,B5,MethodRatings!$I$5:$I$52,">0"),"") | V5: =IFERROR(SUMIFS(MethodRatings!$J$5:$J$52,MethodRatings!$A$5:$A$52,A5,MethodRatings!$D$5:$D$52,B5,MethodRatings!$J$5:$J$52,">0")/COUNTIFS(MethodRatings!$A$5:$A$52,A5,MethodRatings!$D$5:$D$52,B5,MethodRatings!$J$5:$J$52,">0"),"") | W5: =IFERROR(SUMIFS(MethodRatings!$K$5:$K$52,MethodRatings!$A$5:$A$52,A5,MethodRatings!$D$5:$D$52,B5,MethodRatings!$K$5:$K$52,">0")/COUNTIFS(MethodRatings!$A$5:$A$52,A5,MethodRatings!$D$5:$D$52,B5,MethodRatings!$K$5:$K$52,">0"),"") | X5: =IF(COUNT(U5:W5)=3,AVERAGE(U5:W5),"") | Y5: =IFERROR(SUMIFS(MethodRatings!$M$5:$M$52,MethodRatings!$A$5:$A$52,A5,MethodRatings!$D$5:$D$52,B5,MethodRatings!$M$5:$M$52,">0")/COUNTIFS(MethodRatings!$A$5:$A$52,A5,MethodRatings!$D$5:$D$52,B5,MethodRatings!$M$5:$M$52,">0"),"") | Z5: =IFERROR(SUMIFS(MethodRatings!$N$5:$N$52,MethodRatings!$A$5:$A$52,A5,MethodRatings!$D$5:$D$52,B5,MethodRatings!$N$5:$N$52,">0")/COUNTIFS(MethodRatings!$A$5:$A$52,A5,MethodRatings!$D$5:$D$52,B5,MethodRatings!$N$5:$N$52,">0"),"") | AA5: =IFERROR(SUMIFS(MethodRatings!$O$5:$O$52,MethodRatings!$A$5:$A$52,A5,MethodRatings!$D$5:$D$52,B5,MethodRatings!$O$5:$O$52,">0")/COUNTIFS(MethodRatings!$A$5:$A$52,A5,MethodRatings!$D$5:$D$52,B5,MethodRatings!$O$5:$O$52,">0"),"") | AB5: =IF(COUNT(I5:K5)=3,SUM(I5:K5),"") | AC5: =IF(COUNT(M5:O5)=3,SUM(M5:O5),"") | AD5: =IF(COUNT(Q5:S5)=3,SUM(Q5:S5),"") | AE5: =IF(COUNT(U5:W5)=3,SUM(U5:W5),"") | AF5: =IF((COUNT(F5:K5)+COUNT(M5:O5)+COUNT(Q5:S5)+COUNT(U5:W5)+COUNT(Y5:AA5))=18,"完整","缺失") -> 缺失
A6: P002 | B6: EgoAnchor | C6: =IF(B6=VLOOKUP(A6,Participants!$A$5:$W$28,22,FALSE),"方法A","方法B") -> 方法A | D6: =VLOOKUP(A6,Participants!$A$5:$B$28,2,FALSE) -> 是 | E6: =COUNTIFS(TaskRatings!$A$5:$A$148,A6,TaskRatings!$F$5:$F$148,B6,TaskRatings!$O$5:$O$148,"是") -> 3 | F6: =IFERROR(SUMIFS(TaskRatings!$H$5:$H$148,TaskRatings!$A$5:$A$148,A6,TaskRatings!$F$5:$F$148,B6,TaskRatings!$O$5:$O$148,"是",TaskRatings!$H$5:$H$148,">0")/COUNTIFS(TaskRatings!$A$5:$A$148,A6,TaskRatings!$F$5:$F$148,B6,TaskRatings!$O$5:$O$148,"是",TaskRatings!$H$5:$H$148,">0"),"") | G6: =IFERROR(SUMIFS(TaskRatings!$J$5:$J$148,TaskRatings!$A$5:$A$148,A6,TaskRatings!$F$5:$F$148,B6,TaskRatings!$O$5:$O$148,"是",TaskRatings!$J$5:$J$148,">0")/COUNTIFS(TaskRatings!$A$5:$A$148,A6,TaskRatings!$F$5:$F$148,B6,TaskRatings!$O$5:$O$148,"是",TaskRatings!$J$5:$J$148,">0"),"") | H6: =IFERROR(SUMIFS(TaskRatings!$L$5:$L$148,TaskRatings!$A$5:$A$148,A6,TaskRatings!$F$5:$F$148,B6,TaskRatings!$O$5:$O$148,"是",TaskRatings!$L$5:$L$148,">0")/COUNTIFS(TaskRatings!$A$5:$A$148,A6,TaskRatings!$F$5:$F$148,B6,TaskRatings!$O$5:$O$148,"是",TaskRatings!$L$5:$L$148,">0"),"") | I6: =IFERROR(SUMIFS(BlockRatings_AQ!$H$5:$H$148,BlockRatings_AQ!$A$5:$A$148,A6,BlockRatings_AQ!$F$5:$F$148,B6,BlockRatings_AQ!$R$5:$R$148,"是",BlockRatings_AQ!$H$5:$H$148,">0")/COUNTIFS(BlockRatings_AQ!$A$5:$A$148,A6,BlockRatings_AQ!$F$5:$F$148,B6,BlockRatings_AQ!$R$5:$R$148,"是",BlockRatings_AQ!$H$5:$H$148,">0"),"") | J6: =IFERROR(SUMIFS(BlockRatings_AQ!$I$5:$I$148,BlockRatings_AQ!$A$5:$A$148,A6,BlockRatings_AQ!$F$5:$F$148,B6,BlockRatings_AQ!$R$5:$R$148,"是",BlockRatings_AQ!$I$5:$I$148,">0")/COUNTIFS(BlockRatings_AQ!$A$5:$A$148,A6,BlockRatings_AQ!$F$5:$F$148,B6,BlockRatings_AQ!$R$5:$R$148,"是",BlockRatings_AQ!$I$5:$I$148,">0"),"") | K6: =IFERROR(SUMIFS(BlockRatings_AQ!$J$5:$J$148,BlockRatings_AQ!$A$5:$A$148,A6,BlockRatings_AQ!$F$5:$F$148,B6,BlockRatings_AQ!$R$5:$R$148,"是",BlockRatings_AQ!$J$5:$J$148,">0")/COUNTIFS(BlockRatings_AQ!$A$5:$A$148,A6,BlockRatings_AQ!$F$5:$F$148,B6,BlockRatings_AQ!$R$5:$R$148,"是",BlockRatings_AQ!$J$5:$J$148,">0"),"") | L6: =IF(COUNT(I6:K6)=3,AVERAGE(I6:K6),"") | M6: =IFERROR(SUMIFS(BlockRatings_AQ!$L$5:$L$148,BlockRatings_AQ!$A$5:$A$148,A6,BlockRatings_AQ!$F$5:$F$148,B6,BlockRatings_AQ!$R$5:$R$148,"是",BlockRatings_AQ!$L$5:$L$148,">0")/COUNTIFS(BlockRatings_AQ!$A$5:$A$148,A6,BlockRatings_AQ!$F$5:$F$148,B6,BlockRatings_AQ!$R$5:$R$148,"是",BlockRatings_AQ!$L$5:$L$148,">0"),"") | N6: =IFERROR(SUMIFS(BlockRatings_AQ!$M$5:$M$148,BlockRatings_AQ!$A$5:$A$148,A6,BlockRatings_AQ!$F$5:$F$148,B6,BlockRatings_AQ!$R$5:$R$148,"是",BlockRatings_AQ!$M$5:$M$148,">0")/COUNTIFS(BlockRatings_AQ!$A$5:$A$148,A6,BlockRatings_AQ!$F$5:$F$148,B6,BlockRatings_AQ!$R$5:$R$148,"是",BlockRatings_AQ!$M$5:$M$148,">0"),"") | O6: =IFERROR(SUMIFS(BlockRatings_AQ!$N$5:$N$148,BlockRatings_AQ!$A$5:$A$148,A6,BlockRatings_AQ!$F$5:$F$148,B6,BlockRatings_AQ!$R$5:$R$148,"是",BlockRatings_AQ!$N$5:$N$148,">0")/COUNTIFS(BlockRatings_AQ!$A$5:$A$148,A6,BlockRatings_AQ!$F$5:$F$148,B6,BlockRatings_AQ!$R$5:$R$148,"是",BlockRatings_AQ!$N$5:$N$148,">0"),"") | P6: =IF(COUNT(M6:O6)=3,AVERAGE(M6:O6),"") | Q6: =IFERROR(SUMIFS(MethodRatings!$E$5:$E$52,MethodRatings!$A$5:$A$52,A6,MethodRatings!$D$5:$D$52,B6,MethodRatings!$E$5:$E$52,">0")/COUNTIFS(MethodRatings!$A$5:$A$52,A6,MethodRatings!$D$5:$D$52,B6,MethodRatings!$E$5:$E$52,">0"),"") | R6: =IFERROR(SUMIFS(MethodRatings!$F$5:$F$52,MethodRatings!$A$5:$A$52,A6,MethodRatings!$D$5:$D$52,B6,MethodRatings!$F$5:$F$52,">0")/COUNTIFS(MethodRatings!$A$5:$A$52,A6,MethodRatings!$D$5:$D$52,B6,MethodRatings!$F$5:$F$52,">0"),"") | S6: =IFERROR(SUMIFS(MethodRatings!$G$5:$G$52,MethodRatings!$A$5:$A$52,A6,MethodRatings!$D$5:$D$52,B6,MethodRatings!$G$5:$G$52,">0")/COUNTIFS(MethodRatings!$A$5:$A$52,A6,MethodRatings!$D$5:$D$52,B6,MethodRatings!$G$5:$G$52,">0"),"") | T6: =IF(COUNT(Q6:S6)=3,AVERAGE(Q6:S6),"") | U6: =IFERROR(SUMIFS(MethodRatings!$I$5:$I$52,MethodRatings!$A$5:$A$52,A6,MethodRatings!$D$5:$D$52,B6,MethodRatings!$I$5:$I$52,">0")/COUNTIFS(MethodRatings!$A$5:$A$52,A6,MethodRatings!$D$5:$D$52,B6,MethodRatings!$I$5:$I$52,">0"),"") | V6: =IFERROR(SUMIFS(MethodRatings!$J$5:$J$52,MethodRatings!$A$5:$A$52,A6,MethodRatings!$D$5:$D$52,B6,MethodRatings!$J$5:$J$52,">0")/COUNTIFS(MethodRatings!$A$5:$A$52,A6,MethodRatings!$D$5:$D$52,B6,MethodRatings!$J$5:$J$52,">0"),"") | W6: =IFERROR(SUMIFS(MethodRatings!$K$5:$K$52,MethodRatings!$A$5:$A$52,A6,MethodRatings!$D$5:$D$52,B6,MethodRatings!$K$5:$K$52,">0")/COUNTIFS(MethodRatings!$A$5:$A$52,A6,MethodRatings!$D$5:$D$52,B6,MethodRatings!$K$5:$K$52,">0"),"") | X6: =IF(COUNT(U6:W6)=3,AVERAGE(U6:W6),"") | Y6: =IFERROR(SUMIFS(MethodRatings!$M$5:$M$52,MethodRatings!$A$5:$A$52,A6,MethodRatings!$D$5:$D$52,B6,MethodRatings!$M$5:$M$52,">0")/COUNTIFS(MethodRatings!$A$5:$A$52,A6,MethodRatings!$D$5:$D$52,B6,MethodRatings!$M$5:$M$52,">0"),"") | Z6: =IFERROR(SUMIFS(MethodRatings!$N$5:$N$52,MethodRatings!$A$5:$A$52,A6,MethodRatings!$D$5:$D$52,B6,MethodRatings!$N$5:$N$52,">0")/COUNTIFS(MethodRatings!$A$5:$A$52,A6,MethodRatings!$D$5:$D$52,B6,MethodRatings!$N$5:$N$52,">0"),"") | AA6: =IFERROR(SUMIFS(MethodRatings!$O$5:$O$52,MethodRatings!$A$5:$A$52,A6,MethodRatings!$D$5:$D$52,B6,MethodRatings!$O$5:$O$52,">0")/COUNTIFS(MethodRatings!$A$5:$A$52,A6,MethodRatings!$D$5:$D$52,B6,MethodRatings!$O$5:$O$52,">0"),"") | AB6: =IF(COUNT(I6:K6)=3,SUM(I6:K6),"") | AC6: =IF(COUNT(M6:O6)=3,SUM(M6:O6),"") | AD6: =IF(COUNT(Q6:S6)=3,SUM(Q6:S6),"") | AE6: =IF(COUNT(U6:W6)=3,SUM(U6:W6),"") | AF6: =IF((COUNT(F6:K6)+COUNT(M6:O6)+COUNT(Q6:S6)+COUNT(U6:W6)+COUNT(Y6:AA6))=18,"完整","缺失") -> 缺失
A7: P003 | B7: EgoAnchor | C7: =IF(B7=VLOOKUP(A7,Participants!$A$5:$W$28,22,FALSE),"方法A","方法B") -> 方法A | D7: =VLOOKUP(A7,Participants!$A$5:$B$28,2,FALSE) -> 是 | E7: =COUNTIFS(TaskRatings!$A$5:$A$148,A7,TaskRatings!$F$5:$F$148,B7,TaskRatings!$O$5:$O$148,"是") -> 3 | F7: =IFERROR(SUMIFS(TaskRatings!$H$5:$H$148,TaskRatings!$A$5:$A$148,A7,TaskRatings!$F$5:$F$148,B7,TaskRatings!$O$5:$O$148,"是",TaskRatings!$H$5:$H$148,">0")/COUNTIFS(TaskRatings!$A$5:$A$148,A7,TaskRatings!$F$5:$F$148,B7,TaskRatings!$O$5:$O$148,"是",TaskRatings!$H$5:$H$148,">0"),"") | G7: =IFERROR(SUMIFS(TaskRatings!$J$5:$J$148,TaskRatings!$A$5:$A$148,A7,TaskRatings!$F$5:$F$148,B7,TaskRatings!$O$5:$O$148,"是",TaskRatings!$J$5:$J$148,">0")/COUNTIFS(TaskRatings!$A$5:$A$148,A7,TaskRatings!$F$5:$F$148,B7,TaskRatings!$O$5:$O$148,"是",TaskRatings!$J$5:$J$148,">0"),"") | H7: =IFERROR(SUMIFS(TaskRatings!$L$5:$L$148,TaskRatings!$A$5:$A$148,A7,TaskRatings!$F$5:$F$148,B7,TaskRatings!$O$5:$O$148,"是",TaskRatings!$L$5:$L$148,">0")/COUNTIFS(TaskRatings!$A$5:$A$148,A7,TaskRatings!$F$5:$F$148,B7,TaskRatings!$O$5:$O$148,"是",TaskRatings!$L$5:$L$148,">0"),"") | I7: =IFERROR(SUMIFS(BlockRatings_AQ!$H$5:$H$148,BlockRatings_AQ!$A$5:$A$148,A7,BlockRatings_AQ!$F$5:$F$148,B7,BlockRatings_AQ!$R$5:$R$148,"是",BlockRatings_AQ!$H$5:$H$148,">0")/COUNTIFS(BlockRatings_AQ!$A$5:$A$148,A7,BlockRatings_AQ!$F$5:$F$148,B7,BlockRatings_AQ!$R$5:$R$148,"是",BlockRatings_AQ!$H$5:$H$148,">0"),"") | J7: =IFERROR(SUMIFS(BlockRatings_AQ!$I$5:$I$148,BlockRatings_AQ!$A$5:$A$148,A7,BlockRatings_AQ!$F$5:$F$148,B7,BlockRatings_AQ!$R$5:$R$148,"是",BlockRatings_AQ!$I$5:$I$148,">0")/COUNTIFS(BlockRatings_AQ!$A$5:$A$148,A7,BlockRatings_AQ!$F$5:$F$148,B7,BlockRatings_AQ!$R$5:$R$148,"是",BlockRatings_AQ!$I$5:$I$148,">0"),"") | K7: =IFERROR(SUMIFS(BlockRatings_AQ!$J$5:$J$148,BlockRatings_AQ!$A$5:$A$148,A7,BlockRatings_AQ!$F$5:$F$148,B7,BlockRatings_AQ!$R$5:$R$148,"是",BlockRatings_AQ!$J$5:$J$148,">0")/COUNTIFS(BlockRatings_AQ!$A$5:$A$148,A7,BlockRatings_AQ!$F$5:$F$148,B7,BlockRatings_AQ!$R$5:$R$148,"是",BlockRatings_AQ!$J$5:$J$148,">0"),"") | L7: =IF(COUNT(I7:K7)=3,AVERAGE(I7:K7),"") | M7: =IFERROR(SUMIFS(BlockRatings_AQ!$L$5:$L$148,BlockRatings_AQ!$A$5:$A$148,A7,BlockRatings_AQ!$F$5:$F$148,B7,BlockRatings_AQ!$R$5:$R$148,"是",BlockRatings_AQ!$L$5:$L$148,">0")/COUNTIFS(BlockRatings_AQ!$A$5:$A$148,A7,BlockRatings_AQ!$F$5:$F$148,B7,BlockRatings_AQ!$R$5:$R$148,"是",BlockRatings_AQ!$L$5:$L$148,">0"),"") | N7: =IFERROR(SUMIFS(BlockRatings_AQ!$M$5:$M$148,BlockRatings_AQ!$A$5:$A$148,A7,BlockRatings_AQ!$F$5:$F$148,B7,BlockRatings_AQ!$R$5:$R$148,"是",BlockRatings_AQ!$M$5:$M$148,">0")/COUNTIFS(BlockRatings_AQ!$A$5:$A$148,A7,BlockRatings_AQ!$F$5:$F$148,B7,BlockRatings_AQ!$R$5:$R$148,"是",BlockRatings_AQ!$M$5:$M$148,">0"),"") | O7: =IFERROR(SUMIFS(BlockRatings_AQ!$N$5:$N$148,BlockRatings_AQ!$A$5:$A$148,A7,BlockRatings_AQ!$F$5:$F$148,B7,BlockRatings_AQ!$R$5:$R$148,"是",BlockRatings_AQ!$N$5:$N$148,">0")/COUNTIFS(BlockRatings_AQ!$A$5:$A$148,A7,BlockRatings_AQ!$F$5:$F$148,B7,BlockRatings_AQ!$R$5:$R$148,"是",BlockRatings_AQ!$N$5:$N$148,">0"),"") | P7: =IF(COUNT(M7:O7)=3,AVERAGE(M7:O7),"") | Q7: =IFERROR(SUMIFS(MethodRatings!$E$5:$E$52,MethodRatings!$A$5:$A$52,A7,MethodRatings!$D$5:$D$52,B7,MethodRatings!$E$5:$E$52,">0")/COUNTIFS(MethodRatings!$A$5:$A$52,A7,MethodRatings!$D$5:$D$52,B7,MethodRatings!$E$5:$E$52,">0"),"") | R7: =IFERROR(SUMIFS(MethodRatings!$F$5:$F$52,MethodRatings!$A$5:$A$52,A7,MethodRatings!$D$5:$D$52,B7,MethodRatings!$F$5:$F$52,">0")/COUNTIFS(MethodRatings!$A$5:$A$52,A7,MethodRatings!$D$5:$D$52,B7,MethodRatings!$F$5:$F$52,">0"),"") | S7: =IFERROR(SUMIFS(MethodRatings!$G$5:$G$52,MethodRatings!$A$5:$A$52,A7,MethodRatings!$D$5:$D$52,B7,MethodRatings!$G$5:$G$52,">0")/COUNTIFS(MethodRatings!$A$5:$A$52,A7,MethodRatings!$D$5:$D$52,B7,MethodRatings!$G$5:$G$52,">0"),"") | T7: =IF(COUNT(Q7:S7)=3,AVERAGE(Q7:S7),"") | U7: =IFERROR(SUMIFS(MethodRatings!$I$5:$I$52,MethodRatings!$A$5:$A$52,A7,MethodRatings!$D$5:$D$52,B7,MethodRatings!$I$5:$I$52,">0")/COUNTIFS(MethodRatings!$A$5:$A$52,A7,MethodRatings!$D$5:$D$52,B7,MethodRatings!$I$5:$I$52,">0"),"") | V7: =IFERROR(SUMIFS(MethodRatings!$J$5:$J$52,MethodRatings!$A$5:$A$52,A7,MethodRatings!$D$5:$D$52,B7,MethodRatings!$J$5:$J$52,">0")/COUNTIFS(MethodRatings!$A$5:$A$52,A7,MethodRatings!$D$5:$D$52,B7,MethodRatings!$J$5:$J$52,">0"),"") | W7: =IFERROR(SUMIFS(MethodRatings!$K$5:$K$52,MethodRatings!$A$5:$A$52,A7,MethodRatings!$D$5:$D$52,B7,MethodRatings!$K$5:$K$52,">0")/COUNTIFS(MethodRatings!$A$5:$A$52,A7,MethodRatings!$D$5:$D$52,B7,MethodRatings!$K$5:$K$52,">0"),"") | X7: =IF(COUNT(U7:W7)=3,AVERAGE(U7:W7),"") | Y7: =IFERROR(SUMIFS(MethodRatings!$M$5:$M$52,MethodRatings!$A$5:$A$52,A7,MethodRatings!$D$5:$D$52,B7,MethodRatings!$M$5:$M$52,">0")/COUNTIFS(MethodRatings!$A$5:$A$52,A7,MethodRatings!$D$5:$D$52,B7,MethodRatings!$M$5:$M$52,">0"),"") | Z7: =IFERROR(SUMIFS(MethodRatings!$N$5:$N$52,MethodRatings!$A$5:$A$52,A7,MethodRatings!$D$5:$D$52,B7,MethodRatings!$N$5:$N$52,">0")/COUNTIFS(MethodRatings!$A$5:$A$52,A7,MethodRatings!$D$5:$D$52,B7,MethodRatings!$N$5:$N$52,">0"),"") | AA7: =IFERROR(SUMIFS(MethodRatings!$O$5:$O$52,MethodRatings!$A$5:$A$52,A7,MethodRatings!$D$5:$D$52,B7,MethodRatings!$O$5:$O$52,">0")/COUNTIFS(MethodRatings!$A$5:$A$52,A7,MethodRatings!$D$5:$D$52,B7,MethodRatings!$O$5:$O$52,">0"),"") | AB7: =IF(COUNT(I7:K7)=3,SUM(I7:K7),"") | AC7: =IF(COUNT(M7:O7)=3,SUM(M7:O7),"") | AD7: =IF(COUNT(Q7:S7)=3,SUM(Q7:S7),"") | AE7: =IF(COUNT(U7:W7)=3,SUM(U7:W7),"") | AF7: =IF((COUNT(F7:K7)+COUNT(M7:O7)+COUNT(Q7:S7)+COUNT(U7:W7)+COUNT(Y7:AA7))=18,"完整","缺失") -> 缺失
A8: P004 | B8: EgoAnchor | C8: =IF(B8=VLOOKUP(A8,Participants!$A$5:$W$28,22,FALSE),"方法A","方法B") -> 方法A | D8: =VLOOKUP(A8,Participants!$A$5:$B$28,2,FALSE) -> 是 | E8: =COUNTIFS(TaskRatings!$A$5:$A$148,A8,TaskRatings!$F$5:$F$148,B8,TaskRatings!$O$5:$O$148,"是") -> 3 | F8: =IFERROR(SUMIFS(TaskRatings!$H$5:$H$148,TaskRatings!$A$5:$A$148,A8,TaskRatings!$F$5:$F$148,B8,TaskRatings!$O$5:$O$148,"是",TaskRatings!$H$5:$H$148,">0")/COUNTIFS(TaskRatings!$A$5:$A$148,A8,TaskRatings!$F$5:$F$148,B8,TaskRatings!$O$5:$O$148,"是",TaskRatings!$H$5:$H$148,">0"),"") | G8: =IFERROR(SUMIFS(TaskRatings!$J$5:$J$148,TaskRatings!$A$5:$A$148,A8,TaskRatings!$F$5:$F$148,B8,TaskRatings!$O$5:$O$148,"是",TaskRatings!$J$5:$J$148,">0")/COUNTIFS(TaskRatings!$A$5:$A$148,A8,TaskRatings!$F$5:$F$148,B8,TaskRatings!$O$5:$O$148,"是",TaskRatings!$J$5:$J$148,">0"),"") | H8: =IFERROR(SUMIFS(TaskRatings!$L$5:$L$148,TaskRatings!$A$5:$A$148,A8,TaskRatings!$F$5:$F$148,B8,TaskRatings!$O$5:$O$148,"是",TaskRatings!$L$5:$L$148,">0")/COUNTIFS(TaskRatings!$A$5:$A$148,A8,TaskRatings!$F$5:$F$148,B8,TaskRatings!$O$5:$O$148,"是",TaskRatings!$L$5:$L$148,">0"),"") | I8: =IFERROR(SUMIFS(BlockRatings_AQ!$H$5:$H$148,BlockRatings_AQ!$A$5:$A$148,A8,BlockRatings_AQ!$F$5:$F$148,B8,BlockRatings_AQ!$R$5:$R$148,"是",BlockRatings_AQ!$H$5:$H$148,">0")/COUNTIFS(BlockRatings_AQ!$A$5:$A$148,A8,BlockRatings_AQ!$F$5:$F$148,B8,BlockRatings_AQ!$R$5:$R$148,"是",BlockRatings_AQ!$H$5:$H$148,">0"),"") | J8: =IFERROR(SUMIFS(BlockRatings_AQ!$I$5:$I$148,BlockRatings_AQ!$A$5:$A$148,A8,BlockRatings_AQ!$F$5:$F$148,B8,BlockRatings_AQ!$R$5:$R$148,"是",BlockRatings_AQ!$I$5:$I$148,">0")/COUNTIFS(BlockRatings_AQ!$A$5:$A$148,A8,BlockRatings_AQ!$F$5:$F$148,B8,BlockRatings_AQ!$R$5:$R$148,"是",BlockRatings_AQ!$I$5:$I$148,">0"),"") | K8: =IFERROR(SUMIFS(BlockRatings_AQ!$J$5:$J$148,BlockRatings_AQ!$A$5:$A$148,A8,BlockRatings_AQ!$F$5:$F$148,B8,BlockRatings_AQ!$R$5:$R$148,"是",BlockRatings_AQ!$J$5:$J$148,">0")/COUNTIFS(BlockRatings_AQ!$A$5:$A$148,A8,BlockRatings_AQ!$F$5:$F$148,B8,BlockRatings_AQ!$R$5:$R$148,"是",BlockRatings_AQ!$J$5:$J$148,">0"),"") | L8: =IF(COUNT(I8:K8)=3,AVERAGE(I8:K8),"") | M8: =IFERROR(SUMIFS(BlockRatings_AQ!$L$5:$L$148,BlockRatings_AQ!$A$5:$A$148,A8,BlockRatings_AQ!$F$5:$F$148,B8,BlockRatings_AQ!$R$5:$R$148,"是",BlockRatings_AQ!$L$5:$L$148,">0")/COUNTIFS(BlockRatings_AQ!$A$5:$A$148,A8,BlockRatings_AQ!$F$5:$F$148,B8,BlockRatings_AQ!$R$5:$R$148,"是",BlockRatings_AQ!$L$5:$L$148,">0"),"") | N8: =IFERROR(SUMIFS(BlockRatings_AQ!$M$5:$M$148,BlockRatings_AQ!$A$5:$A$148,A8,BlockRatings_AQ!$F$5:$F$148,B8,BlockRatings_AQ!$R$5:$R$148,"是",BlockRatings_AQ!$M$5:$M$148,">0")/COUNTIFS(BlockRatings_AQ!$A$5:$A$148,A8,BlockRatings_AQ!$F$5:$F$148,B8,BlockRatings_AQ!$R$5:$R$148,"是",BlockRatings_AQ!$M$5:$M$148,">0"),"") | O8: =IFERROR(SUMIFS(BlockRatings_AQ!$N$5:$N$148,BlockRatings_AQ!$A$5:$A$148,A8,BlockRatings_AQ!$F$5:$F$148,B8,BlockRatings_AQ!$R$5:$R$148,"是",BlockRatings_AQ!$N$5:$N$148,">0")/COUNTIFS(BlockRatings_AQ!$A$5:$A$148,A8,BlockRatings_AQ!$F$5:$F$148,B8,BlockRatings_AQ!$R$5:$R$148,"是",BlockRatings_AQ!$N$5:$N$148,">0"),"") | P8: =IF(COUNT(M8:O8)=3,AVERAGE(M8:O8),"") | Q8: =IFERROR(SUMIFS(MethodRatings!$E$5:$E$52,MethodRatings!$A$5:$A$52,A8,MethodRatings!$D$5:$D$52,B8,MethodRatings!$E$5:$E$52,">0")/COUNTIFS(MethodRatings!$A$5:$A$52,A8,MethodRatings!$D$5:$D$52,B8,MethodRatings!$E$5:$E$52,">0"),"") | R8: =IFERROR(SUMIFS(MethodRatings!$F$5:$F$52,MethodRatings!$A$5:$A$52,A8,MethodRatings!$D$5:$D$52,B8,MethodRatings!$F$5:$F$52,">0")/COUNTIFS(MethodRatings!$A$5:$A$52,A8,MethodRatings!$D$5:$D$52,B8,MethodRatings!$F$5:$F$52,">0"),"") | S8: =IFERROR(SUMIFS(MethodRatings!$G$5:$G$52,MethodRatings!$A$5:$A$52,A8,MethodRatings!$D$5:$D$52,B8,MethodRatings!$G$5:$G$52,">0")/COUNTIFS(MethodRatings!$A$5:$A$52,A8,MethodRatings!$D$5:$D$52,B8,MethodRatings!$G$5:$G$52,">0"),"") | T8: =IF(COUNT(Q8:S8)=3,AVERAGE(Q8:S8),"") | U8: =IFERROR(SUMIFS(MethodRatings!$I$5:$I$52,MethodRatings!$A$5:$A$52,A8,MethodRatings!$D$5:$D$52,B8,MethodRatings!$I$5:$I$52,">0")/COUNTIFS(MethodRatings!$A$5:$A$52,A8,MethodRatings!$D$5:$D$52,B8,MethodRatings!$I$5:$I$52,">0"),"") | V8: =IFERROR(SUMIFS(MethodRatings!$J$5:$J$52,MethodRatings!$A$5:$A$52,A8,MethodRatings!$D$5:$D$52,B8,MethodRatings!$J$5:$J$52,">0")/COUNTIFS(MethodRatings!$A$5:$A$52,A8,MethodRatings!$D$5:$D$52,B8,MethodRatings!$J$5:$J$52,">0"),"") | W8: =IFERROR(SUMIFS(MethodRatings!$K$5:$K$52,MethodRatings!$A$5:$A$52,A8,MethodRatings!$D$5:$D$52,B8,MethodRatings!$K$5:$K$52,">0")/COUNTIFS(MethodRatings!$A$5:$A$52,A8,MethodRatings!$D$5:$D$52,B8,MethodRatings!$K$5:$K$52,">0"),"") | X8: =IF(COUNT(U8:W8)=3,AVERAGE(U8:W8),"") | Y8: =IFERROR(SUMIFS(MethodRatings!$M$5:$M$52,MethodRatings!$A$5:$A$52,A8,MethodRatings!$D$5:$D$52,B8,MethodRatings!$M$5:$M$52,">0")/COUNTIFS(MethodRatings!$A$5:$A$52,A8,MethodRatings!$D$5:$D$52,B8,MethodRatings!$M$5:$M$52,">0"),"") | Z8: =IFERROR(SUMIFS(MethodRatings!$N$5:$N$52,MethodRatings!$A$5:$A$52,A8,MethodRatings!$D$5:$D$52,B8,MethodRatings!$N$5:$N$52,">0")/COUNTIFS(MethodRatings!$A$5:$A$52,A8,MethodRatings!$D$5:$D$52,B8,MethodRatings!$N$5:$N$52,">0"),"") | AA8: =IFERROR(SUMIFS(MethodRatings!$O$5:$O$52,MethodRatings!$A$5:$A$52,A8,MethodRatings!$D$5:$D$52,B8,MethodRatings!$O$5:$O$52,">0")/COUNTIFS(MethodRatings!$A$5:$A$52,A8,MethodRatings!$D$5:$D$52,B8,MethodRatings!$O$5:$O$52,">0"),"") | AB8: =IF(COUNT(I8:K8)=3,SUM(I8:K8),"") | AC8: =IF(COUNT(M8:O8)=3,SUM(M8:O8),"") | AD8: =IF(COUNT(Q8:S8)=3,SUM(Q8:S8),"") | AE8: =IF(COUNT(U8:W8)=3,SUM(U8:W8),"") | AF8: =IF((COUNT(F8:K8)+COUNT(M8:O8)+COUNT(Q8:S8)+COUNT(U8:W8)+COUNT(Y8:AA8))=18,"完整","缺失") -> 缺失
A9: P005 | B9: EgoAnchor | C9: =IF(B9=VLOOKUP(A9,Participants!$A$5:$W$28,22,FALSE),"方法A","方法B") -> 方法A | D9: =VLOOKUP(A9,Participants!$A$5:$B$28,2,FALSE) -> 是 | E9: =COUNTIFS(TaskRatings!$A$5:$A$148,A9,TaskRatings!$F$5:$F$148,B9,TaskRatings!$O$5:$O$148,"是") -> 3 | F9: =IFERROR(SUMIFS(TaskRatings!$H$5:$H$148,TaskRatings!$A$5:$A$148,A9,TaskRatings!$F$5:$F$148,B9,TaskRatings!$O$5:$O$148,"是",TaskRatings!$H$5:$H$148,">0")/COUNTIFS(TaskRatings!$A$5:$A$148,A9,TaskRatings!$F$5:$F$148,B9,TaskRatings!$O$5:$O$148,"是",TaskRatings!$H$5:$H$148,">0"),"") | G9: =IFERROR(SUMIFS(TaskRatings!$J$5:$J$148,TaskRatings!$A$5:$A$148,A9,TaskRatings!$F$5:$F$148,B9,TaskRatings!$O$5:$O$148,"是",TaskRatings!$J$5:$J$148,">0")/COUNTIFS(TaskRatings!$A$5:$A$148,A9,TaskRatings!$F$5:$F$148,B9,TaskRatings!$O$5:$O$148,"是",TaskRatings!$J$5:$J$148,">0"),"") | H9: =IFERROR(SUMIFS(TaskRatings!$L$5:$L$148,TaskRatings!$A$5:$A$148,A9,TaskRatings!$F$5:$F$148,B9,TaskRatings!$O$5:$O$148,"是",TaskRatings!$L$5:$L$148,">0")/COUNTIFS(TaskRatings!$A$5:$A$148,A9,TaskRatings!$F$5:$F$148,B9,TaskRatings!$O$5:$O$148,"是",TaskRatings!$L$5:$L$148,">0"),"") | I9: =IFERROR(SUMIFS(BlockRatings_AQ!$H$5:$H$148,BlockRatings_AQ!$A$5:$A$148,A9,BlockRatings_AQ!$F$5:$F$148,B9,BlockRatings_AQ!$R$5:$R$148,"是",BlockRatings_AQ!$H$5:$H$148,">0")/COUNTIFS(BlockRatings_AQ!$A$5:$A$148,A9,BlockRatings_AQ!$F$5:$F$148,B9,BlockRatings_AQ!$R$5:$R$148,"是",BlockRatings_AQ!$H$5:$H$148,">0"),"") | J9: =IFERROR(SUMIFS(BlockRatings_AQ!$I$5:$I$148,BlockRatings_AQ!$A$5:$A$148,A9,BlockRatings_AQ!$F$5:$F$148,B9,BlockRatings_AQ!$R$5:$R$148,"是",BlockRatings_AQ!$I$5:$I$148,">0")/COUNTIFS(BlockRatings_AQ!$A$5:$A$148,A9,BlockRatings_AQ!$F$5:$F$148,B9,BlockRatings_AQ!$R$5:$R$148,"是",BlockRatings_AQ!$I$5:$I$148,">0"),"") | K9: =IFERROR(SUMIFS(BlockRatings_AQ!$J$5:$J$148,BlockRatings_AQ!$A$5:$A$148,A9,BlockRatings_AQ!$F$5:$F$148,B9,BlockRatings_AQ!$R$5:$R$148,"是",BlockRatings_AQ!$J$5:$J$148,">0")/COUNTIFS(BlockRatings_AQ!$A$5:$A$148,A9,BlockRatings_AQ!$F$5:$F$148,B9,BlockRatings_AQ!$R$5:$R$148,"是",BlockRatings_AQ!$J$5:$J$148,">0"),"") | L9: =IF(COUNT(I9:K9)=3,AVERAGE(I9:K9),"") | M9: =IFERROR(SUMIFS(BlockRatings_AQ!$L$5:$L$148,BlockRatings_AQ!$A$5:$A$148,A9,BlockRatings_AQ!$F$5:$F$148,B9,BlockRatings_AQ!$R$5:$R$148,"是",BlockRatings_AQ!$L$5:$L$148,">0")/COUNTIFS(BlockRatings_AQ!$A$5:$A$148,A9,BlockRatings_AQ!$F$5:$F$148,B9,BlockRatings_AQ!$R$5:$R$148,"是",BlockRatings_AQ!$L$5:$L$148,">0"),"") | N9: =IFERROR(SUMIFS(BlockRatings_AQ!$M$5:$M$148,BlockRatings_AQ!$A$5:$A$148,A9,BlockRatings_AQ!$F$5:$F$148,B9,BlockRatings_AQ!$R$5:$R$148,"是",BlockRatings_AQ!$M$5:$M$148,">0")/COUNTIFS(BlockRatings_AQ!$A$5:$A$148,A9,BlockRatings_AQ!$F$5:$F$148,B9,BlockRatings_AQ!$R$5:$R$148,"是",BlockRatings_AQ!$M$5:$M$148,">0"),"") | O9: =IFERROR(SUMIFS(BlockRatings_AQ!$N$5:$N$148,BlockRatings_AQ!$A$5:$A$148,A9,BlockRatings_AQ!$F$5:$F$148,B9,BlockRatings_AQ!$R$5:$R$148,"是",BlockRatings_AQ!$N$5:$N$148,">0")/COUNTIFS(BlockRatings_AQ!$A$5:$A$148,A9,BlockRatings_AQ!$F$5:$F$148,B9,BlockRatings_AQ!$R$5:$R$148,"是",BlockRatings_AQ!$N$5:$N$148,">0"),"") | P9: =IF(COUNT(M9:O9)=3,AVERAGE(M9:O9),"") | Q9: =IFERROR(SUMIFS(MethodRatings!$E$5:$E$52,MethodRatings!$A$5:$A$52,A9,MethodRatings!$D$5:$D$52,B9,MethodRatings!$E$5:$E$52,">0")/COUNTIFS(MethodRatings!$A$5:$A$52,A9,MethodRatings!$D$5:$D$52,B9,MethodRatings!$E$5:$E$52,">0"),"") | R9: =IFERROR(SUMIFS(MethodRatings!$F$5:$F$52,MethodRatings!$A$5:$A$52,A9,MethodRatings!$D$5:$D$52,B9,MethodRatings!$F$5:$F$52,">0")/COUNTIFS(MethodRatings!$A$5:$A$52,A9,MethodRatings!$D$5:$D$52,B9,MethodRatings!$F$5:$F$52,">0"),"") | S9: =IFERROR(SUMIFS(MethodRatings!$G$5:$G$52,MethodRatings!$A$5:$A$52,A9,MethodRatings!$D$5:$D$52,B9,MethodRatings!$G$5:$G$52,">0")/COUNTIFS(MethodRatings!$A$5:$A$52,A9,MethodRatings!$D$5:$D$52,B9,MethodRatings!$G$5:$G$52,">0"),"") | T9: =IF(COUNT(Q9:S9)=3,AVERAGE(Q9:S9),"") | U9: =IFERROR(SUMIFS(MethodRatings!$I$5:$I$52,MethodRatings!$A$5:$A$52,A9,MethodRatings!$D$5:$D$52,B9,MethodRatings!$I$5:$I$52,">0")/COUNTIFS(MethodRatings!$A$5:$A$52,A9,MethodRatings!$D$5:$D$52,B9,MethodRatings!$I$5:$I$52,">0"),"") | V9: =IFERROR(SUMIFS(MethodRatings!$J$5:$J$52,MethodRatings!$A$5:$A$52,A9,MethodRatings!$D$5:$D$52,B9,MethodRatings!$J$5:$J$52,">0")/COUNTIFS(MethodRatings!$A$5:$A$52,A9,MethodRatings!$D$5:$D$52,B9,MethodRatings!$J$5:$J$52,">0"),"") | W9: =IFERROR(SUMIFS(MethodRatings!$K$5:$K$52,MethodRatings!$A$5:$A$52,A9,MethodRatings!$D$5:$D$52,B9,MethodRatings!$K$5:$K$52,">0")/COUNTIFS(MethodRatings!$A$5:$A$52,A9,MethodRatings!$D$5:$D$52,B9,MethodRatings!$K$5:$K$52,">0"),"") | X9: =IF(COUNT(U9:W9)=3,AVERAGE(U9:W9),"") | Y9: =IFERROR(SUMIFS(MethodRatings!$M$5:$M$52,MethodRatings!$A$5:$A$52,A9,MethodRatings!$D$5:$D$52,B9,MethodRatings!$M$5:$M$52,">0")/COUNTIFS(MethodRatings!$A$5:$A$52,A9,MethodRatings!$D$5:$D$52,B9,MethodRatings!$M$5:$M$52,">0"),"") | Z9: =IFERROR(SUMIFS(MethodRatings!$N$5:$N$52,MethodRatings!$A$5:$A$52,A9,MethodRatings!$D$5:$D$52,B9,MethodRatings!$N$5:$N$52,">0")/COUNTIFS(MethodRatings!$A$5:$A$52,A9,MethodRatings!$D$5:$D$52,B9,MethodRatings!$N$5:$N$52,">0"),"") | AA9: =IFERROR(SUMIFS(MethodRatings!$O$5:$O$52,MethodRatings!$A$5:$A$52,A9,MethodRatings!$D$5:$D$52,B9,MethodRatings!$O$5:$O$52,">0")/COUNTIFS(MethodRatings!$A$5:$A$52,A9,MethodRatings!$D$5:$D$52,B9,MethodRatings!$O$5:$O$52,">0"),"") | AB9: =IF(COUNT(I9:K9)=3,SUM(I9:K9),"") | AC9: =IF(COUNT(M9:O9)=3,SUM(M9:O9),"") | AD9: =IF(COUNT(Q9:S9)=3,SUM(Q9:S9),"") | AE9: =IF(COUNT(U9:W9)=3,SUM(U9:W9),"") | AF9: =IF((COUNT(F9:K9)+COUNT(M9:O9)+COUNT(Q9:S9)+COUNT(U9:W9)+COUNT(Y9:AA9))=18,"完整","缺失") -> 缺失
