Workbook

Sheet README
A1: 【SYNTHETIC / 模拟数据，非真实被试证据】EgoAnchor 实验三采集与分析工作簿（v5.1 模板）
A2: 唯一权威规格：2026-EgoAnchor/experiment_3_questionnaire_design_zh.md（v5.1）。本精简版保留 6 个工作表：问卷条目集中在 Questionnaire，实验记录集中在 Records（三段堆叠）。本次美化仅加入标准单元格样式、冻结窗格和基础输入校验，不在采集表中派生复合分。原始评分不得被反向分覆盖；TiA 反向计分（6−原始分）仅在分析代码中生成。
A4: 使用流程 | B4: 时点 | C4: 填写位置 | D4: 内容 | E4: 关键规则
A5: 0 背景 | B5: 到场、知情同意后 | C5: Participants | D5: B1–B6 背景字段、纳入状态、起止时间 | E5: 方法映射列仅实验员可见
A6: 1 区块 | B6: 每个方法×物体区块三项任务完成后 | C6: Records A 段 | D6: 13 项统一七点同意度（Q10 默认停用） | E6: 任务后统一评分，不逐任务打断
A7: 2 方法级 | B7: 全部 6 区块完成后 | C7: Records B 段 | D7: 按平衡顺序（S1 先 A、S2 先 B）分别评价两方法：TiA 10 + 提示页 + S-TIAS 3 | E7: 不得插入第 5/6 区块之间
A8: 3 最终 | B8: 摘下头显后 | C8: Records C 段 | D8: 2 强制选择 + 偏好强度 + 区分信心 + 2 开放题 + 安全检查 | E8: 回答完成前保持匿名
A9: 4 审计 | B9: 每区块同步 | C9: Records A 段（审计列） | D9: 候选/VCD/接纳/生命周期/重获取/时长 | E9: 只作操纵检验，不是配准误差
A10: 5 分析 | B10: 采集完成后 | C10: Analysis | D10: 已回填模拟统计结果、稳健性近似、逐物体描述、操纵检验、最终计数与开放题编码 | E10: 正式模型在 R/Python 中运行
A12: 冻结分析家族
A13: 主证实家族（7） | B13: Q1/Q8/Q2/Q9/Q3/Q6/Q7 | C13: 三物体取均值 → 配对 Wilcoxon → 家族内 Holm（MDE dz=0.801）
A14: 已发表量表家族（5） | B14: AQ-EQ / AQ-IQ / TiA-R/C / TiA-U/P / S-TIAS | C14: 同上；仅此家族报告当前样本 α/ω；TiA 反向项先换向
A15: 次级 | B15: Q10（若预实验启用）；CLMM（方法×物体+区块位置+对象内先后+随机截距） | C15: 独立分析 / 稳健性
A16: 描述性 | B16: 两项强制选择、偏好强度、区分信心、开放题主题、安全检查、运行时审计 | C16: 不作推断
A18: 采集前仍未完成的前置（未完成不得正式采集）
A19: 中文施测措辞已于 2026-07-26 冻结（v5.1 Final wording）：19 条量表条目逐条对照官方原文完成语义等价审计（GPT 正向翻译 → GPT 网页端对照复核 → 仓库助手独立审计，三次独立通过；微调 AQ-IQ2 去"能够"、AQ-EQ2 去"看起来被"）。预实验认知访谈改为确认性检查（最高优先 TIA_RC1/RC4、Q2 与 AQ-IQ3 判别），发现理解不良才按修订—重测—再冻结处理。
A20: 预实验冻结项：遮挡时长（0.6–0.9 s 内取定，避开 0.45/1.0 s 边界）、Q10 是否启用、AQ 缩减规则是否触发（单区块 >150 s 或连续同分 ≥5 项 → 停用 AQ_EQ3/AQ_IQ1）、方法级问卷模态。
A22: 程序日志字段建议（Unity 端长格式事件日志；本表 Records 为实验员宽表）
A23: participant_id / level(block|method|final) / method_id(内部) / shown_label(A|B) / object_id / block_index / item_id / scale_type(agreement_7|agreement_5|intensity_7) / response_raw / timestamp_utc / task_completed / technical_issue / lifecycle_state(遮挡) — 事件只追加不覆盖。
A25: 提前止收规则：招募未满 24 人时按 Participants 编号顺序优先补齐整组 4 人（同一物体排列的四个单元），N 下限 18。

Sheet Verification_Audit
A1: 【待核对】内容核验记录（2026-07-26；依据公开原始论文、附录与官方量表来源核对）
A2: 区分“官方原文/量尺已核对”与“对象锚定情境适配”：适配版不自动继承原量表在原场景的效度证据；正式采集前仍须完成独立回译与认知访谈。
A4: 核对对象 | B4: 状态 | C4: 结论/修正 | D4: 依据/来源
A5: AQ 英文条目 | B5: 已核对 | C5: 原计划英文系语义转述；已替换为附录官方原文（指代为 The virtual object，对象化替换极小） | D5: doi:10.1007/s11747-025-01108-2 Appendix
A6: AQ 量尺 | B6: 已核对 | C6: 七点：1 = I do not agree … 7 = I fully agree；中文“完全不同意–完全同意”正确 | D6: 同上
A7: AQ 书目 | B7: 已核对 | C7: Schein, K. E.; Rauschnabel, P. A.; Praxmarer-Carus, S.; Babin, B. J. Unpacking augmentation quality and local presence: Factors that drive effective augmented reality marketing. JAMS 54:49–69（2025 在线） | D7: CC BY 4.0
A8: TiA 条目结构 | B8: 已核对 | C8: R/C 6 项（官方条目 1,6,10,13,15,19）+ U/P 4 项（2,7,11,16）；6+4 正确、语料 7+3 系误标 | D8: 官方 GitHub（CC BY-SA 4.0）
A9: TiA 反向计分 | B9: 已核对 | C9: 反向项 RC3/RC5/UP2/UP4（官方条目 10,15,7,16）；五点反向分 = 6 − 原始分 | D9: 同上
A10: TiA 量尺 | B10: 已核对 | C10: 五点同意度 + 允许 No response（记缺失） | D10: 同上
A11: TiA 效度措辞 | B11: 需遵守 | C11: 英文版仍需进一步验证（德文原版才有初步心理计量证据）；论文只写 adapted TiA subscales + 当前样本信度，不得写“已验证英文/中文量表” | D11: 官方 GitHub 声明
A12: S-TIAS 条目 | B12: 已核对 | C12: 三项原文指代 the AI assistant；本研究替换为“这种对象锚定方法”→ adapted S-TIAS | D12: doi:10.3389/frai.2025.1582880
A13: S-TIAS 量尺 | B13: 已核对 | C13: 1 = Not at all … 7 = Extremely；三项均值 | D13: 同上
A14: S-TIAS 书目 | B14: 已核对（作者更正） | C14: McGrath, M. J.; Lack, O.; Tisch, J.; Duenser, A. Measuring trust in artificial intelligence: validation of an established scale and its short form. Frontiers in AI 8:1582880。语料曾误标为 Karpus；bib 键 mcgrath2025stias | D14: CC BY
A15: Gottsacker 2024 书目 | B15: 已核对 | C15: Gottsacker, M.; Furuya, H.; Choudhary, Z. D.; Erickson, A.; Schubert, R.; Bruder, G.; Browne, M. P.; Welch, G. F. Investigating the relationships between user behaviors and tracking factors on task performance and trust in augmented reality. Computers & Graphics 123:104035 | D15: doi:10.1016/j.cag.2024.104035
... A20: 中文施测措辞 | B20: 已冻结（2026-07-26） | C20: 19 条量表条目（AQ 6 + TiA 10 + S-TIAS 3）逐条对照官方原文完成语义等价审计并冻结；审计微调两处：AQ-IQ2 去"能够"（避免行为陈述变能力陈述）、AQ-EQ2 去"看起来被"（避免在 realistically 上叠加第二层感知模糊）。TIA_RC1/RC4 构念贴合与 Q2/AQ-IQ3 判别留待预实验认知访谈确认性检查。不再单设翻译冻结关卡。 | D20: 本研究语义审计记录（计划书 4.6 核对状态）

Sheet Questionnaire
A1: 实验三问卷全条目（v5.1 Verified）——本表为唯一条目字典，与计划书 4.2/4.4/4.5 逐字一致
A2: 中文施测版为头显/纸面呈现文本；“官方英文原文”为原量表逐字条目（自制条目无）；“对象化英文施测版”供论文附录与英文施测用。TiA 中文列回译待完成，冻结前不得正式施测。
A4: A. 实验前背景（Participants 表填写，每人一次）
A5: ID | B5: 中文 | C5: 应答格式/选项
A6: B1_Age | B6: 年龄 | C6: 整数
A7: B2_Gender | B7: 性别 | C7: 女 / 男 / 非二元或其他 / 不愿透露
A8: B3_Handedness | B8: 主手（精细操作） | C8: 右手 / 左手 / 双手均可
A9: B4_Vision | B9: 视力情况 | C9: 正常 / 矫正后正常 / 其他
A10: B5_VRMR_Experience | B10: VR/MR 使用经验 | C10: 从未 / 1–5 次 / 6–20 次 / 超过 20 次 / 经常使用
A11: B6_PhysObj_MR_Experience | B11: 实物 AR/MR 交互经验（需操作真实物体的应用） | C11: 从未 / 1–2 次 / 数次 / 经常
A13: B. 区块级 13 项必答 + Q10 可选（每个方法×物体区块后；统一七点同意度；界面标题：请根据刚才在这个物体上的体验作答）
A14: 页序 | B14: Item_ID | C14: 简称 | D14: 中文施测版 | E14: 官方英文原文 | F14: 对象化英文施测版 | G14: 分析家族 | H14: 来源 | I14: 备注
A15: 1 | B15: Q1 | C15: 静止稳定 | D15: 在静止观察阶段，虚拟内容保持在同一位置不动。 | E15: — | F15: During static observation, the virtual content stayed in the same position without moving. | G15: 主证实 | H15: 自制（v4 冻结） | I15: 时间稳定性；pilot 检查“同一位置”参照系理解
A16: 2 | B16: Q2 | C16: 运动附着 | D16: 在拿起、移动和旋转物体时，虚拟内容始终附着在真实物体上的同一位置。 | E16: — | F16: While I picked up, moved, and rotated the object, the virtual content remained attached to the same location on the physical object. | G16: 主证实 | H16: 自制（v5.1 锐化措辞） | I16: 测附着位置恒定，与 AQ_IQ3 平滑正交；认知访谈确认区分
A17: 3 | B17: Q9 | C17: 姿态一致 | D17: 旋转物体时，虚拟内容的朝向与真实物体的朝向保持一致。 | E17: — | F17: While I rotated the object, the orientation of the virtual content stayed consistent with the orientation of the physical object. | G17: 主证实 | H17: 自制（v4 冻结） | I17: 旋转通道独立诊断
A18: 3' | B18: Q10_OPT | C18: 放置后稳定（可选） | D18: 把物体放到桌面后，虚拟内容很快就稳定下来。 | E18: — | F18: After I placed the object on the table, the virtual content settled quickly. | G18: 次级 | H18: 自制（v4 可选） | I18: 默认停用；预实验冻结是否启用
A19: 4 | B19: AQ_IQ2 | C19: 响应及时 | D19: 虚拟内容实时响应我对真实物体的操作。 | E19: The virtual object responds in real-time. | F19: The virtual content responds in real-time to my manipulation of the physical object. | G19: 已发表量表 | H19: AQ Interaction Quality（对象化适配） | I19: AQ-IQ 子量表分 = IQ1/IQ2/IQ3 均值（分析派生）
A20: 5 | B20: AQ_IQ3 | C20: 运动平滑 | D20: 在交互过程中，虚拟内容随真实物体平滑运动。 | E20: The virtual object moves smoothly. | F20: The virtual content moves smoothly with the physical object during interaction. | G20: 已发表量表 | H20: AQ Interaction Quality（对象化适配）
A21: 6 | B21: Q3 | C21: 恢复一致 | D21: 遮挡移除后，虚拟内容恢复到了与真实物体一致的位置。 | E21: — | F21: After the occlusion was removed, the virtual content recovered to a position consistent with the physical object. | G21: 主证实 | H21: 自制（v4 冻结） | I21: 恢复后空间一致性
A22: 7 | B22: Q8 | C22: 位置正确 | D22: 虚拟内容出现的位置，与真实物体实际所在的位置相符。 | E22: — | F22: The virtual content appeared at a position that matched where the physical object actually was. | G22: 主证实 | H22: 自制（v4 冻结） | I22: 主观空间正确性，不作客观配准误差；与 Q1 相隔五题
A23: 8 | B23: AQ_EQ1 | C23: 融合 | D23: 虚拟内容与真实物体及周围真实元素自然融合。 | E23: The virtual object blends in with real elements. | F23: The virtual content blends in with the physical object and surrounding real elements. | G23: 已发表量表 | H23: AQ Embedding Quality（对象化适配） | I23: AQ-EQ 子量表分 = EQ1/EQ2/EQ3 均值（分析派生）
A24: 9 | B24: AQ_EQ2 | C24: 嵌入可信 | D24: 虚拟内容真实地嵌入在真实物体及其现实环境中。 | E24: The virtual object is realistically embedded in the environment. | F24: The virtual content is realistically embedded in the physical object and its real-world context. | G24: 已发表量表 | H24: AQ Embedding Quality（对象化适配） | I24: 接管原 Q4 合理可信构念
A25: 10 | B25: AQ_EQ3 | C25: 尺度协调 | D25: 虚拟内容的尺度与真实物体及现实世界中的事物相匹配。 | E25: The size of the virtual object is in scale to things in the real world. | F25: The size of the virtual content is in scale to the physical object and things in the real world. | G25: 已发表量表 | H25: AQ Embedding Quality（对象化适配） | I25: 预期天花板；保留以维持完整子量表
A26: 11 | B26: AQ_IQ1 | C26: 交互直观 | D26: 通过操作真实物体与虚拟内容进行交互是直观的。 | E26: Interaction with the virtual object is intuitive. | F26: Interaction with the virtual content through manipulation of the physical object is intuitive. | G26: 已发表量表 | H26: AQ Interaction Quality（对象化适配）
A27: 12 | B27: Q6 | C27: 依赖意愿 | D27: 在需要虚拟内容准确附着于真实物体的混合现实应用中，我愿意依赖这种锚定方法。 | E27: — | F27: I would be willing to rely on this anchoring method in an MR application that requires virtual content to be accurately attached to a physical object. | G27: 主证实 | H27: 自制（v4 冻结） | I27: 应用侧依赖意愿（区块级信任）
A28: 13 | B28: Q7 | C28: 稳定-响应平衡 | D28: 总体而言，该方法在锚点稳定性与响应及时性之间取得了合适的平衡。 | E28: — | F28: Overall, this method achieved an appropriate balance between anchor stability and responsiveness. | G28: 主证实 | H28: 自制（v4 冻结） | I28: 双构念总结项；与实验一稳定/时延结果联合解释
A29: 量尺 | B29: 七点同意度：1 完全不同意 … 7 完全同意 | C29: 同一条目在全部区块中措辞与刻度完全相同；每页一题、确认后翻页；不显示既往回答
A31: C. 方法级（全部六区块完成后，按 S1 先 A / S2 先 B 依次评价两方法；界面标题：请根据方法 X 在全部三个物体上的整体表现作答）
A32: C1. adapted TiA 两分量表（10 项） | B32: 五点同意度：1 Strongly disagree / 2 Rather disagree / 3 Neither / 4 Rather agree / 5 Strongly agree；允许无法回答（记缺失） | C32: 反向项计分 = 6 − 原始分（仅分析派生）；分量表分 = 有效条目均值；呈现按官方相对顺序交错（官方条目 1,2,6,7,10,11,13,15,16,19），参与者界面只显示中性序号第 1–10 题，下表按分量表分组仅为规格
A33: Item_ID | B33: 分量表 | C33: 官方英文原文 | D33: 中文施测版（已冻结） | E33: 反向 | F33: 官方条目号
A34: TIA_RC1 | B34: Reliability/Competence | C34: The system is capable of interpreting situations correctly. | D34: 这种对象锚定方法能够正确判断当前状况。 | E34: 否 | F34: 1
A35: TIA_RC2 | B35: Reliability/Competence | C35: The system works reliably. | D35: 这种对象锚定方法运行可靠。 | E35: 否 | F35: 6
A36: TIA_RC3 | B36: Reliability/Competence | C36: A system malfunction is likely. | D36: 这种对象锚定方法很可能发生故障。 | E36: 是 | F36: 10
A37: TIA_RC4 | B37: Reliability/Competence | C37: The system is capable of taking over complicated tasks. | D37: 这种对象锚定方法能够承担复杂的锚定任务。 | E37: 否 | F37: 13
A38: TIA_RC5 | B38: Reliability/Competence | C38: The system might make sporadic errors. | D38: 这种对象锚定方法可能偶尔出错。 | E38: 是 | F38: 15
A39: TIA_RC6 | B39: Reliability/Competence | C39: I am confident about the system's capabilities. | D39: 我对这种对象锚定方法的能力有信心。 | E39: 否 | F39: 19
A40: TIA_UP1 | B40: Understanding/Predictability | C40: The system state was always clear to me. | D40: 这种对象锚定方法的状态对我来说始终清楚。 | E40: 否 | F40: 2
A41: TIA_UP2 | B41: Understanding/Predictability | C41: The system reacts unpredictably. | D41: 这种对象锚定方法的反应难以预测。 | E41: 是 | F41: 7
A42: TIA_UP3 | B42: Understanding/Predictability | C42: I was able to understand why things happened. | D42: 我能够理解为什么会出现刚才的锚定行为。 | E42: 否 | F42: 11
A43: TIA_UP4 | B43: Understanding/Predictability | C43: It's difficult to identify what the system will do next. | D43: 我很难判断这种对象锚定方法接下来会怎样表现。 | E43: 是 | F43: 16
...

Sheet Participants
A1: 【SYNTHETIC / 模拟数据】参与者信息与 24 平衡单元（不得作为真实人类受试数据报告）
A2: Participant_ID | B2: 平衡单元 | C2: 物体排列ID | D2: 标签序列 | E2: 物体1 | F2: 物体2 | G2: 物体3 | H2: 区块内标签顺序 | I2: 方法A=（保密） | J2: 方法B=（保密） | K2: 先行实际方法 | L2: B1_年龄 | M2: B2_性别 | N2: B3_主手 | O2: B4_视力 | P2: B5_VR/MR经验 | Q2: B6_实物MR经验 | R2: 签署同意 | S2: 基线不适 | T2: 开始时间 | U2: 结束时间 | V2: 纳入分析 | W2: 退出/技术问题 | X2: 备注
A3: P001 | B3: O1-S1-EA | C3: 1 | D3: S1 | E3: 鼠标 | F3: 固定订书机 | G3: 游戏手柄 | H3: A-B / B-A / A-B | I3: EgoAnchor | J3: One-Euro | K3: EgoAnchor | L3: 29 | M3: 男 | N3: 右手 | O3: 正常 | P3: 6–20 次 | Q3: 1–2 次 | R3: 是 | S3: 无 | T3: 46237.379 | U3: 46237.423 | V3: 是 | W3: 无 | X3: 模拟画像：响应敏感型；独立随机种子=570334。
A4: P002 | B4: O1-S2-EA | C4: 1 | D4: S2 | E4: 鼠标 | F4: 固定订书机 | G4: 游戏手柄 | H4: B-A / A-B / B-A | I4: EgoAnchor | J4: One-Euro | K4: One-Euro | L4: 33 | M4: 男 | N4: 右手 | O4: 正常 | P4: 1–5 次 | Q4: 数次 | R4: 是 | S4: 无 | T4: 46237.444 | U4: 46237.487 | V4: 是 | W4: 无 | X4: 模拟画像：稳定敏感型；独立随机种子=580341。
A5: P003 | B5: O1-S2-OE | C5: 1 | D5: S2 | E5: 鼠标 | F5: 固定订书机 | G5: 游戏手柄 | H5: B-A / A-B / B-A | I5: One-Euro | J5: EgoAnchor | K5: EgoAnchor | L5: 25 | M5: 男 | N5: 右手 | O5: 矫正后正常 | P5: 6–20 次 | Q5: 经常 | R5: 是 | S5: 无 | T5: 46237.565 | U5: 46237.603 | V5: 是 | W5: 无 | X5: 模拟画像：平衡权衡型；独立随机种子=590348。
A6: P004 | B6: O1-S1-OE | C6: 1 | D6: S1 | E6: 鼠标 | F6: 固定订书机 | G6: 游戏手柄 | H6: A-B / B-A / A-B | I6: One-Euro | J6: EgoAnchor | K6: One-Euro | L6: 25 | M6: 女 | N6: 右手 | O6: 正常 | P6: 1–5 次 | Q6: 1–2 次 | R6: 是 | S6: 轻微 | T6: 46237.641 | U6: 46237.684 | V6: 是 | W6: 无 | X6: 模拟画像：响应敏感型；独立随机种子=600355。
A7: P005 | B7: O2-S1-EA | C7: 2 | D7: S1 | E7: 鼠标 | F7: 游戏手柄 | G7: 固定订书机 | H7: A-B / B-A / A-B | I7: EgoAnchor | J7: One-Euro | K7: EgoAnchor | L7: 23 | M7: 女 | N7: 右手 | O7: 正常 | P7: 1–5 次 | Q7: 从未 | R7: 是 | S7: 无 | T7: 46238.379 | U7: 46238.417 | V7: 是 | W7: 无 | X7: 模拟画像：平衡权衡型；独立随机种子=610362。
A8: P006 | B8: O2-S2-EA | C8: 2 | D8: S2 | E8: 鼠标 | F8: 游戏手柄 | G8: 固定订书机 | H8: B-A / A-B / B-A | I8: EgoAnchor | J8: One-Euro | K8: One-Euro | L8: 27 | M8: 女 | N8: 右手 | O8: 矫正后正常 | P8: 6–20 次 | Q8: 从未 | R8: 是 | S8: 无 | T8: 46238.446 | U8: 46238.491 | V8: 是 | W8: 无 | X8: 模拟画像：平衡权衡型；独立随机种子=620369。
A9: P007 | B9: O2-S2-OE | C9: 2 | D9: S2 | E9: 鼠标 | F9: 游戏手柄 | G9: 固定订书机 | H9: B-A / A-B / B-A | I9: One-Euro | J9: EgoAnchor | K9: EgoAnchor | L9: 24 | M9: 男 | N9: 左手 | O9: 矫正后正常 | P9: 经常使用 | Q9: 数次 | R9: 是 | S9: 无 | T9: 46238.562 | U9: 46238.61 | V9: 是 | W9: 无 | X9: 模拟画像：稳定敏感型；独立随机种子=630376。
A10: P008 | B10: O2-S1-OE | C10: 2 | D10: S1 | E10: 鼠标 | F10: 游戏手柄 | G10: 固定订书机 | H10: A-B / B-A / A-B | I10: One-Euro | J10: EgoAnchor | K10: One-Euro | L10: 32 | M10: 女 | N10: 右手 | O10: 正常 | P10: 6–20 次 | Q10: 经常 | R10: 是 | S10: 轻微 | T10: 46238.633 | U10: 46238.67 | V10: 是 | W10: 无 | X10: 模拟画像：低区分/谨慎型；独立随机种子=640383。
A11: P009 | B11: O3-S1-EA | C11: 3 | D11: S1 | E11: 固定订书机 | F11: 鼠标 | G11: 游戏手柄 | H11: A-B / B-A / A-B | I11: EgoAnchor | J11: One-Euro | K11: EgoAnchor | L11: 27 | M11: 男 | N11: 右手 | O11: 矫正后正常 | P11: 6–20 次 | Q11: 1–2 次 | R11: 是 | S11: 无 | T11: 46239.375 | U11: 46239.414 | V11: 是 | W11: 无 | X11: 模拟画像：响应敏感型；独立随机种子=650390。
A12: P010 | B12: O3-S2-EA | C12: 3 | D12: S2 | E12: 固定订书机 | F12: 鼠标 | G12: 游戏手柄 | H12: B-A / A-B / B-A | I12: EgoAnchor | J12: One-Euro | K12: One-Euro | L12: 33 | M12: 女 | N12: 右手 | O12: 矫正后正常 | P12: 经常使用 | Q12: 1–2 次 | R12: 是 | S12: 无 | T12: 46239.447 | U12: 46239.486 | V12: 是 | W12: 无 | X12: 模拟画像：平衡权衡型；独立随机种子=660397。
A13: P011 | B13: O3-S2-OE | C13: 3 | D13: S2 | E13: 固定订书机 | F13: 鼠标 | G13: 游戏手柄 | H13: B-A / A-B / B-A | I13: One-Euro | J13: EgoAnchor | K13: EgoAnchor | L13: 28 | M13: 女 | N13: 左手 | O13: 正常 | P13: 经常使用 | Q13: 从未 | R13: 是 | S13: 无 | T13: 46239.565 | U13: 46239.605 | V13: 是 | W13: 无 | X13: 模拟画像：稳定敏感型；独立随机种子=670404。
A14: P012 | B14: O3-S1-OE | C14: 3 | D14: S1 | E14: 固定订书机 | F14: 鼠标 | G14: 游戏手柄 | H14: A-B / B-A / A-B | I14: One-Euro | J14: EgoAnchor | K14: One-Euro | L14: 30 | M14: 男 | N14: 右手 | O14: 正常 | P14: 经常使用 | Q14: 1–2 次 | R14: 是 | S14: 无 | T14: 46239.64 | U14: 46239.685 | V14: 是 | W14: 无 | X14: 模拟画像：稳定敏感型；独立随机种子=680411。
... A26: P024 | B26: O6-S1-OE | C26: 6 | D26: S1 | E26: 游戏手柄 | F26: 固定订书机 | G26: 鼠标 | H26: A-B / B-A / A-B | I26: One-Euro | J26: EgoAnchor | K26: One-Euro | L26: 30 | M26: 男 | N26: 左手 | O26: 矫正后正常 | P26: 超过 20 次 | Q26: 数次 | R26: 是 | S26: 无 | T26: 46242.636 | U26: 46242.68 | V26: 是 | W26: 无 | X26: 模拟画像：稳定敏感型；独立随机种子=800495。

Sheet Records
A1: 【SYNTHETIC / 模拟数据】实验记录：24 个独立模拟参与者；Q10 默认停用；原始分保留，分量表由 Formula_Scores 公式计算。
A3: A. 区块记录（每行 = 一个方法×物体区块：进度 + 13+1 项评分 + 问卷时长 + 运行时审计）
A4: Participant_ID | B4: Block_Index | C4: 平衡单元 | D4: 物体位置 | E4: 物体 | F4: Object_Key | G4: Shown_Label | H4: Condition(保密) | I4: 物体内先后 | J4: 该方法第几次 | K4: Q1 | L4: Q2 | M4: Q9 | N4: Q10_OPT | O4: AQ_IQ2 | P4: AQ_IQ3 | Q4: Q3 | R4: Q8 | S4: AQ_EQ1 | T4: AQ_EQ2 | U4: AQ_EQ3 | V4: AQ_IQ1 | W4: Q6 | X4: Q7 | Y4: 问卷开始 | Z4: 问卷结束 | AA4: 问卷时长_s | AB4: 任务完成 | AC4: 问卷完成 | AD4: 区块有效 | AE4: 技术问题 | AF4: Candidate_Rate_Hz | AG4: VCD_Median | AH4: VCD_Admission_Rate | AI4: Output_Availability | AJ4: 遮挡时长_s | AK4: 遮挡生命周期状态 | AL4: 进入Lost | AM4: 服务器重获取次数 | AN4: StaticLock进入次数 | AO4: 备注
A5: P001 | B5: 1 | C5: O1-S1-EA | D5: 1 | E5: 鼠标 | F5: blue_mouse | G5: 方法A | H5: EgoAnchor | I5: 1 | J5: 1 | K5: 5 | L5: 5 | M5: 5 | O5: 4 | P5: 5 | Q5: 5 | R5: 5 | S5: 5 | T5: 5 | U5: 5 | V5: 5 | W5: 4 | X5: 5 | Y5: 46237.386 | Z5: 46237.387 | AA5: 90.8 | AB5: 是 | AC5: 是 | AD5: 是 | AE5: 无 | AF5: 13.08 | AG5: 0.859 | AH5: 0.871 | AI5: 0.985 | AJ5: 0.718 | AK5: FrozenUncertain | AL5: 否 | AM5: 0 | AN5: 4
A6: P001 | B6: 2 | C6: O1-S1-EA | D6: 1 | E6: 鼠标 | F6: blue_mouse | G6: 方法B | H6: One-Euro | I6: 2 | J6: 1 | K6: 3 | L6: 6 | M6: 4 | O6: 6 | P6: 5 | Q6: 4 | R6: 5 | S6: 5 | T6: 4 | U6: 5 | V6: 5 | W6: 3 | X6: 4 | Y6: 46237.388 | Z6: 46237.389 | AA6: 87.9 | AB6: 是 | AC6: 是 | AD6: 是 | AE6: 无 | AF6: 12.76 | AG6: 0.698 | AH6: 0.843 | AI6: 0.99 | AJ6: 0.787 | AK6: FrozenUncertain | AL6: 否 | AM6: 1 | AN6: 0 | AO6: 遮挡恢复后出现一次小跳变
A7: P001 | B7: 3 | C7: O1-S1-EA | D7: 2 | E7: 固定订书机 | F7: stapler | G7: 方法B | H7: One-Euro | I7: 1 | J7: 2 | K7: 4 | L7: 4 | M7: 3 | O7: 5 | P7: 5 | Q7: 3 | R7: 6 | S7: 5 | T7: 5 | U7: 6 | V7: 4 | W7: 5 | X7: 5 | Y7: 46237.391 | Z7: 46237.391 | AA7: 77 | AB7: 是 | AC7: 是 | AD7: 是 | AE7: 无 | AF7: 11.85 | AG7: 0.797 | AH7: 0.891 | AI7: 0.992 | AJ7: 0.757 | AK7: FrozenUncertain | AL7: 否 | AM7: 1 | AN7: 0 | AO7: 静止阶段可见轻微抖动
A8: P001 | B8: 4 | C8: O1-S1-EA | D8: 2 | E8: 固定订书机 | F8: stapler | G8: 方法A | H8: EgoAnchor | I8: 2 | J8: 2 | K8: 5 | L8: 6 | M8: 5 | O8: 5 | P8: 5 | Q8: 6 | R8: 6 | S8: 7 | T8: 5 | U8: 4 | V8: 5 | W8: 6 | X8: 4 | Y8: 46237.392 | Z8: 46237.393 | AA8: 85.6 | AB8: 是 | AC8: 是 | AD8: 是 | AE8: 无 | AF8: 12.22 | AG8: 0.809 | AH8: 0.941 | AI8: 0.985 | AJ8: 0.698 | AK8: FrozenUncertain | AL8: 否 | AM8: 1 | AN8: 3
A9: P001 | B9: 5 | C9: O1-S1-EA | D9: 3 | E9: 游戏手柄 | F9: gamepad | G9: 方法A | H9: EgoAnchor | I9: 1 | J9: 3 | K9: 5 | L9: 5 | M9: 4 | O9: 4 | P9: 5 | Q9: 5 | R9: 5 | S9: 4 | T9: 4 | U9: 5 | V9: 6 | W9: 5 | X9: 5 | Y9: 46237.394 | Z9: 46237.396 | AA9: 109.9 | AB9: 是 | AC9: 是 | AD9: 是 | AE9: 无 | AF9: 13.08 | AG9: 0.786 | AH9: 0.861 | AI9: 0.985 | AJ9: 0.786 | AK9: FrozenUncertain | AL9: 否 | AM9: 1 | AN9: 4
A10: P001 | B10: 6 | C10: O1-S1-EA | D10: 3 | E10: 游戏手柄 | F10: gamepad | G10: 方法B | H10: One-Euro | I10: 2 | J10: 3 | K10: 3 | L10: 5 | M10: 6 | O10: 5 | P10: 4 | Q10: 4 | R10: 5 | S10: 4 | T10: 4 | U10: 4 | V10: 5 | W10: 4 | X10: 4 | Y10: 46237.397 | Z10: 46237.398 | AA10: 109.6 | AB10: 是 | AC10: 是 | AD10: 是 | AE10: 短暂帧率波动 | AF10: 13.15 | AG10: 0.798 | AH10: 0.904 | AI10: 0.972 | AJ10: 0.772 | AK10: FrozenUncertain | AL10: 否 | AM10: 1 | AN10: 0 | AO10: 短暂画面卡顿，自动恢复；任务与问卷均完成。
A11: P002 | B11: 1 | C11: O1-S2-EA | D11: 1 | E11: 鼠标 | F11: blue_mouse | G11: 方法B | H11: One-Euro | I11: 1 | J11: 1 | K11: 5 | L11: 7 | M11: 4 | O11: 5 | P11: 6 | Q11: 6 | R11: 5 | S11: 5 | T11: 6 | U11: 5 | V11: 6 | W11: 4 | X11: 6 | Y11: 46237.452 | Z11: 46237.453 | AA11: 106.2 | AB11: 是 | AC11: 是 | AD11: 是 | AE11: 无 | AF11: 12.33 | AG11: 0.74 | AH11: 0.843 | AI11: 0.999 | AJ11: 0.802 | AK11: FrozenUncertain | AL11: 否 | AM11: 1 | AN11: 0
A12: P002 | B12: 2 | C12: O1-S2-EA | D12: 1 | E12: 鼠标 | F12: blue_mouse | G12: 方法A | H12: EgoAnchor | I12: 2 | J12: 1 | K12: 5 | L12: 7 | M12: 6 | O12: 5 | P12: 4 | Q12: 6 | R12: 5 | S12: 6 | T12: 5 | U12: 7 | V12: 5 | W12: 7 | X12: 6 | Y12: 46237.454 | Z12: 46237.456 | AA12: 122.1 | AB12: 是 | AC12: 是 | AD12: 是 | AE12: 无 | AF12: 11.73 | AG12: 0.771 | AH12: 0.846 | AI12: 0.986 | AJ12: 0.7 | AK12: FrozenUncertain | AL12: 否 | AM12: 1 | AN12: 3
A13: P002 | B13: 3 | C13: O1-S2-EA | D13: 2 | E13: 固定订书机 | F13: stapler | G13: 方法A | H13: EgoAnchor | I13: 1 | J13: 2 | K13: 5 | L13: 5 | M13: 6 | O13: 5 | P13: 7 | Q13: 7 | R13: 6 | S13: 6 | T13: 5 | U13: 5 | V13: 7 | W13: 7 | X13: 6 | Y13: 46237.456 | Z13: 46237.458 | AA13: 91.2 | AB13: 是 | AC13: 是 | AD13: 是 | AE13: 无 | AF13: 12.81 | AG13: 0.804 | AH13: 0.885 | AI13: 0.995 | AJ13: 0.762 | AK13: FrozenUncertain | AL13: 否 | AM13: 1 | AN13: 2
A14: P002 | B14: 4 | C14: O1-S2-EA | D14: 2 | E14: 固定订书机 | F14: stapler | G14: 方法B | H14: One-Euro | I14: 2 | J14: 2 | K14: 5 | L14: 7 | M14: 5 | O14: 7 | P14: 6 | Q14: 3 | R14: 5 | S14: 5 | T14: 5 | U14: 6 | V14: 6 | W14: 5 | X14: 5 | Y14: 46237.458 | Z14: 46237.459 | AA14: 74.5 | AB14: 是 | AC14: 是 | AD14: 是 | AE14: 无 | AF14: 12.61 | AG14: 0.794 | AH14: 0.918 | AI14: 0.994 | AJ14: 0.785 | AK14: FrozenUncertain | AL14: 否 | AM14: 1 | AN14: 0
A15: P002 | B15: 5 | C15: O1-S2-EA | D15: 3 | E15: 游戏手柄 | F15: gamepad | G15: 方法B | H15: One-Euro | I15: 1 | J15: 3 | K15: 4 | L15: 5 | M15: 4 | O15: 6 | P15: 4 | Q15: 5 | R15: 4 | S15: 5 | T15: 4 | U15: 6 | V15: 5 | W15: 6 | X15: 3 | Y15: 46237.46 | Z15: 46237.461 | AA15: 93.9 | AB15: 是 | AC15: 是 | AD15: 是 | AE15: 无 | AF15: 12.61 | AG15: 0.729 | AH15: 0.852 | AI15: 0.988 | AJ15: 0.774 | AK15: FrozenUncertain | AL15: 否 | AM15: 1 | AN15: 0 | AO15: 静止阶段可见轻微抖动
A16: P002 | B16: 6 | C16: O1-S2-EA | D16: 3 | E16: 游戏手柄 | F16: gamepad | G16: 方法A | H16: EgoAnchor | I16: 2 | J16: 3 | K16: 6 | L16: 3 | M16: 6 | O16: 5 | P16: 6 | Q16: 6 | R16: 7 | S16: 6 | T16: 5 | U16: 6 | V16: 6 | W16: 6 | X16: 4 | Y16: 46237.462 | Z16: 46237.464 | AA16: 96.3 | AB16: 是 | AC16: 是 | AD16: 是 | AE16: 无 | AF16: 13.25 | AG16: 0.762 | AH16: 0.89 | AI16: 0.985 | AJ16: 0.758 | AK16: FrozenUncertain | AL16: 否 | AM16: 1 | AN16: 2
A17: P003 | B17: 1 | C17: O1-S2-OE | D17: 1 | E17: 鼠标 | F17: blue_mouse | G17: 方法B | H17: EgoAnchor | I17: 1 | J17: 1 | K17: 5 | L17: 4 | M17: 5 | O17: 5 | P17: 5 | Q17: 6 | R17: 5 | S17: 6 | T17: 5 | U17: 6 | V17: 6 | W17: 5 | X17: 5 | Y17: 46237.574 | Z17: 46237.575 | AA17: 89 | AB17: 是 | AC17: 是 | AD17: 是 | AE17: 无 | AF17: 13.88 | AG17: 0.803 | AH17: 0.888 | AI17: 0.987 | AJ17: 0.772 | AK17: FrozenUncertain | AL17: 否 | AM17: 1 | AN17: 2
A18: P003 | B18: 2 | C18: O1-S2-OE | D18: 1 | E18: 鼠标 | F18: blue_mouse | G18: 方法A | H18: One-Euro | I18: 2 | J18: 1 | K18: 5 | L18: 5 | M18: 4 | O18: 7 | P18: 6 | Q18: 5 | R18: 5 | S18: 4 | T18: 5 | U18: 5 | V18: 5 | W18: 4 | X18: 6 | Y18: 46237.576 | Z18: 46237.578 | AA18: 106.3 | AB18: 是 | AC18: 是 | AD18: 是 | AE18: 无 | AF18: 12.83 | AG18: 0.714 | AH18: 0.902 | AI18: 0.996 | AJ18: 0.844 | AK18: FrozenUncertain | AL18: 否 | AM18: 0 | AN18: 0
A19: P003 | B19: 3 | C19: O1-S2-OE | D19: 2 | E19: 固定订书机 | F19: stapler | G19: 方法A | H19: One-Euro | I19: 1 | J19: 2 | K19: 4 | L19: 3 | M19: 4 | O19: 4 | P19: 5 | Q19: 5 | R19: 6 | S19: 5 | T19: 5 | U19: 6 | V19: 5 | W19: 5 | X19: 5 | Y19: 46237.579 | Z19: 46237.579 | AA19: 68.4 | AB19: 是 | AC19: 是 | AD19: 是 | AE19: 无 | AF19: 12.85 | AG19: 0.869 | AH19: 0.92 | AI19: 0.999 | AJ19: 0.732 | AK19: FrozenUncertain | AL19: 否 | AM19: 0 | AN19: 0
A20: P003 | B20: 4 | C20: O1-S2-OE | D20: 2 | E20: 固定订书机 | F20: stapler | G20: 方法B | H20: EgoAnchor | I20: 2 | J20: 2 | K20: 6 | L20: 5 | M20: 5 | O20: 6 | P20: 7 | Q20: 5 | R20: 5 | S20: 4 | T20: 6 | U20: 6 | V20: 6 | W20: 5 | X20: 5 | Y20: 46237.58 | Z20: 46237.581 | AA20: 86.2 | AB20: 是 | AC20: 是 | AD20: 是 | AE20: 无 | AF20: 13.18 | AG20: 0.837 | AH20: 0.878 | AI20: 0.993 | AJ20: 0.766 | AK20: FrozenUncertain | AL20: 否 | AM20: 1 | AN20: 4
A21: P003 | B21: 5 | C21: O1-S2-OE | D21: 3 | E21: 游戏手柄 | F21: gamepad | G21: 方法B | H21: EgoAnchor | I21: 1 | J21: 3 | K21: 6 | L21: 5 | M21: 6 | O21: 5 | P21: 6 | Q21: 6 | R21: 5 | S21: 6 | T21: 6 | U21: 6 | V21: 6 | W21: 6 | X21: 5 | Y21: 46237.582 | Z21: 46237.583 | AA21: 110.5 | AB21: 是 | AC21: 是 | AD21: 是 | AE21: 无 | AF21: 12.53 | AG21: 0.823 | AH21: 0.867 | AI21: 0.995 | AJ21: 0.795 | AK21: FrozenUncertain | AL21: 否 | AM21: 0 | AN21: 2
A22: P003 | B22: 6 | C22: O1-S2-OE | D22: 3 | E22: 游戏手柄 | F22: gamepad | G22: 方法A | H22: One-Euro | I22: 2 | J22: 3 | K22: 5 | L22: 7 | M22: 5 | O22: 6 | P22: 5 | Q22: 4 | R22: 4 | S22: 5 | T22: 4 | U22: 6 | V22: 5 | W22: 4 | X22: 4 | Y22: 46237.584 | Z22: 46237.585 | AA22: 91.7 | AB22: 是 | AC22: 是 | AD22: 是 | AE22: 无 | AF22: 12.3 | AG22: 0.753 | AH22: 0.906 | AI22: 0.993 | AJ22: 0.692 | AK22: FrozenUncertain | AL22: 否 | AM22: 1 | AN22: 0 | AO22: 遮挡恢复后出现一次小跳变
A23: P004 | B23: 1 | C23: O1-S1-OE | D23: 1 | E23: 鼠标 | F23: blue_mouse | G23: 方法A | H23: One-Euro | I23: 1 | J23: 1 | K23: 5 | L23: 4 | M23: 3 | O23: 6 | P23: 3 | Q23: 5 | R23: 5 | S23: 4 | T23: 4 | U23: 5 | V23: 4 | W23: 5 | X23: 4 | Y23: 46237.648 | Z23: 46237.65 | AA23: 126.5 | AB23: 是 | AC23: 是 | AD23: 是 | AE23: 无 | AF23: 12.42 | AG23: 0.722 | AH23: 0.849 | AI23: 1 | AJ23: 0.742 | AK23: FrozenUncertain | AL23: 否 | AM23: 0 | AN23: 0
A24: P004 | B24: 2 | C24: O1-S1-OE | D24: 1 | E24: 鼠标 | F24: blue_mouse | G24: 方法B | H24: EgoAnchor | I24: 2 | J24: 1 | K24: 4 | L24: 5 | M24: 4 | O24: 4 | P24: 5 | Q24: 3 | R24: 5 | S24: 4 | T24: 4 | U24: 6 | V24: 5 | W24: 5 | X24: 5 | Y24: 46237.651 | Z24: 46237.652 | AA24: 105.9 | AB24: 是 | AC24: 是 | AD24: 是 | AE24: 无 | AF24: 13.77 | AG24: 0.765 | AH24: 0.87 | AI24: 0.993 | AJ24: 0.737 | AK24: FrozenUncertain | AL24: 否 | AM24: 1 | AN24: 3
A25: P004 | B25: 3 | C25: O1-S1-OE | D25: 2 | E25: 固定订书机 | F25: stapler | G25: 方法B | H25: EgoAnchor | I25: 1 | J25: 2 | K25: 4 | L25: 4 | M25: 4 | O25: 5 | P25: 5 | Q25: 3 | R25: 6 | S25: 4 | T25: 5 | U25: 4 | V25: 6 | W25: 5 | X25: 4 | Y25: 46237.653 | Z25: 46237.654 | AA25: 98.8 | AB25: 是 | AC25: 是 | AD25: 是 | AE25: 无 | AF25: 12.87 | AG25: 0.796 | AH25: 0.894 | AI25: 0.989 | AJ25: 0.751 | AK25: FrozenUncertain | AL25: 否 | AM25: 2 | AN25: 2 | AO25: 遮挡恢复后出现一次小跳变
A26: P004 | B26: 4 | C26: O1-S1-OE | D26: 2 | E26: 固定订书机 | F26: stapler | G26: 方法A | H26: One-Euro | I26: 2 | J26: 2 | K26: 6 | L26: 4 | M26: 5 | O26: 5 | P26: 4 | Q26: 5 | R26: 4 | S26: 4 | T26: 4 | U26: 5 | V26: 5 | W26: 3 | X26: 3 | Y26: 46237.655 | Z26: 46237.656 | AA26: 110.2 | AB26: 是 | AC26: 是 | AD26: 是 | AE26: 无 | AF26: 12.51 | AG26: 0.865 | AH26: 0.922 | AI26: 0.987 | AJ26: 0.689 | AK26: FrozenUncertain | AL26: 否 | AM26: 1 | AN26: 0
A27: P004 | B27: 5 | C27: O1-S1-OE | D27: 3 | E27: 游戏手柄 | F27: gamepad | G27: 方法A | H27: One-Euro | I27: 1 | J27: 3 | K27: 5 | L27: 4 | M27: 4 | O27: 4 | P27: 5 | Q27: 4 | R27: 5 | S27: 4 | T27: 4 | U27: 4 | V27: 4 | W27: 5 | X27: 4 | Y27: 46237.657 | Z27: 46237.658 | AA27: 103.5 | AB27: 是 | AC27: 是 | AD27: 是 | AE27: 无 | AF27: 13.13 | AG27: 0.779 | AH27: 0.894 | AI27: 0.99 | AJ27: 0.749 | AK27: FrozenUncertain | AL27: 否 | AM27: 1 | AN27: 0
A28: P004 | B28: 6 | C28: O1-S1-OE | D28: 3 | E28: 游戏手柄 | F28: gamepad | G28: 方法B | H28: EgoAnchor | I28: 2 | J28: 3 | K28: 5 | L28: 4 | M28: 6 | O28: 3 | P28: 5 | Q28: 2 | R28: 5 | S28: 4 | T28: 5 | U28: 6 | V28: 3 | W28: 2 | X28: 5 | Y28: 46237.659 | Z28: 46237.661 | AA28: 117.5 | AB28: 是 | AC28: 是 | AD28: 是 | AE28: 无 | AF28: 13.01 | AG28: 0.793 | AH28: 0.852 | AI28: 0.991 | AJ28: 0.742 | AK28: FrozenUncertain | AL28: 否 | AM28: 1 | AN28: 2 | AO28: 拿起时感觉略有滞后
A29: P005 | B29: 1 | C29: O2-S1-EA | D29: 1 | E29: 鼠标 | F29: blue_mouse | G29: 方法A | H29: EgoAnchor | I29: 1 | J29: 1 | K29: 7 | L29: 5 | M29: 4 | O29: 5 | P29: 5 | Q29: 6 | R29: 5 | S29: 6 | T29: 5 | U29: 4 | V29: 5 | W29: 5 | X29: 6 | Y29: 46238.386 | Z29: 46238.388 | AA29: 115.7 | AB29: 是 | AC29: 是 | AD29: 是 | AE29: 无 | AF29: 12.67 | AG29: 0.762 | AH29: 0.826 | AI29: 0.994 | AJ29: 0.767 | AK29: FrozenUncertain | AL29: 否 | AM29: 1 | AN29: 4
A30: P005 | B30: 2 | C30: O2-S1-EA | D30: 1 | E30: 鼠标 | F30: blue_mouse | G30: 方法B | H30: One-Euro | I30: 2 | J30: 1 | K30: 4 | L30: 5 | M30: 5 | O30: 4 | P30: 6 | Q30: 3 | R30: 5 | S30: 4 | T30: 4 | U30: 6 | V30: 5 | W30: 4 | X30: 5 | Y30: 46238.389 | Z30: 46238.39 | AA30: 97.2 | AB30: 是 | AC30: 是 | AD30: 是 | AE30: 短暂帧率波动 | AF30: 13.83 | AG30: 0.728 | AH30: 0.897 | AI30: 0.973 | AJ30: 0.81 | AK30: FrozenUncertain | AL30: 否 | AM30: 1 | AN30: 0 | AO30: 短暂画面卡顿，自动恢复；任务与问卷均完成。
A31: P005 | B31: 3 | C31: O2-S1-EA | D31: 2 | E31: 游戏手柄 | F31: gamepad | G31: 方法B | H31: One-Euro | I31: 1 | J31: 2 | K31: 5 | L31: 5 | M31: 4 | O31: 5 | P31: 5 | Q31: 4 | R31: 4 | S31: 5 | T31: 5 | U31: 6 | V31: 6 | W31: 5 | X31: 5 | Y31: 46238.391 | Z31: 46238.392 | AA31: 100.6 | AB31: 是 | AC31: 是 | AD31: 是 | AE31: 无 | AF31: 12.23 | AG31: 0.79 | AH31: 0.897 | AI31: 0.995 | AJ31: 0.714 | AK31: FrozenUncertain | AL31: 否 | AM31: 1 | AN31: 0
A32: P005 | B32: 4 | C32: O2-S1-EA | D32: 2 | E32: 游戏手柄 | F32: gamepad | G32: 方法A | H32: EgoAnchor | I32: 2 | J32: 2 | K32: 6 | L32: 5 | M32: 6 | O32: 5 | P32: 6 | Q32: 6 | R32: 7 | S32: 5 | T32: 6 | U32: 6 | V32: 5 | W32: 4 | X32: 5 | Y32: 46238.393 | Z32: 46238.394 | AA32: 78.4 | AB32: 是 | AC32: 是 | AD32: 是 | AE32: 无 | AF32: 12.25 | AG32: 0.828 | AH32: 0.844 | AI32: 0.997 | AJ32: 0.79 | AK32: FrozenUncertain | AL32: 否 | AM32: 1 | AN32: 2
A33: P005 | B33: 5 | C33: O2-S1-EA | D33: 3 | E33: 固定订书机 | F33: stapler | G33: 方法A | H33: EgoAnchor | I33: 1 | J33: 3 | K33: 6 | L33: 6 | M33: 6 | O33: 5 | P33: 4 | Q33: 7 | R33: 7 | S33: 5 | T33: 7 | U33: 5 | V33: 6 | W33: 6 | X33: 4 | Y33: 46238.395 | Z33: 46238.396 | AA33: 86.4 | AB33: 是 | AC33: 是 | AD33: 是 | AE33: 无 | AF33: 12.75 | AG33: 0.825 | AH33: 0.92 | AI33: 0.997 | AJ33: 0.748 | AK33: FrozenUncertain | AL33: 否 | AM33: 1 | AN33: 3
A34: P005 | B34: 6 | C34: O2-S1-EA | D34: 3 | E34: 固定订书机 | F34: stapler | G34: 方法B | H34: One-Euro | I34: 2 | J34: 3 | K34: 4 | L34: 3 | M34: 5 | O34: 6 | P34: 5 | Q34: 3 | R34: 4 | S34: 5 | T34: 5 | U34: 6 | V34: 6 | W34: 5 | X34: 5 | Y34: 46238.397 | Z34: 46238.398 | AA34: 86.4 | AB34: 是 | AC34: 是 | AD34: 是 | AE34: 无 | AF34: 12.86 | AG34: 0.8 | AH34: 0.916 | AI34: 0.991 | AJ34: 0.764 | AK34: FrozenUncertain | AL34: 否 | AM34: 1 | AN34: 0
A35: P006 | B35: 1 | C35: O2-S2-EA | D35: 1 | E35: 鼠标 | F35: blue_mouse | G35: 方法B | H35: One-Euro | I35: 1 | J35: 1 | K35: 5 | L35: 4 | M35: 5 | O35: 6 | P35: 5 | Q35: 4 | R35: 5 | S35: 5 | T35: 5 | U35: 5 | V35: 6 | W35: 4 | X35: 4 | Y35: 46238.454 | Z35: 46238.456 | AA35: 97.4 | AB35: 是 | AC35: 是 | AD35: 是 | AE35: 无 | AF35: 13.05 | AG35: 0.765 | AH35: 0.86 | AI35: 0.989 | AJ35: 0.783 | AK35: FrozenUncertain | AL35: 否 | AM35: 1 | AN35: 0 | AO35: 遮挡恢复后出现一次小跳变
A36: P006 | B36: 2 | C36: O2-S2-EA | D36: 1 | E36: 鼠标 | F36: blue_mouse | G36: 方法A | H36: EgoAnchor | I36: 2 | J36: 1 | K36: 4 | L36: 5 | M36: 3 | O36: 4 | P36: 5 | Q36: 5 | R36: 5 | S36: 5 | T36: 5 | U36: 5 | V36: 5 | W36: 5 | X36: 4 | Y36: 46238.457 | Z36: 46238.458 | AA36: 105.3 | AB36: 是 | AC36: 是 | AD36: 是 | AE36: 无 | AF36: 13.26 | AG36: 0.803 | AH36: 0.882 | AI36: 0.995 | AJ36: 0.812 | AK36: FrozenUncertain | AL36: 否 | AM36: 1 | AN36: 2 | AO36: 拿起时感觉略有滞后
A37: P006 | B37: 3 | C37: O2-S2-EA | D37: 2 | E37: 游戏手柄 | F37: gamepad | G37: 方法A | H37: EgoAnchor | I37: 1 | J37: 2 | K37: 4 | L37: 5 | M37: 5 | O37: 4 | P37: 5 | Q37: 6 | R37: 5 | S37: 5 | T37: 5 | U37: 5 | V37: 4 | W37: 5 | X37: 6 | Y37: 46238.459 | Z37: 46238.46 | AA37: 97.7 | AB37: 是 | AC37: 是 | AD37: 是 | AE37: 无 | AF37: 12.72 | AG37: 0.749 | AH37: 0.863 | AI37: 0.988 | AJ37: 0.784 | AK37: FrozenUncertain | AL37: 否 | AM37: 1 | AN37: 4 | AO37: 拿起时感觉略有滞后
A38: P006 | B38: 4 | C38: O2-S2-EA | D38: 2 | E38: 游戏手柄 | F38: gamepad | G38: 方法B | H38: One-Euro | I38: 2 | J38: 2 | K38: 3 | L38: 4 | M38: 4 | O38: 4 | P38: 4 | Q38: 3 | R38: 6 | S38: 5 | T38: 5 | U38: 5 | V38: 5 | W38: 4 | X38: 5 | Y38: 46238.461 | Z38: 46238.462 | AA38: 84 | AB38: 是 | AC38: 是 | AD38: 是 | AE38: 无 | AF38: 13.36 | AG38: 0.771 | AH38: 0.861 | AI38: 0.988 | AJ38: 0.764 | AK38: FrozenUncertain | AL38: 否 | AM38: 0 | AN38: 0
A39: P006 | B39: 5 | C39: O2-S2-EA | D39: 3 | E39: 固定订书机 | F39: stapler | G39: 方法B | H39: One-Euro | I39: 1 | J39: 3 | K39: 3 | L39: 4 | M39: 5 | O39: 6 | P39: 4 | Q39: 3 | R39: 5 | S39: 4 | T39: 4 | U39: 5 | V39: 4 | W39: 5 | X39: 5 | Y39: 46238.462 | Z39: 46238.463 | AA39: 65.3 | AB39: 是 | AC39: 是 | AD39: 是 | AE39: 无 | AF39: 12.81 | AG39: 0.763 | AH39: 0.943 | AI39: 0.99 | AJ39: 0.752 | AK39: FrozenUncertain | AL39: 否 | AM39: 1 | AN39: 0
A40: P006 | B40: 6 | C40: O2-S2-EA | D40: 3 | E40: 固定订书机 | F40: stapler | G40: 方法A | H40: EgoAnchor | I40: 2 | J40: 3 | K40: 5 | L40: 4 | M40: 5 | O40: 5 | P40: 5 | Q40: 5 | R40: 6 | S40: 5 | T40: 6 | U40: 5 | V40: 5 | W40: 5 | X40: 5 | Y40: 46238.464 | Z40: 46238.466 | AA40: 115.5 | AB40: 是 | AC40: 是 | AD40: 是 | AE40: 无 | AF40: 12.41 | AG40: 0.792 | AH40: 0.896 | AI40: 0.991 | AJ40: 0.752 | AK40: FrozenUncertain | AL40: 否 | AM40: 1 | AN40: 2
A41: P007 | B41: 1 | C41: O2-S2-OE | D41: 1 | E41: 鼠标 | F41: blue_mouse | G41: 方法B | H41: EgoAnchor | I41: 1 | J41: 1 | K41: 5 | L41: 6 | M41: 5 | O41: 6 | P41: 6 | Q41: 5 | R41: 6 | S41: 5 | T41: 5 | U41: 6 | V41: 6 | W41: 3 | X41: 5 | Y41: 46238.57 | Z41: 46238.572 | AA41: 116.9 | AB41: 是 | AC41: 是 | AD41: 是 | AE41: 无 | AF41: 12.44 | AG41: 0.774 | AH41: 0.894 | AI41: 0.997 | AJ41: 0.762 | AK41: FrozenUncertain | AL41: 否 | AM41: 1 | AN41: 2
...

Sheet Analysis
A1: 【SYNTHETIC / 模拟分析结果】GPT-5.6-Thinking v3；仅用于流程、计分与分析管线验证，不得作为真实被试证据
A2: 核心模拟模式：EgoAnchor 在静止稳定、位置正确、遮挡恢复、依赖意愿与总体稳定—响应平衡上较高；运动附着与姿态一致差异较小。所有推断仅描述该合成生成结果。
A3: A. 主证实家族（三物体均值 → 配对 Wilcoxon → 家族内 Holm） | M3: 快速结果 | N3: One-Euro M | O3: EgoAnchor M | P3: EA−OE
A4: 条目 | B4: 简称 | C4: One-Euro Mdn[IQR] | D4: EgoAnchor Mdn[IQR] | E4: 配对差中位 | F4: W | G4: p_raw | H4: p_Holm | I4: 匹配秩双列r | J4: r 95%CI | K4: 结论 | M4: Q1 静止稳定 | N4: 4.25 | O4: 5.1944444 | P4: 0.94444444
A5: Q1 | B5: 静止稳定 | C5: 4.33 [3.92, 4.67] | D5: 5.00 [4.58, 5.67] | E5: 1 | F5: 14.5 | G5: 0.00016965555 | H5: 0.0011875888 | I5: 0.89492754 | J5: [0.67, 1.00] | K5: EgoAnchor 更高（Holm 校正后显著） | M5: Q8 位置正确 | N5: 4.4722222 | O5: 5.1666667 | P5: 0.69444444
A6: Q8 | B6: 位置正确 | C6: 4.67 [4.00, 5.00] | D6: 5.00 [4.67, 5.75] | E6: 0.66666667 | F6: 18 | G6: 0.0011314977 | H6: 0.0056574886 | I6: 0.82857143 | J6: [0.54, 1.00] | K6: EgoAnchor 更高（Holm 校正后显著） | M6: Q2 运动附着 | N6: 4.875 | O6: 4.9861111 | P6: 0.11111111
A7: Q2 | B7: 运动附着 | C7: 5.00 [4.33, 5.08] | D7: 5.17 [4.58, 5.33] | E7: 0.33333333 | F7: 72.5 | G7: 0.36175458 | H7: 0.72350917 | I7: 0.23684211 | J7: [-0.28, 0.75] | K7: Holm 校正后未检出差异 | M7: Q9 姿态一致 | N7: 4.8888889 | O7: 4.9861111 | P7: 0.097222222
A8: Q9 | B8: 姿态一致 | C8: 4.67 [4.67, 5.33] | D8: 5.00 [4.58, 5.33] | E8: 0.16666667 | F8: 115.5 | G8: 0.49162625 | H8: 0.72350917 | I8: 0.16304348 | J8: [-0.32, 0.60] | K8: Holm 校正后未检出差异 | M8: Q3 恢复一致 | N8: 4.1527778 | O8: 4.9583333 | P8: 0.80555556
A9: Q3 | B9: 恢复一致 | C9: 4.17 [3.92, 4.33] | D9: 5.00 [4.33, 5.42] | E9: 0.83333333 | F9: 35 | G9: 0.0029231295 | H9: 0.0087693884 | I9: 0.72332016 | J9: [0.33, 0.99] | K9: EgoAnchor 更高（Holm 校正后显著） | M9: Q6 依赖意愿 | N9: 4.1527778 | O9: 4.8888889 | P9: 0.73611111
A10: Q6 | B10: 依赖意愿 | C10: 4.00 [4.00, 4.33] | D10: 5.00 [4.33, 5.33] | E10: 1 | F10: 14.5 | G10: 0.00026884981 | H10: 0.0016130989 | I10: 0.88537549 | J10: [0.66, 1.00] | K10: EgoAnchor 更高（Holm 校正后显著） | M10: Q7 稳定-响应平衡 | N10: 4.4305556 | O10: 4.9027778 | P10: 0.47222222
A11: Q7 | B11: 稳定-响应平衡 | C11: 4.50 [4.25, 4.75] | D11: 4.83 [4.58, 5.33] | E11: 0.33333333 | F11: 4 | G11: 0.0014471173 | H11: 0.0057884693 | I11: 0.93333333 | J11: [0.73, 1.00] | K11: EgoAnchor 更高（Holm 校正后显著）
A13: B. 已发表量表家族（TiA 反向项先按 6−raw 换向；α 为 Cronbach's α；ω 为单因子标准化 PCA 近似，仅作管线检查）
A14: 量表 | B14: One-Euro Mdn [IQR] | C14: EgoAnchor Mdn [IQR] | D14: 配对差中位 | E14: W | F14: p_raw | G14: p_Holm | H14: 匹配秩双列 r | I14: α(OE) | J14: α(EA) | K14: ω(OE) | L14: ω(EA) | M14: 结论
A15: AQ-EQ（3 项均值） | B15: 4.78 [4.50, 5.03] | C15: 5.17 [4.50, 5.47] | D15: 0.44444444 | E15: 32.5 | F15: 0.0022627867 | G15: 0.0078660722 | H15: 0.743083 | I15: 0.76806236 | J15: 0.76875122 | K15: 0.86600306 | L15: 0.86724195 | M15: EgoAnchor 更高（Holm 校正后显著）
A16: AQ-IQ（3 项均值） | B16: 4.89 [4.64, 5.14] | C16: 5.06 [4.50, 5.33] | D16: 0.055555556 | E16: 104.5 | F16: 0.4744058 | G16: 0.4744058 | H16: 0.17391304 | I16: 0.50420168 | J16: 0.89236452 | K16: 0.75174992 | L16: 0.93561649 | M16: Holm 校正后未检出差异
A17: TiA-R/C（6 项均值） | B17: 4.17 [3.83, 4.50] | C17: 4.58 [4.29, 4.83] | D17: 0.33333333 | E17: 0 | F17: 0.00012916383 | G17: 0.00064581917 | H17: 1 | I17: 0.79179811 | J17: 0.75114504 | K17: 0.85669505 | L17: 0.83003478 | M17: EgoAnchor 更高（Holm 校正后显著）
A18: TiA-U/P（4 项均值） | B18: 4.00 [3.94, 4.25] | C18: 4.38 [4.00, 5.00] | D18: 0.375 | E18: 32 | F18: 0.0019665181 | G18: 0.0078660722 | H18: 0.74703557 | I18: 0.56455493 | J18: 0.76857749 | K18: 0.76017655 | L18: 0.85324061 | M18: EgoAnchor 更高（Holm 校正后显著）
A19: S-TIAS（3 项均值） | B19: 5.33 [4.92, 5.67] | C19: 5.67 [5.33, 6.00] | D19: 0.5 | E19: 25 | F19: 0.0026651357 | G19: 0.0078660722 | H19: 0.76190476 | I19: 0.67167102 | J19: 0.69726248 | K19: 0.82971471 | L19: 0.83028327 | M19: EgoAnchor 更高（Holm 校正后显著）
A21: C. 次级序数模型（本环境用参与者固定效应累积 logit 近似 CLMM；正式分析须改用参与者随机截距 CLMM）
A22: 结局 | B22: 固定效应 | C22: 共同优势比 | D22: 95%CI | E22: p | F22: 备注
A23: Q1 | B23: EgoAnchor vs One-Euro（对象特异） | C23: 鼠标 6.55; 订书机 32.41; 手柄 27.55 | D23: 鼠标 [1.99,21.55]; 订书机 [8.87,118.47]; 手柄 [8.09,93.83] | E23: 鼠标 0.002; 订书机 0.000; 手柄 0.000 | F23: 参与者固定效应累积logit近似；含方法×物体、区块位置、对象内先后；正式论文改用CLMM随机截距
A24: Q8 | B24: EgoAnchor vs One-Euro（对象特异） | C24: 鼠标 4.38; 订书机 8.19; 手柄 12.40 | D24: 鼠标 [1.38,13.88]; 订书机 [2.46,27.25]; 手柄 [3.55,43.28] | E24: 鼠标 0.012; 订书机 0.001; 手柄 0.000 | F24: 参与者固定效应累积logit近似；含方法×物体、区块位置、对象内先后；正式论文改用CLMM随机截距
A25: Q2 | B25: EgoAnchor vs One-Euro（对象特异） | C25: 鼠标 1.68; 订书机 0.83; 手柄 2.70 | D25: 鼠标 [0.57,4.96]; 订书机 [0.27,2.52]; 手柄 [0.89,8.23] | E25: 鼠标 0.343; 订书机 0.741; 手柄 0.081 | F25: 参与者固定效应累积logit近似；含方法×物体、区块位置、对象内先后；正式论文改用CLMM随机截距
A26: Q9 | B26: EgoAnchor vs One-Euro（对象特异） | C26: 鼠标 1.31; 订书机 0.96; 手柄 1.96 | D26: 鼠标 [0.45,3.88]; 订书机 [0.32,2.89]; 手柄 [0.65,5.94] | E26: 鼠标 0.621; 订书机 0.949; 手柄 0.235 | F26: 参与者固定效应累积logit近似；含方法×物体、区块位置、对象内先后；正式论文改用CLMM随机截距
A27: Q3 | B27: EgoAnchor vs One-Euro（对象特异） | C27: 鼠标 3.45; 订书机 10.18; 手柄 6.34 | D27: 鼠标 [1.19,9.96]; 订书机 [3.11,33.32]; 手柄 [2.09,19.25] | E27: 鼠标 0.022; 订书机 0.000; 手柄 0.001 | F27: 参与者固定效应累积logit近似；含方法×物体、区块位置、对象内先后；正式论文改用CLMM随机截距
A28: Q6 | B28: EgoAnchor vs One-Euro（对象特异） | C28: 鼠标 3.71; 订书机 6.89; 手柄 14.52 | D28: 鼠标 [1.22,11.25]; 订书机 [2.19,21.66]; 手柄 [4.43,47.59] | E28: 鼠标 0.020; 订书机 0.001; 手柄 0.000 | F28: 参与者固定效应累积logit近似；含方法×物体、区块位置、对象内先后；正式论文改用CLMM随机截距
A29: Q7 | B29: EgoAnchor vs One-Euro（对象特异） | C29: 鼠标 1.34; 订书机 2.05; 手柄 17.29 | D29: 鼠标 [0.44,4.05]; 订书机 [0.65,6.41]; 手柄 [5.10,58.60] | E29: 鼠标 0.606; 订书机 0.218; 手柄 0.000 | F29: 参与者固定效应累积logit近似；含方法×物体、区块位置、对象内先后；正式论文改用CLMM随机截距
A30: 模型说明 | B30: 非正式CLMM | F30: 每个条目含方法、物体、方法×物体、区块位置、对象内先后及参与者固定效应；OR 为各物体内 EgoAnchor 相对 One-Euro 的比例优势比。
A40: D. 逐物体描述（探索性；方向一致性检查，不作未校正的逐物体检验）
A41: 结局 | B41: 物体 | C41: One-Euro M | D41: EgoAnchor M | E41: 差值 | F41: 方向 | G41: 备注
A42: Q1 | B42: 鼠标 | C42: 4.375 | D42: 5 | E42: 0.625 | F42: EgoAnchor↑ | G42: n=24/方法；描述性
A43: Q1 | B43: 固定订书机 | C43: 4.0833333 | D43: 5.1666667 | E43: 1.0833333 | F43: EgoAnchor↑ | G43: n=24/方法；描述性
A44: Q1 | B44: 游戏手柄 | C44: 4.2916667 | D44: 5.4166667 | E44: 1.125 | F44: EgoAnchor↑ | G44: n=24/方法；描述性
A45: Q2 | B45: 鼠标 | C45: 4.875 | D45: 5.0416667 | E45: 0.16666667 | F45: EgoAnchor↑ | G45: n=24/方法；描述性
A46: Q2 | B46: 固定订书机 | C46: 4.9583333 | D46: 4.9166667 | E46: -0.041666667 | F46: 近似相同 | G46: n=24/方法；描述性
A47: Q2 | B47: 游戏手柄 | C47: 4.7916667 | D47: 5 | E47: 0.20833333 | F47: EgoAnchor↑ | G47: n=24/方法；描述性
A48: Q9 | B48: 鼠标 | C48: 4.7083333 | D48: 4.75 | E48: 0.041666667 | F48: 近似相同 | G48: n=24/方法；描述性
A49: Q9 | B49: 固定订书机 | C49: 5.2083333 | D49: 5.2083333 | E49: 0 | F49: 近似相同 | G49: n=24/方法；描述性
A50: Q9 | B50: 游戏手柄 | C50: 4.75 | D50: 5 | E50: 0.25 | F50: EgoAnchor↑ | G50: n=24/方法；描述性
A51: Q10_OPT | B51: 鼠标 | F51: 未启用 | G51: Q10 默认停用
...

Sheet Synthetic_Notice
A1: SYNTHETIC DATA NOTICE / 模拟数据声明
A3: 字段 | B3: 内容
A4: 模型 | B4: GPT-5.6-Thinking
A5: 版本 | B5: v3
A6: 生成日期 | B6: 2026-07-27
A7: 主随机种子 | B7: 560327
A8: 模拟规模 | B8: 24 名独立模拟参与者；144 个方法×物体区块；48 份方法级问卷；24 份最终问卷
A9: 数据性质 | B9: 全部为合成数据，不代表真实人类参与者，不得作为 IEEE VR 论文的实证结果或伦理审批下的被试数据。
A10: 已读取输入 | B10: 实验三 v5.1 空白采集模板、论文手稿中的实验三设计、replay_grid 图与 JSON 配置。
A11: 明确未读取 | B11: task_4_complete(3).xlsx、task_5_complete(4).xlsx，以及任何其他既有模拟结果。
A12: 独立性 | B12: 每位模拟参与者使用独立随机种子，并具有独立的人口学、经验、稳定性偏好、响应性偏好、信任倾向、疲劳与噪声。
A14: 用途边界：本工作簿用于流程演练、问卷计分公式验证、分析脚本调试与功效/稳健性管线测试。正式投稿中的用户研究结果必须由真实招募、知情同意、伦理审批/豁免与冻结协议下的实际采集产生。

Sheet Formula_Scores
A1: Formula-driven questionnaire subscores / 公式驱动问卷小分
A2: 所有小分直接引用 Records 原始应答；修改原始分后，Excel 将自动重算。TiA 反向项仅在本表派生，不覆盖原始分。
A4: Participant_ID | B4: Block_Index | C4: 物体 | D4: Shown_Label | E4: Condition | F4: Q1 | G4: Q8 | H4: Q2 | I4: Q9 | J4: Q3 | K4: Q6 | L4: Q7 | M4: AQ_EQ_mean | N4: AQ_IQ_mean | O4: Block_Valid | P4: Source_Row
A5: =Records!A5 -> P001 | B5: =Records!B5 -> 1 | C5: =Records!E5 -> 鼠标 | D5: =Records!G5 -> 方法A | E5: =Records!H5 -> EgoAnchor | F5: =Records!K5 -> 5 | G5: =Records!R5 -> 5 | H5: =Records!L5 -> 5 | I5: =Records!M5 -> 5 | J5: =Records!Q5 -> 5 | K5: =Records!W5 -> 4 | L5: =Records!X5 -> 5 | M5: =IF(COUNT(Records!S5:U5)=0,"",AVERAGE(Records!S5:U5)) -> 5 | N5: =IF(COUNT(Records!O5,Records!P5,Records!V5)=0,"",AVERAGE(Records!O5,Records!P5,Records!V5)) -> 4.6666667 | O5: =Records!AD5 -> 是 | P5: =5 -> 5
A6: =Records!A6 -> P001 | B6: =Records!B6 -> 2 | C6: =Records!E6 -> 鼠标 | D6: =Records!G6 -> 方法B | E6: =Records!H6 -> One-Euro | F6: =Records!K6 -> 3 | G6: =Records!R6 -> 5 | H6: =Records!L6 -> 6 | I6: =Records!M6 -> 4 | J6: =Records!Q6 -> 4 | K6: =Records!W6 -> 3 | L6: =Records!X6 -> 4 | M6: =IF(COUNT(Records!S6:U6)=0,"",AVERAGE(Records!S6:U6)) -> 4.6666667 | N6: =IF(COUNT(Records!O6,Records!P6,Records!V6)=0,"",AVERAGE(Records!O6,Records!P6,Records!V6)) -> 5.3333333 | O6: =Records!AD6 -> 是 | P6: =6 -> 6
A7: =Records!A7 -> P001 | B7: =Records!B7 -> 3 | C7: =Records!E7 -> 固定订书机 | D7: =Records!G7 -> 方法B | E7: =Records!H7 -> One-Euro | F7: =Records!K7 -> 4 | G7: =Records!R7 -> 6 | H7: =Records!L7 -> 4 | I7: =Records!M7 -> 3 | J7: =Records!Q7 -> 3 | K7: =Records!W7 -> 5 | L7: =Records!X7 -> 5 | M7: =IF(COUNT(Records!S7:U7)=0,"",AVERAGE(Records!S7:U7)) -> 5.3333333 | N7: =IF(COUNT(Records!O7,Records!P7,Records!V7)=0,"",AVERAGE(Records!O7,Records!P7,Records!V7)) -> 4.6666667 | O7: =Records!AD7 -> 是 | P7: =7 -> 7
A8: =Records!A8 -> P001 | B8: =Records!B8 -> 4 | C8: =Records!E8 -> 固定订书机 | D8: =Records!G8 -> 方法A | E8: =Records!H8 -> EgoAnchor | F8: =Records!K8 -> 5 | G8: =Records!R8 -> 6 | H8: =Records!L8 -> 6 | I8: =Records!M8 -> 5 | J8: =Records!Q8 -> 6 | K8: =Records!W8 -> 6 | L8: =Records!X8 -> 4 | M8: =IF(COUNT(Records!S8:U8)=0,"",AVERAGE(Records!S8:U8)) -> 5.3333333 | N8: =IF(COUNT(Records!O8,Records!P8,Records!V8)=0,"",AVERAGE(Records!O8,Records!P8,Records!V8)) -> 5 | O8: =Records!AD8 -> 是 | P8: =8 -> 8
A9: =Records!A9 -> P001 | B9: =Records!B9 -> 5 | C9: =Records!E9 -> 游戏手柄 | D9: =Records!G9 -> 方法A | E9: =Records!H9 -> EgoAnchor | F9: =Records!K9 -> 5 | G9: =Records!R9 -> 5 | H9: =Records!L9 -> 5 | I9: =Records!M9 -> 4 | J9: =Records!Q9 -> 5 | K9: =Records!W9 -> 5 | L9: =Records!X9 -> 5 | M9: =IF(COUNT(Records!S9:U9)=0,"",AVERAGE(Records!S9:U9)) -> 4.3333333 | N9: =IF(COUNT(Records!O9,Records!P9,Records!V9)=0,"",AVERAGE(Records!O9,Records!P9,Records!V9)) -> 5 | O9: =Records!AD9 -> 是 | P9: =9 -> 9
A10: =Records!A10 -> P001 | B10: =Records!B10 -> 6 | C10: =Records!E10 -> 游戏手柄 | D10: =Records!G10 -> 方法B | E10: =Records!H10 -> One-Euro | F10: =Records!K10 -> 3 | G10: =Records!R10 -> 5 | H10: =Records!L10 -> 5 | I10: =Records!M10 -> 6 | J10: =Records!Q10 -> 4 | K10: =Records!W10 -> 4 | L10: =Records!X10 -> 4 | M10: =IF(COUNT(Records!S10:U10)=0,"",AVERAGE(Records!S10:U10)) -> 4 | N10: =IF(COUNT(Records!O10,Records!P10,Records!V10)=0,"",AVERAGE(Records!O10,Records!P10,Records!V10)) -> 4.6666667 | O10: =Records!AD10 -> 是 | P10: =10 -> 10
A11: =Records!A11 -> P002 | B11: =Records!B11 -> 1 | C11: =Records!E11 -> 鼠标 | D11: =Records!G11 -> 方法B | E11: =Records!H11 -> One-Euro | F11: =Records!K11 -> 5 | G11: =Records!R11 -> 5 | H11: =Records!L11 -> 7 | I11: =Records!M11 -> 4 | J11: =Records!Q11 -> 6 | K11: =Records!W11 -> 4 | L11: =Records!X11 -> 6 | M11: =IF(COUNT(Records!S11:U11)=0,"",AVERAGE(Records!S11:U11)) -> 5.3333333 | N11: =IF(COUNT(Records!O11,Records!P11,Records!V11)=0,"",AVERAGE(Records!O11,Records!P11,Records!V11)) -> 5.6666667 | O11: =Records!AD11 -> 是 | P11: =11 -> 11
A12: =Records!A12 -> P002 | B12: =Records!B12 -> 2 | C12: =Records!E12 -> 鼠标 | D12: =Records!G12 -> 方法A | E12: =Records!H12 -> EgoAnchor | F12: =Records!K12 -> 5 | G12: =Records!R12 -> 5 | H12: =Records!L12 -> 7 | I12: =Records!M12 -> 6 | J12: =Records!Q12 -> 6 | K12: =Records!W12 -> 7 | L12: =Records!X12 -> 6 | M12: =IF(COUNT(Records!S12:U12)=0,"",AVERAGE(Records!S12:U12)) -> 6 | N12: =IF(COUNT(Records!O12,Records!P12,Records!V12)=0,"",AVERAGE(Records!O12,Records!P12,Records!V12)) -> 4.6666667 | O12: =Records!AD12 -> 是 | P12: =12 -> 12
A13: =Records!A13 -> P002 | B13: =Records!B13 -> 3 | C13: =Records!E13 -> 固定订书机 | D13: =Records!G13 -> 方法A | E13: =Records!H13 -> EgoAnchor | F13: =Records!K13 -> 5 | G13: =Records!R13 -> 6 | H13: =Records!L13 -> 5 | I13: =Records!M13 -> 6 | J13: =Records!Q13 -> 7 | K13: =Records!W13 -> 7 | L13: =Records!X13 -> 6 | M13: =IF(COUNT(Records!S13:U13)=0,"",AVERAGE(Records!S13:U13)) -> 5.3333333 | N13: =IF(COUNT(Records!O13,Records!P13,Records!V13)=0,"",AVERAGE(Records!O13,Records!P13,Records!V13)) -> 6.3333333 | O13: =Records!AD13 -> 是 | P13: =13 -> 13
A14: =Records!A14 -> P002 | B14: =Records!B14 -> 4 | C14: =Records!E14 -> 固定订书机 | D14: =Records!G14 -> 方法B | E14: =Records!H14 -> One-Euro | F14: =Records!K14 -> 5 | G14: =Records!R14 -> 5 | H14: =Records!L14 -> 7 | I14: =Records!M14 -> 5 | J14: =Records!Q14 -> 3 | K14: =Records!W14 -> 5 | L14: =Records!X14 -> 5 | M14: =IF(COUNT(Records!S14:U14)=0,"",AVERAGE(Records!S14:U14)) -> 5.3333333 | N14: =IF(COUNT(Records!O14,Records!P14,Records!V14)=0,"",AVERAGE(Records!O14,Records!P14,Records!V14)) -> 6.3333333 | O14: =Records!AD14 -> 是 | P14: =14 -> 14
A15: =Records!A15 -> P002 | B15: =Records!B15 -> 5 | C15: =Records!E15 -> 游戏手柄 | D15: =Records!G15 -> 方法B | E15: =Records!H15 -> One-Euro | F15: =Records!K15 -> 4 | G15: =Records!R15 -> 4 | H15: =Records!L15 -> 5 | I15: =Records!M15 -> 4 | J15: =Records!Q15 -> 5 | K15: =Records!W15 -> 6 | L15: =Records!X15 -> 3 | M15: =IF(COUNT(Records!S15:U15)=0,"",AVERAGE(Records!S15:U15)) -> 5 | N15: =IF(COUNT(Records!O15,Records!P15,Records!V15)=0,"",AVERAGE(Records!O15,Records!P15,Records!V15)) -> 5 | O15: =Records!AD15 -> 是 | P15: =15 -> 15
A16: =Records!A16 -> P002 | B16: =Records!B16 -> 6 | C16: =Records!E16 -> 游戏手柄 | D16: =Records!G16 -> 方法A | E16: =Records!H16 -> EgoAnchor | F16: =Records!K16 -> 6 | G16: =Records!R16 -> 7 | H16: =Records!L16 -> 3 | I16: =Records!M16 -> 6 | J16: =Records!Q16 -> 6 | K16: =Records!W16 -> 6 | L16: =Records!X16 -> 4 | M16: =IF(COUNT(Records!S16:U16)=0,"",AVERAGE(Records!S16:U16)) -> 5.6666667 | N16: =IF(COUNT(Records!O16,Records!P16,Records!V16)=0,"",AVERAGE(Records!O16,Records!P16,Records!V16)) -> 5.6666667 | O16: =Records!AD16 -> 是 | P16: =16 -> 16
A17: =Records!A17 -> P003 | B17: =Records!B17 -> 1 | C17: =Records!E17 -> 鼠标 | D17: =Records!G17 -> 方法B | E17: =Records!H17 -> EgoAnchor | F17: =Records!K17 -> 5 | G17: =Records!R17 -> 5 | H17: =Records!L17 -> 4 | I17: =Records!M17 -> 5 | J17: =Records!Q17 -> 6 | K17: =Records!W17 -> 5 | L17: =Records!X17 -> 5 | M17: =IF(COUNT(Records!S17:U17)=0,"",AVERAGE(Records!S17:U17)) -> 5.6666667 | N17: =IF(COUNT(Records!O17,Records!P17,Records!V17)=0,"",AVERAGE(Records!O17,Records!P17,Records!V17)) -> 5.3333333 | O17: =Records!AD17 -> 是 | P17: =17 -> 17
A18: =Records!A18 -> P003 | B18: =Records!B18 -> 2 | C18: =Records!E18 -> 鼠标 | D18: =Records!G18 -> 方法A | E18: =Records!H18 -> One-Euro | F18: =Records!K18 -> 5 | G18: =Records!R18 -> 5 | H18: =Records!L18 -> 5 | I18: =Records!M18 -> 4 | J18: =Records!Q18 -> 5 | K18: =Records!W18 -> 4 | L18: =Records!X18 -> 6 | M18: =IF(COUNT(Records!S18:U18)=0,"",AVERAGE(Records!S18:U18)) -> 4.6666667 | N18: =IF(COUNT(Records!O18,Records!P18,Records!V18)=0,"",AVERAGE(Records!O18,Records!P18,Records!V18)) -> 6 | O18: =Records!AD18 -> 是 | P18: =18 -> 18
A19: =Records!A19 -> P003 | B19: =Records!B19 -> 3 | C19: =Records!E19 -> 固定订书机 | D19: =Records!G19 -> 方法A | E19: =Records!H19 -> One-Euro | F19: =Records!K19 -> 4 | G19: =Records!R19 -> 6 | H19: =Records!L19 -> 3 | I19: =Records!M19 -> 4 | J19: =Records!Q19 -> 5 | K19: =Records!W19 -> 5 | L19: =Records!X19 -> 5 | M19: =IF(COUNT(Records!S19:U19)=0,"",AVERAGE(Records!S19:U19)) -> 5.3333333 | N19: =IF(COUNT(Records!O19,Records!P19,Records!V19)=0,"",AVERAGE(Records!O19,Records!P19,Records!V19)) -> 4.6666667 | O19: =Records!AD19 -> 是 | P19: =19 -> 19
A20: =Records!A20 -> P003 | B20: =Records!B20 -> 4 | C20: =Records!E20 -> 固定订书机 | D20: =Records!G20 -> 方法B | E20: =Records!H20 -> EgoAnchor | F20: =Records!K20 -> 6 | G20: =Records!R20 -> 5 | H20: =Records!L20 -> 5 | I20: =Records!M20 -> 5 | J20: =Records!Q20 -> 5 | K20: =Records!W20 -> 5 | L20: =Records!X20 -> 5 | M20: =IF(COUNT(Records!S20:U20)=0,"",AVERAGE(Records!S20:U20)) -> 5.3333333 | N20: =IF(COUNT(Records!O20,Records!P20,Records!V20)=0,"",AVERAGE(Records!O20,Records!P20,Records!V20)) -> 6.3333333 | O20: =Records!AD20 -> 是 | P20: =20 -> 20
A21: =Records!A21 -> P003 | B21: =Records!B21 -> 5 | C21: =Records!E21 -> 游戏手柄 | D21: =Records!G21 -> 方法B | E21: =Records!H21 -> EgoAnchor | F21: =Records!K21 -> 6 | G21: =Records!R21 -> 5 | H21: =Records!L21 -> 5 | I21: =Records!M21 -> 6 | J21: =Records!Q21 -> 6 | K21: =Records!W21 -> 6 | L21: =Records!X21 -> 5 | M21: =IF(COUNT(Records!S21:U21)=0,"",AVERAGE(Records!S21:U21)) -> 6 | N21: =IF(COUNT(Records!O21,Records!P21,Records!V21)=0,"",AVERAGE(Records!O21,Records!P21,Records!V21)) -> 5.6666667 | O21: =Records!AD21 -> 是 | P21: =21 -> 21
A22: =Records!A22 -> P003 | B22: =Records!B22 -> 6 | C22: =Records!E22 -> 游戏手柄 | D22: =Records!G22 -> 方法A | E22: =Records!H22 -> One-Euro | F22: =Records!K22 -> 5 | G22: =Records!R22 -> 4 | H22: =Records!L22 -> 7 | I22: =Records!M22 -> 5 | J22: =Records!Q22 -> 4 | K22: =Records!W22 -> 4 | L22: =Records!X22 -> 4 | M22: =IF(COUNT(Records!S22:U22)=0,"",AVERAGE(Records!S22:U22)) -> 5 | N22: =IF(COUNT(Records!O22,Records!P22,Records!V22)=0,"",AVERAGE(Records!O22,Records!P22,Records!V22)) -> 5.3333333 | O22: =Records!AD22 -> 是 | P22: =22 -> 22
A23: =Records!A23 -> P004 | B23: =Records!B23 -> 1 | C23: =Records!E23 -> 鼠标 | D23: =Records!G23 -> 方法A | E23: =Records!H23 -> One-Euro | F23: =Records!K23 -> 5 | G23: =Records!R23 -> 5 | H23: =Records!L23 -> 4 | I23: =Records!M23 -> 3 | J23: =Records!Q23 -> 5 | K23: =Records!W23 -> 5 | L23: =Records!X23 -> 4 | M23: =IF(COUNT(Records!S23:U23)=0,"",AVERAGE(Records!S23:U23)) -> 4.3333333 | N23: =IF(COUNT(Records!O23,Records!P23,Records!V23)=0,"",AVERAGE(Records!O23,Records!P23,Records!V23)) -> 4.3333333 | O23: =Records!AD23 -> 是 | P23: =23 -> 23
A24: =Records!A24 -> P004 | B24: =Records!B24 -> 2 | C24: =Records!E24 -> 鼠标 | D24: =Records!G24 -> 方法B | E24: =Records!H24 -> EgoAnchor | F24: =Records!K24 -> 4 | G24: =Records!R24 -> 5 | H24: =Records!L24 -> 5 | I24: =Records!M24 -> 4 | J24: =Records!Q24 -> 3 | K24: =Records!W24 -> 5 | L24: =Records!X24 -> 5 | M24: =IF(COUNT(Records!S24:U24)=0,"",AVERAGE(Records!S24:U24)) -> 4.6666667 | N24: =IF(COUNT(Records!O24,Records!P24,Records!V24)=0,"",AVERAGE(Records!O24,Records!P24,Records!V24)) -> 4.6666667 | O24: =Records!AD24 -> 是 | P24: =24 -> 24
A25: =Records!A25 -> P004 | B25: =Records!B25 -> 3 | C25: =Records!E25 -> 固定订书机 | D25: =Records!G25 -> 方法B | E25: =Records!H25 -> EgoAnchor | F25: =Records!K25 -> 4 | G25: =Records!R25 -> 6 | H25: =Records!L25 -> 4 | I25: =Records!M25 -> 4 | J25: =Records!Q25 -> 3 | K25: =Records!W25 -> 5 | L25: =Records!X25 -> 4 | M25: =IF(COUNT(Records!S25:U25)=0,"",AVERAGE(Records!S25:U25)) -> 4.3333333 | N25: =IF(COUNT(Records!O25,Records!P25,Records!V25)=0,"",AVERAGE(Records!O25,Records!P25,Records!V25)) -> 5.3333333 | O25: =Records!AD25 -> 是 | P25: =25 -> 25
A26: =Records!A26 -> P004 | B26: =Records!B26 -> 4 | C26: =Records!E26 -> 固定订书机 | D26: =Records!G26 -> 方法A | E26: =Records!H26 -> One-Euro | F26: =Records!K26 -> 6 | G26: =Records!R26 -> 4 | H26: =Records!L26 -> 4 | I26: =Records!M26 -> 5 | J26: =Records!Q26 -> 5 | K26: =Records!W26 -> 3 | L26: =Records!X26 -> 3 | M26: =IF(COUNT(Records!S26:U26)=0,"",AVERAGE(Records!S26:U26)) -> 4.3333333 | N26: =IF(COUNT(Records!O26,Records!P26,Records!V26)=0,"",AVERAGE(Records!O26,Records!P26,Records!V26)) -> 4.6666667 | O26: =Records!AD26 -> 是 | P26: =26 -> 26
A27: =Records!A27 -> P004 | B27: =Records!B27 -> 5 | C27: =Records!E27 -> 游戏手柄 | D27: =Records!G27 -> 方法A | E27: =Records!H27 -> One-Euro | F27: =Records!K27 -> 5 | G27: =Records!R27 -> 5 | H27: =Records!L27 -> 4 | I27: =Records!M27 -> 4 | J27: =Records!Q27 -> 4 | K27: =Records!W27 -> 5 | L27: =Records!X27 -> 4 | M27: =IF(COUNT(Records!S27:U27)=0,"",AVERAGE(Records!S27:U27)) -> 4 | N27: =IF(COUNT(Records!O27,Records!P27,Records!V27)=0,"",AVERAGE(Records!O27,Records!P27,Records!V27)) -> 4.3333333 | O27: =Records!AD27 -> 是 | P27: =27 -> 27
A28: =Records!A28 -> P004 | B28: =Records!B28 -> 6 | C28: =Records!E28 -> 游戏手柄 | D28: =Records!G28 -> 方法B | E28: =Records!H28 -> EgoAnchor | F28: =Records!K28 -> 5 | G28: =Records!R28 -> 5 | H28: =Records!L28 -> 4 | I28: =Records!M28 -> 6 | J28: =Records!Q28 -> 2 | K28: =Records!W28 -> 2 | L28: =Records!X28 -> 5 | M28: =IF(COUNT(Records!S28:U28)=0,"",AVERAGE(Records!S28:U28)) -> 5 | N28: =IF(COUNT(Records!O28,Records!P28,Records!V28)=0,"",AVERAGE(Records!O28,Records!P28,Records!V28)) -> 3.6666667 | O28: =Records!AD28 -> 是 | P28: =28 -> 28
A29: =Records!A29 -> P005 | B29: =Records!B29 -> 1 | C29: =Records!E29 -> 鼠标 | D29: =Records!G29 -> 方法A | E29: =Records!H29 -> EgoAnchor | F29: =Records!K29 -> 7 | G29: =Records!R29 -> 5 | H29: =Records!L29 -> 5 | I29: =Records!M29 -> 4 | J29: =Records!Q29 -> 6 | K29: =Records!W29 -> 5 | L29: =Records!X29 -> 6 | M29: =IF(COUNT(Records!S29:U29)=0,"",AVERAGE(Records!S29:U29)) -> 5 | N29: =IF(COUNT(Records!O29,Records!P29,Records!V29)=0,"",AVERAGE(Records!O29,Records!P29,Records!V29)) -> 5 | O29: =Records!AD29 -> 是 | P29: =29 -> 29
A30: =Records!A30 -> P005 | B30: =Records!B30 -> 2 | C30: =Records!E30 -> 鼠标 | D30: =Records!G30 -> 方法B | E30: =Records!H30 -> One-Euro | F30: =Records!K30 -> 4 | G30: =Records!R30 -> 5 | H30: =Records!L30 -> 5 | I30: =Records!M30 -> 5 | J30: =Records!Q30 -> 3 | K30: =Records!W30 -> 4 | L30: =Records!X30 -> 5 | M30: =IF(COUNT(Records!S30:U30)=0,"",AVERAGE(Records!S30:U30)) -> 4.6666667 | N30: =IF(COUNT(Records!O30,Records!P30,Records!V30)=0,"",AVERAGE(Records!O30,Records!P30,Records!V30)) -> 5 | O30: =Records!AD30 -> 是 | P30: =30 -> 30
A31: =Records!A31 -> P005 | B31: =Records!B31 -> 3 | C31: =Records!E31 -> 游戏手柄 | D31: =Records!G31 -> 方法B | E31: =Records!H31 -> One-Euro | F31: =Records!K31 -> 5 | G31: =Records!R31 -> 4 | H31: =Records!L31 -> 5 | I31: =Records!M31 -> 4 | J31: =Records!Q31 -> 4 | K31: =Records!W31 -> 5 | L31: =Records!X31 -> 5 | M31: =IF(COUNT(Records!S31:U31)=0,"",AVERAGE(Records!S31:U31)) -> 5.3333333 | N31: =IF(COUNT(Records!O31,Records!P31,Records!V31)=0,"",AVERAGE(Records!O31,Records!P31,Records!V31)) -> 5.3333333 | O31: =Records!AD31 -> 是 | P31: =31 -> 31
A32: =Records!A32 -> P005 | B32: =Records!B32 -> 4 | C32: =Records!E32 -> 游戏手柄 | D32: =Records!G32 -> 方法A | E32: =Records!H32 -> EgoAnchor | F32: =Records!K32 -> 6 | G32: =Records!R32 -> 7 | H32: =Records!L32 -> 5 | I32: =Records!M32 -> 6 | J32: =Records!Q32 -> 6 | K32: =Records!W32 -> 4 | L32: =Records!X32 -> 5 | M32: =IF(COUNT(Records!S32:U32)=0,"",AVERAGE(Records!S32:U32)) -> 5.6666667 | N32: =IF(COUNT(Records!O32,Records!P32,Records!V32)=0,"",AVERAGE(Records!O32,Records!P32,Records!V32)) -> 5.3333333 | O32: =Records!AD32 -> 是 | P32: =32 -> 32
A33: =Records!A33 -> P005 | B33: =Records!B33 -> 5 | C33: =Records!E33 -> 固定订书机 | D33: =Records!G33 -> 方法A | E33: =Records!H33 -> EgoAnchor | F33: =Records!K33 -> 6 | G33: =Records!R33 -> 7 | H33: =Records!L33 -> 6 | I33: =Records!M33 -> 6 | J33: =Records!Q33 -> 7 | K33: =Records!W33 -> 6 | L33: =Records!X33 -> 4 | M33: =IF(COUNT(Records!S33:U33)=0,"",AVERAGE(Records!S33:U33)) -> 5.6666667 | N33: =IF(COUNT(Records!O33,Records!P33,Records!V33)=0,"",AVERAGE(Records!O33,Records!P33,Records!V33)) -> 5 | O33: =Records!AD33 -> 是 | P33: =33 -> 33
A34: =Records!A34 -> P005 | B34: =Records!B34 -> 6 | C34: =Records!E34 -> 固定订书机 | D34: =Records!G34 -> 方法B | E34: =Records!H34 -> One-Euro | F34: =Records!K34 -> 4 | G34: =Records!R34 -> 4 | H34: =Records!L34 -> 3 | I34: =Records!M34 -> 5 | J34: =Records!Q34 -> 3 | K34: =Records!W34 -> 5 | L34: =Records!X34 -> 5 | M34: =IF(COUNT(Records!S34:U34)=0,"",AVERAGE(Records!S34:U34)) -> 5.3333333 | N34: =IF(COUNT(Records!O34,Records!P34,Records!V34)=0,"",AVERAGE(Records!O34,Records!P34,Records!V34)) -> 5.6666667 | O34: =Records!AD34 -> 是 | P34: =34 -> 34
A35: =Records!A35 -> P006 | B35: =Records!B35 -> 1 | C35: =Records!E35 -> 鼠标 | D35: =Records!G35 -> 方法B | E35: =Records!H35 -> One-Euro | F35: =Records!K35 -> 5 | G35: =Records!R35 -> 5 | H35: =Records!L35 -> 4 | I35: =Records!M35 -> 5 | J35: =Records!Q35 -> 4 | K35: =Records!W35 -> 4 | L35: =Records!X35 -> 4 | M35: =IF(COUNT(Records!S35:U35)=0,"",AVERAGE(Records!S35:U35)) -> 5 | N35: =IF(COUNT(Records!O35,Records!P35,Records!V35)=0,"",AVERAGE(Records!O35,Records!P35,Records!V35)) -> 5.6666667 | O35: =Records!AD35 -> 是 | P35: =35 -> 35
A36: =Records!A36 -> P006 | B36: =Records!B36 -> 2 | C36: =Records!E36 -> 鼠标 | D36: =Records!G36 -> 方法A | E36: =Records!H36 -> EgoAnchor | F36: =Records!K36 -> 4 | G36: =Records!R36 -> 5 | H36: =Records!L36 -> 5 | I36: =Records!M36 -> 3 | J36: =Records!Q36 -> 5 | K36: =Records!W36 -> 5 | L36: =Records!X36 -> 4 | M36: =IF(COUNT(Records!S36:U36)=0,"",AVERAGE(Records!S36:U36)) -> 5 | N36: =IF(COUNT(Records!O36,Records!P36,Records!V36)=0,"",AVERAGE(Records!O36,Records!P36,Records!V36)) -> 4.6666667 | O36: =Records!AD36 -> 是 | P36: =36 -> 36
A37: =Records!A37 -> P006 | B37: =Records!B37 -> 3 | C37: =Records!E37 -> 游戏手柄 | D37: =Records!G37 -> 方法A | E37: =Records!H37 -> EgoAnchor | F37: =Records!K37 -> 4 | G37: =Records!R37 -> 5 | H37: =Records!L37 -> 5 | I37: =Records!M37 -> 5 | J37: =Records!Q37 -> 6 | K37: =Records!W37 -> 5 | L37: =Records!X37 -> 6 | M37: =IF(COUNT(Records!S37:U37)=0,"",AVERAGE(Records!S37:U37)) -> 5 | N37: =IF(COUNT(Records!O37,Records!P37,Records!V37)=0,"",AVERAGE(Records!O37,Records!P37,Records!V37)) -> 4.3333333 | O37: =Records!AD37 -> 是 | P37: =37 -> 37
A38: =Records!A38 -> P006 | B38: =Records!B38 -> 4 | C38: =Records!E38 -> 游戏手柄 | D38: =Records!G38 -> 方法B | E38: =Records!H38 -> One-Euro | F38: =Records!K38 -> 3 | G38: =Records!R38 -> 6 | H38: =Records!L38 -> 4 | I38: =Records!M38 -> 4 | J38: =Records!Q38 -> 3 | K38: =Records!W38 -> 4 | L38: =Records!X38 -> 5 | M38: =IF(COUNT(Records!S38:U38)=0,"",AVERAGE(Records!S38:U38)) -> 5 | N38: =IF(COUNT(Records!O38,Records!P38,Records!V38)=0,"",AVERAGE(Records!O38,Records!P38,Records!V38)) -> 4.3333333 | O38: =Records!AD38 -> 是 | P38: =38 -> 38
A39: =Records!A39 -> P006 | B39: =Records!B39 -> 5 | C39: =Records!E39 -> 固定订书机 | D39: =Records!G39 -> 方法B | E39: =Records!H39 -> One-Euro | F39: =Records!K39 -> 3 | G39: =Records!R39 -> 5 | H39: =Records!L39 -> 4 | I39: =Records!M39 -> 5 | J39: =Records!Q39 -> 3 | K39: =Records!W39 -> 5 | L39: =Records!X39 -> 5 | M39: =IF(COUNT(Records!S39:U39)=0,"",AVERAGE(Records!S39:U39)) -> 4.3333333 | N39: =IF(COUNT(Records!O39,Records!P39,Records!V39)=0,"",AVERAGE(Records!O39,Records!P39,Records!V39)) -> 4.6666667 | O39: =Records!AD39 -> 是 | P39: =39 -> 39
A40: =Records!A40 -> P006 | B40: =Records!B40 -> 6 | C40: =Records!E40 -> 固定订书机 | D40: =Records!G40 -> 方法A | E40: =Records!H40 -> EgoAnchor | F40: =Records!K40 -> 5 | G40: =Records!R40 -> 6 | H40: =Records!L40 -> 4 | I40: =Records!M40 -> 5 | J40: =Records!Q40 -> 5 | K40: =Records!W40 -> 5 | L40: =Records!X40 -> 5 | M40: =IF(COUNT(Records!S40:U40)=0,"",AVERAGE(Records!S40:U40)) -> 5.3333333 | N40: =IF(COUNT(Records!O40,Records!P40,Records!V40)=0,"",AVERAGE(Records!O40,Records!P40,Records!V40)) -> 5 | O40: =Records!AD40 -> 是 | P40: =40 -> 40
A41: =Records!A41 -> P007 | B41: =Records!B41 -> 1 | C41: =Records!E41 -> 鼠标 | D41: =Records!G41 -> 方法B | E41: =Records!H41 -> EgoAnchor | F41: =Records!K41 -> 5 | G41: =Records!R41 -> 6 | H41: =Records!L41 -> 6 | I41: =Records!M41 -> 5 | J41: =Records!Q41 -> 5 | K41: =Records!W41 -> 3 | L41: =Records!X41 -> 5 | M41: =IF(COUNT(Records!S41:U41)=0,"",AVERAGE(Records!S41:U41)) -> 5.3333333 | N41: =IF(COUNT(Records!O41,Records!P41,Records!V41)=0,"",AVERAGE(Records!O41,Records!P41,Records!V41)) -> 6 | O41: =Records!AD41 -> 是 | P41: =41 -> 41
...

Sheet Synthetic_Summary
A1: GPT-5.6-Thinking v3 — Synthetic Experiment 3 Summary
