Workbook

Sheet README
A1: 【合成演练数据 · 不得进入论文结果】EgoAnchor 实验三 AI 模拟采集与分析工作簿（Claude-Opus-5 v3）
A2: 本工作簿全部数据由 Claude Opus 5 按 v5.1 冻结设计模拟生成，用于采集表与分析流程演练。严禁作为真实参与者数据、论文证据、效应量/功效/样本量依据，也不得与真实采集数据合并。唯一权威设计规格为 2026-EgoAnchor/experiment_3_questionnaire_design_zh.md（v5.1）；唯一正式采集工作簿为 EgoAnchor_Experiment3_DataCollection_24P_v5_1_Beautified_Checked_VSCodeSafe.xlsx。
A4: 一、本轮模拟的基本信息
A5: 项 | B5: 内容
A6: 模拟模型 | B6: Claude-Opus-5（Claude Opus 5）
A7: 生成日期 | B7: 2026-07-27
A8: 主种子 | B8: 20260727
A9: 参与者数 | B9: 24（24 平衡单元各 1 人，先行方法 12/12，标签映射 12/12）
A10: 评分总数 | B10: 2592（区块 78 + 方法级 26 + 最终 4 = 每人 108）
A11: Q10 状态 | B11: 默认停用（计划书 4.2/第八节）；启用判据的实测评估见 Simulation_Audit
A12: 遮挡冻结时长 | B12: 0.75 s（0.6–0.9 s 区间内，避开 0.45/1.0 s 边界）
A13: 刺激来源 | B13: 实验一/二正式批次 experiment1_summary.csv 的 One-Euro Anchor 与 EgoAnchor 两行
A14: 是否事后校准 | B14: 否。模型为纯前向生成，不按目标效应量反向校准
A16: 二、表结构与公式约定（本轮按要求用公式实时计算问卷小分）
A17: 工作表 | B17: 角色 | C17: 是否含公式 | D17: 说明
A18: README | B18: 声明与导读 | C18: 无 | D18: 合成边界、模拟信息、表结构约定
A19: Verification_Audit | B19: 量表核对存档 | C19: 无 | D19: 沿用正式采集表的逐条核对结论，另附本轮模拟边界记录
A20: Questionnaire | B20: 条目字典 | C20: 无 | D20: 背景 B1–B6、区块 13+1、TiA 6+4、S-TIAS 3、最终 7 项与量尺锚点
A21: Participants | B21: 24 平衡单元与背景 | C21: 无 | D21: 平衡单元、物体顺序、标签映射、B1–B6、纳入审计、人物设定摘要
A22: Records | B22: 唯一输入表 | C22: 无 | D22: A 区块 144 行 + B 方法级 48 行 + C 最终 24 行，只放原始评分
A23: Derived | B23: 四级派生 | C23: 全为公式 | D23: L1 区块级子量表 → L2 三物体均值 → L3 TiA 反向与量表分 → L4 配对差
A24: Analysis | B24: 结果表 | C24: 多数为公式 | D24: Mdn/IQR、配对差、dz、逐物体、计数为公式；W/p/Holm/r_rb CI/α/ω/TOST 由代码写数值
A25: Simulation_Audit | B25: 模型可审计层 | C25: 部分公式 | D25: 通道刺激剖面、条目权重、事件日志、问卷负担诊断、换种子重抽结果
A27: 三、颜色约定
A28: 绿色底 | B28: 原始录入值（Records 唯一输入；不得被派生值覆盖）
A29: 琥珀底 | B29: 公式实时计算（Excel 打开时全量重算；离线缓存值由受限求值器注入）
A30: 无底色 | B30: 由分析代码写入的统计量（Wilcoxon W/p、Holm p、r_rb 自举 CI、α/ω、TOST p）
A32: 四、冻结分析家族（与计划书 6.1 一致）
A33: 主证实家族（7） | B33: Q1 静止稳定 / Q8 位置正确 / Q2 运动附着 / Q9 姿态一致 / Q3 恢复一致 / Q6 依赖意愿 / Q7 稳定–响应平衡 | D33: 三物体取均值 → 配对 Wilcoxon → 家族内 Holm（N=24 最严 MDE dz=0.801）
A34: 已发表量表家族（5） | B34: AQ-EQ / AQ-IQ / TiA-R/C / TiA-U/P / S-TIAS | D34: 同上；仅此家族报告当前样本 α/ω；TiA 反向项先按 6−原始分换向
A35: 次级 | B35: Q10（本轮停用） | D35: CLMM 见 Analysis C 段说明
A36: 描述性 | B36: 两项强制选择、偏好强度、区分信心、开放题主题、安全检查、运行时审计 | D36: 不作推断

Sheet Verification_Audit
A1: 量表与内容核验记录（沿用正式采集表 2026-07-26 结论）+ 本轮模拟边界
A2: 前 16 行为正式采集表 Verification_Audit 的逐条结论，模拟工作簿原样保留以保证条目与署名一致；第二节为本轮 AI 模拟自身的边界与方法记录。
A4: 一、量表核对结论（原样沿用）
A5: 核对对象 | B5: 状态 | C5: 结论/修正 | D5: 依据/来源
A6: AQ 英文条目 | B6: 已核对 | C6: 官方原文六条（指代 The virtual object），对象化替换极小 | D6: doi:10.1007/s11747-025-01108-2 Appendix
A7: AQ 量尺 | B7: 已核对 | C7: 七点：1 = I do not agree … 7 = I fully agree | D7: 同上
A8: AQ 书目 | B8: 已核对 | C8: Schein, Rauschnabel, Praxmarer-Carus, Babin. JAMS 54:49–69 | D8: CC BY 4.0
A9: TiA 条目结构 | B9: 已核对 | C9: R/C 6 项（官方 1,6,10,13,15,19）+ U/P 4 项（2,7,11,16） | D9: 官方 GitHub（CC BY-SA 4.0）
A10: TiA 反向计分 | B10: 已核对 | C10: 反向项 RC3/RC5/UP2/UP4；五点反向分 = 6 − 原始分 | D10: 同上
A11: TiA 量尺 | B11: 已核对 | C11: 五点同意度 + 允许 No response（记缺失） | D11: 同上
A12: TiA 效度措辞 | B12: 需遵守 | C12: 只写 adapted TiA subscales + 当前样本信度 | D12: 官方 GitHub 声明
A13: S-TIAS 条目 | B13: 已核对 | C13: 原文指代 the AI assistant → 本研究替换为“这种对象锚定方法” | D13: doi:10.3389/frai.2025.1582880
A14: S-TIAS 量尺 | B14: 已核对 | C14: 1 = Not at all … 7 = Extremely；三项均值 | D14: 同上
A15: S-TIAS 书目 | B15: 已核对（作者更正） | C15: McGrath, Lack, Tisch, Duenser. Frontiers in AI 8:1582880（语料误标 Karpus） | D15: CC BY
A16: Gottsacker 2024 书目 | B16: 已核对 | C16: Computers & Graphics 123:104035（八位作者） | D16: doi:10.1016/j.cag.2024.104035
... A21: 中文施测措辞 | B21: 已冻结 | C21: 19 条量表条目逐条对照官方原文完成语义等价审计并冻结 | D21: 计划书 4.6 核对状态
A23: 二、本轮 AI 模拟的边界与方法记录
A24: 项 | B24: 状态 | C24: 说明 | D24: 依据
A25: 数据性质 | B25: 合成 | C25: 全部评分由生成模型产出，无真实参与者；不得进入论文结果或与真实数据合并 | D25: AGENTS.md 合成数据边界
A26: 刺激标定 | B26: 实测驱动 | C26: 15 个知觉通道的量级全部取自实验一/二正式批次实测值，按 log 压缩折算 | D26: analysis/metrics/experiment1_summary.csv
A27: 事后校准 | B27: 未使用 | C27: 不按目标效应量反向校准；效应量是前向模型的结果而非输入 | D27: 本轮方法约定
A28: 公式实时计算 | B28: 已启用 | C28: 问卷小分（AQ 两子量表、TiA 两分量表、S-TIAS）与派生统计全由公式计算 | D28: 用户本轮要求
A29: 公式正确性 | B29: 双路交叉验证 | C29: 公式文本→受限求值器→缓存值，对比 Records 原始分→独立 Python 重算，逐格容差 1e-9 | D29: sim_opus5_v3_verify.py
A30: 参与者独立性 | B30: 逐人独立随机流 | C30: 每人使用独立种子与独立随机流，单人结果不受他人影响 | D30: 用户本轮要求
A31: 次级 CLMM | B31: 未拟合 | C31: 本环境无支持随机效应的累积链接混合模型；不以代理模型冒充，改由逐物体方向一致性承担 | D31: Analysis C 段

Sheet Questionnaire
A1: 实验三问卷全条目（v5.1 Verified）——本表为唯一条目字典
A2: 中文施测版为头显/纸面呈现文本；官方英文原文为原量表逐字条目（自制条目无）。本表内容与正式采集表一致，仅供模拟工作簿自洽引用。
A4: A. 实验前背景（Participants 表填写，每人一次）
A5: ID | B5: 中文 | C5: 应答格式/选项
A6: B1_Age | B6: 年龄 | C6: 整数
A7: B2_Gender | B7: 性别 | C7: 女 / 男 / 非二元或其他 / 不愿透露
A8: B3_Handedness | B8: 主手（精细操作） | C8: 右手 / 左手 / 双手均可
A9: B4_Vision | B9: 视力情况 | C9: 正常 / 矫正后正常 / 其他
A10: B5_VRMR_Experience | B10: VR/MR 使用经验 | C10: 从未 / 1–5 次 / 6–20 次 / 超过 20 次 / 经常使用
A11: B6_PhysObj_MR_Experience | B11: 实物 AR/MR 交互经验 | C11: 从未 / 1–2 次 / 数次 / 经常
A13: B. 区块级 13 项必答 + Q10 可选（统一七点同意度；界面标题：请根据刚才在这个物体上的体验作答）
A14: 页序 | B14: Item_ID | C14: 简称 | D14: 中文施测版 | E14: 官方英文原文 | F14: 分析家族 | G14: 来源 | H14: 本轮状态 | I14: 备注
A15: 1 | B15: Q1 | C15: 静止稳定 | D15: 在静止观察阶段，虚拟内容保持在同一位置不动。 | E15: — | F15: 主证实 | G15: 自制（v4 冻结） | H15: 启用
A16: 2 | B16: Q2 | C16: 运动附着 | D16: 在拿起、移动和旋转物体时，虚拟内容始终附着在真实物体上的同一位置。 | E16: — | F16: 主证实 | G16: 自制（v5.1 锐化措辞） | H16: 启用
A17: 3 | B17: Q9 | C17: 姿态一致 | D17: 旋转物体时，虚拟内容的朝向与真实物体的朝向保持一致。 | E17: — | F17: 主证实 | G17: 自制（v4 冻结） | H17: 启用
A18: 3' | B18: Q10_OPT | C18: 放置后稳定（可选） | D18: 把物体放到桌面后，虚拟内容很快就稳定下来。 | E18: — | F18: 次级 | G18: 自制（v4 可选，本轮停用） | H18: 停用
A19: 4 | B19: AQ_IQ2 | C19: 响应及时 | D19: 虚拟内容实时响应我对真实物体的操作。 | E19: The virtual object responds in real-time. | F19: 已发表量表 | G19: AQ Interaction Quality（对象化适配） | H19: 启用
A20: 5 | B20: AQ_IQ3 | C20: 运动平滑 | D20: 在交互过程中，虚拟内容随真实物体平滑运动。 | E20: The virtual object moves smoothly. | F20: 已发表量表 | G20: AQ Interaction Quality（对象化适配） | H20: 启用
A21: 6 | B21: Q3 | C21: 恢复一致 | D21: 遮挡移除后，虚拟内容恢复到了与真实物体一致的位置。 | E21: — | F21: 主证实 | G21: 自制（v4 冻结） | H21: 启用
A22: 7 | B22: Q8 | C22: 位置正确 | D22: 虚拟内容出现的位置，与真实物体实际所在的位置相符。 | E22: — | F22: 主证实 | G22: 自制（v4 冻结） | H22: 启用
A23: 8 | B23: AQ_EQ1 | C23: 融合 | D23: 虚拟内容与真实物体及周围真实元素自然融合。 | E23: The virtual object blends in with real elements. | F23: 已发表量表 | G23: AQ Embedding Quality（对象化适配） | H23: 启用
A24: 9 | B24: AQ_EQ2 | C24: 嵌入可信 | D24: 虚拟内容真实地嵌入在真实物体及其现实环境中。 | E24: The virtual object is realistically embedded in the environment. | F24: 已发表量表 | G24: AQ Embedding Quality（对象化适配） | H24: 启用
A25: 10 | B25: AQ_EQ3 | C25: 尺度协调 | D25: 虚拟内容的尺度与真实物体及现实世界中的事物相匹配。 | E25: The size of the virtual object is in scale to things in the real world. | F25: 已发表量表 | G25: AQ Embedding Quality（对象化适配） | H25: 启用
A26: 11 | B26: AQ_IQ1 | C26: 交互直观 | D26: 通过操作真实物体与虚拟内容进行交互是直观的。 | E26: Interaction with the virtual object is intuitive. | F26: 已发表量表 | G26: AQ Interaction Quality（对象化适配） | H26: 启用
... A28: 13 | B28: Q7 | C28: 稳定-响应平衡 | D28: 总体而言，该方法在锚点稳定性与响应及时性之间取得了合适的平衡。 | E28: — | F28: 主证实 | G28: 自制（v4 冻结） | H28: 启用
A29: 量尺 | B29: 七点同意度：1 完全不同意 … 7 完全同意
A31: C. 方法级（全部六区块完成后，按 S1 先 A / S2 先 B 依次评价两方法）
A32: C1. adapted TiA 两分量表（10 项） | B32: 五点同意度：1 Strongly disagree … 5 Strongly agree；允许无法回答（记缺失）。反向项计分 = 6 − 原始分（仅分析派生）；呈现按官方相对顺序 1,2,6,7,10,11,13,15,16,19 交错。
A33: Item_ID | B33: 分量表 | C33: 官方英文原文 | D33: 中文施测版（已冻结） | E33: 反向 | F33: 官方条目号
A34: TIA_RC1 | B34: Reliability/Competence | C34: The system is capable of interpreting situations correctly. | D34: 这种对象锚定方法能够正确判断当前状况。 | E34: 否 | F34: 1
A35: TIA_RC2 | B35: Reliability/Competence | C35: The system works reliably. | D35: 这种对象锚定方法运行可靠。 | E35: 否 | F35: 6
A36: TIA_RC3 | B36: Reliability/Competence | C36: A system malfunction is likely. | D36: 这种对象锚定方法很可能发生故障。 | E36: 是 | F36: 10
A37: TIA_RC4 | B37: Reliability/Competence | C37: The system is capable of taking over complicated tasks. | D37: 这种对象锚定方法能够承担复杂的锚定任务。 | E37: 否 | F37: 13
A38: TIA_RC5 | B38: Reliability/Competence | C38: The system might make sporadic errors. | D38: 这种对象锚定方法可能偶尔出错。 | E38: 是 | F38: 15
A39: TIA_RC6 | B39: Reliability/Competence | C39: I am confident about the system's capabilities. | D39: 我对这种对象锚定方法的能力有信心。 | E39: 否 | F39: 19
A40: TIA_UP1 | B40: Understanding/Predictability | C40: The system state was always clear to me. | D40: 这种对象锚定方法的状态对我来说始终清楚。 | E40: 否 | F40: 2
A41: TIA_UP2 | B41: Understanding/Predictability | C41: The system reacts unpredictably. | D41: 这种对象锚定方法的反应难以预测。 | E41: 是 | F41: 7
A42: TIA_UP3 | B42: Understanding/Predictability | C42: I was able to understand why things happened. | D42: 我能够理解为什么会出现刚才的锚定行为。 | E42: 否 | F42: 11
A43: TIA_UP4 | B43: Understanding/Predictability | C43: It's difficult to identify what the system will do next. | D43: 我很难判断这种对象锚定方法接下来会怎样表现。 | E43: 是 | F43: 16
A44: —— 尺度切换提示页：TiA（五点同意度）→ S-TIAS（七点程度尺），端点改变须参与者确认 ——
...

Sheet Participants
A1: 参与者信息与 24 平衡单元（合成数据；方法映射两列在真实采集中仅实验员可见）
A2: Participant_ID | B2: 平衡单元 | C2: 物体排列ID | D2: 标签序列 | E2: 物体1 | F2: 物体2 | G2: 物体3 | H2: 区块内标签顺序 | I2: 方法A=（保密） | J2: 方法B=（保密） | K2: 先行实际方法 | L2: B1_年龄 | M2: B2_性别 | N2: B3_主手 | O2: B4_视力 | P2: B5_VR/MR经验 | Q2: B6_实物MR经验 | R2: 签署同意 | S2: 基线不适 | T2: 实际时长_min | U2: 纳入分析 | V2: 退出/技术问题 | W2: 区分信心 | X2: 人物设定（仅模拟）
A3: P001 | B3: O1-S1-EA | C3: 1 | D3: S1 | E3: 鼠标 | F3: 固定订书机 | G3: 游戏手柄 | H3: A-B / B-A / A-B | I3: EgoAnchor | J3: One-Euro | K3: EgoAnchor | L3: 30 | M3: 男 | N3: 右手 | O3: 矫正后正常 | P3: 1–5 次 | Q3: 从未 | R3: 是 | S3: 轻微 | T3: 62.3 | U3: 是 | V3: 无 | W3: 7 | X3: 软件工程师·易疲劳｜平时不戴头显，到第四个区块后明显疲劳，后段作答变快、刻度收窄，出现连续同分。
A4: P002 | B4: O1-S2-EA | C4: 1 | D4: S2 | E4: 鼠标 | F4: 固定订书机 | G4: 游戏手柄 | H4: B-A / A-B / B-A | I4: EgoAnchor | J4: One-Euro | K4: One-Euro | L4: 29 | M4: 男 | N4: 右手 | O4: 正常 | P4: 经常使用 | Q4: 数次 | R4: 是 | S4: 无 | T4: 57.1 | U4: 是 | V4: 无 | W4: 6 | X4: 电子工程博士·反向权衡者｜明确认为交互系统里延迟比抖动更致命；即使看到稳定性差异，也可能在权衡题和最终选择上偏向响应更快的一方。
A5: P003 | B5: O1-S2-OE | C5: 1 | D5: S2 | E5: 鼠标 | F5: 固定订书机 | G5: 游戏手柄 | H5: B-A / A-B / B-A | I5: One-Euro | J5: EgoAnchor | K5: EgoAnchor | L5: 20 | M5: 男 | N5: 右手 | O5: 正常 | P5: 1–5 次 | Q5: 从未 | R5: 是 | S5: 无 | T5: 55.4 | U5: 是 | V5: 无 | W5: 6 | X5: 物理系本科·量化思维｜会自己估计毫米量级并在心里换算，静止阶段刻意做大幅头动来放大差异。
A6: P004 | B6: O1-S1-OE | C6: 1 | D6: S1 | E6: 鼠标 | F6: 固定订书机 | G6: 游戏手柄 | H6: A-B / B-A / A-B | I6: One-Euro | J6: EgoAnchor | K6: One-Euro | L6: 25 | M6: 非二元或其他 | N6: 右手 | O6: 正常 | P6: 6–20 次 | Q6: 1–2 次 | R6: 是 | S6: 无 | T6: 58.1 | U6: 是 | V6: 无 | W6: 7 | X6: 研究生助教·需求特征敏感｜做过实验助教，最容易推测研究假设并顺着假设作答；是本组需求特征风险的上界样本。
A7: P005 | B7: O2-S1-EA | C7: 2 | D7: S1 | E7: 鼠标 | F7: 游戏手柄 | G7: 固定订书机 | H7: A-B / B-A / A-B | I7: EgoAnchor | J7: One-Euro | K7: EgoAnchor | L7: 24 | M7: 男 | N7: 右手 | O7: 正常 | P7: 6–20 次 | Q7: 1–2 次 | R7: 是 | S7: 无 | T7: 54.8 | U7: 是 | V7: 无 | W7: 7 | X7: 机械工程硕士·分析型｜习惯把现象拆成量级来判断，静止阶段会刻意左右移动头部反复确认，措辞克制。
A8: P006 | B8: O2-S2-EA | C8: 2 | D8: S2 | E8: 鼠标 | F8: 游戏手柄 | G8: 固定订书机 | H8: B-A / A-B / B-A | I8: EgoAnchor | J8: One-Euro | K8: One-Euro | L8: 28 | M8: 男 | N8: 右手 | O8: 矫正后正常 | P8: 1–5 次 | Q8: 从未 | R8: 是 | S8: 无 | T8: 55.2 | U8: 是 | V8: 无 | W8: 5 | X8: 材料学博士·低敏感高标准｜知觉敏感度偏低但打分标准很严：两个方法他都不太满意，整体分最低、差异幅度中等。
A9: P007 | B9: O2-S2-OE | C9: 2 | D9: S2 | E9: 鼠标 | F9: 游戏手柄 | G9: 固定订书机 | H9: B-A / A-B / B-A | I9: One-Euro | J9: EgoAnchor | K9: EgoAnchor | L9: 19 | M9: 女 | N9: 右手 | O9: 正常 | P9: 从未 | Q9: 从未 | R9: 是 | S9: 无 | T9: 60 | U9: 是 | V9: 无 | W9: 5 | X9: 大一新生·首次VR｜第一次戴头显，整体新奇感强，缺少参照系，倾向给偏高的分；只有明显跳变才会注意到。
A10: P008 | B10: O2-S1-OE | C10: 2 | D10: S1 | E10: 鼠标 | F10: 游戏手柄 | G10: 固定订书机 | H10: A-B / B-A / A-B | I10: One-Euro | J10: EgoAnchor | K10: One-Euro | L10: 25 | M10: 女 | N10: 右手 | O10: 正常 | P10: 6–20 次 | Q10: 1–2 次 | R10: 是 | S10: 无 | T10: 55.1 | U10: 是 | V10: 无 | W10: 2 | X10: 建筑学硕士·空间判断强｜受过空间训练，会用桌面网格和物体边缘做参照判断绝对位置与朝向，对偏移比对抖动更敏感。
A11: P009 | B11: O3-S1-EA | C11: 3 | D11: S1 | E11: 固定订书机 | F11: 鼠标 | G11: 游戏手柄 | H11: A-B / B-A / A-B | I11: EgoAnchor | J11: One-Euro | K11: EgoAnchor | L11: 21 | M11: 男 | N11: 右手 | O11: 正常 | P11: 超过 20 次 | Q11: 经常 | R11: 是 | S11: 无 | T11: 51.7 | U11: 是 | V11: 无 | W11: 6 | X11: 机器人竞赛学生·技术乐观｜做过视觉跟踪项目，能说出机制名词，对系统整体持乐观态度，给分偏高但区分清楚。
A12: P010 | B12: O3-S2-EA | C12: 3 | D12: S2 | E12: 固定订书机 | F12: 鼠标 | G12: 游戏手柄 | H12: B-A / A-B / B-A | I12: EgoAnchor | J12: One-Euro | K12: One-Euro | L12: 45 | M12: 女 | N12: 右手 | O12: 矫正后正常 | P12: 从未 | Q12: 从未 | R12: 是 | S12: 无 | T12: 63.7 | U12: 是 | V12: 无 | W12: 6 | X12: 图书馆员·耐心细致｜最慢最认真的参与者，逐题反复确认，问卷时长最长；对遮挡恢复的正确性印象最深。
A13: P011 | B13: O3-S2-OE | C13: 3 | D13: S2 | E13: 固定订书机 | F13: 鼠标 | G13: 游戏手柄 | H13: B-A / A-B / B-A | I13: One-Euro | J13: EgoAnchor | K13: EgoAnchor | L13: 24 | M13: 女 | N13: 右手 | O13: 正常 | P13: 从未 | Q13: 1–2 次 | R13: 是 | S13: 无 | T13: 60.5 | U13: 是 | V13: 无 | W13: 2 | X13: 护理专业·配合度高｜严格按指令完成动作，作答偏正面；对遮挡恢复后的正确性比较在意。
A14: P012 | B14: O3-S1-OE | C14: 3 | D14: S1 | E14: 固定订书机 | F14: 鼠标 | G14: 游戏手柄 | H14: A-B / B-A / A-B | I14: One-Euro | J14: EgoAnchor | K14: One-Euro | L14: 28 | M14: 非二元或其他 | N14: 左手 | O14: 正常 | P14: 6–20 次 | Q14: 数次 | R14: 是 | S14: 无 | T14: 57 | U14: 是 | V14: 无 | W14: 7 | X14: 工业设计师·细节挑剔｜职业习惯是找瑕疵，任何一处不贴合都会拉低整块评分；给分整体偏低但区分度最高。
... A26: P024 | B26: O6-S1-OE | C26: 6 | D26: S1 | E26: 游戏手柄 | F26: 固定订书机 | G26: 鼠标 | H26: A-B / B-A / A-B | I26: One-Euro | J26: EgoAnchor | K26: One-Euro | L26: 23 | M26: 女 | N26: 右手 | O26: 正常 | P26: 1–5 次 | Q26: 1–2 次 | R26: 是 | S26: 无 | T26: 55.8 | U26: 是 | V26: 无 | W26: 5 | X26: 医学生·安全导向｜把这套东西代入手术导航之类的场景想，一次明显失败就会让她大幅下调依赖意愿并记很久。

Sheet Records
A1: 实验记录（合成数据）：A 区块 144 行 → B 方法级 48 行 → C 最终问卷 24 行。本表只放原始评分，原始分不得被反向分覆盖。
A3: A. 区块记录（每行 = 一个方法×物体区块：进度 + 13 项评分（Q10 停用） + 问卷时长 + 运行时审计）
A4: Participant_ID | B4: Block_Index | C4: 平衡单元 | D4: 物体位置 | E4: 物体 | F4: Object_Key | G4: Shown_Label | H4: Condition(保密) | I4: 物体内先后 | J4: 该方法第几次 | K4: Q1 | L4: Q2 | M4: Q9 | N4: Q10_OPT | O4: AQ_IQ2 | P4: AQ_IQ3 | Q4: Q3 | R4: Q8 | S4: AQ_EQ1 | T4: AQ_EQ2 | U4: AQ_EQ3 | V4: AQ_IQ1 | W4: Q6 | X4: Q7 | Y4: 问卷开始 | Z4: 问卷结束 | AA4: 问卷时长_s | AB4: 任务完成 | AC4: 问卷完成 | AD4: 区块有效 | AE4: 技术问题 | AF4: Candidate_Rate_Hz | AG4: VCD_Median | AH4: VCD_Admission_Rate | AI4: Output_Availability | AJ4: 遮挡时长_s | AK4: 遮挡生命周期状态 | AL4: 进入Lost | AM4: 服务器重获取次数 | AN4: StaticLock进入次数 | AO4: 注意力失效 | AP4: 最长连续同分 | AQ4: 备注
A5: P001 | B5: 1 | C5: O1-S1-EA | D5: 1 | E5: 鼠标 | F5: blue_mouse | G5: 方法A | H5: EgoAnchor | I5: 1 | J5: 1 | K5: 5 | L5: 4 | M5: 4 | O5: 5 | P5: 4 | Q5: 4 | R5: 5 | S5: 5 | T5: 5 | U5: 6 | V5: 5 | W5: 5 | X5: 4 | Y5: 09:15:00 | Z5: 09:18:15 | AA5: 195.6 | AB5: 是 | AC5: 是 | AD5: 是 | AE5: 无 | AF5: 9.85 | AG5: 0.892 | AH5: 0.934 | AI5: 0.985 | AJ5: 0.722 | AK5: FrozenUncertain | AL5: 否 | AM5: 0 | AN5: 5 | AO5: 否 | AP5: 3
A6: P001 | B6: 2 | C6: O1-S1-EA | D6: 1 | E6: 鼠标 | F6: blue_mouse | G6: 方法B | H6: One-Euro | I6: 2 | J6: 1 | K6: 3 | L6: 4 | M6: 5 | O6: 4 | P6: 4 | Q6: 4 | R6: 4 | S6: 3 | T6: 4 | U6: 4 | V6: 3 | W6: 4 | X6: 4 | Y6: 09:19:50 | Z6: 09:22:57 | AA6: 186.7 | AB6: 是 | AC6: 是 | AD6: 是 | AE6: 无 | AF6: 9.33 | AG6: 0.889 | AH6: 0.952 | AI6: 0.991 | AJ6: 0.725 | AK6: FrozenUncertain | AL6: 否 | AM6: 0 | AN6: 0 | AO6: 是 | AP6: 4
A7: P001 | B7: 3 | C7: O1-S1-EA | D7: 2 | E7: 固定订书机 | F7: stapler | G7: 方法B | H7: One-Euro | I7: 1 | J7: 2 | K7: 4 | L7: 5 | M7: 5 | O7: 5 | P7: 4 | Q7: 4 | R7: 5 | S7: 5 | T7: 4 | U7: 5 | V7: 5 | W7: 5 | X7: 4 | Y7: 09:24:32 | Z7: 09:27:16 | AA7: 164.3 | AB7: 是 | AC7: 是 | AD7: 是 | AE7: 无 | AF7: 9.51 | AG7: 0.931 | AH7: 0.941 | AI7: 0.995 | AJ7: 0.827 | AK7: FrozenUncertain | AL7: 否 | AM7: 0 | AN7: 0 | AO7: 否 | AP7: 3
A8: P001 | B8: 4 | C8: O1-S1-EA | D8: 2 | E8: 固定订书机 | F8: stapler | G8: 方法A | H8: EgoAnchor | I8: 2 | J8: 2 | K8: 5 | L8: 5 | M8: 5 | O8: 6 | P8: 5 | Q8: 5 | R8: 5 | S8: 5 | T8: 5 | U8: 7 | V8: 5 | W8: 5 | X8: 6 | Y8: 09:28:51 | Z8: 09:31:42 | AA8: 170.4 | AB8: 是 | AC8: 是 | AD8: 是 | AE8: 无 | AF8: 9.8 | AG8: 0.917 | AH8: 0.953 | AI8: 0.997 | AJ8: 0.825 | AK8: FrozenUncertain | AL8: 否 | AM8: 0 | AN8: 3 | AO8: 否 | AP8: 5
A9: P001 | B9: 5 | C9: O1-S1-EA | D9: 3 | E9: 游戏手柄 | F9: gamepad | G9: 方法A | H9: EgoAnchor | I9: 1 | J9: 3 | K9: 4 | L9: 6 | M9: 5 | O9: 4 | P9: 3 | Q9: 5 | R9: 5 | S9: 5 | T9: 5 | U9: 7 | V9: 7 | W9: 7 | X9: 5 | Y9: 09:33:17 | Z9: 09:36:04 | AA9: 167.8 | AB9: 是 | AC9: 是 | AD9: 是 | AE9: 无 | AF9: 9.45 | AG9: 0.851 | AH9: 0.93 | AI9: 0.981 | AJ9: 0.847 | AK9: FrozenUncertain | AL9: 否 | AM9: 0 | AN9: 5 | AO9: 是 | AP9: 4
A10: P001 | B10: 6 | C10: O1-S1-EA | D10: 3 | E10: 游戏手柄 | F10: gamepad | G10: 方法B | H10: One-Euro | I10: 2 | J10: 3 | K10: 3 | L10: 3 | M10: 3 | O10: 5 | P10: 5 | Q10: 5 | R10: 4 | S10: 5 | T10: 4 | U10: 6 | V10: 6 | W10: 4 | X10: 5 | Y10: 09:37:39 | Z10: 09:40:15 | AA10: 155.9 | AB10: 是 | AC10: 是 | AD10: 是 | AE10: 无 | AF10: 9.21 | AG10: 0.857 | AH10: 0.899 | AI10: 0.982 | AJ10: 0.876 | AK10: FrozenUncertain | AL10: 否 | AM10: 0 | AN10: 0 | AO10: 否 | AP10: 3
A11: P002 | B11: 1 | C11: O1-S2-EA | D11: 1 | E11: 鼠标 | F11: blue_mouse | G11: 方法B | H11: One-Euro | I11: 1 | J11: 1 | K11: 3 | L11: 3 | M11: 3 | O11: 4 | P11: 5 | Q11: 1 | R11: 4 | S11: 5 | T11: 3 | U11: 6 | V11: 6 | W11: 1 | X11: 4 | Y11: 09:15:00 | Z11: 09:16:59 | AA11: 119.7 | AB11: 是 | AC11: 是 | AD11: 是 | AE11: 无 | AF11: 9.24 | AG11: 0.879 | AH11: 0.913 | AI11: 0.987 | AJ11: 0.712 | AK11: FrozenUncertain | AL11: 否 | AM11: 0 | AN11: 0 | AO11: 否 | AP11: 3 | AQ11: 灾难性恢复失效(>40mm 级)
A12: P002 | B12: 2 | C12: O1-S2-EA | D12: 1 | E12: 鼠标 | F12: blue_mouse | G12: 方法A | H12: EgoAnchor | I12: 2 | J12: 1 | K12: 6 | L12: 5 | M12: 5 | O12: 5 | P12: 5 | Q12: 6 | R12: 6 | S12: 6 | T12: 7 | U12: 7 | V12: 6 | W12: 6 | X12: 5 | Y12: 09:18:34 | Z12: 09:20:37 | AA12: 122.3 | AB12: 是 | AC12: 是 | AD12: 是 | AE12: 无 | AF12: 9.4 | AG12: 0.929 | AH12: 0.96 | AI12: 0.988 | AJ12: 0.716 | AK12: FrozenUncertain | AL12: 否 | AM12: 0 | AN12: 8 | AO12: 否 | AP12: 4
A13: P002 | B13: 3 | C13: O1-S2-EA | D13: 2 | E13: 固定订书机 | F13: stapler | G13: 方法A | H13: EgoAnchor | I13: 1 | J13: 2 | K13: 6 | L13: 5 | M13: 6 | O13: 5 | P13: 6 | Q13: 5 | R13: 6 | S13: 7 | T13: 6 | U13: 6 | V13: 6 | W13: 5 | X13: 6 | Y13: 09:22:12 | Z13: 09:23:54 | AA13: 102.4 | AB13: 是 | AC13: 是 | AD13: 是 | AE13: 无 | AF13: 9.64 | AG13: 0.941 | AH13: 0.96 | AI13: 0.998 | AJ13: 0.782 | AK13: FrozenUncertain | AL13: 否 | AM13: 0 | AN13: 5 | AO13: 否 | AP13: 3
A14: P002 | B14: 4 | C14: O1-S2-EA | D14: 2 | E14: 固定订书机 | F14: stapler | G14: 方法B | H14: One-Euro | I14: 2 | J14: 2 | K14: 5 | L14: 6 | M14: 5 | O14: 6 | P14: 5 | Q14: 4 | R14: 4 | S14: 6 | T14: 5 | U14: 6 | V14: 6 | W14: 5 | X14: 4 | Y14: 09:25:29 | Z14: 09:27:37 | AA14: 127.7 | AB14: 是 | AC14: 是 | AD14: 是 | AE14: 无 | AF14: 9.25 | AG14: 0.932 | AH14: 0.976 | AI14: 0.98 | AJ14: 0.741 | AK14: FrozenUncertain | AL14: 否 | AM14: 0 | AN14: 0 | AO14: 否 | AP14: 2
A15: P002 | B15: 5 | C15: O1-S2-EA | D15: 3 | E15: 游戏手柄 | F15: gamepad | G15: 方法B | H15: One-Euro | I15: 1 | J15: 3 | K15: 5 | L15: 3 | M15: 4 | O15: 5 | P15: 4 | Q15: 5 | R15: 5 | S15: 5 | T15: 4 | U15: 6 | V15: 5 | W15: 4 | X15: 4 | Y15: 09:29:12 | Z15: 09:30:56 | AA15: 103.9 | AB15: 是 | AC15: 是 | AD15: 是 | AE15: 无 | AF15: 9.22 | AG15: 0.868 | AH15: 0.911 | AI15: 0.973 | AJ15: 0.743 | AK15: FrozenUncertain | AL15: 否 | AM15: 0 | AN15: 0 | AO15: 否 | AP15: 3
A16: P002 | B16: 6 | C16: O1-S2-EA | D16: 3 | E16: 游戏手柄 | F16: gamepad | G16: 方法A | H16: EgoAnchor | I16: 2 | J16: 3 | K16: 4 | L16: 7 | M16: 6 | O16: 4 | P16: 2 | Q16: 3 | R16: 4 | S16: 7 | T16: 6 | U16: 5 | V16: 7 | W16: 7 | X16: 7 | Y16: 09:32:31 | Z16: 09:34:41 | AA16: 130.3 | AB16: 是 | AC16: 是 | AD16: 是 | AE16: 无 | AF16: 9.18 | AG16: 0.89 | AH16: 0.918 | AI16: 0.969 | AJ16: 0.818 | AK16: FrozenUncertain | AL16: 否 | AM16: 0 | AN16: 4 | AO16: 是 | AP16: 3
A17: P003 | B17: 1 | C17: O1-S2-OE | D17: 1 | E17: 鼠标 | F17: blue_mouse | G17: 方法B | H17: EgoAnchor | I17: 1 | J17: 1 | K17: 6 | L17: 5 | M17: 5 | O17: 5 | P17: 5 | Q17: 4 | R17: 6 | S17: 6 | T17: 5 | U17: 6 | V17: 5 | W17: 6 | X17: 7 | Y17: 09:15:00 | Z17: 09:16:52 | AA17: 112.8 | AB17: 是 | AC17: 是 | AD17: 是 | AE17: 无 | AF17: 9.35 | AG17: 0.896 | AH17: 0.927 | AI17: 0.98 | AJ17: 0.738 | AK17: FrozenUncertain | AL17: 否 | AM17: 0 | AN17: 6 | AO17: 否 | AP17: 4
A18: P003 | B18: 2 | C18: O1-S2-OE | D18: 1 | E18: 鼠标 | F18: blue_mouse | G18: 方法A | H18: One-Euro | I18: 2 | J18: 1 | K18: 5 | L18: 6 | M18: 4 | O18: 6 | P18: 4 | Q18: 4 | R18: 3 | S18: 4 | T18: 4 | U18: 6 | V18: 6 | W18: 4 | X18: 3 | Y18: 09:18:27 | Z18: 09:20:30 | AA18: 122.8 | AB18: 是 | AC18: 是 | AD18: 是 | AE18: 无 | AF18: 9.63 | AG18: 0.909 | AH18: 0.962 | AI18: 0.985 | AJ18: 0.781 | AK18: FrozenUncertain | AL18: 否 | AM18: 0 | AN18: 0 | AO18: 是 | AP18: 2
A19: P003 | B19: 3 | C19: O1-S2-OE | D19: 2 | E19: 固定订书机 | F19: stapler | G19: 方法A | H19: One-Euro | I19: 1 | J19: 2 | K19: 4 | L19: 4 | M19: 4 | O19: 5 | P19: 4 | Q19: 4 | R19: 5 | S19: 6 | T19: 5 | U19: 6 | V19: 4 | W19: 5 | X19: 4 | Y19: 09:22:05 | Z19: 09:24:11 | AA19: 125.8 | AB19: 是 | AC19: 是 | AD19: 是 | AE19: 无 | AF19: 9.8 | AG19: 0.9 | AH19: 0.955 | AI19: 0.989 | AJ19: 0.691 | AK19: FrozenUncertain | AL19: 否 | AM19: 0 | AN19: 0 | AO19: 否 | AP19: 3
A20: P003 | B20: 4 | C20: O1-S2-OE | D20: 2 | E20: 固定订书机 | F20: stapler | G20: 方法B | H20: EgoAnchor | I20: 2 | J20: 2 | K20: 7 | L20: 6 | M20: 6 | O20: 5 | P20: 6 | Q20: 5 | R20: 6 | S20: 6 | T20: 6 | U20: 6 | V20: 6 | W20: 6 | X20: 6 | Y20: 09:25:46 | Z20: 09:28:07 | AA20: 141.2 | AB20: 是 | AC20: 是 | AD20: 是 | AE20: 无 | AF20: 9.57 | AG20: 0.959 | AH20: 0.951 | AI20: 0.986 | AJ20: 0.694 | AK20: FrozenUncertain | AL20: 否 | AM20: 0 | AN20: 8 | AO20: 否 | AP20: 7
A21: P003 | B21: 5 | C21: O1-S2-OE | D21: 3 | E21: 游戏手柄 | F21: gamepad | G21: 方法B | H21: EgoAnchor | I21: 1 | J21: 3 | K21: 5 | L21: 4 | M21: 4 | O21: 4 | P21: 4 | Q21: 4 | R21: 6 | S21: 5 | T21: 5 | U21: 5 | V21: 4 | W21: 5 | X21: 5 | Y21: 09:29:42 | Z21: 09:31:48 | AA21: 126.1 | AB21: 是 | AC21: 是 | AD21: 是 | AE21: 无 | AF21: 9.43 | AG21: 0.892 | AH21: 0.945 | AI21: 0.986 | AJ21: 0.768 | AK21: FrozenUncertain | AL21: 否 | AM21: 0 | AN21: 7 | AO21: 否 | AP21: 5
A22: P003 | B22: 6 | C22: O1-S2-OE | D22: 3 | E22: 游戏手柄 | F22: gamepad | G22: 方法A | H22: One-Euro | I22: 2 | J22: 3 | K22: 4 | L22: 4 | M22: 4 | O22: 4 | P22: 3 | Q22: 3 | R22: 4 | S22: 4 | T22: 4 | U22: 6 | V22: 5 | W22: 4 | X22: 4 | Y22: 09:33:23 | Z22: 09:35:30 | AA22: 126.8 | AB22: 是 | AC22: 是 | AD22: 是 | AE22: 无 | AF22: 9.04 | AG22: 0.901 | AH22: 0.933 | AI22: 0.992 | AJ22: 0.743 | AK22: FrozenUncertain | AL22: 否 | AM22: 0 | AN22: 0 | AO22: 否 | AP22: 4
A23: P004 | B23: 1 | C23: O1-S1-OE | D23: 1 | E23: 鼠标 | F23: blue_mouse | G23: 方法A | H23: One-Euro | I23: 1 | J23: 1 | K23: 6 | L23: 5 | M23: 6 | O23: 6 | P23: 5 | Q23: 2 | R23: 4 | S23: 6 | T23: 5 | U23: 7 | V23: 6 | W23: 2 | X23: 6 | Y23: 09:15:00 | Z23: 09:17:12 | AA23: 132.1 | AB23: 是 | AC23: 是 | AD23: 是 | AE23: 无 | AF23: 9.26 | AG23: 0.925 | AH23: 0.926 | AI23: 0.987 | AJ23: 0.826 | AK23: FrozenUncertain | AL23: 否 | AM23: 0 | AN23: 0 | AO23: 否 | AP23: 2 | AQ23: 灾难性恢复失效(>40mm 级)
A24: P004 | B24: 2 | C24: O1-S1-OE | D24: 1 | E24: 鼠标 | F24: blue_mouse | G24: 方法B | H24: EgoAnchor | I24: 2 | J24: 1 | K24: 6 | L24: 5 | M24: 5 | O24: 3 | P24: 5 | Q24: 5 | R24: 5 | S24: 5 | T24: 5 | U24: 6 | V24: 6 | W24: 5 | X24: 4 | Y24: 09:18:47 | Z24: 09:21:18 | AA24: 151.1 | AB24: 是 | AC24: 是 | AD24: 是 | AE24: 无 | AF24: 9.39 | AG24: 0.882 | AH24: 0.939 | AI24: 0.997 | AJ24: 0.795 | AK24: FrozenUncertain | AL24: 否 | AM24: 0 | AN24: 3 | AO24: 否 | AP24: 5
A25: P004 | B25: 3 | C25: O1-S1-OE | D25: 2 | E25: 固定订书机 | F25: stapler | G25: 方法B | H25: EgoAnchor | I25: 1 | J25: 2 | K25: 7 | L25: 6 | M25: 6 | O25: 6 | P25: 6 | Q25: 4 | R25: 4 | S25: 6 | T25: 7 | U25: 6 | V25: 6 | W25: 5 | X25: 6 | Y25: 09:22:53 | Z25: 09:25:26 | AA25: 153.7 | AB25: 是 | AC25: 是 | AD25: 是 | AE25: 无 | AF25: 9.82 | AG25: 0.906 | AH25: 0.949 | AI25: 0.995 | AJ25: 0.761 | AK25: FrozenUncertain | AL25: 否 | AM25: 0 | AN25: 3 | AO25: 否 | AP25: 4
A26: P004 | B26: 4 | C26: O1-S1-OE | D26: 2 | E26: 固定订书机 | F26: stapler | G26: 方法A | H26: One-Euro | I26: 2 | J26: 2 | K26: 6 | L26: 4 | M26: 5 | O26: 6 | P26: 4 | Q26: 5 | R26: 5 | S26: 6 | T26: 6 | U26: 5 | V26: 6 | W26: 4 | X26: 4 | Y26: 09:27:01 | Z26: 09:29:18 | AA26: 136.3 | AB26: 是 | AC26: 是 | AD26: 是 | AE26: 无 | AF26: 9.33 | AG26: 0.962 | AH26: 0.959 | AI26: 0.997 | AJ26: 0.793 | AK26: FrozenUncertain | AL26: 否 | AM26: 0 | AN26: 0 | AO26: 否 | AP26: 2
A27: P004 | B27: 5 | C27: O1-S1-OE | D27: 3 | E27: 游戏手柄 | F27: gamepad | G27: 方法A | H27: One-Euro | I27: 1 | J27: 3 | K27: 4 | L27: 5 | M27: 5 | O27: 4 | P27: 4 | Q27: 2 | R27: 4 | S27: 5 | T27: 5 | U27: 5 | V27: 5 | W27: 1 | X27: 4 | Y27: 09:30:53 | Z27: 09:33:22 | AA27: 149.6 | AB27: 是 | AC27: 是 | AD27: 是 | AE27: 无 | AF27: 9.09 | AG27: 0.879 | AH27: 0.934 | AI27: 0.971 | AJ27: 0.612 | AK27: FrozenUncertain | AL27: 否 | AM27: 0 | AN27: 0 | AO27: 否 | AP27: 4 | AQ27: 灾难性恢复失效(>40mm 级)
A28: P004 | B28: 6 | C28: O1-S1-OE | D28: 3 | E28: 游戏手柄 | F28: gamepad | G28: 方法B | H28: EgoAnchor | I28: 2 | J28: 3 | K28: 6 | L28: 4 | M28: 4 | O28: 6 | P28: 6 | Q28: 5 | R28: 5 | S28: 5 | T28: 6 | U28: 6 | V28: 5 | W28: 5 | X28: 5 | Y28: 09:34:57 | Z28: 09:36:57 | AA28: 119.7 | AB28: 是 | AC28: 是 | AD28: 是 | AE28: 无 | AF28: 9.39 | AG28: 0.881 | AH28: 0.913 | AI28: 0.979 | AJ28: 0.746 | AK28: FrozenUncertain | AL28: 否 | AM28: 0 | AN28: 4 | AO28: 否 | AP28: 3
A29: P005 | B29: 1 | C29: O2-S1-EA | D29: 1 | E29: 鼠标 | F29: blue_mouse | G29: 方法A | H29: EgoAnchor | I29: 1 | J29: 1 | K29: 7 | L29: 4 | M29: 4 | O29: 5 | P29: 6 | Q29: 4 | R29: 4 | S29: 4 | T29: 4 | U29: 6 | V29: 6 | W29: 4 | X29: 5 | Y29: 09:15:00 | Z29: 09:17:02 | AA29: 122.8 | AB29: 是 | AC29: 是 | AD29: 是 | AE29: 无 | AF29: 9.53 | AG29: 0.894 | AH29: 0.941 | AI29: 0.986 | AJ29: 0.755 | AK29: FrozenUncertain | AL29: 否 | AM29: 0 | AN29: 4 | AO29: 否 | AP29: 4 | AQ29: StaticLock 锁在略偏位姿
A30: P005 | B30: 2 | C30: O2-S1-EA | D30: 1 | E30: 鼠标 | F30: blue_mouse | G30: 方法B | H30: One-Euro | I30: 2 | J30: 1 | K30: 4 | L30: 5 | M30: 4 | O30: 6 | P30: 4 | Q30: 4 | R30: 4 | S30: 5 | T30: 4 | U30: 6 | V30: 5 | W30: 4 | X30: 4 | Y30: 09:18:37 | Z30: 09:20:38 | AA30: 121 | AB30: 是 | AC30: 是 | AD30: 是 | AE30: 无 | AF30: 9.79 | AG30: 0.92 | AH30: 0.924 | AI30: 0.989 | AJ30: 0.829 | AK30: FrozenUncertain | AL30: 否 | AM30: 0 | AN30: 0 | AO30: 否 | AP30: 3
A31: P005 | B31: 3 | C31: O2-S1-EA | D31: 2 | E31: 游戏手柄 | F31: gamepad | G31: 方法B | H31: One-Euro | I31: 1 | J31: 2 | K31: 1 | L31: 4 | M31: 3 | O31: 3 | P31: 4 | Q31: 3 | R31: 3 | S31: 4 | T31: 3 | U31: 4 | V31: 5 | W31: 3 | X31: 3 | Y31: 09:22:13 | Z31: 09:23:51 | AA31: 97.9 | AB31: 是 | AC31: 是 | AD31: 是 | AE31: 无 | AF31: 9.34 | AG31: 0.869 | AH31: 0.924 | AI31: 0.988 | AJ31: 0.789 | AK31: FrozenUncertain | AL31: 否 | AM31: 0 | AN31: 0 | AO31: 否 | AP31: 2
A32: P005 | B32: 4 | C32: O2-S1-EA | D32: 2 | E32: 游戏手柄 | F32: gamepad | G32: 方法A | H32: EgoAnchor | I32: 2 | J32: 2 | K32: 6 | L32: 6 | M32: 6 | O32: 6 | P32: 4 | Q32: 5 | R32: 6 | S32: 6 | T32: 4 | U32: 6 | V32: 5 | W32: 5 | X32: 5 | Y32: 09:25:26 | Z32: 09:26:53 | AA32: 86.6 | AB32: 是 | AC32: 是 | AD32: 是 | AE32: 无 | AF32: 9.34 | AG32: 0.862 | AH32: 0.938 | AI32: 0.994 | AJ32: 0.769 | AK32: FrozenUncertain | AL32: 否 | AM32: 0 | AN32: 2 | AO32: 否 | AP32: 4
A33: P005 | B33: 5 | C33: O2-S1-EA | D33: 3 | E33: 固定订书机 | F33: stapler | G33: 方法A | H33: EgoAnchor | I33: 1 | J33: 3 | K33: 6 | L33: 4 | M33: 5 | O33: 5 | P33: 5 | Q33: 5 | R33: 5 | S33: 6 | T33: 5 | U33: 7 | V33: 6 | W33: 5 | X33: 4 | Y33: 09:28:28 | Z33: 09:30:31 | AA33: 122.7 | AB33: 是 | AC33: 是 | AD33: 是 | AE33: 无 | AF33: 9.73 | AG33: 0.935 | AH33: 0.939 | AI33: 0.99 | AJ33: 0.742 | AK33: FrozenUncertain | AL33: 否 | AM33: 0 | AN33: 4 | AO33: 否 | AP33: 5
A34: P005 | B34: 6 | C34: O2-S1-EA | D34: 3 | E34: 固定订书机 | F34: stapler | G34: 方法B | H34: One-Euro | I34: 2 | J34: 3 | K34: 5 | L34: 6 | M34: 5 | O34: 6 | P34: 6 | Q34: 5 | R34: 6 | S34: 7 | T34: 5 | U34: 7 | V34: 7 | W34: 5 | X34: 6 | Y34: 09:32:06 | Z34: 09:34:07 | AA34: 121.4 | AB34: 是 | AC34: 是 | AD34: 是 | AE34: 无 | AF34: 9.31 | AG34: 0.902 | AH34: 0.94 | AI34: 0.985 | AJ34: 0.81 | AK34: FrozenUncertain | AL34: 否 | AM34: 0 | AN34: 0 | AO34: 否 | AP34: 2
A35: P006 | B35: 1 | C35: O2-S2-EA | D35: 1 | E35: 鼠标 | F35: blue_mouse | G35: 方法B | H35: One-Euro | I35: 1 | J35: 1 | K35: 4 | L35: 5 | M35: 4 | O35: 4 | P35: 4 | Q35: 4 | R35: 5 | S35: 5 | T35: 5 | U35: 5 | V35: 4 | W35: 4 | X35: 4 | Y35: 09:15:00 | Z35: 09:17:15 | AA35: 135.1 | AB35: 是 | AC35: 是 | AD35: 是 | AE35: 无 | AF35: 9.35 | AG35: 0.919 | AH35: 0.931 | AI35: 0.994 | AJ35: 0.776 | AK35: FrozenUncertain | AL35: 否 | AM35: 0 | AN35: 0 | AO35: 否 | AP35: 4
A36: P006 | B36: 2 | C36: O2-S2-EA | D36: 1 | E36: 鼠标 | F36: blue_mouse | G36: 方法A | H36: EgoAnchor | I36: 2 | J36: 1 | K36: 3 | L36: 4 | M36: 4 | O36: 3 | P36: 4 | Q36: 3 | R36: 4 | S36: 5 | T36: 4 | U36: 4 | V36: 4 | W36: 4 | X36: 4 | Y36: 09:18:50 | Z36: 09:21:29 | AA36: 159.1 | AB36: 是 | AC36: 是 | AD36: 是 | AE36: 无 | AF36: 9.5 | AG36: 0.932 | AH36: 0.952 | AI36: 0.985 | AJ36: 0.839 | AK36: FrozenUncertain | AL36: 否 | AM36: 0 | AN36: 9 | AO36: 否 | AP36: 5
A37: P006 | B37: 3 | C37: O2-S2-EA | D37: 2 | E37: 游戏手柄 | F37: gamepad | G37: 方法A | H37: EgoAnchor | I37: 1 | J37: 2 | K37: 5 | L37: 5 | M37: 5 | O37: 4 | P37: 4 | Q37: 4 | R37: 5 | S37: 5 | T37: 5 | U37: 5 | V37: 5 | W37: 5 | X37: 6 | Y37: 09:23:04 | Z37: 09:25:13 | AA37: 129.7 | AB37: 是 | AC37: 是 | AD37: 是 | AE37: 无 | AF37: 9.23 | AG37: 0.881 | AH37: 0.931 | AI37: 0.975 | AJ37: 0.702 | AK37: FrozenUncertain | AL37: 否 | AM37: 0 | AN37: 2 | AO37: 否 | AP37: 6
A38: P006 | B38: 4 | C38: O2-S2-EA | D38: 2 | E38: 游戏手柄 | F38: gamepad | G38: 方法B | H38: One-Euro | I38: 2 | J38: 2 | K38: 3 | L38: 5 | M38: 3 | O38: 4 | P38: 4 | Q38: 2 | R38: 4 | S38: 5 | T38: 4 | U38: 4 | V38: 5 | W38: 1 | X38: 4 | Y38: 09:26:48 | Z38: 09:29:14 | AA38: 145.4 | AB38: 是 | AC38: 是 | AD38: 是 | AE38: 无 | AF38: 9.52 | AG38: 0.863 | AH38: 0.923 | AI38: 0.99 | AJ38: 0.81 | AK38: FrozenUncertain | AL38: 否 | AM38: 0 | AN38: 0 | AO38: 否 | AP38: 2 | AQ38: 灾难性恢复失效(>40mm 级)
A39: P006 | B39: 5 | C39: O2-S2-EA | D39: 3 | E39: 固定订书机 | F39: stapler | G39: 方法B | H39: One-Euro | I39: 1 | J39: 3 | K39: 4 | L39: 5 | M39: 4 | O39: 3 | P39: 5 | Q39: 5 | R39: 4 | S39: 5 | T39: 4 | U39: 4 | V39: 6 | W39: 4 | X39: 4 | Y39: 09:30:49 | Z39: 09:32:39 | AA39: 110 | AB39: 是 | AC39: 是 | AD39: 是 | AE39: 无 | AF39: 9.72 | AG39: 0.922 | AH39: 0.935 | AI39: 0.994 | AJ39: 0.686 | AK39: FrozenUncertain | AL39: 否 | AM39: 0 | AN39: 0 | AO39: 否 | AP39: 2
A40: P006 | B40: 6 | C40: O2-S2-EA | D40: 3 | E40: 固定订书机 | F40: stapler | G40: 方法A | H40: EgoAnchor | I40: 2 | J40: 3 | K40: 5 | L40: 5 | M40: 5 | O40: 4 | P40: 6 | Q40: 6 | R40: 6 | S40: 6 | T40: 5 | U40: 5 | V40: 5 | W40: 3 | X40: 6 | Y40: 09:34:14 | Z40: 09:36:09 | AA40: 115.5 | AB40: 是 | AC40: 是 | AD40: 是 | AE40: 无 | AF40: 9.86 | AG40: 0.959 | AH40: 0.979 | AI40: 1 | AJ40: 0.709 | AK40: FrozenUncertain | AL40: 否 | AM40: 0 | AN40: 5 | AO40: 是 | AP40: 4
A41: P007 | B41: 1 | C41: O2-S2-OE | D41: 1 | E41: 鼠标 | F41: blue_mouse | G41: 方法B | H41: EgoAnchor | I41: 1 | J41: 1 | K41: 6 | L41: 6 | M41: 6 | O41: 6 | P41: 6 | Q41: 5 | R41: 5 | S41: 6 | T41: 6 | U41: 6 | V41: 6 | W41: 6 | X41: 6 | Y41: 09:15:00 | Z41: 09:17:43 | AA41: 163.7 | AB41: 是 | AC41: 是 | AD41: 是 | AE41: 无 | AF41: 9.56 | AG41: 0.914 | AH41: 0.965 | AI41: 0.979 | AJ41: 0.735 | AK41: FrozenUncertain | AL41: 否 | AM41: 0 | AN41: 2 | AO41: 否 | AP41: 6
...

Sheet Derived
A1: 派生层（全部为公式，Excel 打开时实时重算）：L1 区块子量表 → L2 三物体均值 → L3 TiA 反向与量表分 → L4 配对差
A3: L1. 区块级派生（每行 = 一个方法×物体区块；13 项引用 Records A 段，AQ 两子量表分 = 3 项均值，公式实时计算）
A4: Participant_ID | B4: Method(内部) | C4: Object_Key | D4: Records行 | E4: Q1 | F4: Q8 | G4: Q2 | H4: Q9 | I4: Q3 | J4: Q6 | K4: Q7 | L4: AQ_EQ1 | M4: AQ_EQ2 | N4: AQ_EQ3 | O4: AQ_IQ1 | P4: AQ_IQ2 | Q4: AQ_IQ3 | R4: AQ_EQ(3项均值) | S4: AQ_IQ(3项均值) | T4: 问卷时长_s | U4: 最长连续同分 | V4: 问卷>150s
A5: P001 | B5: One-Euro | C5: blue_mouse | D5: 6 | E5: =Records!K6 -> 3 | F5: =Records!R6 -> 4 | G5: =Records!L6 -> 4 | H5: =Records!M6 -> 5 | I5: =Records!Q6 -> 4 | J5: =Records!W6 -> 4 | K5: =Records!X6 -> 4 | L5: =Records!S6 -> 3 | M5: =Records!T6 -> 4 | N5: =Records!U6 -> 4 | O5: =Records!V6 -> 3 | P5: =Records!O6 -> 4 | Q5: =Records!P6 -> 4 | R5: =AVERAGE(Records!S6,Records!T6,Records!U6) -> 3.6666667 | S5: =AVERAGE(Records!V6,Records!O6,Records!P6) -> 3.6666667 | T5: =Records!AA6 -> 186.7 | U5: =Records!AP6 -> 4 | V5: =IF(Records!AA6>150,1,0) -> 1
A6: P002 | B6: One-Euro | C6: blue_mouse | D6: 11 | E6: =Records!K11 -> 3 | F6: =Records!R11 -> 4 | G6: =Records!L11 -> 3 | H6: =Records!M11 -> 3 | I6: =Records!Q11 -> 1 | J6: =Records!W11 -> 1 | K6: =Records!X11 -> 4 | L6: =Records!S11 -> 5 | M6: =Records!T11 -> 3 | N6: =Records!U11 -> 6 | O6: =Records!V11 -> 6 | P6: =Records!O11 -> 4 | Q6: =Records!P11 -> 5 | R6: =AVERAGE(Records!S11,Records!T11,Records!U11) -> 4.6666667 | S6: =AVERAGE(Records!V11,Records!O11,Records!P11) -> 5 | T6: =Records!AA11 -> 119.7 | U6: =Records!AP11 -> 3 | V6: =IF(Records!AA11>150,1,0) -> 0
A7: P003 | B7: One-Euro | C7: blue_mouse | D7: 18 | E7: =Records!K18 -> 5 | F7: =Records!R18 -> 3 | G7: =Records!L18 -> 6 | H7: =Records!M18 -> 4 | I7: =Records!Q18 -> 4 | J7: =Records!W18 -> 4 | K7: =Records!X18 -> 3 | L7: =Records!S18 -> 4 | M7: =Records!T18 -> 4 | N7: =Records!U18 -> 6 | O7: =Records!V18 -> 6 | P7: =Records!O18 -> 6 | Q7: =Records!P18 -> 4 | R7: =AVERAGE(Records!S18,Records!T18,Records!U18) -> 4.6666667 | S7: =AVERAGE(Records!V18,Records!O18,Records!P18) -> 5.3333333 | T7: =Records!AA18 -> 122.8 | U7: =Records!AP18 -> 2 | V7: =IF(Records!AA18>150,1,0) -> 0
A8: P004 | B8: One-Euro | C8: blue_mouse | D8: 23 | E8: =Records!K23 -> 6 | F8: =Records!R23 -> 4 | G8: =Records!L23 -> 5 | H8: =Records!M23 -> 6 | I8: =Records!Q23 -> 2 | J8: =Records!W23 -> 2 | K8: =Records!X23 -> 6 | L8: =Records!S23 -> 6 | M8: =Records!T23 -> 5 | N8: =Records!U23 -> 7 | O8: =Records!V23 -> 6 | P8: =Records!O23 -> 6 | Q8: =Records!P23 -> 5 | R8: =AVERAGE(Records!S23,Records!T23,Records!U23) -> 6 | S8: =AVERAGE(Records!V23,Records!O23,Records!P23) -> 5.6666667 | T8: =Records!AA23 -> 132.1 | U8: =Records!AP23 -> 2 | V8: =IF(Records!AA23>150,1,0) -> 0
A9: P005 | B9: One-Euro | C9: blue_mouse | D9: 30 | E9: =Records!K30 -> 4 | F9: =Records!R30 -> 4 | G9: =Records!L30 -> 5 | H9: =Records!M30 -> 4 | I9: =Records!Q30 -> 4 | J9: =Records!W30 -> 4 | K9: =Records!X30 -> 4 | L9: =Records!S30 -> 5 | M9: =Records!T30 -> 4 | N9: =Records!U30 -> 6 | O9: =Records!V30 -> 5 | P9: =Records!O30 -> 6 | Q9: =Records!P30 -> 4 | R9: =AVERAGE(Records!S30,Records!T30,Records!U30) -> 5 | S9: =AVERAGE(Records!V30,Records!O30,Records!P30) -> 5 | T9: =Records!AA30 -> 121 | U9: =Records!AP30 -> 3 | V9: =IF(Records!AA30>150,1,0) -> 0
A10: P006 | B10: One-Euro | C10: blue_mouse | D10: 35 | E10: =Records!K35 -> 4 | F10: =Records!R35 -> 5 | G10: =Records!L35 -> 5 | H10: =Records!M35 -> 4 | I10: =Records!Q35 -> 4 | J10: =Records!W35 -> 4 | K10: =Records!X35 -> 4 | L10: =Records!S35 -> 5 | M10: =Records!T35 -> 5 | N10: =Records!U35 -> 5 | O10: =Records!V35 -> 4 | P10: =Records!O35 -> 4 | Q10: =Records!P35 -> 4 | R10: =AVERAGE(Records!S35,Records!T35,Records!U35) -> 5 | S10: =AVERAGE(Records!V35,Records!O35,Records!P35) -> 4 | T10: =Records!AA35 -> 135.1 | U10: =Records!AP35 -> 4 | V10: =IF(Records!AA35>150,1,0) -> 0
A11: P007 | B11: One-Euro | C11: blue_mouse | D11: 42 | E11: =Records!K42 -> 4 | F11: =Records!R42 -> 4 | G11: =Records!L42 -> 5 | H11: =Records!M42 -> 4 | I11: =Records!Q42 -> 4 | J11: =Records!W42 -> 4 | K11: =Records!X42 -> 4 | L11: =Records!S42 -> 4 | M11: =Records!T42 -> 4 | N11: =Records!U42 -> 6 | O11: =Records!V42 -> 5 | P11: =Records!O42 -> 4 | Q11: =Records!P42 -> 5 | R11: =AVERAGE(Records!S42,Records!T42,Records!U42) -> 4.6666667 | S11: =AVERAGE(Records!V42,Records!O42,Records!P42) -> 4.6666667 | T11: =Records!AA42 -> 167 | U11: =Records!AP42 -> 4 | V11: =IF(Records!AA42>150,1,0) -> 1
A12: P008 | B12: One-Euro | C12: blue_mouse | D12: 47 | E12: =Records!K47 -> 5 | F12: =Records!R47 -> 5 | G12: =Records!L47 -> 5 | H12: =Records!M47 -> 4 | I12: =Records!Q47 -> 4 | J12: =Records!W47 -> 3 | K12: =Records!X47 -> 4 | L12: =Records!S47 -> 5 | M12: =Records!T47 -> 5 | N12: =Records!U47 -> 5 | O12: =Records!V47 -> 6 | P12: =Records!O47 -> 5 | Q12: =Records!P47 -> 5 | R12: =AVERAGE(Records!S47,Records!T47,Records!U47) -> 5 | S12: =AVERAGE(Records!V47,Records!O47,Records!P47) -> 5.3333333 | T12: =Records!AA47 -> 142.6 | U12: =Records!AP47 -> 4 | V12: =IF(Records!AA47>150,1,0) -> 0
A13: P009 | B13: One-Euro | C13: blue_mouse | D13: 55 | E13: =Records!K55 -> 5 | F13: =Records!R55 -> 6 | G13: =Records!L55 -> 5 | H13: =Records!M55 -> 5 | I13: =Records!Q55 -> 5 | J13: =Records!W55 -> 5 | K13: =Records!X55 -> 6 | L13: =Records!S55 -> 5 | M13: =Records!T55 -> 5 | N13: =Records!U55 -> 6 | O13: =Records!V55 -> 4 | P13: =Records!O55 -> 6 | Q13: =Records!P55 -> 5 | R13: =AVERAGE(Records!S55,Records!T55,Records!U55) -> 5.3333333 | S13: =AVERAGE(Records!V55,Records!O55,Records!P55) -> 5 | T13: =Records!AA55 -> 110.2 | U13: =Records!AP55 -> 3 | V13: =IF(Records!AA55>150,1,0) -> 0
A14: P010 | B14: One-Euro | C14: blue_mouse | D14: 62 | E14: =Records!K62 -> 4 | F14: =Records!R62 -> 5 | G14: =Records!L62 -> 5 | H14: =Records!M62 -> 5 | I14: =Records!Q62 -> 5 | J14: =Records!W62 -> 5 | K14: =Records!X62 -> 5 | L14: =Records!S62 -> 6 | M14: =Records!T62 -> 6 | N14: =Records!U62 -> 6 | O14: =Records!V62 -> 6 | P14: =Records!O62 -> 6 | Q14: =Records!P62 -> 5 | R14: =AVERAGE(Records!S62,Records!T62,Records!U62) -> 6 | S14: =AVERAGE(Records!V62,Records!O62,Records!P62) -> 5.6666667 | T14: =Records!AA62 -> 202 | U14: =Records!AP62 -> 4 | V14: =IF(Records!AA62>150,1,0) -> 1
A15: P011 | B15: One-Euro | C15: blue_mouse | D15: 67 | E15: =Records!K67 -> 4 | F15: =Records!R67 -> 5 | G15: =Records!L67 -> 6 | H15: =Records!M67 -> 5 | I15: =Records!Q67 -> 4 | J15: =Records!W67 -> 6 | K15: =Records!X67 -> 5 | L15: =Records!S67 -> 6 | M15: =Records!T67 -> 6 | N15: =Records!U67 -> 6 | O15: =Records!V67 -> 5 | P15: =Records!O67 -> 6 | Q15: =Records!P67 -> 5 | R15: =AVERAGE(Records!S67,Records!T67,Records!U67) -> 6 | S15: =AVERAGE(Records!V67,Records!O67,Records!P67) -> 5.3333333 | T15: =Records!AA67 -> 135.7 | U15: =Records!AP67 -> 3 | V15: =IF(Records!AA67>150,1,0) -> 0
A16: P012 | B16: One-Euro | C16: blue_mouse | D16: 74 | E16: =Records!K74 -> 3 | F16: =Records!R74 -> 4 | G16: =Records!L74 -> 4 | H16: =Records!M74 -> 3 | I16: =Records!Q74 -> 4 | J16: =Records!W74 -> 3 | K16: =Records!X74 -> 4 | L16: =Records!S74 -> 4 | M16: =Records!T74 -> 4 | N16: =Records!U74 -> 6 | O16: =Records!V74 -> 4 | P16: =Records!O74 -> 5 | Q16: =Records!P74 -> 4 | R16: =AVERAGE(Records!S74,Records!T74,Records!U74) -> 4.6666667 | S16: =AVERAGE(Records!V74,Records!O74,Records!P74) -> 4.3333333 | T16: =Records!AA74 -> 126.7 | U16: =Records!AP74 -> 5 | V16: =IF(Records!AA74>150,1,0) -> 0
A17: P013 | B17: One-Euro | C17: blue_mouse | D17: 82 | E17: =Records!K82 -> 5 | F17: =Records!R82 -> 5 | G17: =Records!L82 -> 5 | H17: =Records!M82 -> 5 | I17: =Records!Q82 -> 4 | J17: =Records!W82 -> 4 | K17: =Records!X82 -> 5 | L17: =Records!S82 -> 5 | M17: =Records!T82 -> 5 | N17: =Records!U82 -> 6 | O17: =Records!V82 -> 6 | P17: =Records!O82 -> 5 | Q17: =Records!P82 -> 6 | R17: =AVERAGE(Records!S82,Records!T82,Records!U82) -> 5.3333333 | S17: =AVERAGE(Records!V82,Records!O82,Records!P82) -> 5.6666667 | T17: =Records!AA82 -> 113.4 | U17: =Records!AP82 -> 4 | V17: =IF(Records!AA82>150,1,0) -> 0
A18: P014 | B18: One-Euro | C18: blue_mouse | D18: 87 | E18: =Records!K87 -> 3 | F18: =Records!R87 -> 4 | G18: =Records!L87 -> 4 | H18: =Records!M87 -> 4 | I18: =Records!Q87 -> 5 | J18: =Records!W87 -> 5 | K18: =Records!X87 -> 4 | L18: =Records!S87 -> 5 | M18: =Records!T87 -> 5 | N18: =Records!U87 -> 7 | O18: =Records!V87 -> 5 | P18: =Records!O87 -> 5 | Q18: =Records!P87 -> 5 | R18: =AVERAGE(Records!S87,Records!T87,Records!U87) -> 5.6666667 | S18: =AVERAGE(Records!V87,Records!O87,Records!P87) -> 5 | T18: =Records!AA87 -> 129.8 | U18: =Records!AP87 -> 3 | V18: =IF(Records!AA87>150,1,0) -> 0
A19: P015 | B19: One-Euro | C19: blue_mouse | D19: 94 | E19: =Records!K94 -> 4 | F19: =Records!R94 -> 4 | G19: =Records!L94 -> 5 | H19: =Records!M94 -> 4 | I19: =Records!Q94 -> 4 | J19: =Records!W94 -> 4 | K19: =Records!X94 -> 5 | L19: =Records!S94 -> 6 | M19: =Records!T94 -> 6 | N19: =Records!U94 -> 6 | O19: =Records!V94 -> 4 | P19: =Records!O94 -> 4 | Q19: =Records!P94 -> 4 | R19: =AVERAGE(Records!S94,Records!T94,Records!U94) -> 6 | S19: =AVERAGE(Records!V94,Records!O94,Records!P94) -> 4 | T19: =Records!AA94 -> 101.1 | U19: =Records!AP94 -> 5 | V19: =IF(Records!AA94>150,1,0) -> 0
A20: P016 | B20: One-Euro | C20: blue_mouse | D20: 99 | E20: =Records!K99 -> 4 | F20: =Records!R99 -> 4 | G20: =Records!L99 -> 4 | H20: =Records!M99 -> 4 | I20: =Records!Q99 -> 4 | J20: =Records!W99 -> 6 | K20: =Records!X99 -> 4 | L20: =Records!S99 -> 4 | M20: =Records!T99 -> 4 | N20: =Records!U99 -> 4 | O20: =Records!V99 -> 6 | P20: =Records!O99 -> 5 | Q20: =Records!P99 -> 5 | R20: =AVERAGE(Records!S99,Records!T99,Records!U99) -> 4 | S20: =AVERAGE(Records!V99,Records!O99,Records!P99) -> 5.3333333 | T20: =Records!AA99 -> 174.1 | U20: =Records!AP99 -> 5 | V20: =IF(Records!AA99>150,1,0) -> 1
A21: P017 | B21: One-Euro | C21: blue_mouse | D21: 103 | E21: =Records!K103 -> 4 | F21: =Records!R103 -> 5 | G21: =Records!L103 -> 4 | H21: =Records!M103 -> 4 | I21: =Records!Q103 -> 4 | J21: =Records!W103 -> 5 | K21: =Records!X103 -> 4 | L21: =Records!S103 -> 5 | M21: =Records!T103 -> 5 | N21: =Records!U103 -> 6 | O21: =Records!V103 -> 5 | P21: =Records!O103 -> 4 | Q21: =Records!P103 -> 4 | R21: =AVERAGE(Records!S103,Records!T103,Records!U103) -> 5.3333333 | S21: =AVERAGE(Records!V103,Records!O103,Records!P103) -> 4.3333333 | T21: =Records!AA103 -> 159.1 | U21: =Records!AP103 -> 6 | V21: =IF(Records!AA103>150,1,0) -> 1
A22: P018 | B22: One-Euro | C22: blue_mouse | D22: 110 | E22: =Records!K110 -> 3 | F22: =Records!R110 -> 4 | G22: =Records!L110 -> 5 | H22: =Records!M110 -> 4 | I22: =Records!Q110 -> 4 | J22: =Records!W110 -> 4 | K22: =Records!X110 -> 4 | L22: =Records!S110 -> 5 | M22: =Records!T110 -> 4 | N22: =Records!U110 -> 6 | O22: =Records!V110 -> 5 | P22: =Records!O110 -> 5 | Q22: =Records!P110 -> 5 | R22: =AVERAGE(Records!S110,Records!T110,Records!U110) -> 5 | S22: =AVERAGE(Records!V110,Records!O110,Records!P110) -> 5 | T22: =Records!AA110 -> 123.3 | U22: =Records!AP110 -> 2 | V22: =IF(Records!AA110>150,1,0) -> 0
A23: P019 | B23: One-Euro | C23: blue_mouse | D23: 115 | E23: =Records!K115 -> 3 | F23: =Records!R115 -> 4 | G23: =Records!L115 -> 3 | H23: =Records!M115 -> 4 | I23: =Records!Q115 -> 4 | J23: =Records!W115 -> 4 | K23: =Records!X115 -> 4 | L23: =Records!S115 -> 5 | M23: =Records!T115 -> 4 | N23: =Records!U115 -> 6 | O23: =Records!V115 -> 4 | P23: =Records!O115 -> 4 | Q23: =Records!P115 -> 4 | R23: =AVERAGE(Records!S115,Records!T115,Records!U115) -> 5 | S23: =AVERAGE(Records!V115,Records!O115,Records!P115) -> 4 | T23: =Records!AA115 -> 109.9 | U23: =Records!AP115 -> 5 | V23: =IF(Records!AA115>150,1,0) -> 0
A24: P020 | B24: One-Euro | C24: blue_mouse | D24: 122 | E24: =Records!K122 -> 3 | F24: =Records!R122 -> 1 | G24: =Records!L122 -> 4 | H24: =Records!M122 -> 4 | I24: =Records!Q122 -> 1 | J24: =Records!W122 -> 1 | K24: =Records!X122 -> 3 | L24: =Records!S122 -> 4 | M24: =Records!T122 -> 3 | N24: =Records!U122 -> 6 | O24: =Records!V122 -> 2 | P24: =Records!O122 -> 4 | Q24: =Records!P122 -> 4 | R24: =AVERAGE(Records!S122,Records!T122,Records!U122) -> 4.3333333 | S24: =AVERAGE(Records!V122,Records!O122,Records!P122) -> 3.3333333 | T24: =Records!AA122 -> 123.4 | U24: =Records!AP122 -> 4 | V24: =IF(Records!AA122>150,1,0) -> 0
A25: P021 | B25: One-Euro | C25: blue_mouse | D25: 130 | E25: =Records!K130 -> 5 | F25: =Records!R130 -> 6 | G25: =Records!L130 -> 5 | H25: =Records!M130 -> 5 | I25: =Records!Q130 -> 5 | J25: =Records!W130 -> 6 | K25: =Records!X130 -> 4 | L25: =Records!S130 -> 6 | M25: =Records!T130 -> 6 | N25: =Records!U130 -> 6 | O25: =Records!V130 -> 6 | P25: =Records!O130 -> 7 | Q25: =Records!P130 -> 7 | R25: =AVERAGE(Records!S130,Records!T130,Records!U130) -> 6 | S25: =AVERAGE(Records!V130,Records!O130,Records!P130) -> 6.6666667 | T25: =Records!AA130 -> 174.4 | U25: =Records!AP130 -> 6 | V25: =IF(Records!AA130>150,1,0) -> 1
A26: P022 | B26: One-Euro | C26: blue_mouse | D26: 135 | E26: =Records!K135 -> 4 | F26: =Records!R135 -> 4 | G26: =Records!L135 -> 5 | H26: =Records!M135 -> 5 | I26: =Records!Q135 -> 2 | J26: =Records!W135 -> 4 | K26: =Records!X135 -> 4 | L26: =Records!S135 -> 5 | M26: =Records!T135 -> 6 | N26: =Records!U135 -> 7 | O26: =Records!V135 -> 5 | P26: =Records!O135 -> 6 | Q26: =Records!P135 -> 4 | R26: =AVERAGE(Records!S135,Records!T135,Records!U135) -> 6 | S26: =AVERAGE(Records!V135,Records!O135,Records!P135) -> 5 | T26: =Records!AA135 -> 116.7 | U26: =Records!AP135 -> 2 | V26: =IF(Records!AA135>150,1,0) -> 0
A27: P023 | B27: One-Euro | C27: blue_mouse | D27: 142 | E27: =Records!K142 -> 4 | F27: =Records!R142 -> 4 | G27: =Records!L142 -> 5 | H27: =Records!M142 -> 4 | I27: =Records!Q142 -> 4 | J27: =Records!W142 -> 5 | K27: =Records!X142 -> 5 | L27: =Records!S142 -> 5 | M27: =Records!T142 -> 5 | N27: =Records!U142 -> 6 | O27: =Records!V142 -> 5 | P27: =Records!O142 -> 4 | Q27: =Records!P142 -> 5 | R27: =AVERAGE(Records!S142,Records!T142,Records!U142) -> 5.3333333 | S27: =AVERAGE(Records!V142,Records!O142,Records!P142) -> 4.6666667 | T27: =Records!AA142 -> 134.3 | U27: =Records!AP142 -> 3 | V27: =IF(Records!AA142>150,1,0) -> 0
A28: P024 | B28: One-Euro | C28: blue_mouse | D28: 147 | E28: =Records!K147 -> 4 | F28: =Records!R147 -> 5 | G28: =Records!L147 -> 4 | H28: =Records!M147 -> 4 | I28: =Records!Q147 -> 5 | J28: =Records!W147 -> 5 | K28: =Records!X147 -> 4 | L28: =Records!S147 -> 6 | M28: =Records!T147 -> 5 | N28: =Records!U147 -> 6 | O28: =Records!V147 -> 5 | P28: =Records!O147 -> 4 | Q28: =Records!P147 -> 5 | R28: =AVERAGE(Records!S147,Records!T147,Records!U147) -> 5.6666667 | S28: =AVERAGE(Records!V147,Records!O147,Records!P147) -> 4.6666667 | T28: =Records!AA147 -> 137.5 | U28: =Records!AP147 -> 4 | V28: =IF(Records!AA147>150,1,0) -> 0
A29: P001 | B29: One-Euro | C29: stapler | D29: 7 | E29: =Records!K7 -> 4 | F29: =Records!R7 -> 5 | G29: =Records!L7 -> 5 | H29: =Records!M7 -> 5 | I29: =Records!Q7 -> 4 | J29: =Records!W7 -> 5 | K29: =Records!X7 -> 4 | L29: =Records!S7 -> 5 | M29: =Records!T7 -> 4 | N29: =Records!U7 -> 5 | O29: =Records!V7 -> 5 | P29: =Records!O7 -> 5 | Q29: =Records!P7 -> 4 | R29: =AVERAGE(Records!S7,Records!T7,Records!U7) -> 4.6666667 | S29: =AVERAGE(Records!V7,Records!O7,Records!P7) -> 4.6666667 | T29: =Records!AA7 -> 164.3 | U29: =Records!AP7 -> 3 | V29: =IF(Records!AA7>150,1,0) -> 1
A30: P002 | B30: One-Euro | C30: stapler | D30: 14 | E30: =Records!K14 -> 5 | F30: =Records!R14 -> 4 | G30: =Records!L14 -> 6 | H30: =Records!M14 -> 5 | I30: =Records!Q14 -> 4 | J30: =Records!W14 -> 5 | K30: =Records!X14 -> 4 | L30: =Records!S14 -> 6 | M30: =Records!T14 -> 5 | N30: =Records!U14 -> 6 | O30: =Records!V14 -> 6 | P30: =Records!O14 -> 6 | Q30: =Records!P14 -> 5 | R30: =AVERAGE(Records!S14,Records!T14,Records!U14) -> 5.6666667 | S30: =AVERAGE(Records!V14,Records!O14,Records!P14) -> 5.6666667 | T30: =Records!AA14 -> 127.7 | U30: =Records!AP14 -> 2 | V30: =IF(Records!AA14>150,1,0) -> 0
A31: P003 | B31: One-Euro | C31: stapler | D31: 19 | E31: =Records!K19 -> 4 | F31: =Records!R19 -> 5 | G31: =Records!L19 -> 4 | H31: =Records!M19 -> 4 | I31: =Records!Q19 -> 4 | J31: =Records!W19 -> 5 | K31: =Records!X19 -> 4 | L31: =Records!S19 -> 6 | M31: =Records!T19 -> 5 | N31: =Records!U19 -> 6 | O31: =Records!V19 -> 4 | P31: =Records!O19 -> 5 | Q31: =Records!P19 -> 4 | R31: =AVERAGE(Records!S19,Records!T19,Records!U19) -> 5.6666667 | S31: =AVERAGE(Records!V19,Records!O19,Records!P19) -> 4.3333333 | T31: =Records!AA19 -> 125.8 | U31: =Records!AP19 -> 3 | V31: =IF(Records!AA19>150,1,0) -> 0
A32: P004 | B32: One-Euro | C32: stapler | D32: 26 | E32: =Records!K26 -> 6 | F32: =Records!R26 -> 5 | G32: =Records!L26 -> 4 | H32: =Records!M26 -> 5 | I32: =Records!Q26 -> 5 | J32: =Records!W26 -> 4 | K32: =Records!X26 -> 4 | L32: =Records!S26 -> 6 | M32: =Records!T26 -> 6 | N32: =Records!U26 -> 5 | O32: =Records!V26 -> 6 | P32: =Records!O26 -> 6 | Q32: =Records!P26 -> 4 | R32: =AVERAGE(Records!S26,Records!T26,Records!U26) -> 5.6666667 | S32: =AVERAGE(Records!V26,Records!O26,Records!P26) -> 5.3333333 | T32: =Records!AA26 -> 136.3 | U32: =Records!AP26 -> 2 | V32: =IF(Records!AA26>150,1,0) -> 0
A33: P005 | B33: One-Euro | C33: stapler | D33: 34 | E33: =Records!K34 -> 5 | F33: =Records!R34 -> 6 | G33: =Records!L34 -> 6 | H33: =Records!M34 -> 5 | I33: =Records!Q34 -> 5 | J33: =Records!W34 -> 5 | K33: =Records!X34 -> 6 | L33: =Records!S34 -> 7 | M33: =Records!T34 -> 5 | N33: =Records!U34 -> 7 | O33: =Records!V34 -> 7 | P33: =Records!O34 -> 6 | Q33: =Records!P34 -> 6 | R33: =AVERAGE(Records!S34,Records!T34,Records!U34) -> 6.3333333 | S33: =AVERAGE(Records!V34,Records!O34,Records!P34) -> 6.3333333 | T33: =Records!AA34 -> 121.4 | U33: =Records!AP34 -> 2 | V33: =IF(Records!AA34>150,1,0) -> 0
A34: P006 | B34: One-Euro | C34: stapler | D34: 39 | E34: =Records!K39 -> 4 | F34: =Records!R39 -> 4 | G34: =Records!L39 -> 5 | H34: =Records!M39 -> 4 | I34: =Records!Q39 -> 5 | J34: =Records!W39 -> 4 | K34: =Records!X39 -> 4 | L34: =Records!S39 -> 5 | M34: =Records!T39 -> 4 | N34: =Records!U39 -> 4 | O34: =Records!V39 -> 6 | P34: =Records!O39 -> 3 | Q34: =Records!P39 -> 5 | R34: =AVERAGE(Records!S39,Records!T39,Records!U39) -> 4.3333333 | S34: =AVERAGE(Records!V39,Records!O39,Records!P39) -> 4.6666667 | T34: =Records!AA39 -> 110 | U34: =Records!AP39 -> 2 | V34: =IF(Records!AA39>150,1,0) -> 0
A35: P007 | B35: One-Euro | C35: stapler | D35: 46 | E35: =Records!K46 -> 2 | F35: =Records!R46 -> 6 | G35: =Records!L46 -> 7 | H35: =Records!M46 -> 7 | I35: =Records!Q46 -> 6 | J35: =Records!W46 -> 6 | K35: =Records!X46 -> 6 | L35: =Records!S46 -> 6 | M35: =Records!T46 -> 6 | N35: =Records!U46 -> 4 | O35: =Records!V46 -> 6 | P35: =Records!O46 -> 4 | Q35: =Records!P46 -> 6 | R35: =AVERAGE(Records!S46,Records!T46,Records!U46) -> 5.3333333 | S35: =AVERAGE(Records!V46,Records!O46,Records!P46) -> 5.3333333 | T35: =Records!AA46 -> 135.5 | U35: =Records!AP46 -> 5 | V35: =IF(Records!AA46>150,1,0) -> 0
A36: P008 | B36: One-Euro | C36: stapler | D36: 51 | E36: =Records!K51 -> 6 | F36: =Records!R51 -> 6 | G36: =Records!L51 -> 6 | H36: =Records!M51 -> 6 | I36: =Records!Q51 -> 6 | J36: =Records!W51 -> 4 | K36: =Records!X51 -> 6 | L36: =Records!S51 -> 4 | M36: =Records!T51 -> 5 | N36: =Records!U51 -> 7 | O36: =Records!V51 -> 4 | P36: =Records!O51 -> 5 | Q36: =Records!P51 -> 4 | R36: =AVERAGE(Records!S51,Records!T51,Records!U51) -> 5.3333333 | S36: =AVERAGE(Records!V51,Records!O51,Records!P51) -> 4.3333333 | T36: =Records!AA51 -> 117 | U36: =Records!AP51 -> 3 | V36: =IF(Records!AA51>150,1,0) -> 0
A37: P009 | B37: One-Euro | C37: stapler | D37: 54 | E37: =Records!K54 -> 4 | F37: =Records!R54 -> 4 | G37: =Records!L54 -> 5 | H37: =Records!M54 -> 5 | I37: =Records!Q54 -> 5 | J37: =Records!W54 -> 5 | K37: =Records!X54 -> 6 | L37: =Records!S54 -> 5 | M37: =Records!T54 -> 6 | N37: =Records!U54 -> 7 | O37: =Records!V54 -> 6 | P37: =Records!O54 -> 6 | Q37: =Records!P54 -> 5 | R37: =AVERAGE(Records!S54,Records!T54,Records!U54) -> 6 | S37: =AVERAGE(Records!V54,Records!O54,Records!P54) -> 5.6666667 | T37: =Records!AA54 -> 116.4 | U37: =Records!AP54 -> 2 | V37: =IF(Records!AA54>150,1,0) -> 0
A38: P010 | B38: One-Euro | C38: stapler | D38: 59 | E38: =Records!K59 -> 5 | F38: =Records!R59 -> 5 | G38: =Records!L59 -> 6 | H38: =Records!M59 -> 5 | I38: =Records!Q59 -> 5 | J38: =Records!W59 -> 5 | K38: =Records!X59 -> 5 | L38: =Records!S59 -> 5 | M38: =Records!T59 -> 5 | N38: =Records!U59 -> 6 | O38: =Records!V59 -> 6 | P38: =Records!O59 -> 6 | Q38: =Records!P59 -> 5 | R38: =AVERAGE(Records!S59,Records!T59,Records!U59) -> 5.3333333 | S38: =AVERAGE(Records!V59,Records!O59,Records!P59) -> 5.6666667 | T38: =Records!AA59 -> 189.4 | U38: =Records!AP59 -> 5 | V38: =IF(Records!AA59>150,1,0) -> 1
A39: P011 | B39: One-Euro | C39: stapler | D39: 66 | E39: =Records!K66 -> 6 | F39: =Records!R66 -> 5 | G39: =Records!L66 -> 5 | H39: =Records!M66 -> 4 | I39: =Records!Q66 -> 6 | J39: =Records!W66 -> 6 | K39: =Records!X66 -> 6 | L39: =Records!S66 -> 6 | M39: =Records!T66 -> 6 | N39: =Records!U66 -> 7 | O39: =Records!V66 -> 6 | P39: =Records!O66 -> 6 | Q39: =Records!P66 -> 6 | R39: =AVERAGE(Records!S66,Records!T66,Records!U66) -> 6.3333333 | S39: =AVERAGE(Records!V66,Records!O66,Records!P66) -> 6 | T39: =Records!AA66 -> 139.7 | U39: =Records!AP66 -> 3 | V39: =IF(Records!AA66>150,1,0) -> 0
A40: P012 | B40: One-Euro | C40: stapler | D40: 71 | E40: =Records!K71 -> 4 | F40: =Records!R71 -> 5 | G40: =Records!L71 -> 6 | H40: =Records!M71 -> 5 | I40: =Records!Q71 -> 4 | J40: =Records!W71 -> 4 | K40: =Records!X71 -> 5 | L40: =Records!S71 -> 6 | M40: =Records!T71 -> 6 | N40: =Records!U71 -> 6 | O40: =Records!V71 -> 6 | P40: =Records!O71 -> 6 | Q40: =Records!P71 -> 5 | R40: =AVERAGE(Records!S71,Records!T71,Records!U71) -> 6 | S40: =AVERAGE(Records!V71,Records!O71,Records!P71) -> 5.6666667 | T40: =Records!AA71 -> 115.9 | U40: =Records!AP71 -> 4 | V40: =IF(Records!AA71>150,1,0) -> 0
A41: P013 | B41: One-Euro | C41: stapler | D41: 78 | E41: =Records!K78 -> 6 | F41: =Records!R78 -> 5 | G41: =Records!L78 -> 5 | H41: =Records!M78 -> 6 | I41: =Records!Q78 -> 4 | J41: =Records!W78 -> 4 | K41: =Records!X78 -> 5 | L41: =Records!S78 -> 6 | M41: =Records!T78 -> 7 | N41: =Records!U78 -> 7 | O41: =Records!V78 -> 6 | P41: =Records!O78 -> 6 | Q41: =Records!P78 -> 5 | R41: =AVERAGE(Records!S78,Records!T78,Records!U78) -> 6.6666667 | S41: =AVERAGE(Records!V78,Records!O78,Records!P78) -> 5.6666667 | T41: =Records!AA78 -> 144.2 | U41: =Records!AP78 -> 2 | V41: =IF(Records!AA78>150,1,0) -> 0
...

Sheet Analysis
A1: 分析结果（合成数据）：Mdn/IQR、配对差、dz、逐物体均值与计数为公式实时计算；Wilcoxon W/p、Holm p、r_rb 自举 CI、α/ω、TOST p 由分析代码写入
A3: A. 主证实家族（三物体均值 → 配对 Wilcoxon → 家族内 Holm；N=24 最严 MDE dz=0.801）
A4: 条目 | B4: 简称 | C4: One-Euro Mdn[IQR] | D4: EgoAnchor Mdn[IQR] | E4: 配对差中位 | F4: 配对差均值 | G4: 配对差SD | H4: dz | I4: W | J4: p_raw | K4: p_Holm | L4: 匹配秩双列r | M4: r 95%CI下 | N4: r 95%CI上 | O4: 正/负/结平 | P4: 检验方式 | Q4: 显著(Holm) | S4: 结论
A5: Q1 | B5: 静止稳定 | C5: =ROUND(MEDIAN(Derived!C152:C175),2)&" ["&ROUND(QUARTILE.INC(Derived!C152:C175,1),2)&", "&ROUND(QUARTILE.INC(Derived!C152:C175,3),2)&"]" -> 4.33 [3.67, 4.67] | D5: =ROUND(MEDIAN(Derived!C176:C199),2)&" ["&ROUND(QUARTILE.INC(Derived!C176:C199,1),2)&", "&ROUND(QUARTILE.INC(Derived!C176:C199,3),2)&"]" -> 5.67 [5.33, 6] | E5: =ROUND(MEDIAN(Derived!B254:B277),3) -> 1.333 | F5: =ROUND(AVERAGE(Derived!B254:B277),3) -> 1.458 | G5: =ROUND(STDEV.S(Derived!B254:B277),3) -> 0.894 | H5: =ROUND(AVERAGE(Derived!B254:B277)/STDEV.S(Derived!B254:B277),3) -> 1.63 | I5: 0 | J5: 0 | K5: 0 | L5: 1 | M5: 1 | N5: 1 | O5: =COUNTIF(Derived!B254:B277,">0")&"/"&COUNTIF(Derived!B254:B277,"<0")&"/"&COUNTIF(Derived!B254:B277,"=0") -> 23/0/1 | P5: exact | Q5: =IF(K5<0.05,"是","否") -> 是 | S5: Holm 后显著，完整系统更优（dz=+1.63）。与实验一头动泄漏 13.0× 与静止帧间增量 13.3× 的量级一致。
A6: Q8 | B6: 位置正确 | C6: =ROUND(MEDIAN(Derived!D152:D175),2)&" ["&ROUND(QUARTILE.INC(Derived!D152:D175,1),2)&", "&ROUND(QUARTILE.INC(Derived!D152:D175,3),2)&"]" -> 4.33 [4.33, 5] | D6: =ROUND(MEDIAN(Derived!D176:D199),2)&" ["&ROUND(QUARTILE.INC(Derived!D176:D199,1),2)&", "&ROUND(QUARTILE.INC(Derived!D176:D199,3),2)&"]" -> 5.33 [5, 5.42] | E6: =ROUND(MEDIAN(Derived!C254:C277),3) -> 0.667 | F6: =ROUND(AVERAGE(Derived!C254:C277),3) -> 0.736 | G6: =ROUND(STDEV.S(Derived!C254:C277),3) -> 0.742 | H6: =ROUND(AVERAGE(Derived!C254:C277)/STDEV.S(Derived!C254:C277),3) -> 0.992 | I6: 8 | J6: 2e-05 | K6: 0.00012 | L6: 0.931 | M6: 0.766 | N6: 1 | O6: =COUNTIF(Derived!C254:C277,">0")&"/"&COUNTIF(Derived!C254:C277,"<0")&"/"&COUNTIF(Derived!C254:C277,"=0") -> 19/2/3 | P6: exact | Q6: =IF(K6<0.05,"是","否") -> 是 | S6: Holm 后显著，完整系统更优（dz=+0.99）。对应绝对注册 2.12×；效应小于 Q1，符合稳定/正确分列的设计意图。
A7: Q2 | B7: 运动附着 | C7: =ROUND(MEDIAN(Derived!E152:E175),2)&" ["&ROUND(QUARTILE.INC(Derived!E152:E175,1),2)&", "&ROUND(QUARTILE.INC(Derived!E152:E175,3),2)&"]" -> 5 [4.67, 5.33] | D7: =ROUND(MEDIAN(Derived!E176:E199),2)&" ["&ROUND(QUARTILE.INC(Derived!E176:E199,1),2)&", "&ROUND(QUARTILE.INC(Derived!E176:E199,3),2)&"]" -> 5 [4.33, 5] | E7: =ROUND(MEDIAN(Derived!D254:D277),3) -> -0.167 | F7: =ROUND(AVERAGE(Derived!D254:D277),3) -> -0.069 | G7: =ROUND(STDEV.S(Derived!D254:D277),3) -> 0.629 | H7: =ROUND(AVERAGE(Derived!D254:D277)/STDEV.S(Derived!D254:D277),3) -> -0.11 | I7: 73 | J7: 0.39546 | K7: 0.39546 | L7: -0.232 | M7: -0.719 | N7: 0.275 | O7: =COUNTIF(Derived!D254:D277,">0")&"/"&COUNTIF(Derived!D254:D277,"<0")&"/"&COUNTIF(Derived!D254:D277,"=0") -> 7/12/5 | P7: exact | Q7: =IF(K7<0.05,"是","否") -> 否 | S7: Holm 后不显著（dz=-0.11）。设计声明的预期零效应：中段对齐残差 1.72× 与 Start-transition 反向代价 1.53× 相互抵消。
A8: Q9 | B8: 姿态一致 | C8: =ROUND(MEDIAN(Derived!F152:F175),2)&" ["&ROUND(QUARTILE.INC(Derived!F152:F175,1),2)&", "&ROUND(QUARTILE.INC(Derived!F152:F175,3),2)&"]" -> 4.33 [4.25, 4.75] | D8: =ROUND(MEDIAN(Derived!F176:F199),2)&" ["&ROUND(QUARTILE.INC(Derived!F176:F199,1),2)&", "&ROUND(QUARTILE.INC(Derived!F176:F199,3),2)&"]" -> 5 [4.33, 5.33] | E8: =ROUND(MEDIAN(Derived!E254:E277),3) -> 0.333 | F8: =ROUND(AVERAGE(Derived!E254:E277),3) -> 0.306 | G8: =ROUND(STDEV.S(Derived!E254:E277),3) -> 0.636 | H8: =ROUND(AVERAGE(Derived!E254:E277)/STDEV.S(Derived!E254:E277),3) -> 0.48 | I8: 62.5 | J8: 0.03907 | K8: 0.07815 | L8: 0.506 | M8: 0.065 | N8: 0.857 | O8: =COUNTIF(Derived!E254:E277,">0")&"/"&COUNTIF(Derived!E254:E277,"<0")&"/"&COUNTIF(Derived!E254:E277,"=0") -> 16/6/2 | P8: exact | Q8: =IF(K8<0.05,"是","否") -> 否 | S8: Holm 后不显著（dz=+0.48）。对应旋转 aligned RMSE 仅 1.15×；措辞同时承载旋转跟随与静止朝向两个量级悬殊的通道，检出力不足。
A9: Q3 | B9: 恢复一致 | C9: =ROUND(MEDIAN(Derived!G152:G175),2)&" ["&ROUND(QUARTILE.INC(Derived!G152:G175,1),2)&", "&ROUND(QUARTILE.INC(Derived!G152:G175,3),2)&"]" -> 4.33 [3.67, 4.67] | D9: =ROUND(MEDIAN(Derived!G176:G199),2)&" ["&ROUND(QUARTILE.INC(Derived!G176:G199,1),2)&", "&ROUND(QUARTILE.INC(Derived!G176:G199,3),2)&"]" -> 4.67 [4.67, 5.08] | E9: =ROUND(MEDIAN(Derived!F254:F277),3) -> 0.667 | F9: =ROUND(AVERAGE(Derived!F254:F277),3) -> 0.792 | G9: =ROUND(STDEV.S(Derived!F254:F277),3) -> 0.754 | H9: =ROUND(AVERAGE(Derived!F254:F277)/STDEV.S(Derived!F254:F277),3) -> 1.05 | I9: 20 | J9: 9e-05 | K9: 0.00035 | L9: 0.855 | M9: 0.593 | N9: 1 | O9: =COUNTIF(Derived!F254:F277,">0")&"/"&COUNTIF(Derived!F254:F277,"<0")&"/"&COUNTIF(Derived!F254:F277,"=0") -> 21/2/1 | P9: exact | Q9: =IF(K9<0.05,"是","否") -> 是 | S9: Holm 后显著，完整系统更优（dz=+1.05）。对应遮挡平移 2.14× 与灾难性失效 1→0；离散失效事件使分布重尾。
A10: Q6 | B10: 依赖意愿 | C10: =ROUND(MEDIAN(Derived!H152:H175),2)&" ["&ROUND(QUARTILE.INC(Derived!H152:H175,1),2)&", "&ROUND(QUARTILE.INC(Derived!H152:H175,3),2)&"]" -> 4.33 [3.67, 4.75] | D10: =ROUND(MEDIAN(Derived!H176:H199),2)&" ["&ROUND(QUARTILE.INC(Derived!H176:H199,1),2)&", "&ROUND(QUARTILE.INC(Derived!H176:H199,3),2)&"]" -> 5.5 [5, 5.75] | E10: =ROUND(MEDIAN(Derived!G254:G277),3) -> 1 | F10: =ROUND(AVERAGE(Derived!G254:G277),3) -> 1.097 | G10: =ROUND(STDEV.S(Derived!G254:G277),3) -> 0.67 | H10: =ROUND(AVERAGE(Derived!G254:G277)/STDEV.S(Derived!G254:G277),3) -> 1.637 | I10: 0 | J10: 0 | K10: 0 | L10: 1 | M10: 1 | N10: 1 | O10: =COUNTIF(Derived!G254:G277,">0")&"/"&COUNTIF(Derived!G254:G277,"<0")&"/"&COUNTIF(Derived!G254:G277,"=0") -> 23/0/1 | P10: exact | Q10: =IF(K10<0.05,"是","否") -> 是 | S10: Holm 后显著，完整系统更优（dz=+1.64）。应用侧依赖意愿，受灾难性失效记忆与个体信任不对称性放大。
