Workbook

Sheet README
A1: EgoAnchor 实验三正式原始数据工作簿（v5.1）
A2: 唯一权威规格：2026-EgoAnchor/experiment_3_questionnaire_design_zh.md（v5.1）。Participants 与 Records 是唯一人工输入；Derived 是只读公式派生层，Analysis 是现场描述性仪表板。Python 分析另行写出结果工作簿，不会回填本文件的黄色区域。TiA 反向计分仅在派生层执行。
A4: 使用流程 | B4: 时点 | C4: 填写位置 | D4: 内容 | E4: 关键规则
A5: 0 背景 | B5: 到场、知情同意后 | C5: Participants | D5: B1–B6 背景字段、纳入状态、起止时间 | E5: 方法映射列仅实验员可见
A6: 1 区块 | B6: 每个方法×物体区块三项任务完成后 | C6: Records A 段 | D6: 13 项统一七点同意度（Q10 默认停用） | E6: 任务后统一评分，不逐任务打断
A7: 2 方法级 | B7: 全部 6 区块完成后 | C7: Records B 段 | D7: 按平衡顺序（S1 先 A、S2 先 B）分别评价两方法：TiA 10 + 提示页 + S-TIAS 3 | E7: 不得插入第 5/6 区块之间
A8: 3 最终 | B8: 摘下头显后 | C8: Records C 段 | D8: 2 强制选择 + 偏好强度 + 区分信心 + 2 开放题 + 安全检查 | E8: 回答完成前保持匿名
A9: 4 审计 | B9: 每区块同步 | C9: Records A 段（审计列） | D9: 候选/VCD/接纳/生命周期/重获取/时长 | E9: 只作操纵检验，不是配准误差
A10: 5 现场核对 | B10: 采集完成后 | C10: Analysis | D10: Derived/Analysis 公式实时显示完整性、参与者概况和可计算描述量 | E10: 正式推断由 pixi run eval analyze exp3 另写结果 XLSX
A12: 冻结分析家族
A13: 主证实家族（7） | B13: Q1/Q8/Q2/Q9/Q3/Q6/Q7 | C13: 三物体取均值 → 配对 Wilcoxon → 家族内 Holm（MDE dz=0.801）
A14: 已发表量表家族（5） | B14: AQ-EQ / AQ-IQ / TiA-R/C / TiA-U/P / S-TIAS | C14: 同上；仅此家族报告当前样本 α/ω；TiA 反向项先换向
A15: 次级 | B15: Q10（若预实验启用）；CLMM（方法×物体+区块位置+对象内先后+随机截距） | C15: 独立分析 / 稳健性
A16: 描述性 | B16: 两项强制选择、偏好强度、区分信心、开放题主题、安全检查、运行时审计 | C16: 不作推断
A18: 采集前仍未完成的前置（未完成不得正式采集）
A19: 中文施测措辞已于 2026-07-26 冻结为 v5.1 Final wording。正式采集前完成确认性认知访谈；只有发现理解不良时，才按修订、重测、再冻结的顺序处理。
A20: 预实验冻结项：遮挡时长（0.6–0.9 s 内取定，避开 0.45/1.0 s 边界）、Q10 是否启用、AQ 缩减规则是否触发（单区块 >150 s 或连续同分 ≥5 项 → 停用 AQ_EQ3/AQ_IQ1）、方法级问卷模态。
A22: 程序日志字段建议（Unity 端长格式事件日志；本表 Records 为实验员宽表）
A23: participant_id / level(block|method|final) / method_id(内部) / shown_label(A|B) / object_id / block_index / item_id / scale_type(agreement_7|agreement_5|intensity_7) / response_raw / timestamp_utc / task_completed / technical_issue / lifecycle_state(遮挡) — 事件只追加不覆盖。
A25: 提前止收规则：招募未满 24 人时按 Participants 编号顺序优先补齐整组 4 人（同一物体排列的四个单元），N 下限 18。
A27: 工作簿契约 | B27: EgoAnchor.Experiment3.RawData.v5.1
A28: 数据类别 | B28: formal-participant-data

Sheet Verification_Audit
A1: 内容核验记录（v5.1；正式采集前审计）
A2: 官方原文、对象化改编和当前样本信度必须分开表述；正式采集前剩余前置为确认性认知访谈与预留参数冻结。
A4: 核对对象 | B4: 状态 | C4: 结论/修正 | D4: 依据/来源
A5: AQ 英文条目 | B5: 已核对 | C5: 原计划英文系语义转述；已替换为附录官方原文（指代为 The virtual object，对象化替换极小） | D5: doi:10.1007/s11747-025-01108-2 Appendix
A6: AQ 量尺 | B6: 已核对 | C6: 七点：1 = I do not agree … 7 = I fully agree；中文“完全不同意–完全同意”正确 | D6: 同上
A7: AQ 书目 | B7: 已核对 | C7: Schein, K. E.; Rauschnabel, P. A.; Praxmarer-Carus, S.; Babin, B. J. Unpacking augmentation quality and local presence: Factors that drive effective augmented reality marketing. JAMS 54:49–69（2025 在线） | D7: CC BY 4.0
A8: TiA 条目结构 | B8: 已核对 | C8: R/C 6 项（官方条目 1,6,10,13,15,19）+ U/P 4 项（2,7,11,16）；6+4 正确、语料 7+3 系误标 | D8: 官方 GitHub（CC BY-SA 4.0）
A9: TiA 反向计分 | B9: 已核对 | C9: 反向项 RC3/RC5/UP2/UP4（官方条目 10,15,7,16）；五点反向分 = 6 − 原始分 | D9: 同上
A10: TiA 量尺 | B10: 已核对 | C10: 五点同意度 + 允许 No response（记缺失） | D10: 同上
A11: TiA 效度措辞 | B11: 需遵守 | C11: 英文版仍需进一步验证（德文原版才有初步心理计量证据）；论文只写 adapted TiA subscales + 当前样本信度，不得写“已验证英文/中文量表” | D11: 官方 GitHub 声明
A12: S-TIAS 条目 | B12: 已核对 | C12: 三项原文指代 the AI assistant；本研究替换为“这种对象锚定方法”→ adapted S-TIAS | D12: doi:10.3389/frai.2025.1582880
A13: S-TIAS 量尺 | B13: 已核对 | C13: 1 = Not at all … 7 = Extremely；三项均值 | D13: 同上
A14: S-TIAS 书目 | B14: 已核对（作者更正） | C14: McGrath, M. J.; Lack, O.; Tisch, J.; Duenser, A. Measuring trust in artificial intelligence: validation of an established scale and its short form. Frontiers in AI 8:1582880。语料曾误标为 Karpus；bib 键 mcgrath2025stias | D14: CC BY
A15: Gottsacker 2024 书目 | B15: 已核对 | C15: Gottsacker, M.; Furuya, H.; Choudhary, Z. D.; Erickson, A.; Schubert, R.; Bruder, G.; Browne, M. P.; Welch, G. F. Investigating the relationships between user behaviors and tracking factors on task performance and trust in augmented reality. Computers & Graphics 123:104035 | D15: doi:10.1016/j.cag.2024.104035
... A20: 中文施测措辞 | B20: 已冻结（2026-07-26） | C20: 19 条量表条目（AQ 6 + TiA 10 + S-TIAS 3）逐条对照官方原文完成语义等价审计并冻结；审计微调两处：AQ-IQ2 去"能够"（避免行为陈述变能力陈述）、AQ-EQ2 去"看起来被"（避免在 realistically 上叠加第二层感知模糊）。TIA_RC1/RC4 构念贴合与 Q2/AQ-IQ3 判别留待预实验认知访谈确认性检查。不再单设翻译冻结关卡。 | D20: 本研究语义审计记录（计划书 4.6 核对状态）

Sheet Questionnaire
A1: 实验三问卷全条目（v5.1 Verified）——本表为唯一条目字典，与计划书 4.2/4.4/4.5 逐字一致
A2: 中文施测版为头显或纸面呈现文本；官方英文原文仅用于核对，对象化英文施测版用于附录与英文施测。正式中文措辞已经逐条语义审计，预实验继续做确认性认知访谈。
A4: A. 实验前背景（Participants 表填写，每人一次）
A5: ID | B5: 中文 | C5: 应答格式/选项
A6: B1_Age | B6: 年龄 | C6: 整数
A7: B2_Gender | B7: 性别 | C7: 女 / 男 / 非二元或其他 / 不愿透露
A8: B3_Handedness | B8: 主手（精细操作） | C8: 右手 / 左手 / 双手均可
A9: B4_Vision | B9: 视力情况 | C9: 正常 / 矫正后正常 / 其他
A10: B5_VRMR_Experience | B10: VR/MR 使用经验 | C10: 从未 / 1–5 次 / 6–20 次 / 超过 20 次 / 经常使用
A11: B6_PhysObj_MR_Experience | B11: 实物 AR/MR 交互经验（需操作真实物体的应用） | C11: 从未 / 1–2 次 / 数次 / 经常
A13: B. 区块级 13 项必答 + Q10 可选（每个方法×物体区块后；统一七点同意度；界面标题：请根据刚才在这个物体上的体验作答）
A14: 页序 | B14: Item_ID | C14: 简称 | D14: 中文施测版 | E14: 官方英文原文 | F14: 对象化英文施测版 | G14: 分析家族 | H14: 来源 | I14: 备注
A15: 1 | B15: Q1 | C15: 静止稳定 | D15: 在静止观察阶段，虚拟内容保持在同一位置不动。 | E15: — | F15: During static observation, the virtual content stayed in the same position without moving. | G15: 主证实 | H15: 自制（v4 冻结） | I15: 时间稳定性；pilot 检查“同一位置”参照系理解
A16: 2 | B16: Q2 | C16: 运动附着 | D16: 在拿起、移动和旋转物体时，虚拟内容始终附着在真实物体上的同一位置。 | E16: — | F16: While I picked up, moved, and rotated the object, the virtual content remained attached to the same location on the physical object. | G16: 主证实 | H16: 自制（v5.1 锐化措辞） | I16: 测附着位置恒定，与 AQ_IQ3 平滑正交；认知访谈确认区分
A17: 3 | B17: Q9 | C17: 姿态一致 | D17: 旋转物体时，虚拟内容的朝向与真实物体的朝向保持一致。 | E17: — | F17: While I rotated the object, the orientation of the virtual content stayed consistent with the orientation of the physical object. | G17: 主证实 | H17: 自制（v4 冻结） | I17: 旋转通道独立诊断
A18: 3' | B18: Q10_OPT | C18: 放置后稳定（可选） | D18: 把物体放到桌面后，虚拟内容很快就稳定下来。 | E18: — | F18: After I placed the object on the table, the virtual content settled quickly. | G18: 次级 | H18: 自制（v4 可选） | I18: 默认停用；预实验冻结是否启用
A19: 4 | B19: AQ_IQ2 | C19: 响应及时 | D19: 虚拟内容实时响应我对真实物体的操作。 | E19: The virtual object responds in real-time. | F19: The virtual content responds in real-time to my manipulation of the physical object. | G19: 已发表量表 | H19: AQ Interaction Quality（对象化适配） | I19: AQ-IQ 子量表分 = IQ1/IQ2/IQ3 均值（分析派生）
A20: 5 | B20: AQ_IQ3 | C20: 运动平滑 | D20: 在交互过程中，虚拟内容随真实物体平滑运动。 | E20: The virtual object moves smoothly. | F20: The virtual content moves smoothly with the physical object during interaction. | G20: 已发表量表 | H20: AQ Interaction Quality（对象化适配）
A21: 6 | B21: Q3 | C21: 恢复一致 | D21: 遮挡移除后，虚拟内容恢复到了与真实物体一致的位置。 | E21: — | F21: After the occlusion was removed, the virtual content recovered to a position consistent with the physical object. | G21: 主证实 | H21: 自制（v4 冻结） | I21: 恢复后空间一致性
A22: 7 | B22: Q8 | C22: 位置正确 | D22: 虚拟内容出现的位置，与真实物体实际所在的位置相符。 | E22: — | F22: The virtual content appeared at a position that matched where the physical object actually was. | G22: 主证实 | H22: 自制（v4 冻结） | I22: 主观空间正确性，不作客观配准误差；与 Q1 相隔五题
A23: 8 | B23: AQ_EQ1 | C23: 融合 | D23: 虚拟内容与真实物体及周围真实元素自然融合。 | E23: The virtual object blends in with real elements. | F23: The virtual content blends in with the physical object and surrounding real elements. | G23: 已发表量表 | H23: AQ Embedding Quality（对象化适配） | I23: AQ-EQ 子量表分 = EQ1/EQ2/EQ3 均值（分析派生）
A24: 9 | B24: AQ_EQ2 | C24: 嵌入可信 | D24: 虚拟内容真实地嵌入在真实物体及其现实环境中。 | E24: The virtual object is realistically embedded in the environment. | F24: The virtual content is realistically embedded in the physical object and its real-world context. | G24: 已发表量表 | H24: AQ Embedding Quality（对象化适配） | I24: 接管原 Q4 合理可信构念
A25: 10 | B25: AQ_EQ3 | C25: 尺度协调 | D25: 虚拟内容的尺度与真实物体及现实世界中的事物相匹配。 | E25: The size of the virtual object is in scale to things in the real world. | F25: The size of the virtual content is in scale to the physical object and things in the real world. | G25: 已发表量表 | H25: AQ Embedding Quality（对象化适配） | I25: 预期天花板；保留以维持完整子量表
A26: 11 | B26: AQ_IQ1 | C26: 交互直观 | D26: 通过操作真实物体与虚拟内容进行交互是直观的。 | E26: Interaction with the virtual object is intuitive. | F26: Interaction with the virtual content through manipulation of the physical object is intuitive. | G26: 已发表量表 | H26: AQ Interaction Quality（对象化适配）
A27: 12 | B27: Q6 | C27: 依赖意愿 | D27: 在需要虚拟内容准确附着于真实物体的混合现实应用中，我愿意依赖这种锚定方法。 | E27: — | F27: I would be willing to rely on this anchoring method in an MR application that requires virtual content to be accurately attached to a physical object. | G27: 主证实 | H27: 自制（v4 冻结） | I27: 应用侧依赖意愿（区块级信任）
A28: 13 | B28: Q7 | C28: 稳定-响应平衡 | D28: 总体而言，该方法在锚点稳定性与响应及时性之间取得了合适的平衡。 | E28: — | F28: Overall, this method achieved an appropriate balance between anchor stability and responsiveness. | G28: 主证实 | H28: 自制（v4 冻结） | I28: 双构念总结项；与实验一稳定/时延结果联合解释
A29: 量尺 | B29: 七点同意度：1 完全不同意 … 7 完全同意 | C29: 同一条目在全部区块中措辞与刻度完全相同；每页一题、确认后翻页；不显示既往回答
A31: C. 方法级（全部六区块完成后，按 S1 先 A / S2 先 B 依次评价两方法；界面标题：请根据方法 X 在全部三个物体上的整体表现作答）
A32: C1. adapted TiA 两分量表（10 项） | B32: 五点同意度：1 Strongly disagree / 2 Rather disagree / 3 Neither / 4 Rather agree / 5 Strongly agree；允许无法回答（记缺失） | C32: 反向项计分 = 6 − 原始分（仅分析派生）；分量表分 = 有效条目均值；呈现按官方相对顺序交错（官方条目 1,2,6,7,10,11,13,15,16,19），参与者界面只显示中性序号第 1–10 题，下表按分量表分组仅为规格
A33: Item_ID | B33: 分量表 | C33: 官方英文原文 | D33: 中文施测版（已冻结） | E33: 反向 | F33: 官方条目号
A34: TIA_RC1 | B34: Reliability/Competence | C34: The system is capable of interpreting situations correctly. | D34: 这种对象锚定方法能够正确判断当前状况。 | E34: 否 | F34: 1
A35: TIA_RC2 | B35: Reliability/Competence | C35: The system works reliably. | D35: 这种对象锚定方法运行可靠。 | E35: 否 | F35: 6
A36: TIA_RC3 | B36: Reliability/Competence | C36: A system malfunction is likely. | D36: 这种对象锚定方法很可能发生故障。 | E36: 是 | F36: 10
A37: TIA_RC4 | B37: Reliability/Competence | C37: The system is capable of taking over complicated tasks. | D37: 这种对象锚定方法能够承担复杂的锚定任务。 | E37: 否 | F37: 13
A38: TIA_RC5 | B38: Reliability/Competence | C38: The system might make sporadic errors. | D38: 这种对象锚定方法可能偶尔出错。 | E38: 是 | F38: 15
A39: TIA_RC6 | B39: Reliability/Competence | C39: I am confident about the system's capabilities. | D39: 我对这种对象锚定方法的能力有信心。 | E39: 否 | F39: 19
A40: TIA_UP1 | B40: Understanding/Predictability | C40: The system state was always clear to me. | D40: 这种对象锚定方法的状态对我来说始终清楚。 | E40: 否 | F40: 2
A41: TIA_UP2 | B41: Understanding/Predictability | C41: The system reacts unpredictably. | D41: 这种对象锚定方法的反应难以预测。 | E41: 是 | F41: 7
A42: TIA_UP3 | B42: Understanding/Predictability | C42: I was able to understand why things happened. | D42: 我能够理解为什么会出现刚才的锚定行为。 | E42: 否 | F42: 11
A43: TIA_UP4 | B43: Understanding/Predictability | C43: It's difficult to identify what the system will do next. | D43: 我很难判断这种对象锚定方法接下来会怎样表现。 | E43: 是 | F43: 16
...

Sheet Participants
A1: 参与者信息与 24 平衡单元（预设列勿改；空列人工填写；方法映射两列仅实验员可见）
A2: Participant_ID | B2: 平衡单元 | C2: 物体排列ID | D2: 标签序列 | E2: 物体1 | F2: 物体2 | G2: 物体3 | H2: 区块内标签顺序 | I2: 方法A=（保密） | J2: 方法B=（保密） | K2: 先行实际方法 | L2: B1_年龄 | M2: B2_性别 | N2: B3_主手 | O2: B4_视力 | P2: B5_VR/MR经验 | Q2: B6_实物MR经验 | R2: 签署同意 | S2: 基线不适 | T2: 开始时间 | U2: 结束时间 | V2: 纳入分析 | W2: 退出/技术问题 | X2: 备注
A3: P001 | B3: O1-S1-EA | C3: 1 | D3: S1 | E3: 鼠标 | F3: 固定订书机 | G3: 游戏手柄 | H3: A-B / B-A / A-B | I3: EgoAnchor | J3: One-Euro | K3: EgoAnchor
A4: P002 | B4: O1-S2-EA | C4: 1 | D4: S2 | E4: 鼠标 | F4: 固定订书机 | G4: 游戏手柄 | H4: B-A / A-B / B-A | I4: EgoAnchor | J4: One-Euro | K4: One-Euro
A5: P003 | B5: O1-S2-OE | C5: 1 | D5: S2 | E5: 鼠标 | F5: 固定订书机 | G5: 游戏手柄 | H5: B-A / A-B / B-A | I5: One-Euro | J5: EgoAnchor | K5: EgoAnchor
A6: P004 | B6: O1-S1-OE | C6: 1 | D6: S1 | E6: 鼠标 | F6: 固定订书机 | G6: 游戏手柄 | H6: A-B / B-A / A-B | I6: One-Euro | J6: EgoAnchor | K6: One-Euro
A7: P005 | B7: O2-S1-EA | C7: 2 | D7: S1 | E7: 鼠标 | F7: 游戏手柄 | G7: 固定订书机 | H7: A-B / B-A / A-B | I7: EgoAnchor | J7: One-Euro | K7: EgoAnchor
A8: P006 | B8: O2-S2-EA | C8: 2 | D8: S2 | E8: 鼠标 | F8: 游戏手柄 | G8: 固定订书机 | H8: B-A / A-B / B-A | I8: EgoAnchor | J8: One-Euro | K8: One-Euro
A9: P007 | B9: O2-S2-OE | C9: 2 | D9: S2 | E9: 鼠标 | F9: 游戏手柄 | G9: 固定订书机 | H9: B-A / A-B / B-A | I9: One-Euro | J9: EgoAnchor | K9: EgoAnchor
A10: P008 | B10: O2-S1-OE | C10: 2 | D10: S1 | E10: 鼠标 | F10: 游戏手柄 | G10: 固定订书机 | H10: A-B / B-A / A-B | I10: One-Euro | J10: EgoAnchor | K10: One-Euro
A11: P009 | B11: O3-S1-EA | C11: 3 | D11: S1 | E11: 固定订书机 | F11: 鼠标 | G11: 游戏手柄 | H11: A-B / B-A / A-B | I11: EgoAnchor | J11: One-Euro | K11: EgoAnchor
A12: P010 | B12: O3-S2-EA | C12: 3 | D12: S2 | E12: 固定订书机 | F12: 鼠标 | G12: 游戏手柄 | H12: B-A / A-B / B-A | I12: EgoAnchor | J12: One-Euro | K12: One-Euro
A13: P011 | B13: O3-S2-OE | C13: 3 | D13: S2 | E13: 固定订书机 | F13: 鼠标 | G13: 游戏手柄 | H13: B-A / A-B / B-A | I13: One-Euro | J13: EgoAnchor | K13: EgoAnchor
A14: P012 | B14: O3-S1-OE | C14: 3 | D14: S1 | E14: 固定订书机 | F14: 鼠标 | G14: 游戏手柄 | H14: A-B / B-A / A-B | I14: One-Euro | J14: EgoAnchor | K14: One-Euro
... A26: P024 | B26: O6-S1-OE | C26: 6 | D26: S1 | E26: 游戏手柄 | F26: 固定订书机 | G26: 鼠标 | H26: A-B / B-A / A-B | I26: One-Euro | J26: EgoAnchor | K26: One-Euro

Sheet Records
A1: 实验记录（三段堆叠：A 区块记录 144 行 → B 方法级记录 48 行 → C 最终问卷 24 行）。区块评分填 1–7；TiA 填 1–5；S-TIAS 填 1–7；缺失留空。原始分不得被反向分覆盖。
A3: A. 区块记录（每行 = 一个方法×物体区块：进度 + 13+1 项评分 + 问卷时长 + 运行时审计）
A4: Participant_ID | B4: Block_Index | C4: 平衡单元 | D4: 物体位置 | E4: 物体 | F4: Object_Key | G4: Shown_Label | H4: Condition(保密) | I4: 物体内先后 | J4: 该方法第几次 | K4: Q1 | L4: Q2 | M4: Q9 | N4: Q10_OPT | O4: AQ_IQ2 | P4: AQ_IQ3 | Q4: Q3 | R4: Q8 | S4: AQ_EQ1 | T4: AQ_EQ2 | U4: AQ_EQ3 | V4: AQ_IQ1 | W4: Q6 | X4: Q7 | Y4: 问卷开始 | Z4: 问卷结束 | AA4: 问卷时长_s | AB4: 任务完成 | AC4: 问卷完成 | AD4: 区块有效 | AE4: 技术问题 | AF4: Candidate_Rate_Hz | AG4: VCD_Median | AH4: VCD_Admission_Rate | AI4: Output_Availability | AJ4: 遮挡时长_s | AK4: 遮挡生命周期状态 | AL4: 进入Lost | AM4: 服务器重获取次数 | AN4: StaticLock进入次数 | AO4: 备注
A5: P001 | B5: 1 | C5: O1-S1-EA | D5: 1 | E5: 鼠标 | F5: blue_mouse | G5: 方法A | H5: EgoAnchor | I5: 1 | J5: 1
A6: P001 | B6: 2 | C6: O1-S1-EA | D6: 1 | E6: 鼠标 | F6: blue_mouse | G6: 方法B | H6: One-Euro | I6: 2 | J6: 1
A7: P001 | B7: 3 | C7: O1-S1-EA | D7: 2 | E7: 固定订书机 | F7: stapler | G7: 方法B | H7: One-Euro | I7: 1 | J7: 2
A8: P001 | B8: 4 | C8: O1-S1-EA | D8: 2 | E8: 固定订书机 | F8: stapler | G8: 方法A | H8: EgoAnchor | I8: 2 | J8: 2
A9: P001 | B9: 5 | C9: O1-S1-EA | D9: 3 | E9: 游戏手柄 | F9: gamepad | G9: 方法A | H9: EgoAnchor | I9: 1 | J9: 3
A10: P001 | B10: 6 | C10: O1-S1-EA | D10: 3 | E10: 游戏手柄 | F10: gamepad | G10: 方法B | H10: One-Euro | I10: 2 | J10: 3
A11: P002 | B11: 1 | C11: O1-S2-EA | D11: 1 | E11: 鼠标 | F11: blue_mouse | G11: 方法B | H11: One-Euro | I11: 1 | J11: 1
A12: P002 | B12: 2 | C12: O1-S2-EA | D12: 1 | E12: 鼠标 | F12: blue_mouse | G12: 方法A | H12: EgoAnchor | I12: 2 | J12: 1
A13: P002 | B13: 3 | C13: O1-S2-EA | D13: 2 | E13: 固定订书机 | F13: stapler | G13: 方法A | H13: EgoAnchor | I13: 1 | J13: 2
A14: P002 | B14: 4 | C14: O1-S2-EA | D14: 2 | E14: 固定订书机 | F14: stapler | G14: 方法B | H14: One-Euro | I14: 2 | J14: 2
A15: P002 | B15: 5 | C15: O1-S2-EA | D15: 3 | E15: 游戏手柄 | F15: gamepad | G15: 方法B | H15: One-Euro | I15: 1 | J15: 3
A16: P002 | B16: 6 | C16: O1-S2-EA | D16: 3 | E16: 游戏手柄 | F16: gamepad | G16: 方法A | H16: EgoAnchor | I16: 2 | J16: 3
... A148: P024 | B148: 6 | C148: O6-S1-OE | D148: 3 | E148: 鼠标 | F148: blue_mouse | G148: 方法B | H148: EgoAnchor | I148: 2 | J148: 3
A150: B. 方法级记录（全部六区块完成后；S1 先评方法 A、S2 先评方法 B；TiA→提示页→S-TIAS）
A151: Participant_ID | B151: Rating_Order | C151: Shown_Label | D151: Condition(保密) | E151: TIA_RC1 | F151: TIA_RC2 | G151: TIA_RC3_REV | H151: TIA_RC4 | I151: TIA_RC5_REV | J151: TIA_RC6 | K151: TIA_UP1 | L151: TIA_UP2_REV | M151: TIA_UP3 | N151: TIA_UP4_REV | O151: STIAS1 | P151: STIAS2 | Q151: STIAS3 | R151: 尺度切换确认 | S151: 问卷开始 | T151: 问卷结束 | U151: 时长_s | V151: 技术问题 | W151: 备注 | X151: A/B归属回忆确认 | Y151: 方法级记录有效
A152: P001 | B152: 1 | C152: 方法A | D152: EgoAnchor
A153: P001 | B153: 2 | C153: 方法B | D153: One-Euro
A154: P002 | B154: 1 | C154: 方法B | D154: One-Euro
A155: P002 | B155: 2 | C155: 方法A | D155: EgoAnchor
A156: P003 | B156: 1 | C156: 方法B | D156: EgoAnchor
A157: P003 | B157: 2 | C157: 方法A | D157: One-Euro
A158: P004 | B158: 1 | C158: 方法A | D158: One-Euro
A159: P004 | B159: 2 | C159: 方法B | D159: EgoAnchor
A160: P005 | B160: 1 | C160: 方法A | D160: EgoAnchor
A161: P005 | B161: 2 | C161: 方法B | D161: One-Euro
A162: P006 | B162: 1 | C162: 方法B | D162: One-Euro
A163: P006 | B163: 2 | C163: 方法A | D163: EgoAnchor
... A199: P024 | B199: 2 | C199: 方法B | D199: EgoAnchor
A201: C. 最终问卷记录（摘下头显后；解码列离场后由分析代码按 Participants 映射填写）
A202: Participant_ID | B202: 方法选择(标签) | C202: 偏好强度(1-7/NA) | D202: 信任选择(标签) | E202: 区分信心(1-7) | F202: 开放:最明显区别 | G202: 开放:最破坏信任的现象 | H202: 结束不适 | I202: 方法选择(解码) | J202: 信任选择(解码) | K202: 访谈备注
A203: P001
A204: P002
A205: P003
A206: P004
A207: P005
A208: P006
A209: P007
...

Sheet Derived
A1: 实时派生（仅公式）：区块有效性与 AQ → TiA 换向与方法分 → 三物体均值 → 配对差
A2: 本表无需填写，也不是实施检查表。D1 计算区块与 AQ；D2 换向 TiA 并计算方法级小分；D3 形成每人每方法的三物体均值；D4 计算 EgoAnchor-One-Euro 配对差；D5 审计最终问卷；D6 派生论文参与者概况。正式分析不读取这些公式缓存。
A3: D1. 区块级派生：144 行与 Records A 段逐行对应
A4: Participant_ID | B4: Block_Index | C4: Condition | D4: Object_Key | E4: Valid_Block | F4: Q1 | G4: Q8 | H4: Q2 | I4: Q9 | J4: Q3 | K4: Q6 | L4: Q7 | M4: AQ_EQ | N4: AQ_IQ | O4: Q10 | P4: Duration_Over_150s | Q4: Straightline_5Plus | R4: Candidate_Rate_Hz | S4: VCD_Median | T4: VCD_Admission_Rate | U4: Output_Availability | V4: Occlusion_Seconds | W4: Lifecycle_State | X4: Entered_Lost | Y4: Reacquisition_Count | Z4: StaticLock_Count
A5: =IF(Records!A5="","",Records!A5) | B5: =IF(Records!B5="","",Records!B5) | C5: =IF(Records!H5="","",Records!H5) | D5: =IF(Records!F5="","",Records!F5) | E5: =IF(AND(COUNTIFS(Participants!$A$3:$A$26,Records!A5,Participants!$V$3:$V$26,"是")=1,Records!AB5="是",Records!AC5="是",Records!AD5="是",COUNT(Records!K5,Records!L5,Records!M5,Records!O5,Records!P5,Records!Q5,Records!R5,Records!S5,Records!T5,Records!U5,Records!V5,Records!W5,Records!X5)=13),"是","否") | F5: =IF(Records!K5="","",Records!K5) | G5: =IF(Records!R5="","",Records!R5) | H5: =IF(Records!L5="","",Records!L5) | I5: =IF(Records!M5="","",Records!M5) | J5: =IF(Records!Q5="","",Records!Q5) | K5: =IF(Records!W5="","",Records!W5) | L5: =IF(Records!X5="","",Records!X5) | M5: =IF(COUNT(Records!S5,Records!T5,Records!U5)=3,AVERAGE(Records!S5,Records!T5,Records!U5),"") | N5: =IF(COUNT(Records!V5,Records!O5,Records!P5)=3,AVERAGE(Records!V5,Records!O5,Records!P5),"") | O5: =IF(Records!N5="","",Records!N5) | P5: =IF(Records!AA5="","",IF(Records!AA5>150,"是","否")) | Q5: =IF(COUNT(Records!K5,Records!L5,Records!M5,Records!O5,Records!P5,Records!Q5,Records!R5,Records!S5,Records!T5,Records!U5,Records!V5,Records!W5,Records!X5)<13,"",IF(OR(AND(Records!K5=Records!L5,Records!L5=Records!M5,Records!M5=Records!O5,Records!O5=Records!P5),AND(Records!L5=Records!M5,Records!M5=Records!O5,Records!O5=Records!P5,Records!P5=Records!Q5),AND(Records!M5=Records!O5,Records!O5=Records!P5,Records!P5=Records!Q5,Records!Q5=Records!R5),AND(Records!O5=Records!P5,Records!P5=Records!Q5,Records!Q5=Records!R5,Records!R5=Records!S5),AND(Records!P5=Records!Q5,Records!Q5=Records!R5,Records!R5=Records!S5,Records!S5=Records!T5),AND(Records!Q5=Records!R5,Records!R5=Records!S5,Records!S5=Records!T5,Records!T5=Records!U5),AND(Records!R5=Records!S5,Records!S5=Records!T5,Records!T5=Records!U5,Records!U5=Records!V5),AND(Records!S5=Records!T5,Records!T5=Records!U5,Records!U5=Records!V5,Records!V5=Records!W5),AND(Records!T5=Records!U5,Records!U5=Records!V5,Records!V5=Records!W5,Records!W5=Records!X5)),"是","否")) | R5: =IF(Records!AF5="","",Records!AF5) | S5: =IF(Records!AG5="","",Records!AG5) | T5: =IF(Records!AH5="","",Records!AH5) | U5: =IF(Records!AI5="","",Records!AI5) | V5: =IF(Records!AJ5="","",Records!AJ5) | W5: =IF(Records!AK5="","",Records!AK5) | X5: =IF(Records!AL5="","",Records!AL5) | Y5: =IF(Records!AM5="","",Records!AM5) | Z5: =IF(Records!AN5="","",Records!AN5)
A6: =IF(Records!A6="","",Records!A6) | B6: =IF(Records!B6="","",Records!B6) | C6: =IF(Records!H6="","",Records!H6) | D6: =IF(Records!F6="","",Records!F6) | E6: =IF(AND(COUNTIFS(Participants!$A$3:$A$26,Records!A6,Participants!$V$3:$V$26,"是")=1,Records!AB6="是",Records!AC6="是",Records!AD6="是",COUNT(Records!K6,Records!L6,Records!M6,Records!O6,Records!P6,Records!Q6,Records!R6,Records!S6,Records!T6,Records!U6,Records!V6,Records!W6,Records!X6)=13),"是","否") | F6: =IF(Records!K6="","",Records!K6) | G6: =IF(Records!R6="","",Records!R6) | H6: =IF(Records!L6="","",Records!L6) | I6: =IF(Records!M6="","",Records!M6) | J6: =IF(Records!Q6="","",Records!Q6) | K6: =IF(Records!W6="","",Records!W6) | L6: =IF(Records!X6="","",Records!X6) | M6: =IF(COUNT(Records!S6,Records!T6,Records!U6)=3,AVERAGE(Records!S6,Records!T6,Records!U6),"") | N6: =IF(COUNT(Records!V6,Records!O6,Records!P6)=3,AVERAGE(Records!V6,Records!O6,Records!P6),"") | O6: =IF(Records!N6="","",Records!N6) | P6: =IF(Records!AA6="","",IF(Records!AA6>150,"是","否")) | Q6: =IF(COUNT(Records!K6,Records!L6,Records!M6,Records!O6,Records!P6,Records!Q6,Records!R6,Records!S6,Records!T6,Records!U6,Records!V6,Records!W6,Records!X6)<13,"",IF(OR(AND(Records!K6=Records!L6,Records!L6=Records!M6,Records!M6=Records!O6,Records!O6=Records!P6),AND(Records!L6=Records!M6,Records!M6=Records!O6,Records!O6=Records!P6,Records!P6=Records!Q6),AND(Records!M6=Records!O6,Records!O6=Records!P6,Records!P6=Records!Q6,Records!Q6=Records!R6),AND(Records!O6=Records!P6,Records!P6=Records!Q6,Records!Q6=Records!R6,Records!R6=Records!S6),AND(Records!P6=Records!Q6,Records!Q6=Records!R6,Records!R6=Records!S6,Records!S6=Records!T6),AND(Records!Q6=Records!R6,Records!R6=Records!S6,Records!S6=Records!T6,Records!T6=Records!U6),AND(Records!R6=Records!S6,Records!S6=Records!T6,Records!T6=Records!U6,Records!U6=Records!V6),AND(Records!S6=Records!T6,Records!T6=Records!U6,Records!U6=Records!V6,Records!V6=Records!W6),AND(Records!T6=Records!U6,Records!U6=Records!V6,Records!V6=Records!W6,Records!W6=Records!X6)),"是","否")) | R6: =IF(Records!AF6="","",Records!AF6) | S6: =IF(Records!AG6="","",Records!AG6) | T6: =IF(Records!AH6="","",Records!AH6) | U6: =IF(Records!AI6="","",Records!AI6) | V6: =IF(Records!AJ6="","",Records!AJ6) | W6: =IF(Records!AK6="","",Records!AK6) | X6: =IF(Records!AL6="","",Records!AL6) | Y6: =IF(Records!AM6="","",Records!AM6) | Z6: =IF(Records!AN6="","",Records!AN6)
A7: =IF(Records!A7="","",Records!A7) | B7: =IF(Records!B7="","",Records!B7) | C7: =IF(Records!H7="","",Records!H7) | D7: =IF(Records!F7="","",Records!F7) | E7: =IF(AND(COUNTIFS(Participants!$A$3:$A$26,Records!A7,Participants!$V$3:$V$26,"是")=1,Records!AB7="是",Records!AC7="是",Records!AD7="是",COUNT(Records!K7,Records!L7,Records!M7,Records!O7,Records!P7,Records!Q7,Records!R7,Records!S7,Records!T7,Records!U7,Records!V7,Records!W7,Records!X7)=13),"是","否") | F7: =IF(Records!K7="","",Records!K7) | G7: =IF(Records!R7="","",Records!R7) | H7: =IF(Records!L7="","",Records!L7) | I7: =IF(Records!M7="","",Records!M7) | J7: =IF(Records!Q7="","",Records!Q7) | K7: =IF(Records!W7="","",Records!W7) | L7: =IF(Records!X7="","",Records!X7) | M7: =IF(COUNT(Records!S7,Records!T7,Records!U7)=3,AVERAGE(Records!S7,Records!T7,Records!U7),"") | N7: =IF(COUNT(Records!V7,Records!O7,Records!P7)=3,AVERAGE(Records!V7,Records!O7,Records!P7),"") | O7: =IF(Records!N7="","",Records!N7) | P7: =IF(Records!AA7="","",IF(Records!AA7>150,"是","否")) | Q7: =IF(COUNT(Records!K7,Records!L7,Records!M7,Records!O7,Records!P7,Records!Q7,Records!R7,Records!S7,Records!T7,Records!U7,Records!V7,Records!W7,Records!X7)<13,"",IF(OR(AND(Records!K7=Records!L7,Records!L7=Records!M7,Records!M7=Records!O7,Records!O7=Records!P7),AND(Records!L7=Records!M7,Records!M7=Records!O7,Records!O7=Records!P7,Records!P7=Records!Q7),AND(Records!M7=Records!O7,Records!O7=Records!P7,Records!P7=Records!Q7,Records!Q7=Records!R7),AND(Records!O7=Records!P7,Records!P7=Records!Q7,Records!Q7=Records!R7,Records!R7=Records!S7),AND(Records!P7=Records!Q7,Records!Q7=Records!R7,Records!R7=Records!S7,Records!S7=Records!T7),AND(Records!Q7=Records!R7,Records!R7=Records!S7,Records!S7=Records!T7,Records!T7=Records!U7),AND(Records!R7=Records!S7,Records!S7=Records!T7,Records!T7=Records!U7,Records!U7=Records!V7),AND(Records!S7=Records!T7,Records!T7=Records!U7,Records!U7=Records!V7,Records!V7=Records!W7),AND(Records!T7=Records!U7,Records!U7=Records!V7,Records!V7=Records!W7,Records!W7=Records!X7)),"是","否")) | R7: =IF(Records!AF7="","",Records!AF7) | S7: =IF(Records!AG7="","",Records!AG7) | T7: =IF(Records!AH7="","",Records!AH7) | U7: =IF(Records!AI7="","",Records!AI7) | V7: =IF(Records!AJ7="","",Records!AJ7) | W7: =IF(Records!AK7="","",Records!AK7) | X7: =IF(Records!AL7="","",Records!AL7) | Y7: =IF(Records!AM7="","",Records!AM7) | Z7: =IF(Records!AN7="","",Records!AN7)
A8: =IF(Records!A8="","",Records!A8) | B8: =IF(Records!B8="","",Records!B8) | C8: =IF(Records!H8="","",Records!H8) | D8: =IF(Records!F8="","",Records!F8) | E8: =IF(AND(COUNTIFS(Participants!$A$3:$A$26,Records!A8,Participants!$V$3:$V$26,"是")=1,Records!AB8="是",Records!AC8="是",Records!AD8="是",COUNT(Records!K8,Records!L8,Records!M8,Records!O8,Records!P8,Records!Q8,Records!R8,Records!S8,Records!T8,Records!U8,Records!V8,Records!W8,Records!X8)=13),"是","否") | F8: =IF(Records!K8="","",Records!K8) | G8: =IF(Records!R8="","",Records!R8) | H8: =IF(Records!L8="","",Records!L8) | I8: =IF(Records!M8="","",Records!M8) | J8: =IF(Records!Q8="","",Records!Q8) | K8: =IF(Records!W8="","",Records!W8) | L8: =IF(Records!X8="","",Records!X8) | M8: =IF(COUNT(Records!S8,Records!T8,Records!U8)=3,AVERAGE(Records!S8,Records!T8,Records!U8),"") | N8: =IF(COUNT(Records!V8,Records!O8,Records!P8)=3,AVERAGE(Records!V8,Records!O8,Records!P8),"") | O8: =IF(Records!N8="","",Records!N8) | P8: =IF(Records!AA8="","",IF(Records!AA8>150,"是","否")) | Q8: =IF(COUNT(Records!K8,Records!L8,Records!M8,Records!O8,Records!P8,Records!Q8,Records!R8,Records!S8,Records!T8,Records!U8,Records!V8,Records!W8,Records!X8)<13,"",IF(OR(AND(Records!K8=Records!L8,Records!L8=Records!M8,Records!M8=Records!O8,Records!O8=Records!P8),AND(Records!L8=Records!M8,Records!M8=Records!O8,Records!O8=Records!P8,Records!P8=Records!Q8),AND(Records!M8=Records!O8,Records!O8=Records!P8,Records!P8=Records!Q8,Records!Q8=Records!R8),AND(Records!O8=Records!P8,Records!P8=Records!Q8,Records!Q8=Records!R8,Records!R8=Records!S8),AND(Records!P8=Records!Q8,Records!Q8=Records!R8,Records!R8=Records!S8,Records!S8=Records!T8),AND(Records!Q8=Records!R8,Records!R8=Records!S8,Records!S8=Records!T8,Records!T8=Records!U8),AND(Records!R8=Records!S8,Records!S8=Records!T8,Records!T8=Records!U8,Records!U8=Records!V8),AND(Records!S8=Records!T8,Records!T8=Records!U8,Records!U8=Records!V8,Records!V8=Records!W8),AND(Records!T8=Records!U8,Records!U8=Records!V8,Records!V8=Records!W8,Records!W8=Records!X8)),"是","否")) | R8: =IF(Records!AF8="","",Records!AF8) | S8: =IF(Records!AG8="","",Records!AG8) | T8: =IF(Records!AH8="","",Records!AH8) | U8: =IF(Records!AI8="","",Records!AI8) | V8: =IF(Records!AJ8="","",Records!AJ8) | W8: =IF(Records!AK8="","",Records!AK8) | X8: =IF(Records!AL8="","",Records!AL8) | Y8: =IF(Records!AM8="","",Records!AM8) | Z8: =IF(Records!AN8="","",Records!AN8)
A9: =IF(Records!A9="","",Records!A9) | B9: =IF(Records!B9="","",Records!B9) | C9: =IF(Records!H9="","",Records!H9) | D9: =IF(Records!F9="","",Records!F9) | E9: =IF(AND(COUNTIFS(Participants!$A$3:$A$26,Records!A9,Participants!$V$3:$V$26,"是")=1,Records!AB9="是",Records!AC9="是",Records!AD9="是",COUNT(Records!K9,Records!L9,Records!M9,Records!O9,Records!P9,Records!Q9,Records!R9,Records!S9,Records!T9,Records!U9,Records!V9,Records!W9,Records!X9)=13),"是","否") | F9: =IF(Records!K9="","",Records!K9) | G9: =IF(Records!R9="","",Records!R9) | H9: =IF(Records!L9="","",Records!L9) | I9: =IF(Records!M9="","",Records!M9) | J9: =IF(Records!Q9="","",Records!Q9) | K9: =IF(Records!W9="","",Records!W9) | L9: =IF(Records!X9="","",Records!X9) | M9: =IF(COUNT(Records!S9,Records!T9,Records!U9)=3,AVERAGE(Records!S9,Records!T9,Records!U9),"") | N9: =IF(COUNT(Records!V9,Records!O9,Records!P9)=3,AVERAGE(Records!V9,Records!O9,Records!P9),"") | O9: =IF(Records!N9="","",Records!N9) | P9: =IF(Records!AA9="","",IF(Records!AA9>150,"是","否")) | Q9: =IF(COUNT(Records!K9,Records!L9,Records!M9,Records!O9,Records!P9,Records!Q9,Records!R9,Records!S9,Records!T9,Records!U9,Records!V9,Records!W9,Records!X9)<13,"",IF(OR(AND(Records!K9=Records!L9,Records!L9=Records!M9,Records!M9=Records!O9,Records!O9=Records!P9),AND(Records!L9=Records!M9,Records!M9=Records!O9,Records!O9=Records!P9,Records!P9=Records!Q9),AND(Records!M9=Records!O9,Records!O9=Records!P9,Records!P9=Records!Q9,Records!Q9=Records!R9),AND(Records!O9=Records!P9,Records!P9=Records!Q9,Records!Q9=Records!R9,Records!R9=Records!S9),AND(Records!P9=Records!Q9,Records!Q9=Records!R9,Records!R9=Records!S9,Records!S9=Records!T9),AND(Records!Q9=Records!R9,Records!R9=Records!S9,Records!S9=Records!T9,Records!T9=Records!U9),AND(Records!R9=Records!S9,Records!S9=Records!T9,Records!T9=Records!U9,Records!U9=Records!V9),AND(Records!S9=Records!T9,Records!T9=Records!U9,Records!U9=Records!V9,Records!V9=Records!W9),AND(Records!T9=Records!U9,Records!U9=Records!V9,Records!V9=Records!W9,Records!W9=Records!X9)),"是","否")) | R9: =IF(Records!AF9="","",Records!AF9) | S9: =IF(Records!AG9="","",Records!AG9) | T9: =IF(Records!AH9="","",Records!AH9) | U9: =IF(Records!AI9="","",Records!AI9) | V9: =IF(Records!AJ9="","",Records!AJ9) | W9: =IF(Records!AK9="","",Records!AK9) | X9: =IF(Records!AL9="","",Records!AL9) | Y9: =IF(Records!AM9="","",Records!AM9) | Z9: =IF(Records!AN9="","",Records!AN9)
A10: =IF(Records!A10="","",Records!A10) | B10: =IF(Records!B10="","",Records!B10) | C10: =IF(Records!H10="","",Records!H10) | D10: =IF(Records!F10="","",Records!F10) | E10: =IF(AND(COUNTIFS(Participants!$A$3:$A$26,Records!A10,Participants!$V$3:$V$26,"是")=1,Records!AB10="是",Records!AC10="是",Records!AD10="是",COUNT(Records!K10,Records!L10,Records!M10,Records!O10,Records!P10,Records!Q10,Records!R10,Records!S10,Records!T10,Records!U10,Records!V10,Records!W10,Records!X10)=13),"是","否") | F10: =IF(Records!K10="","",Records!K10) | G10: =IF(Records!R10="","",Records!R10) | H10: =IF(Records!L10="","",Records!L10) | I10: =IF(Records!M10="","",Records!M10) | J10: =IF(Records!Q10="","",Records!Q10) | K10: =IF(Records!W10="","",Records!W10) | L10: =IF(Records!X10="","",Records!X10) | M10: =IF(COUNT(Records!S10,Records!T10,Records!U10)=3,AVERAGE(Records!S10,Records!T10,Records!U10),"") | N10: =IF(COUNT(Records!V10,Records!O10,Records!P10)=3,AVERAGE(Records!V10,Records!O10,Records!P10),"") | O10: =IF(Records!N10="","",Records!N10) | P10: =IF(Records!AA10="","",IF(Records!AA10>150,"是","否")) | Q10: =IF(COUNT(Records!K10,Records!L10,Records!M10,Records!O10,Records!P10,Records!Q10,Records!R10,Records!S10,Records!T10,Records!U10,Records!V10,Records!W10,Records!X10)<13,"",IF(OR(AND(Records!K10=Records!L10,Records!L10=Records!M10,Records!M10=Records!O10,Records!O10=Records!P10),AND(Records!L10=Records!M10,Records!M10=Records!O10,Records!O10=Records!P10,Records!P10=Records!Q10),AND(Records!M10=Records!O10,Records!O10=Records!P10,Records!P10=Records!Q10,Records!Q10=Records!R10),AND(Records!O10=Records!P10,Records!P10=Records!Q10,Records!Q10=Records!R10,Records!R10=Records!S10),AND(Records!P10=Records!Q10,Records!Q10=Records!R10,Records!R10=Records!S10,Records!S10=Records!T10),AND(Records!Q10=Records!R10,Records!R10=Records!S10,Records!S10=Records!T10,Records!T10=Records!U10),AND(Records!R10=Records!S10,Records!S10=Records!T10,Records!T10=Records!U10,Records!U10=Records!V10),AND(Records!S10=Records!T10,Records!T10=Records!U10,Records!U10=Records!V10,Records!V10=Records!W10),AND(Records!T10=Records!U10,Records!U10=Records!V10,Records!V10=Records!W10,Records!W10=Records!X10)),"是","否")) | R10: =IF(Records!AF10="","",Records!AF10) | S10: =IF(Records!AG10="","",Records!AG10) | T10: =IF(Records!AH10="","",Records!AH10) | U10: =IF(Records!AI10="","",Records!AI10) | V10: =IF(Records!AJ10="","",Records!AJ10) | W10: =IF(Records!AK10="","",Records!AK10) | X10: =IF(Records!AL10="","",Records!AL10) | Y10: =IF(Records!AM10="","",Records!AM10) | Z10: =IF(Records!AN10="","",Records!AN10)
A11: =IF(Records!A11="","",Records!A11) | B11: =IF(Records!B11="","",Records!B11) | C11: =IF(Records!H11="","",Records!H11) | D11: =IF(Records!F11="","",Records!F11) | E11: =IF(AND(COUNTIFS(Participants!$A$3:$A$26,Records!A11,Participants!$V$3:$V$26,"是")=1,Records!AB11="是",Records!AC11="是",Records!AD11="是",COUNT(Records!K11,Records!L11,Records!M11,Records!O11,Records!P11,Records!Q11,Records!R11,Records!S11,Records!T11,Records!U11,Records!V11,Records!W11,Records!X11)=13),"是","否") | F11: =IF(Records!K11="","",Records!K11) | G11: =IF(Records!R11="","",Records!R11) | H11: =IF(Records!L11="","",Records!L11) | I11: =IF(Records!M11="","",Records!M11) | J11: =IF(Records!Q11="","",Records!Q11) | K11: =IF(Records!W11="","",Records!W11) | L11: =IF(Records!X11="","",Records!X11) | M11: =IF(COUNT(Records!S11,Records!T11,Records!U11)=3,AVERAGE(Records!S11,Records!T11,Records!U11),"") | N11: =IF(COUNT(Records!V11,Records!O11,Records!P11)=3,AVERAGE(Records!V11,Records!O11,Records!P11),"") | O11: =IF(Records!N11="","",Records!N11) | P11: =IF(Records!AA11="","",IF(Records!AA11>150,"是","否")) | Q11: =IF(COUNT(Records!K11,Records!L11,Records!M11,Records!O11,Records!P11,Records!Q11,Records!R11,Records!S11,Records!T11,Records!U11,Records!V11,Records!W11,Records!X11)<13,"",IF(OR(AND(Records!K11=Records!L11,Records!L11=Records!M11,Records!M11=Records!O11,Records!O11=Records!P11),AND(Records!L11=Records!M11,Records!M11=Records!O11,Records!O11=Records!P11,Records!P11=Records!Q11),AND(Records!M11=Records!O11,Records!O11=Records!P11,Records!P11=Records!Q11,Records!Q11=Records!R11),AND(Records!O11=Records!P11,Records!P11=Records!Q11,Records!Q11=Records!R11,Records!R11=Records!S11),AND(Records!P11=Records!Q11,Records!Q11=Records!R11,Records!R11=Records!S11,Records!S11=Records!T11),AND(Records!Q11=Records!R11,Records!R11=Records!S11,Records!S11=Records!T11,Records!T11=Records!U11),AND(Records!R11=Records!S11,Records!S11=Records!T11,Records!T11=Records!U11,Records!U11=Records!V11),AND(Records!S11=Records!T11,Records!T11=Records!U11,Records!U11=Records!V11,Records!V11=Records!W11),AND(Records!T11=Records!U11,Records!U11=Records!V11,Records!V11=Records!W11,Records!W11=Records!X11)),"是","否")) | R11: =IF(Records!AF11="","",Records!AF11) | S11: =IF(Records!AG11="","",Records!AG11) | T11: =IF(Records!AH11="","",Records!AH11) | U11: =IF(Records!AI11="","",Records!AI11) | V11: =IF(Records!AJ11="","",Records!AJ11) | W11: =IF(Records!AK11="","",Records!AK11) | X11: =IF(Records!AL11="","",Records!AL11) | Y11: =IF(Records!AM11="","",Records!AM11) | Z11: =IF(Records!AN11="","",Records!AN11)
A12: =IF(Records!A12="","",Records!A12) | B12: =IF(Records!B12="","",Records!B12) | C12: =IF(Records!H12="","",Records!H12) | D12: =IF(Records!F12="","",Records!F12) | E12: =IF(AND(COUNTIFS(Participants!$A$3:$A$26,Records!A12,Participants!$V$3:$V$26,"是")=1,Records!AB12="是",Records!AC12="是",Records!AD12="是",COUNT(Records!K12,Records!L12,Records!M12,Records!O12,Records!P12,Records!Q12,Records!R12,Records!S12,Records!T12,Records!U12,Records!V12,Records!W12,Records!X12)=13),"是","否") | F12: =IF(Records!K12="","",Records!K12) | G12: =IF(Records!R12="","",Records!R12) | H12: =IF(Records!L12="","",Records!L12) | I12: =IF(Records!M12="","",Records!M12) | J12: =IF(Records!Q12="","",Records!Q12) | K12: =IF(Records!W12="","",Records!W12) | L12: =IF(Records!X12="","",Records!X12) | M12: =IF(COUNT(Records!S12,Records!T12,Records!U12)=3,AVERAGE(Records!S12,Records!T12,Records!U12),"") | N12: =IF(COUNT(Records!V12,Records!O12,Records!P12)=3,AVERAGE(Records!V12,Records!O12,Records!P12),"") | O12: =IF(Records!N12="","",Records!N12) | P12: =IF(Records!AA12="","",IF(Records!AA12>150,"是","否")) | Q12: =IF(COUNT(Records!K12,Records!L12,Records!M12,Records!O12,Records!P12,Records!Q12,Records!R12,Records!S12,Records!T12,Records!U12,Records!V12,Records!W12,Records!X12)<13,"",IF(OR(AND(Records!K12=Records!L12,Records!L12=Records!M12,Records!M12=Records!O12,Records!O12=Records!P12),AND(Records!L12=Records!M12,Records!M12=Records!O12,Records!O12=Records!P12,Records!P12=Records!Q12),AND(Records!M12=Records!O12,Records!O12=Records!P12,Records!P12=Records!Q12,Records!Q12=Records!R12),AND(Records!O12=Records!P12,Records!P12=Records!Q12,Records!Q12=Records!R12,Records!R12=Records!S12),AND(Records!P12=Records!Q12,Records!Q12=Records!R12,Records!R12=Records!S12,Records!S12=Records!T12),AND(Records!Q12=Records!R12,Records!R12=Records!S12,Records!S12=Records!T12,Records!T12=Records!U12),AND(Records!R12=Records!S12,Records!S12=Records!T12,Records!T12=Records!U12,Records!U12=Records!V12),AND(Records!S12=Records!T12,Records!T12=Records!U12,Records!U12=Records!V12,Records!V12=Records!W12),AND(Records!T12=Records!U12,Records!U12=Records!V12,Records!V12=Records!W12,Records!W12=Records!X12)),"是","否")) | R12: =IF(Records!AF12="","",Records!AF12) | S12: =IF(Records!AG12="","",Records!AG12) | T12: =IF(Records!AH12="","",Records!AH12) | U12: =IF(Records!AI12="","",Records!AI12) | V12: =IF(Records!AJ12="","",Records!AJ12) | W12: =IF(Records!AK12="","",Records!AK12) | X12: =IF(Records!AL12="","",Records!AL12) | Y12: =IF(Records!AM12="","",Records!AM12) | Z12: =IF(Records!AN12="","",Records!AN12)
A13: =IF(Records!A13="","",Records!A13) | B13: =IF(Records!B13="","",Records!B13) | C13: =IF(Records!H13="","",Records!H13) | D13: =IF(Records!F13="","",Records!F13) | E13: =IF(AND(COUNTIFS(Participants!$A$3:$A$26,Records!A13,Participants!$V$3:$V$26,"是")=1,Records!AB13="是",Records!AC13="是",Records!AD13="是",COUNT(Records!K13,Records!L13,Records!M13,Records!O13,Records!P13,Records!Q13,Records!R13,Records!S13,Records!T13,Records!U13,Records!V13,Records!W13,Records!X13)=13),"是","否") | F13: =IF(Records!K13="","",Records!K13) | G13: =IF(Records!R13="","",Records!R13) | H13: =IF(Records!L13="","",Records!L13) | I13: =IF(Records!M13="","",Records!M13) | J13: =IF(Records!Q13="","",Records!Q13) | K13: =IF(Records!W13="","",Records!W13) | L13: =IF(Records!X13="","",Records!X13) | M13: =IF(COUNT(Records!S13,Records!T13,Records!U13)=3,AVERAGE(Records!S13,Records!T13,Records!U13),"") | N13: =IF(COUNT(Records!V13,Records!O13,Records!P13)=3,AVERAGE(Records!V13,Records!O13,Records!P13),"") | O13: =IF(Records!N13="","",Records!N13) | P13: =IF(Records!AA13="","",IF(Records!AA13>150,"是","否")) | Q13: =IF(COUNT(Records!K13,Records!L13,Records!M13,Records!O13,Records!P13,Records!Q13,Records!R13,Records!S13,Records!T13,Records!U13,Records!V13,Records!W13,Records!X13)<13,"",IF(OR(AND(Records!K13=Records!L13,Records!L13=Records!M13,Records!M13=Records!O13,Records!O13=Records!P13),AND(Records!L13=Records!M13,Records!M13=Records!O13,Records!O13=Records!P13,Records!P13=Records!Q13),AND(Records!M13=Records!O13,Records!O13=Records!P13,Records!P13=Records!Q13,Records!Q13=Records!R13),AND(Records!O13=Records!P13,Records!P13=Records!Q13,Records!Q13=Records!R13,Records!R13=Records!S13),AND(Records!P13=Records!Q13,Records!Q13=Records!R13,Records!R13=Records!S13,Records!S13=Records!T13),AND(Records!Q13=Records!R13,Records!R13=Records!S13,Records!S13=Records!T13,Records!T13=Records!U13),AND(Records!R13=Records!S13,Records!S13=Records!T13,Records!T13=Records!U13,Records!U13=Records!V13),AND(Records!S13=Records!T13,Records!T13=Records!U13,Records!U13=Records!V13,Records!V13=Records!W13),AND(Records!T13=Records!U13,Records!U13=Records!V13,Records!V13=Records!W13,Records!W13=Records!X13)),"是","否")) | R13: =IF(Records!AF13="","",Records!AF13) | S13: =IF(Records!AG13="","",Records!AG13) | T13: =IF(Records!AH13="","",Records!AH13) | U13: =IF(Records!AI13="","",Records!AI13) | V13: =IF(Records!AJ13="","",Records!AJ13) | W13: =IF(Records!AK13="","",Records!AK13) | X13: =IF(Records!AL13="","",Records!AL13) | Y13: =IF(Records!AM13="","",Records!AM13) | Z13: =IF(Records!AN13="","",Records!AN13)
A14: =IF(Records!A14="","",Records!A14) | B14: =IF(Records!B14="","",Records!B14) | C14: =IF(Records!H14="","",Records!H14) | D14: =IF(Records!F14="","",Records!F14) | E14: =IF(AND(COUNTIFS(Participants!$A$3:$A$26,Records!A14,Participants!$V$3:$V$26,"是")=1,Records!AB14="是",Records!AC14="是",Records!AD14="是",COUNT(Records!K14,Records!L14,Records!M14,Records!O14,Records!P14,Records!Q14,Records!R14,Records!S14,Records!T14,Records!U14,Records!V14,Records!W14,Records!X14)=13),"是","否") | F14: =IF(Records!K14="","",Records!K14) | G14: =IF(Records!R14="","",Records!R14) | H14: =IF(Records!L14="","",Records!L14) | I14: =IF(Records!M14="","",Records!M14) | J14: =IF(Records!Q14="","",Records!Q14) | K14: =IF(Records!W14="","",Records!W14) | L14: =IF(Records!X14="","",Records!X14) | M14: =IF(COUNT(Records!S14,Records!T14,Records!U14)=3,AVERAGE(Records!S14,Records!T14,Records!U14),"") | N14: =IF(COUNT(Records!V14,Records!O14,Records!P14)=3,AVERAGE(Records!V14,Records!O14,Records!P14),"") | O14: =IF(Records!N14="","",Records!N14) | P14: =IF(Records!AA14="","",IF(Records!AA14>150,"是","否")) | Q14: =IF(COUNT(Records!K14,Records!L14,Records!M14,Records!O14,Records!P14,Records!Q14,Records!R14,Records!S14,Records!T14,Records!U14,Records!V14,Records!W14,Records!X14)<13,"",IF(OR(AND(Records!K14=Records!L14,Records!L14=Records!M14,Records!M14=Records!O14,Records!O14=Records!P14),AND(Records!L14=Records!M14,Records!M14=Records!O14,Records!O14=Records!P14,Records!P14=Records!Q14),AND(Records!M14=Records!O14,Records!O14=Records!P14,Records!P14=Records!Q14,Records!Q14=Records!R14),AND(Records!O14=Records!P14,Records!P14=Records!Q14,Records!Q14=Records!R14,Records!R14=Records!S14),AND(Records!P14=Records!Q14,Records!Q14=Records!R14,Records!R14=Records!S14,Records!S14=Records!T14),AND(Records!Q14=Records!R14,Records!R14=Records!S14,Records!S14=Records!T14,Records!T14=Records!U14),AND(Records!R14=Records!S14,Records!S14=Records!T14,Records!T14=Records!U14,Records!U14=Records!V14),AND(Records!S14=Records!T14,Records!T14=Records!U14,Records!U14=Records!V14,Records!V14=Records!W14),AND(Records!T14=Records!U14,Records!U14=Records!V14,Records!V14=Records!W14,Records!W14=Records!X14)),"是","否")) | R14: =IF(Records!AF14="","",Records!AF14) | S14: =IF(Records!AG14="","",Records!AG14) | T14: =IF(Records!AH14="","",Records!AH14) | U14: =IF(Records!AI14="","",Records!AI14) | V14: =IF(Records!AJ14="","",Records!AJ14) | W14: =IF(Records!AK14="","",Records!AK14) | X14: =IF(Records!AL14="","",Records!AL14) | Y14: =IF(Records!AM14="","",Records!AM14) | Z14: =IF(Records!AN14="","",Records!AN14)
A15: =IF(Records!A15="","",Records!A15) | B15: =IF(Records!B15="","",Records!B15) | C15: =IF(Records!H15="","",Records!H15) | D15: =IF(Records!F15="","",Records!F15) | E15: =IF(AND(COUNTIFS(Participants!$A$3:$A$26,Records!A15,Participants!$V$3:$V$26,"是")=1,Records!AB15="是",Records!AC15="是",Records!AD15="是",COUNT(Records!K15,Records!L15,Records!M15,Records!O15,Records!P15,Records!Q15,Records!R15,Records!S15,Records!T15,Records!U15,Records!V15,Records!W15,Records!X15)=13),"是","否") | F15: =IF(Records!K15="","",Records!K15) | G15: =IF(Records!R15="","",Records!R15) | H15: =IF(Records!L15="","",Records!L15) | I15: =IF(Records!M15="","",Records!M15) | J15: =IF(Records!Q15="","",Records!Q15) | K15: =IF(Records!W15="","",Records!W15) | L15: =IF(Records!X15="","",Records!X15) | M15: =IF(COUNT(Records!S15,Records!T15,Records!U15)=3,AVERAGE(Records!S15,Records!T15,Records!U15),"") | N15: =IF(COUNT(Records!V15,Records!O15,Records!P15)=3,AVERAGE(Records!V15,Records!O15,Records!P15),"") | O15: =IF(Records!N15="","",Records!N15) | P15: =IF(Records!AA15="","",IF(Records!AA15>150,"是","否")) | Q15: =IF(COUNT(Records!K15,Records!L15,Records!M15,Records!O15,Records!P15,Records!Q15,Records!R15,Records!S15,Records!T15,Records!U15,Records!V15,Records!W15,Records!X15)<13,"",IF(OR(AND(Records!K15=Records!L15,Records!L15=Records!M15,Records!M15=Records!O15,Records!O15=Records!P15),AND(Records!L15=Records!M15,Records!M15=Records!O15,Records!O15=Records!P15,Records!P15=Records!Q15),AND(Records!M15=Records!O15,Records!O15=Records!P15,Records!P15=Records!Q15,Records!Q15=Records!R15),AND(Records!O15=Records!P15,Records!P15=Records!Q15,Records!Q15=Records!R15,Records!R15=Records!S15),AND(Records!P15=Records!Q15,Records!Q15=Records!R15,Records!R15=Records!S15,Records!S15=Records!T15),AND(Records!Q15=Records!R15,Records!R15=Records!S15,Records!S15=Records!T15,Records!T15=Records!U15),AND(Records!R15=Records!S15,Records!S15=Records!T15,Records!T15=Records!U15,Records!U15=Records!V15),AND(Records!S15=Records!T15,Records!T15=Records!U15,Records!U15=Records!V15,Records!V15=Records!W15),AND(Records!T15=Records!U15,Records!U15=Records!V15,Records!V15=Records!W15,Records!W15=Records!X15)),"是","否")) | R15: =IF(Records!AF15="","",Records!AF15) | S15: =IF(Records!AG15="","",Records!AG15) | T15: =IF(Records!AH15="","",Records!AH15) | U15: =IF(Records!AI15="","",Records!AI15) | V15: =IF(Records!AJ15="","",Records!AJ15) | W15: =IF(Records!AK15="","",Records!AK15) | X15: =IF(Records!AL15="","",Records!AL15) | Y15: =IF(Records!AM15="","",Records!AM15) | Z15: =IF(Records!AN15="","",Records!AN15)
A16: =IF(Records!A16="","",Records!A16) | B16: =IF(Records!B16="","",Records!B16) | C16: =IF(Records!H16="","",Records!H16) | D16: =IF(Records!F16="","",Records!F16) | E16: =IF(AND(COUNTIFS(Participants!$A$3:$A$26,Records!A16,Participants!$V$3:$V$26,"是")=1,Records!AB16="是",Records!AC16="是",Records!AD16="是",COUNT(Records!K16,Records!L16,Records!M16,Records!O16,Records!P16,Records!Q16,Records!R16,Records!S16,Records!T16,Records!U16,Records!V16,Records!W16,Records!X16)=13),"是","否") | F16: =IF(Records!K16="","",Records!K16) | G16: =IF(Records!R16="","",Records!R16) | H16: =IF(Records!L16="","",Records!L16) | I16: =IF(Records!M16="","",Records!M16) | J16: =IF(Records!Q16="","",Records!Q16) | K16: =IF(Records!W16="","",Records!W16) | L16: =IF(Records!X16="","",Records!X16) | M16: =IF(COUNT(Records!S16,Records!T16,Records!U16)=3,AVERAGE(Records!S16,Records!T16,Records!U16),"") | N16: =IF(COUNT(Records!V16,Records!O16,Records!P16)=3,AVERAGE(Records!V16,Records!O16,Records!P16),"") | O16: =IF(Records!N16="","",Records!N16) | P16: =IF(Records!AA16="","",IF(Records!AA16>150,"是","否")) | Q16: =IF(COUNT(Records!K16,Records!L16,Records!M16,Records!O16,Records!P16,Records!Q16,Records!R16,Records!S16,Records!T16,Records!U16,Records!V16,Records!W16,Records!X16)<13,"",IF(OR(AND(Records!K16=Records!L16,Records!L16=Records!M16,Records!M16=Records!O16,Records!O16=Records!P16),AND(Records!L16=Records!M16,Records!M16=Records!O16,Records!O16=Records!P16,Records!P16=Records!Q16),AND(Records!M16=Records!O16,Records!O16=Records!P16,Records!P16=Records!Q16,Records!Q16=Records!R16),AND(Records!O16=Records!P16,Records!P16=Records!Q16,Records!Q16=Records!R16,Records!R16=Records!S16),AND(Records!P16=Records!Q16,Records!Q16=Records!R16,Records!R16=Records!S16,Records!S16=Records!T16),AND(Records!Q16=Records!R16,Records!R16=Records!S16,Records!S16=Records!T16,Records!T16=Records!U16),AND(Records!R16=Records!S16,Records!S16=Records!T16,Records!T16=Records!U16,Records!U16=Records!V16),AND(Records!S16=Records!T16,Records!T16=Records!U16,Records!U16=Records!V16,Records!V16=Records!W16),AND(Records!T16=Records!U16,Records!U16=Records!V16,Records!V16=Records!W16,Records!W16=Records!X16)),"是","否")) | R16: =IF(Records!AF16="","",Records!AF16) | S16: =IF(Records!AG16="","",Records!AG16) | T16: =IF(Records!AH16="","",Records!AH16) | U16: =IF(Records!AI16="","",Records!AI16) | V16: =IF(Records!AJ16="","",Records!AJ16) | W16: =IF(Records!AK16="","",Records!AK16) | X16: =IF(Records!AL16="","",Records!AL16) | Y16: =IF(Records!AM16="","",Records!AM16) | Z16: =IF(Records!AN16="","",Records!AN16)
... A148: =IF(Records!A148="","",Records!A148) | B148: =IF(Records!B148="","",Records!B148) | C148: =IF(Records!H148="","",Records!H148) | D148: =IF(Records!F148="","",Records!F148) | E148: =IF(AND(COUNTIFS(Participants!$A$3:$A$26,Records!A148,Participants!$V$3:$V$26,"是")=1,Records!AB148="是",Records!AC148="是",Records!AD148="是",COUNT(Records!K148,Records!L148,Records!M148,Records!O148,Records!P148,Records!Q148,Records!R148,Records!S148,Records!T148,Records!U148,Records!V148,Records!W148,Records!X148)=13),"是","否") | F148: =IF(Records!K148="","",Records!K148) | G148: =IF(Records!R148="","",Records!R148) | H148: =IF(Records!L148="","",Records!L148) | I148: =IF(Records!M148="","",Records!M148) | J148: =IF(Records!Q148="","",Records!Q148) | K148: =IF(Records!W148="","",Records!W148) | L148: =IF(Records!X148="","",Records!X148) | M148: =IF(COUNT(Records!S148,Records!T148,Records!U148)=3,AVERAGE(Records!S148,Records!T148,Records!U148),"") | N148: =IF(COUNT(Records!V148,Records!O148,Records!P148)=3,AVERAGE(Records!V148,Records!O148,Records!P148),"") | O148: =IF(Records!N148="","",Records!N148) | P148: =IF(Records!AA148="","",IF(Records!AA148>150,"是","否")) | Q148: =IF(COUNT(Records!K148,Records!L148,Records!M148,Records!O148,Records!P148,Records!Q148,Records!R148,Records!S148,Records!T148,Records!U148,Records!V148,Records!W148,Records!X148)<13,"",IF(OR(AND(Records!K148=Records!L148,Records!L148=Records!M148,Records!M148=Records!O148,Records!O148=Records!P148),AND(Records!L148=Records!M148,Records!M148=Records!O148,Records!O148=Records!P148,Records!P148=Records!Q148),AND(Records!M148=Records!O148,Records!O148=Records!P148,Records!P148=Records!Q148,Records!Q148=Records!R148),AND(Records!O148=Records!P148,Records!P148=Records!Q148,Records!Q148=Records!R148,Records!R148=Records!S148),AND(Records!P148=Records!Q148,Records!Q148=Records!R148,Records!R148=Records!S148,Records!S148=Records!T148),AND(Records!Q148=Records!R148,Records!R148=Records!S148,Records!S148=Records!T148,Records!T148=Records!U148),AND(Records!R148=Records!S148,Records!S148=Records!T148,Records!T148=Records!U148,Records!U148=Records!V148),AND(Records!S148=Records!T148,Records!T148=Records!U148,Records!U148=Records!V148,Records!V148=Records!W148),AND(Records!T148=Records!U148,Records!U148=Records!V148,Records!V148=Records!W148,Records!W148=Records!X148)),"是","否")) | R148: =IF(Records!AF148="","",Records!AF148) | S148: =IF(Records!AG148="","",Records!AG148) | T148: =IF(Records!AH148="","",Records!AH148) | U148: =IF(Records!AI148="","",Records!AI148) | V148: =IF(Records!AJ148="","",Records!AJ148) | W148: =IF(Records!AK148="","",Records!AK148) | X148: =IF(Records!AL148="","",Records!AL148) | Y148: =IF(Records!AM148="","",Records!AM148) | Z148: =IF(Records!AN148="","",Records!AN148)
A150: D2. 方法级派生：区分作答完成、记录有效与各分量表可计分
A151: Participant_ID | B151: Condition | C151: Assessment_Complete | D151: Valid_Record | E151: TIA_RC1 | F151: TIA_RC2 | G151: TIA_RC3 | H151: TIA_RC4 | I151: TIA_RC5 | J151: TIA_RC6 | K151: TIA_UP1 | L151: TIA_UP2 | M151: TIA_UP3 | N151: TIA_UP4 | O151: STIAS1 | P151: STIAS2 | Q151: STIAS3 | R151: TIA_RC | S151: TIA_UP | T151: STIAS | U151: Duration_Seconds
A152: =Records!A152 | B152: =Records!D152 | C152: =IF(AND(COUNTA(Records!E152:Q152)=13,Records!R152="是"),"是","否") | D152: =IF(AND(COUNTIFS(Participants!$A$3:$A$26,Records!A152,Participants!$V$3:$V$26,"是")=1,Records!R152="是",OR(Records!V152="",Records!V152="无"),Records!X152="是",Records!Y152="是"),"是","否") | E152: =IF(ISNUMBER(Records!E152),Records!E152,"") | F152: =IF(ISNUMBER(Records!F152),Records!F152,"") | G152: =IF(ISNUMBER(Records!G152),6-Records!G152,"") | H152: =IF(ISNUMBER(Records!H152),Records!H152,"") | I152: =IF(ISNUMBER(Records!I152),6-Records!I152,"") | J152: =IF(ISNUMBER(Records!J152),Records!J152,"") | K152: =IF(ISNUMBER(Records!K152),Records!K152,"") | L152: =IF(ISNUMBER(Records!L152),6-Records!L152,"") | M152: =IF(ISNUMBER(Records!M152),Records!M152,"") | N152: =IF(ISNUMBER(Records!N152),6-Records!N152,"") | O152: =IF(ISNUMBER(Records!O152),Records!O152,"") | P152: =IF(ISNUMBER(Records!P152),Records!P152,"") | Q152: =IF(ISNUMBER(Records!Q152),Records!Q152,"") | R152: =IF(COUNT(E152:J152)>=5,AVERAGE(E152:J152),"") | S152: =IF(COUNT(K152:N152)>=3,AVERAGE(K152:N152),"") | T152: =IF(COUNT(O152:Q152)>=3,AVERAGE(O152:Q152),"") | U152: =IF(Records!U152="","",Records!U152)
A153: =Records!A153 | B153: =Records!D153 | C153: =IF(AND(COUNTA(Records!E153:Q153)=13,Records!R153="是"),"是","否") | D153: =IF(AND(COUNTIFS(Participants!$A$3:$A$26,Records!A153,Participants!$V$3:$V$26,"是")=1,Records!R153="是",OR(Records!V153="",Records!V153="无"),Records!X153="是",Records!Y153="是"),"是","否") | E153: =IF(ISNUMBER(Records!E153),Records!E153,"") | F153: =IF(ISNUMBER(Records!F153),Records!F153,"") | G153: =IF(ISNUMBER(Records!G153),6-Records!G153,"") | H153: =IF(ISNUMBER(Records!H153),Records!H153,"") | I153: =IF(ISNUMBER(Records!I153),6-Records!I153,"") | J153: =IF(ISNUMBER(Records!J153),Records!J153,"") | K153: =IF(ISNUMBER(Records!K153),Records!K153,"") | L153: =IF(ISNUMBER(Records!L153),6-Records!L153,"") | M153: =IF(ISNUMBER(Records!M153),Records!M153,"") | N153: =IF(ISNUMBER(Records!N153),6-Records!N153,"") | O153: =IF(ISNUMBER(Records!O153),Records!O153,"") | P153: =IF(ISNUMBER(Records!P153),Records!P153,"") | Q153: =IF(ISNUMBER(Records!Q153),Records!Q153,"") | R153: =IF(COUNT(E153:J153)>=5,AVERAGE(E153:J153),"") | S153: =IF(COUNT(K153:N153)>=3,AVERAGE(K153:N153),"") | T153: =IF(COUNT(O153:Q153)>=3,AVERAGE(O153:Q153),"") | U153: =IF(Records!U153="","",Records!U153)
A154: =Records!A154 | B154: =Records!D154 | C154: =IF(AND(COUNTA(Records!E154:Q154)=13,Records!R154="是"),"是","否") | D154: =IF(AND(COUNTIFS(Participants!$A$3:$A$26,Records!A154,Participants!$V$3:$V$26,"是")=1,Records!R154="是",OR(Records!V154="",Records!V154="无"),Records!X154="是",Records!Y154="是"),"是","否") | E154: =IF(ISNUMBER(Records!E154),Records!E154,"") | F154: =IF(ISNUMBER(Records!F154),Records!F154,"") | G154: =IF(ISNUMBER(Records!G154),6-Records!G154,"") | H154: =IF(ISNUMBER(Records!H154),Records!H154,"") | I154: =IF(ISNUMBER(Records!I154),6-Records!I154,"") | J154: =IF(ISNUMBER(Records!J154),Records!J154,"") | K154: =IF(ISNUMBER(Records!K154),Records!K154,"") | L154: =IF(ISNUMBER(Records!L154),6-Records!L154,"") | M154: =IF(ISNUMBER(Records!M154),Records!M154,"") | N154: =IF(ISNUMBER(Records!N154),6-Records!N154,"") | O154: =IF(ISNUMBER(Records!O154),Records!O154,"") | P154: =IF(ISNUMBER(Records!P154),Records!P154,"") | Q154: =IF(ISNUMBER(Records!Q154),Records!Q154,"") | R154: =IF(COUNT(E154:J154)>=5,AVERAGE(E154:J154),"") | S154: =IF(COUNT(K154:N154)>=3,AVERAGE(K154:N154),"") | T154: =IF(COUNT(O154:Q154)>=3,AVERAGE(O154:Q154),"") | U154: =IF(Records!U154="","",Records!U154)
A155: =Records!A155 | B155: =Records!D155 | C155: =IF(AND(COUNTA(Records!E155:Q155)=13,Records!R155="是"),"是","否") | D155: =IF(AND(COUNTIFS(Participants!$A$3:$A$26,Records!A155,Participants!$V$3:$V$26,"是")=1,Records!R155="是",OR(Records!V155="",Records!V155="无"),Records!X155="是",Records!Y155="是"),"是","否") | E155: =IF(ISNUMBER(Records!E155),Records!E155,"") | F155: =IF(ISNUMBER(Records!F155),Records!F155,"") | G155: =IF(ISNUMBER(Records!G155),6-Records!G155,"") | H155: =IF(ISNUMBER(Records!H155),Records!H155,"") | I155: =IF(ISNUMBER(Records!I155),6-Records!I155,"") | J155: =IF(ISNUMBER(Records!J155),Records!J155,"") | K155: =IF(ISNUMBER(Records!K155),Records!K155,"") | L155: =IF(ISNUMBER(Records!L155),6-Records!L155,"") | M155: =IF(ISNUMBER(Records!M155),Records!M155,"") | N155: =IF(ISNUMBER(Records!N155),6-Records!N155,"") | O155: =IF(ISNUMBER(Records!O155),Records!O155,"") | P155: =IF(ISNUMBER(Records!P155),Records!P155,"") | Q155: =IF(ISNUMBER(Records!Q155),Records!Q155,"") | R155: =IF(COUNT(E155:J155)>=5,AVERAGE(E155:J155),"") | S155: =IF(COUNT(K155:N155)>=3,AVERAGE(K155:N155),"") | T155: =IF(COUNT(O155:Q155)>=3,AVERAGE(O155:Q155),"") | U155: =IF(Records!U155="","",Records!U155)
A156: =Records!A156 | B156: =Records!D156 | C156: =IF(AND(COUNTA(Records!E156:Q156)=13,Records!R156="是"),"是","否") | D156: =IF(AND(COUNTIFS(Participants!$A$3:$A$26,Records!A156,Participants!$V$3:$V$26,"是")=1,Records!R156="是",OR(Records!V156="",Records!V156="无"),Records!X156="是",Records!Y156="是"),"是","否") | E156: =IF(ISNUMBER(Records!E156),Records!E156,"") | F156: =IF(ISNUMBER(Records!F156),Records!F156,"") | G156: =IF(ISNUMBER(Records!G156),6-Records!G156,"") | H156: =IF(ISNUMBER(Records!H156),Records!H156,"") | I156: =IF(ISNUMBER(Records!I156),6-Records!I156,"") | J156: =IF(ISNUMBER(Records!J156),Records!J156,"") | K156: =IF(ISNUMBER(Records!K156),Records!K156,"") | L156: =IF(ISNUMBER(Records!L156),6-Records!L156,"") | M156: =IF(ISNUMBER(Records!M156),Records!M156,"") | N156: =IF(ISNUMBER(Records!N156),6-Records!N156,"") | O156: =IF(ISNUMBER(Records!O156),Records!O156,"") | P156: =IF(ISNUMBER(Records!P156),Records!P156,"") | Q156: =IF(ISNUMBER(Records!Q156),Records!Q156,"") | R156: =IF(COUNT(E156:J156)>=5,AVERAGE(E156:J156),"") | S156: =IF(COUNT(K156:N156)>=3,AVERAGE(K156:N156),"") | T156: =IF(COUNT(O156:Q156)>=3,AVERAGE(O156:Q156),"") | U156: =IF(Records!U156="","",Records!U156)
A157: =Records!A157 | B157: =Records!D157 | C157: =IF(AND(COUNTA(Records!E157:Q157)=13,Records!R157="是"),"是","否") | D157: =IF(AND(COUNTIFS(Participants!$A$3:$A$26,Records!A157,Participants!$V$3:$V$26,"是")=1,Records!R157="是",OR(Records!V157="",Records!V157="无"),Records!X157="是",Records!Y157="是"),"是","否") | E157: =IF(ISNUMBER(Records!E157),Records!E157,"") | F157: =IF(ISNUMBER(Records!F157),Records!F157,"") | G157: =IF(ISNUMBER(Records!G157),6-Records!G157,"") | H157: =IF(ISNUMBER(Records!H157),Records!H157,"") | I157: =IF(ISNUMBER(Records!I157),6-Records!I157,"") | J157: =IF(ISNUMBER(Records!J157),Records!J157,"") | K157: =IF(ISNUMBER(Records!K157),Records!K157,"") | L157: =IF(ISNUMBER(Records!L157),6-Records!L157,"") | M157: =IF(ISNUMBER(Records!M157),Records!M157,"") | N157: =IF(ISNUMBER(Records!N157),6-Records!N157,"") | O157: =IF(ISNUMBER(Records!O157),Records!O157,"") | P157: =IF(ISNUMBER(Records!P157),Records!P157,"") | Q157: =IF(ISNUMBER(Records!Q157),Records!Q157,"") | R157: =IF(COUNT(E157:J157)>=5,AVERAGE(E157:J157),"") | S157: =IF(COUNT(K157:N157)>=3,AVERAGE(K157:N157),"") | T157: =IF(COUNT(O157:Q157)>=3,AVERAGE(O157:Q157),"") | U157: =IF(Records!U157="","",Records!U157)
A158: =Records!A158 | B158: =Records!D158 | C158: =IF(AND(COUNTA(Records!E158:Q158)=13,Records!R158="是"),"是","否") | D158: =IF(AND(COUNTIFS(Participants!$A$3:$A$26,Records!A158,Participants!$V$3:$V$26,"是")=1,Records!R158="是",OR(Records!V158="",Records!V158="无"),Records!X158="是",Records!Y158="是"),"是","否") | E158: =IF(ISNUMBER(Records!E158),Records!E158,"") | F158: =IF(ISNUMBER(Records!F158),Records!F158,"") | G158: =IF(ISNUMBER(Records!G158),6-Records!G158,"") | H158: =IF(ISNUMBER(Records!H158),Records!H158,"") | I158: =IF(ISNUMBER(Records!I158),6-Records!I158,"") | J158: =IF(ISNUMBER(Records!J158),Records!J158,"") | K158: =IF(ISNUMBER(Records!K158),Records!K158,"") | L158: =IF(ISNUMBER(Records!L158),6-Records!L158,"") | M158: =IF(ISNUMBER(Records!M158),Records!M158,"") | N158: =IF(ISNUMBER(Records!N158),6-Records!N158,"") | O158: =IF(ISNUMBER(Records!O158),Records!O158,"") | P158: =IF(ISNUMBER(Records!P158),Records!P158,"") | Q158: =IF(ISNUMBER(Records!Q158),Records!Q158,"") | R158: =IF(COUNT(E158:J158)>=5,AVERAGE(E158:J158),"") | S158: =IF(COUNT(K158:N158)>=3,AVERAGE(K158:N158),"") | T158: =IF(COUNT(O158:Q158)>=3,AVERAGE(O158:Q158),"") | U158: =IF(Records!U158="","",Records!U158)
