Workbook

Sheet README
A1: EgoAnchor 实验三 · AI 模拟演练数据（Round 2 · Claude-Opus-5-1M）
A2: 【合成数据 · 严禁作为真实实验数据使用】本工作簿全部评分由语言模型扮演虚拟参与者生成，只用于 v5.1 采集表填写演练与分析流程验证；不得进入论文结果、效应量、功效或样本量推断，不得与真实参与者数据合并。
A4: 生成模型 | B4: Claude-Opus-5-1M
A5: 轮次 | B5: Round 2（独立重抽，不复用 Round 1 参数校准）
A6: 主种子 | B6: 202607272 | C6: 换种子重抽次数 | D6: 400
A7: 生成时间 | B7: 2026-07-27 15:42
A8: 设计版本 | B8: 问卷 v5.1（32 条目 / 每人 108 评分） | C8: 样本 | D8: N=24（24 平衡单元各 1 人）
A9: 结构来源 | B9: 官方采集表 EgoAnchor_Experiment3_DataCollection_24P_v5_1_Beautified_Checked_VSCodeSafe.xlsx
A10: 权威规格 | B10: 2026-EgoAnchor/experiment_3_questionnaire_design_zh.md（v5.1）
A12: 工作簿结构与小分公式约定
A13: 工作表 | B13: 内容 | C13: 小分是否公式计算 | D13: 说明 | E13: 备注
A14: Participants | B14: 24 名虚拟参与者的平衡单元、背景 B1–B6、人物速写 | C14: — | D14: 平衡单元定义沿用官方采集表；人物到单元的指派按感知灵敏度分层随机 | E14: 人物速写为手写内容
A15: Records | B15: 实验记录三段堆叠：A 区块 144 行 / B 方法级 48 行 / C 最终 24 行 | C15: 否（只放原始评分） | D15: 含 TiA 四个反向项的**原始分**；按计划书 9.1，原始评分不得被反向分覆盖 | E15: 唯一的数据输入表
A16: Derived | B16: 四级派生：区块 AQ 子量表 → 方法级反向计分与分量表 → 每人每方法三物体均值 → 每人配对差 | C16: **是 · 全部公式** | D16: 改动 Records 中任一原始评分，本表全部小分立即重算 | E16: 绿底 = 公式
A17: Analysis | B17: 回填壳：主家族 7 项 / 量表家族 5 检验 / 逐物体 / 操纵检验 / 最终计数 / 开放题 | C17: **是 · Mdn、IQR、配对差、dz 均为公式** | D17: W、p、Holm 校正 p、r_rb 自举 CI 与 α/ω 由 Python 写入（普通单元格函数无法表达） | E17: 绿底 = 公式；黄底 = Python 数值
A18: Resample | B18: 400 次换种子重抽的 p 与 dz 分布 | C18: — | D18: 回答「单次抽样是否可复现」：报告分布而非单点 | E18: 本轮新增
A20: 本轮与 Round 1 的差异
A21: 1. 24 名虚拟参与者改为逐人手写人物设定（背景、评分风格、逐通道感知灵敏度、信任倾向、两道开放题原文与访谈备注），生成器只把人物参数映射成 108 个评分。
A22: 2. 不做事后校准：潜在效应量按实验一/二实测通道差异一次设定后不再按实得效应回调，只取单次抽样结果，因此本轮结论是「一次真实抽样」而非「中心估计的一次实现」。
A23: 3. 人物到平衡单元的指派按感知灵敏度分层随机搜索：手写人物按专家/新手交替的叙事节奏排列，若直接顺序对应会使灵敏度与先行方法共线（实测相差 26%），凭空造出顺序效应。
A24: 4. 问卷小分全部改由公式实时计算，Python 只写原始评分。
A25: 5. 追加 400 次换种子重抽，报告 p 与 dz 的分布而非单点。

Sheet Participants
A1: 参与者信息与 24 平衡单元（合成数据；方法映射两列仅实验员可见）
A2: Participant_ID | B2: 平衡单元 | C2: 物体排列ID | D2: 标签序列 | E2: 物体1 | F2: 物体2 | G2: 物体3 | H2: 区块内标签顺序 | I2: 方法A=（保密） | J2: 方法B=（保密） | K2: 先行实际方法 | L2: B1_年龄 | M2: B2_性别 | N2: B3_主手 | O2: B4_视力 | P2: B5_VR/MR经验 | Q2: B6_实物MR经验 | R2: 签署同意 | S2: 基线不适 | T2: 开始时间 | U2: 结束时间 | V2: 纳入分析 | W2: 退出/技术问题 | X2: 备注 | Y2: 人物速写（手写） | Z2: 感知灵敏度设定
A3: P001 | B3: O6-S1-EA | C3: 6 | D3: S1 | E3: 游戏手柄 | F3: 固定订书机 | G3: 鼠标 | H3: A-B / B-A / A-B | I3: EgoAnchor | J3: One-Euro | K3: EgoAnchor | V3: 是 | W3: 无 | Y3: 工科研究生，玩过几款 VR 射击游戏。习惯先盯着物体边缘看有没有“毛边”，静止阶段几乎不动头就先下判断。 | Z3: 1.25
A4: P002 | B4: O4-S2-EA | C4: 4 | D4: S2 | E4: 固定订书机 | F4: 游戏手柄 | G4: 鼠标 | H4: B-A / A-B / B-A | I4: EgoAnchor | J4: One-Euro | K4: One-Euro | V4: 是 | W4: 无 | Y4: 人文社科背景，第二次戴头显，全程比较客气，评分集中在 5–6 分，很少用 1 和 7。 | Z4: 0.7
A5: P003 | B5: O4-S2-OE | C5: 4 | D5: S2 | E5: 固定订书机 | F5: 游戏手柄 | G5: 鼠标 | H5: B-A / A-B / B-A | I5: One-Euro | J5: EgoAnchor | K5: EgoAnchor | V5: 是 | W5: 无 | Y5: 做过 AR 相关外包，见过不少“对不齐”的 demo，标准很高，愿意给 2 分也愿意给 7 分。全程话不多但每题停顿明显。 | Z5: 1.45
A6: P004 | B6: O4-S1-OE | C6: 4 | D6: S1 | E6: 固定订书机 | F6: 游戏手柄 | G6: 鼠标 | H6: A-B / B-A / A-B | I6: One-Euro | J6: EgoAnchor | K6: One-Euro | V6: 是 | W6: 无 | Y6: 设计专业，左手主操作。特别在意“跟不跟手”，对静止时的细微抖动几乎无感，但一说到延迟立刻皱眉。 | Z6: 0.55
A7: P005 | B7: O3-S2-EA | C7: 3 | D7: S2 | E7: 固定订书机 | F7: 鼠标 | G7: 游戏手柄 | H7: B-A / A-B / B-A | I7: EgoAnchor | J7: One-Euro | K7: One-Euro | V7: 是 | W7: 无 | Y7: 计算机视觉方向博士生，日常用头显做开发。会自发对照物体轮廓和虚拟轮廓的边界。 | Z7: 1.3
A8: P006 | B8: O1-S2-OE | C8: 1 | D8: S2 | E8: 鼠标 | F8: 固定订书机 | G8: 游戏手柄 | H8: B-A / A-B / B-A | I8: One-Euro | J8: EgoAnchor | K8: EgoAnchor | V8: 是 | W8: 无 | Y8: 本科一年级，头显新手，全程觉得“很酷”，注意力更多在体验本身而不是对齐质量。评分普遍偏高且集中。 | Z8: 0.3
A9: P007 | B9: O3-S2-OE | C9: 3 | D9: S2 | E9: 固定订书机 | F9: 鼠标 | G9: 游戏手柄 | H9: B-A / A-B / B-A | I9: One-Euro | J9: EgoAnchor | K9: EgoAnchor | V9: 是 | W9: 无 | Y9: 机械工程背景，习惯用公差的语言描述问题，对“大概齐”容忍度低。整体评分基线明显偏低，最高只给到 6。 | Z9: 1.1
A10: P008 | B10: O3-S1-EA | C10: 3 | D10: S1 | E10: 固定订书机 | F10: 鼠标 | G10: 游戏手柄 | H10: A-B / B-A / A-B | I10: EgoAnchor | J10: One-Euro | K10: EgoAnchor | V10: 是 | W10: 无 | Y10: 游戏方向研究生，对旋转特别敏感（常年做第三人称相机）。会主动把物体转到侧面看朝向。 | Z10: 1.15
A11: P009 | B11: O2-S2-OE | C11: 2 | D11: S2 | E11: 鼠标 | F11: 游戏手柄 | G11: 固定订书机 | H11: B-A / A-B / B-A | I11: One-Euro | J11: EgoAnchor | K11: EgoAnchor | V11: 是 | W11: 无 | Y11: 心理学背景，作答认真但不擅长空间判断；对“融合得自然不自然”这类问题反应最强。 | Z11: 0.75
A12: P010 | B12: O5-S2-EA | C12: 5 | D12: S2 | E12: 游戏手柄 | F12: 鼠标 | G12: 固定订书机 | H12: B-A / A-B / B-A | I12: EgoAnchor | J12: One-Euro | K12: One-Euro | V12: 是 | W12: 无 | Y12: 行政岗，首次使用头显，前两个区块主要在适应设备，第三个物体才进入状态。评分整体中间偏上、跨度小。 | Z12: 0.45
A13: P011 | B13: O1-S1-OE | C13: 1 | D13: S1 | E13: 鼠标 | F13: 固定订书机 | G13: 游戏手柄 | H13: A-B / B-A / A-B | I13: One-Euro | J13: EgoAnchor | K13: One-Euro | V13: 是 | W13: 无 | Y13: 做 VR 内容开发，会主动猜测背后的实现（提到“是不是加了个滤波”），需要在记录中如实标注该推测。 | Z13: 1.35
A14: P012 | B14: O3-S1-OE | C14: 3 | D14: S1 | E14: 固定订书机 | F14: 鼠标 | G14: 游戏手柄 | H14: A-B / B-A / A-B | I14: One-Euro | J14: EgoAnchor | K14: One-Euro | V14: 是 | W14: 无 | Y14: 工业设计，评分风格最“中庸”，几乎是全样本的平均画像；作答稳定、时长接近中位数。 | Z14: 0.95
... A26: P024 | B26: O2-S2-EA | C26: 2 | D26: S2 | E26: 鼠标 | F26: 游戏手柄 | G26: 固定订书机 | H26: B-A / A-B / B-A | I26: EgoAnchor | J26: One-Euro | K26: One-Euro | V26: 是 | W26: 无 | Y26: 产品经理，评价角度偏“能不能上线”；末位参与者，第六区块自述有轻微疲劳。 | Z26: 0.95

Sheet Records
A1: 实验记录（合成数据）：A 区块 144 行 → B 方法级 48 行 → C 最终 24 行；本表只放原始评分，全部小分在 Derived 表由公式计算
A3: A. 区块记录（每行 = 一个方法×物体区块：进度 + 13+1 项评分 + 问卷时长 + 运行时审计）
A4: Participant_ID | B4: Block_Index | C4: 平衡单元 | D4: 物体位置 | E4: 物体 | F4: Object_Key | G4: Shown_Label | H4: Condition(保密) | I4: 物体内先后 | J4: 该方法第几次 | K4: Q1 | L4: Q2 | M4: Q9 | N4: Q10_OPT | O4: AQ_IQ2 | P4: AQ_IQ3 | Q4: Q3 | R4: Q8 | S4: AQ_EQ1 | T4: AQ_EQ2 | U4: AQ_EQ3 | V4: AQ_IQ1 | W4: Q6 | X4: Q7 | Y4: 问卷开始 | Z4: 问卷结束 | AA4: 问卷时长_s | AB4: 任务完成 | AC4: 问卷完成 | AD4: 区块有效 | AE4: 技术问题 | AF4: Candidate_Rate_Hz | AG4: VCD_Median | AH4: VCD_Admission_Rate | AI4: Output_Availability | AJ4: 遮挡时长_s | AK4: 遮挡生命周期状态 | AL4: 进入Lost | AM4: 服务器重获取次数 | AN4: StaticLock进入次数 | AO4: 备注
A5: P001 | B5: 1 | C5: O6-S1-EA | D5: 1 | E5: 游戏手柄 | F5: gamepad | G5: 方法A | H5: EgoAnchor | I5: 1 | J5: 1 | K5: 4 | L5: 5 | M5: 5 | O5: 5 | P5: 5 | Q5: 6 | R5: 6 | S5: 6 | T5: 5 | U5: 5 | V5: 5 | W5: 5 | X5: 5 | AA5: 129.9 | AB5: 是 | AC5: 是 | AD5: 是 | AE5: 无 | AF5: 9.62 | AG5: 0.874 | AH5: 0.919 | AI5: 0.938 | AJ5: 0.759 | AK5: FrozenUncertain | AL5: 否 | AM5: 0 | AN5: 3
A6: P001 | B6: 2 | C6: O6-S1-EA | D6: 1 | E6: 游戏手柄 | F6: gamepad | G6: 方法B | H6: One-Euro | I6: 2 | J6: 1 | K6: 4 | L6: 5 | M6: 5 | O6: 7 | P6: 5 | Q6: 5 | R6: 6 | S6: 5 | T6: 5 | U6: 7 | V6: 6 | W6: 6 | X6: 3 | AA6: 127.2 | AB6: 是 | AC6: 是 | AD6: 是 | AE6: 无 | AF6: 9.49 | AG6: 0.926 | AH6: 0.887 | AI6: 0.933 | AJ6: 0.769 | AK6: FrozenUncertain | AL6: 否 | AM6: 0 | AN6: 0
A7: P001 | B7: 3 | C7: O6-S1-EA | D7: 2 | E7: 固定订书机 | F7: stapler | G7: 方法B | H7: One-Euro | I7: 1 | J7: 2 | K7: 5 | L7: 6 | M7: 5 | O7: 7 | P7: 6 | Q7: 6 | R7: 7 | S7: 7 | T7: 6 | U7: 7 | V7: 6 | W7: 5 | X7: 5 | AA7: 119.4 | AB7: 是 | AC7: 是 | AD7: 是 | AE7: 无 | AF7: 10.08 | AG7: 0.896 | AH7: 0.915 | AI7: 0.968 | AJ7: 0.759 | AK7: FrozenUncertain | AL7: 否 | AM7: 0 | AN7: 0
A8: P001 | B8: 4 | C8: O6-S1-EA | D8: 2 | E8: 固定订书机 | F8: stapler | G8: 方法A | H8: EgoAnchor | I8: 2 | J8: 2 | K8: 7 | L8: 6 | M8: 6 | O8: 6 | P8: 6 | Q8: 6 | R8: 7 | S8: 6 | T8: 7 | U8: 7 | V8: 7 | W8: 7 | X8: 5 | AA8: 144.4 | AB8: 是 | AC8: 是 | AD8: 是 | AE8: 无 | AF8: 9.93 | AG8: 0.931 | AH8: 0.891 | AI8: 0.936 | AJ8: 0.735 | AK8: FrozenUncertain | AL8: 否 | AM8: 0 | AN8: 4
A9: P001 | B9: 5 | C9: O6-S1-EA | D9: 3 | E9: 鼠标 | F9: blue_mouse | G9: 方法A | H9: EgoAnchor | I9: 1 | J9: 3 | K9: 4 | L9: 4 | M9: 5 | O9: 5 | P9: 5 | Q9: 4 | R9: 5 | S9: 5 | T9: 4 | U9: 6 | V9: 5 | W9: 5 | X9: 4 | AA9: 144.5 | AB9: 是 | AC9: 是 | AD9: 是 | AE9: 无 | AF9: 9.44 | AG9: 0.863 | AH9: 0.9 | AI9: 0.945 | AJ9: 0.72 | AK9: FrozenUncertain | AL9: 否 | AM9: 0 | AN9: 3
A10: P001 | B10: 6 | C10: O6-S1-EA | D10: 3 | E10: 鼠标 | F10: blue_mouse | G10: 方法B | H10: One-Euro | I10: 2 | J10: 3 | K10: 3 | L10: 5 | M10: 5 | O10: 7 | P10: 3 | Q10: 4 | R10: 6 | S10: 5 | T10: 5 | U10: 6 | V10: 5 | W10: 4 | X10: 4 | AA10: 156.3 | AB10: 是 | AC10: 是 | AD10: 是 | AE10: 无 | AF10: 9.58 | AG10: 0.855 | AH10: 0.867 | AI10: 0.965 | AJ10: 0.736 | AK10: FrozenUncertain | AL10: 否 | AM10: 0 | AN10: 0
A11: P002 | B11: 1 | C11: O4-S2-EA | D11: 1 | E11: 固定订书机 | F11: stapler | G11: 方法B | H11: One-Euro | I11: 1 | J11: 1 | K11: 5 | L11: 5 | M11: 4 | O11: 5 | P11: 4 | Q11: 4 | R11: 4 | S11: 4 | T11: 4 | U11: 6 | V11: 6 | W11: 5 | X11: 4 | AA11: 123.6 | AB11: 是 | AC11: 是 | AD11: 是 | AE11: 无 | AF11: 9.68 | AG11: 0.895 | AH11: 0.993 | AI11: 0.931 | AJ11: 0.717 | AK11: FrozenUncertain | AL11: 否 | AM11: 0 | AN11: 0
A12: P002 | B12: 2 | C12: O4-S2-EA | D12: 1 | E12: 固定订书机 | F12: stapler | G12: 方法A | H12: EgoAnchor | I12: 2 | J12: 1 | K12: 6 | L12: 5 | M12: 5 | O12: 5 | P12: 5 | Q12: 4 | R12: 5 | S12: 4 | T12: 6 | U12: 6 | V12: 6 | W12: 4 | X12: 4 | AA12: 157.2 | AB12: 是 | AC12: 是 | AD12: 是 | AE12: 无 | AF12: 9.68 | AG12: 0.908 | AH12: 0.968 | AI12: 0.919 | AJ12: 0.73 | AK12: FrozenUncertain | AL12: 否 | AM12: 0 | AN12: 6
A13: P002 | B13: 3 | C13: O4-S2-EA | D13: 2 | E13: 游戏手柄 | F13: gamepad | G13: 方法A | H13: EgoAnchor | I13: 1 | J13: 2 | K13: 5 | L13: 4 | M13: 4 | O13: 4 | P13: 5 | Q13: 4 | R13: 4 | S13: 2 | T13: 3 | U13: 5 | V13: 5 | W13: 3 | X13: 3 | AA13: 147.8 | AB13: 是 | AC13: 是 | AD13: 是 | AE13: 无 | AF13: 9.57 | AG13: 0.865 | AH13: 0.95 | AI13: 0.949 | AJ13: 0.764 | AK13: FrozenUncertain | AL13: 否 | AM13: 0 | AN13: 3
A14: P002 | B14: 4 | C14: O4-S2-EA | D14: 2 | E14: 游戏手柄 | F14: gamepad | G14: 方法B | H14: One-Euro | I14: 2 | J14: 2 | K14: 5 | L14: 5 | M14: 4 | O14: 4 | P14: 4 | Q14: 4 | R14: 3 | S14: 3 | T14: 4 | U14: 6 | V14: 6 | W14: 4 | X14: 4 | AA14: 134.7 | AB14: 是 | AC14: 是 | AD14: 是 | AE14: 无 | AF14: 9.43 | AG14: 0.861 | AH14: 0.898 | AI14: 0.952 | AJ14: 0.803 | AK14: FrozenUncertain | AL14: 否 | AM14: 0 | AN14: 0
A15: P002 | B15: 5 | C15: O4-S2-EA | D15: 3 | E15: 鼠标 | F15: blue_mouse | G15: 方法B | H15: One-Euro | I15: 1 | J15: 3 | K15: 5 | L15: 4 | M15: 5 | O15: 5 | P15: 5 | Q15: 4 | R15: 4 | S15: 5 | T15: 5 | U15: 6 | V15: 6 | W15: 3 | X15: 5 | AA15: 157.6 | AB15: 是 | AC15: 是 | AD15: 是 | AE15: 无 | AF15: 9.35 | AG15: 0.846 | AH15: 0.905 | AI15: 0.939 | AJ15: 0.722 | AK15: FrozenUncertain | AL15: 否 | AM15: 0 | AN15: 0
A16: P002 | B16: 6 | C16: O4-S2-EA | D16: 3 | E16: 鼠标 | F16: blue_mouse | G16: 方法A | H16: EgoAnchor | I16: 2 | J16: 3 | K16: 5 | L16: 4 | M16: 3 | O16: 4 | P16: 3 | Q16: 4 | R16: 3 | S16: 3 | T16: 3 | U16: 5 | V16: 4 | W16: 3 | X16: 4 | AA16: 134.7 | AB16: 是 | AC16: 是 | AD16: 是 | AE16: 无 | AF16: 9.64 | AG16: 0.858 | AH16: 0.886 | AI16: 0.948 | AJ16: 0.797 | AK16: FrozenUncertain | AL16: 否 | AM16: 0 | AN16: 3
... A148: P024 | B148: 6 | C148: O2-S2-EA | D148: 3 | E148: 固定订书机 | F148: stapler | G148: 方法A | H148: EgoAnchor | I148: 2 | J148: 3 | K148: 6 | L148: 6 | M148: 6 | O148: 7 | P148: 5 | Q148: 6 | R148: 7 | S148: 6 | T148: 4 | U148: 6 | V148: 4 | W148: 7 | X148: 6 | AA148: 136.1 | AB148: 是 | AC148: 是 | AD148: 是 | AE148: 无 | AF148: 9.84 | AG148: 0.906 | AH148: 0.925 | AI148: 0.931 | AJ148: 0.752 | AK148: FrozenUncertain | AL148: 否 | AM148: 0 | AN148: 3
A150: B. 方法级记录（全部六区块完成后；S1 先评方法 A、S2 先评方法 B；TiA→提示页→S-TIAS）
A151: Participant_ID | B151: Rating_Order | C151: Shown_Label | D151: Condition(保密) | E151: TIA_RC1 | F151: TIA_RC2 | G151: TIA_RC3_REV | H151: TIA_RC4 | I151: TIA_RC5_REV | J151: TIA_RC6 | K151: TIA_UP1 | L151: TIA_UP2_REV | M151: TIA_UP3 | N151: TIA_UP4_REV | O151: STIAS1 | P151: STIAS2 | Q151: STIAS3 | R151: 尺度切换确认 | S151: 问卷开始 | T151: 问卷结束 | U151: 时长_s | V151: 技术问题 | W151: 备注
A152: P001 | B152: 1 | C152: 方法A | D152: EgoAnchor | E152: 4 | F152: 4 | G152: 1 | H152: 4 | I152: 3 | J152: 4 | K152: 3 | L152: 2 | M152: 3 | N152: 2 | O152: 5 | P152: 6 | Q152: 6 | R152: 是 | U152: 150.5 | V152: 无
A153: P001 | B153: 2 | C153: 方法B | D153: One-Euro | E153: 5 | F153: 4 | G153: 2 | H153: 5 | I153: 2 | J153: 4 | K153: 3 | L153: 3 | M153: 5 | N153: 2 | O153: 6 | P153: 6 | Q153: 5 | R153: 是 | U153: 120.2 | V153: 无
A154: P002 | B154: 1 | C154: 方法B | D154: One-Euro | E154: 3 | F154: 2 | G154: 3 | H154: 2 | I154: 4 | J154: 2 | K154: 3 | L154: 4 | M154: 4 | N154: 3 | O154: 3 | P154: 3 | Q154: 4 | R154: 是 | U154: 170.5 | V154: 无
A155: P002 | B155: 2 | C155: 方法A | D155: EgoAnchor | E155: 3 | F155: 3 | G155: 3 | I155: 3 | J155: 3 | K155: 4 | L155: 3 | M155: 3 | N155: 4 | O155: 4 | P155: 4 | Q155: 4 | R155: 是 | U155: 145.9 | V155: 无
A156: P003 | B156: 1 | C156: 方法B | D156: EgoAnchor | E156: 5 | F156: 5 | G156: 3 | H156: 5 | I156: 1 | J156: 5 | K156: 5 | L156: 1 | M156: 4 | N156: 1 | O156: 7 | P156: 5 | Q156: 7 | R156: 是 | U156: 142.5 | V156: 无
A157: P003 | B157: 2 | C157: 方法A | D157: One-Euro | E157: 4 | F157: 3 | G157: 4 | H157: 2 | I157: 3 | J157: 3 | K157: 4 | L157: 2 | M157: 3 | N157: 3 | O157: 5 | P157: 3 | Q157: 4 | R157: 是 | U157: 122.7 | V157: 无
A158: P004 | B158: 1 | C158: 方法A | D158: One-Euro | E158: 4 | F158: 3 | G158: 2 | H158: 4 | I158: 3 | J158: 3 | K158: 4 | L158: 3 | M158: 3 | N158: 2 | O158: 5 | P158: 6 | Q158: 5 | R158: 是 | U158: 145 | V158: 无
A159: P004 | B159: 2 | C159: 方法B | D159: EgoAnchor | E159: 3 | F159: 3 | G159: 3 | H159: 2 | I159: 5 | J159: 3 | K159: 3 | L159: 3 | M159: 1 | N159: 3 | O159: 5 | P159: 4 | Q159: 4 | R159: 是 | U159: 146.7 | V159: 无
A160: P005 | B160: 1 | C160: 方法B | D160: One-Euro | E160: 2 | F160: 1 | G160: 4 | H160: 1 | I160: 3 | J160: 3 | K160: 1 | L160: 5 | M160: 1 | N160: 4 | O160: 1 | P160: 1 | Q160: 3 | R160: 是 | U160: 145.4 | V160: 无
A161: P005 | B161: 2 | C161: 方法A | D161: EgoAnchor | E161: 3 | F161: 2 | G161: 2 | H161: 2 | I161: 3 | J161: 3 | K161: 1 | L161: 3 | M161: 2 | N161: 3 | O161: 4 | P161: 3 | Q161: 3 | R161: 是 | U161: 130.6 | V161: 无
A162: P006 | B162: 1 | C162: 方法B | D162: EgoAnchor | E162: 3 | F162: 3 | G162: 3 | H162: 3 | I162: 2 | J162: 3 | K162: 2 | L162: 4 | M162: 2 | N162: 2 | O162: 4 | P162: 4 | Q162: 4 | R162: 是 | U162: 191 | V162: 无
A163: P006 | B163: 2 | C163: 方法A | D163: One-Euro | E163: 3 | F163: 3 | G163: 2 | H163: 3 | I163: 3 | J163: 3 | K163: 3 | L163: 3 | M163: 4 | N163: 3 | O163: 4 | P163: 4 | Q163: 3 | R163: 是 | U163: 176.6 | V163: 无
A164: P007 | B164: 1 | C164: 方法B | D164: EgoAnchor | E164: 5 | F164: 5 | G164: 1 | H164: 5 | I164: 1 | J164: 5 | K164: 5 | L164: 2 | M164: 5 | N164: 1 | O164: 7 | P164: 7 | Q164: 7 | R164: 是 | U164: 128 | V164: 无
A165: P007 | B165: 2 | C165: 方法A | D165: One-Euro | E165: 5 | F165: 5 | G165: 2 | H165: 5 | I165: 2 | J165: 5 | K165: 5 | L165: 1 | M165: 5 | N165: 2 | O165: 6 | P165: 7 | Q165: 7 | R165: 是 | U165: 119.3 | V165: 无
A166: P008 | B166: 1 | C166: 方法A | D166: EgoAnchor | E166: 3 | F166: 4 | G166: 3 | H166: 4 | I166: 3 | J166: 5 | K166: 5 | L166: 1 | M166: 5 | N166: 2 | O166: 5 | P166: 6 | Q166: 6 | R166: 是 | U166: 139.3 | V166: 无
A167: P008 | B167: 2 | C167: 方法B | D167: One-Euro | E167: 4 | F167: 3 | G167: 3 | H167: 3 | I167: 2 | J167: 4 | K167: 4 | L167: 2 | M167: 4 | N167: 3 | O167: 5 | P167: 6 | Q167: 6 | R167: 是 | U167: 160 | V167: 无
A168: P009 | B168: 1 | C168: 方法B | D168: EgoAnchor | F168: 4 | G168: 2 | H168: 3 | I168: 3 | J168: 3 | K168: 3 | L168: 2 | M168: 4 | N168: 3 | O168: 5 | P168: 4 | Q168: 4 | R168: 是 | U168: 176.6 | V168: 无
A169: P009 | B169: 2 | C169: 方法A | D169: One-Euro | E169: 3 | F169: 3 | G169: 2 | H169: 3 | I169: 4 | J169: 3 | K169: 2 | L169: 3 | M169: 3 | N169: 3 | O169: 4 | P169: 4 | Q169: 4 | R169: 是 | U169: 143.7 | V169: 无
A170: P010 | B170: 1 | C170: 方法B | D170: One-Euro | E170: 3 | F170: 4 | G170: 3 | H170: 4 | I170: 3 | J170: 3 | K170: 3 | L170: 4 | M170: 3 | N170: 2 | O170: 4 | P170: 5 | Q170: 4 | R170: 是 | U170: 210.2 | V170: 无
A171: P010 | B171: 2 | C171: 方法A | D171: EgoAnchor | E171: 3 | F171: 3 | G171: 3 | H171: 3 | I171: 3 | J171: 4 | K171: 2 | L171: 4 | M171: 3 | N171: 2 | O171: 4 | P171: 3 | Q171: 4 | R171: 是 | U171: 170.4 | V171: 无
A172: P011 | B172: 1 | C172: 方法A | D172: One-Euro | E172: 2 | F172: 2 | G172: 3 | H172: 3 | I172: 5 | J172: 1 | K172: 2 | L172: 3 | M172: 2 | N172: 3 | O172: 3 | P172: 3 | Q172: 1 | R172: 是 | U172: 117.2 | V172: 无
A173: P011 | B173: 2 | C173: 方法B | D173: EgoAnchor | E173: 4 | F173: 3 | G173: 3 | H173: 4 | I173: 3 | J173: 4 | K173: 4 | L173: 3 | M173: 4 | N173: 2 | O173: 5 | P173: 5 | Q173: 6 | R173: 是 | U173: 153.9 | V173: 无
...

Sheet Derived
A1: 派生量（全部为公式；绿底单元格 = 实时计算）：区块 AQ 子量表 → 方法级反向计分与分量表 → 每人每方法三物体均值 → 每人配对差
A3: D1. 区块级派生（144 行，与 Records A 段逐行对应）：AQ 两子量表按原计分取 3 项均值；另实时判定 §8 的两条门禁
A4: Participant_ID | B4: Block_Index | C4: Condition | D4: Object_Key | E4: AQ_EQ(3 项均值) | F4: AQ_IQ(3 项均值) | G4: 问卷时长_s | H4: 时长>150s | I4: >=5 连续同分
A5: =Records!A5 -> P001 | B5: =Records!B5 -> 1 | C5: =Records!H5 -> EgoAnchor | D5: =Records!F5 -> gamepad | E5: =AVERAGE(Records!S5:U5) -> 5.3333333 | F5: =AVERAGE(Records!O5:P5,Records!V5) -> 5 | G5: =Records!AA5 -> 129.9 | H5: =IF(Records!AA5>150,"是","否") -> 否 | I5: =IF(OR(AND(Records!K5=Records!L5,Records!L5=Records!M5,Records!M5=Records!O5,Records!O5=Records!P5),AND(Records!L5=Records!M5,Records!M5=Records!O5,Records!O5=Records!P5,Records!P5=Records!Q5),AND(Records!M5=Records!O5,Records!O5=Records!P5,Records!P5=Records!Q5,Records!Q5=Records!R5),AND(Records!O5=Records!P5,Records!P5=Records!Q5,Records!Q5=Records!R5,Records!R5=Records!S5),AND(Records!P5=Records!Q5,Records!Q5=Records!R5,Records!R5=Records!S5,Records!S5=Records!T5),AND(Records!Q5=Records!R5,Records!R5=Records!S5,Records!S5=Records!T5,Records!T5=Records!U5),AND(Records!R5=Records!S5,Records!S5=Records!T5,Records!T5=Records!U5,Records!U5=Records!V5),AND(Records!S5=Records!T5,Records!T5=Records!U5,Records!U5=Records!V5,Records!V5=Records!W5),AND(Records!T5=Records!U5,Records!U5=Records!V5,Records!V5=Records!W5,Records!W5=Records!X5)),"是","否") -> 是
A6: =Records!A6 -> P001 | B6: =Records!B6 -> 2 | C6: =Records!H6 -> One-Euro | D6: =Records!F6 -> gamepad | E6: =AVERAGE(Records!S6:U6) -> 5.6666667 | F6: =AVERAGE(Records!O6:P6,Records!V6) -> 6 | G6: =Records!AA6 -> 127.2 | H6: =IF(Records!AA6>150,"是","否") -> 否 | I6: =IF(OR(AND(Records!K6=Records!L6,Records!L6=Records!M6,Records!M6=Records!O6,Records!O6=Records!P6),AND(Records!L6=Records!M6,Records!M6=Records!O6,Records!O6=Records!P6,Records!P6=Records!Q6),AND(Records!M6=Records!O6,Records!O6=Records!P6,Records!P6=Records!Q6,Records!Q6=Records!R6),AND(Records!O6=Records!P6,Records!P6=Records!Q6,Records!Q6=Records!R6,Records!R6=Records!S6),AND(Records!P6=Records!Q6,Records!Q6=Records!R6,Records!R6=Records!S6,Records!S6=Records!T6),AND(Records!Q6=Records!R6,Records!R6=Records!S6,Records!S6=Records!T6,Records!T6=Records!U6),AND(Records!R6=Records!S6,Records!S6=Records!T6,Records!T6=Records!U6,Records!U6=Records!V6),AND(Records!S6=Records!T6,Records!T6=Records!U6,Records!U6=Records!V6,Records!V6=Records!W6),AND(Records!T6=Records!U6,Records!U6=Records!V6,Records!V6=Records!W6,Records!W6=Records!X6)),"是","否") -> 否
A7: =Records!A7 -> P001 | B7: =Records!B7 -> 3 | C7: =Records!H7 -> One-Euro | D7: =Records!F7 -> stapler | E7: =AVERAGE(Records!S7:U7) -> 6.6666667 | F7: =AVERAGE(Records!O7:P7,Records!V7) -> 6.3333333 | G7: =Records!AA7 -> 119.4 | H7: =IF(Records!AA7>150,"是","否") -> 否 | I7: =IF(OR(AND(Records!K7=Records!L7,Records!L7=Records!M7,Records!M7=Records!O7,Records!O7=Records!P7),AND(Records!L7=Records!M7,Records!M7=Records!O7,Records!O7=Records!P7,Records!P7=Records!Q7),AND(Records!M7=Records!O7,Records!O7=Records!P7,Records!P7=Records!Q7,Records!Q7=Records!R7),AND(Records!O7=Records!P7,Records!P7=Records!Q7,Records!Q7=Records!R7,Records!R7=Records!S7),AND(Records!P7=Records!Q7,Records!Q7=Records!R7,Records!R7=Records!S7,Records!S7=Records!T7),AND(Records!Q7=Records!R7,Records!R7=Records!S7,Records!S7=Records!T7,Records!T7=Records!U7),AND(Records!R7=Records!S7,Records!S7=Records!T7,Records!T7=Records!U7,Records!U7=Records!V7),AND(Records!S7=Records!T7,Records!T7=Records!U7,Records!U7=Records!V7,Records!V7=Records!W7),AND(Records!T7=Records!U7,Records!U7=Records!V7,Records!V7=Records!W7,Records!W7=Records!X7)),"是","否") -> 否
A8: =Records!A8 -> P001 | B8: =Records!B8 -> 4 | C8: =Records!H8 -> EgoAnchor | D8: =Records!F8 -> stapler | E8: =AVERAGE(Records!S8:U8) -> 6.6666667 | F8: =AVERAGE(Records!O8:P8,Records!V8) -> 6.3333333 | G8: =Records!AA8 -> 144.4 | H8: =IF(Records!AA8>150,"是","否") -> 否 | I8: =IF(OR(AND(Records!K8=Records!L8,Records!L8=Records!M8,Records!M8=Records!O8,Records!O8=Records!P8),AND(Records!L8=Records!M8,Records!M8=Records!O8,Records!O8=Records!P8,Records!P8=Records!Q8),AND(Records!M8=Records!O8,Records!O8=Records!P8,Records!P8=Records!Q8,Records!Q8=Records!R8),AND(Records!O8=Records!P8,Records!P8=Records!Q8,Records!Q8=Records!R8,Records!R8=Records!S8),AND(Records!P8=Records!Q8,Records!Q8=Records!R8,Records!R8=Records!S8,Records!S8=Records!T8),AND(Records!Q8=Records!R8,Records!R8=Records!S8,Records!S8=Records!T8,Records!T8=Records!U8),AND(Records!R8=Records!S8,Records!S8=Records!T8,Records!T8=Records!U8,Records!U8=Records!V8),AND(Records!S8=Records!T8,Records!T8=Records!U8,Records!U8=Records!V8,Records!V8=Records!W8),AND(Records!T8=Records!U8,Records!U8=Records!V8,Records!V8=Records!W8,Records!W8=Records!X8)),"是","否") -> 是
A9: =Records!A9 -> P001 | B9: =Records!B9 -> 5 | C9: =Records!H9 -> EgoAnchor | D9: =Records!F9 -> blue_mouse | E9: =AVERAGE(Records!S9:U9) -> 5 | F9: =AVERAGE(Records!O9:P9,Records!V9) -> 5 | G9: =Records!AA9 -> 144.5 | H9: =IF(Records!AA9>150,"是","否") -> 否 | I9: =IF(OR(AND(Records!K9=Records!L9,Records!L9=Records!M9,Records!M9=Records!O9,Records!O9=Records!P9),AND(Records!L9=Records!M9,Records!M9=Records!O9,Records!O9=Records!P9,Records!P9=Records!Q9),AND(Records!M9=Records!O9,Records!O9=Records!P9,Records!P9=Records!Q9,Records!Q9=Records!R9),AND(Records!O9=Records!P9,Records!P9=Records!Q9,Records!Q9=Records!R9,Records!R9=Records!S9),AND(Records!P9=Records!Q9,Records!Q9=Records!R9,Records!R9=Records!S9,Records!S9=Records!T9),AND(Records!Q9=Records!R9,Records!R9=Records!S9,Records!S9=Records!T9,Records!T9=Records!U9),AND(Records!R9=Records!S9,Records!S9=Records!T9,Records!T9=Records!U9,Records!U9=Records!V9),AND(Records!S9=Records!T9,Records!T9=Records!U9,Records!U9=Records!V9,Records!V9=Records!W9),AND(Records!T9=Records!U9,Records!U9=Records!V9,Records!V9=Records!W9,Records!W9=Records!X9)),"是","否") -> 否
A10: =Records!A10 -> P001 | B10: =Records!B10 -> 6 | C10: =Records!H10 -> One-Euro | D10: =Records!F10 -> blue_mouse | E10: =AVERAGE(Records!S10:U10) -> 5.3333333 | F10: =AVERAGE(Records!O10:P10,Records!V10) -> 5 | G10: =Records!AA10 -> 156.3 | H10: =IF(Records!AA10>150,"是","否") -> 是 | I10: =IF(OR(AND(Records!K10=Records!L10,Records!L10=Records!M10,Records!M10=Records!O10,Records!O10=Records!P10),AND(Records!L10=Records!M10,Records!M10=Records!O10,Records!O10=Records!P10,Records!P10=Records!Q10),AND(Records!M10=Records!O10,Records!O10=Records!P10,Records!P10=Records!Q10,Records!Q10=Records!R10),AND(Records!O10=Records!P10,Records!P10=Records!Q10,Records!Q10=Records!R10,Records!R10=Records!S10),AND(Records!P10=Records!Q10,Records!Q10=Records!R10,Records!R10=Records!S10,Records!S10=Records!T10),AND(Records!Q10=Records!R10,Records!R10=Records!S10,Records!S10=Records!T10,Records!T10=Records!U10),AND(Records!R10=Records!S10,Records!S10=Records!T10,Records!T10=Records!U10,Records!U10=Records!V10),AND(Records!S10=Records!T10,Records!T10=Records!U10,Records!U10=Records!V10,Records!V10=Records!W10),AND(Records!T10=Records!U10,Records!U10=Records!V10,Records!V10=Records!W10,Records!W10=Records!X10)),"是","否") -> 否
A11: =Records!A11 -> P002 | B11: =Records!B11 -> 1 | C11: =Records!H11 -> One-Euro | D11: =Records!F11 -> stapler | E11: =AVERAGE(Records!S11:U11) -> 4.6666667 | F11: =AVERAGE(Records!O11:P11,Records!V11) -> 5 | G11: =Records!AA11 -> 123.6 | H11: =IF(Records!AA11>150,"是","否") -> 否 | I11: =IF(OR(AND(Records!K11=Records!L11,Records!L11=Records!M11,Records!M11=Records!O11,Records!O11=Records!P11),AND(Records!L11=Records!M11,Records!M11=Records!O11,Records!O11=Records!P11,Records!P11=Records!Q11),AND(Records!M11=Records!O11,Records!O11=Records!P11,Records!P11=Records!Q11,Records!Q11=Records!R11),AND(Records!O11=Records!P11,Records!P11=Records!Q11,Records!Q11=Records!R11,Records!R11=Records!S11),AND(Records!P11=Records!Q11,Records!Q11=Records!R11,Records!R11=Records!S11,Records!S11=Records!T11),AND(Records!Q11=Records!R11,Records!R11=Records!S11,Records!S11=Records!T11,Records!T11=Records!U11),AND(Records!R11=Records!S11,Records!S11=Records!T11,Records!T11=Records!U11,Records!U11=Records!V11),AND(Records!S11=Records!T11,Records!T11=Records!U11,Records!U11=Records!V11,Records!V11=Records!W11),AND(Records!T11=Records!U11,Records!U11=Records!V11,Records!V11=Records!W11,Records!W11=Records!X11)),"是","否") -> 是
A12: =Records!A12 -> P002 | B12: =Records!B12 -> 2 | C12: =Records!H12 -> EgoAnchor | D12: =Records!F12 -> stapler | E12: =AVERAGE(Records!S12:U12) -> 5.3333333 | F12: =AVERAGE(Records!O12:P12,Records!V12) -> 5.3333333 | G12: =Records!AA12 -> 157.2 | H12: =IF(Records!AA12>150,"是","否") -> 是 | I12: =IF(OR(AND(Records!K12=Records!L12,Records!L12=Records!M12,Records!M12=Records!O12,Records!O12=Records!P12),AND(Records!L12=Records!M12,Records!M12=Records!O12,Records!O12=Records!P12,Records!P12=Records!Q12),AND(Records!M12=Records!O12,Records!O12=Records!P12,Records!P12=Records!Q12,Records!Q12=Records!R12),AND(Records!O12=Records!P12,Records!P12=Records!Q12,Records!Q12=Records!R12,Records!R12=Records!S12),AND(Records!P12=Records!Q12,Records!Q12=Records!R12,Records!R12=Records!S12,Records!S12=Records!T12),AND(Records!Q12=Records!R12,Records!R12=Records!S12,Records!S12=Records!T12,Records!T12=Records!U12),AND(Records!R12=Records!S12,Records!S12=Records!T12,Records!T12=Records!U12,Records!U12=Records!V12),AND(Records!S12=Records!T12,Records!T12=Records!U12,Records!U12=Records!V12,Records!V12=Records!W12),AND(Records!T12=Records!U12,Records!U12=Records!V12,Records!V12=Records!W12,Records!W12=Records!X12)),"是","否") -> 否
A13: =Records!A13 -> P002 | B13: =Records!B13 -> 3 | C13: =Records!H13 -> EgoAnchor | D13: =Records!F13 -> gamepad | E13: =AVERAGE(Records!S13:U13) -> 3.3333333 | F13: =AVERAGE(Records!O13:P13,Records!V13) -> 4.6666667 | G13: =Records!AA13 -> 147.8 | H13: =IF(Records!AA13>150,"是","否") -> 否 | I13: =IF(OR(AND(Records!K13=Records!L13,Records!L13=Records!M13,Records!M13=Records!O13,Records!O13=Records!P13),AND(Records!L13=Records!M13,Records!M13=Records!O13,Records!O13=Records!P13,Records!P13=Records!Q13),AND(Records!M13=Records!O13,Records!O13=Records!P13,Records!P13=Records!Q13,Records!Q13=Records!R13),AND(Records!O13=Records!P13,Records!P13=Records!Q13,Records!Q13=Records!R13,Records!R13=Records!S13),AND(Records!P13=Records!Q13,Records!Q13=Records!R13,Records!R13=Records!S13,Records!S13=Records!T13),AND(Records!Q13=Records!R13,Records!R13=Records!S13,Records!S13=Records!T13,Records!T13=Records!U13),AND(Records!R13=Records!S13,Records!S13=Records!T13,Records!T13=Records!U13,Records!U13=Records!V13),AND(Records!S13=Records!T13,Records!T13=Records!U13,Records!U13=Records!V13,Records!V13=Records!W13),AND(Records!T13=Records!U13,Records!U13=Records!V13,Records!V13=Records!W13,Records!W13=Records!X13)),"是","否") -> 否
A14: =Records!A14 -> P002 | B14: =Records!B14 -> 4 | C14: =Records!H14 -> One-Euro | D14: =Records!F14 -> gamepad | E14: =AVERAGE(Records!S14:U14) -> 4.3333333 | F14: =AVERAGE(Records!O14:P14,Records!V14) -> 4.6666667 | G14: =Records!AA14 -> 134.7 | H14: =IF(Records!AA14>150,"是","否") -> 否 | I14: =IF(OR(AND(Records!K14=Records!L14,Records!L14=Records!M14,Records!M14=Records!O14,Records!O14=Records!P14),AND(Records!L14=Records!M14,Records!M14=Records!O14,Records!O14=Records!P14,Records!P14=Records!Q14),AND(Records!M14=Records!O14,Records!O14=Records!P14,Records!P14=Records!Q14,Records!Q14=Records!R14),AND(Records!O14=Records!P14,Records!P14=Records!Q14,Records!Q14=Records!R14,Records!R14=Records!S14),AND(Records!P14=Records!Q14,Records!Q14=Records!R14,Records!R14=Records!S14,Records!S14=Records!T14),AND(Records!Q14=Records!R14,Records!R14=Records!S14,Records!S14=Records!T14,Records!T14=Records!U14),AND(Records!R14=Records!S14,Records!S14=Records!T14,Records!T14=Records!U14,Records!U14=Records!V14),AND(Records!S14=Records!T14,Records!T14=Records!U14,Records!U14=Records!V14,Records!V14=Records!W14),AND(Records!T14=Records!U14,Records!U14=Records!V14,Records!V14=Records!W14,Records!W14=Records!X14)),"是","否") -> 否
A15: =Records!A15 -> P002 | B15: =Records!B15 -> 5 | C15: =Records!H15 -> One-Euro | D15: =Records!F15 -> blue_mouse | E15: =AVERAGE(Records!S15:U15) -> 5.3333333 | F15: =AVERAGE(Records!O15:P15,Records!V15) -> 5.3333333 | G15: =Records!AA15 -> 157.6 | H15: =IF(Records!AA15>150,"是","否") -> 是 | I15: =IF(OR(AND(Records!K15=Records!L15,Records!L15=Records!M15,Records!M15=Records!O15,Records!O15=Records!P15),AND(Records!L15=Records!M15,Records!M15=Records!O15,Records!O15=Records!P15,Records!P15=Records!Q15),AND(Records!M15=Records!O15,Records!O15=Records!P15,Records!P15=Records!Q15,Records!Q15=Records!R15),AND(Records!O15=Records!P15,Records!P15=Records!Q15,Records!Q15=Records!R15,Records!R15=Records!S15),AND(Records!P15=Records!Q15,Records!Q15=Records!R15,Records!R15=Records!S15,Records!S15=Records!T15),AND(Records!Q15=Records!R15,Records!R15=Records!S15,Records!S15=Records!T15,Records!T15=Records!U15),AND(Records!R15=Records!S15,Records!S15=Records!T15,Records!T15=Records!U15,Records!U15=Records!V15),AND(Records!S15=Records!T15,Records!T15=Records!U15,Records!U15=Records!V15,Records!V15=Records!W15),AND(Records!T15=Records!U15,Records!U15=Records!V15,Records!V15=Records!W15,Records!W15=Records!X15)),"是","否") -> 否
A16: =Records!A16 -> P002 | B16: =Records!B16 -> 6 | C16: =Records!H16 -> EgoAnchor | D16: =Records!F16 -> blue_mouse | E16: =AVERAGE(Records!S16:U16) -> 3.6666667 | F16: =AVERAGE(Records!O16:P16,Records!V16) -> 3.6666667 | G16: =Records!AA16 -> 134.7 | H16: =IF(Records!AA16>150,"是","否") -> 否 | I16: =IF(OR(AND(Records!K16=Records!L16,Records!L16=Records!M16,Records!M16=Records!O16,Records!O16=Records!P16),AND(Records!L16=Records!M16,Records!M16=Records!O16,Records!O16=Records!P16,Records!P16=Records!Q16),AND(Records!M16=Records!O16,Records!O16=Records!P16,Records!P16=Records!Q16,Records!Q16=Records!R16),AND(Records!O16=Records!P16,Records!P16=Records!Q16,Records!Q16=Records!R16,Records!R16=Records!S16),AND(Records!P16=Records!Q16,Records!Q16=Records!R16,Records!R16=Records!S16,Records!S16=Records!T16),AND(Records!Q16=Records!R16,Records!R16=Records!S16,Records!S16=Records!T16,Records!T16=Records!U16),AND(Records!R16=Records!S16,Records!S16=Records!T16,Records!T16=Records!U16,Records!U16=Records!V16),AND(Records!S16=Records!T16,Records!T16=Records!U16,Records!U16=Records!V16,Records!V16=Records!W16),AND(Records!T16=Records!U16,Records!U16=Records!V16,Records!V16=Records!W16,Records!W16=Records!X16)),"是","否") -> 否
... A148: =Records!A148 -> P024 | B148: =Records!B148 -> 6 | C148: =Records!H148 -> EgoAnchor | D148: =Records!F148 -> stapler | E148: =AVERAGE(Records!S148:U148) -> 5.3333333 | F148: =AVERAGE(Records!O148:P148,Records!V148) -> 5.3333333 | G148: =Records!AA148 -> 136.1 | H148: =IF(Records!AA148>150,"是","否") -> 否 | I148: =IF(OR(AND(Records!K148=Records!L148,Records!L148=Records!M148,Records!M148=Records!O148,Records!O148=Records!P148),AND(Records!L148=Records!M148,Records!M148=Records!O148,Records!O148=Records!P148,Records!P148=Records!Q148),AND(Records!M148=Records!O148,Records!O148=Records!P148,Records!P148=Records!Q148,Records!Q148=Records!R148),AND(Records!O148=Records!P148,Records!P148=Records!Q148,Records!Q148=Records!R148,Records!R148=Records!S148),AND(Records!P148=Records!Q148,Records!Q148=Records!R148,Records!R148=Records!S148,Records!S148=Records!T148),AND(Records!Q148=Records!R148,Records!R148=Records!S148,Records!S148=Records!T148,Records!T148=Records!U148),AND(Records!R148=Records!S148,Records!S148=Records!T148,Records!T148=Records!U148,Records!U148=Records!V148),AND(Records!S148=Records!T148,Records!T148=Records!U148,Records!U148=Records!V148,Records!V148=Records!W148),AND(Records!T148=Records!U148,Records!U148=Records!V148,Records!V148=Records!W148,Records!W148=Records!X148)),"是","否") -> 否
A150: D2. 方法级派生（48 行）：TiA 四个反向项按 6−原始分换向（原始分保留在 Records B 段不被覆盖）；分量表 = 有效条目均值，缺失项自动跳过
A151: Participant_ID | B151: Rating_Order | C151: Condition | D151: RC1 | E151: RC2 | F151: RC3(换向) | G151: RC4 | H151: RC5(换向) | I151: RC6 | J151: UP1 | K151: UP2(换向) | L151: UP3 | M151: UP4(换向) | N151: STIAS1 | O151: STIAS2 | P151: STIAS3 | Q151: TiA-R/C(6 项均值) | R151: TiA-U/P(4 项均值) | S151: S-TIAS(3 项均值) | T151: 有效条目数
A152: =Records!A152 -> P001 | B152: =Records!B152 -> 1 | C152: =Records!D152 -> EgoAnchor | D152: =IF(Records!E152="","",Records!E152) -> 4 | E152: =IF(Records!F152="","",Records!F152) -> 4 | F152: =IF(Records!G152="","",6-Records!G152) -> 5 | G152: =IF(Records!H152="","",Records!H152) -> 4 | H152: =IF(Records!I152="","",6-Records!I152) -> 3 | I152: =IF(Records!J152="","",Records!J152) -> 4 | J152: =IF(Records!K152="","",Records!K152) -> 3 | K152: =IF(Records!L152="","",6-Records!L152) -> 4 | L152: =IF(Records!M152="","",Records!M152) -> 3 | M152: =IF(Records!N152="","",6-Records!N152) -> 4 | N152: =IF(Records!O152="","",Records!O152) -> 5 | O152: =IF(Records!P152="","",Records!P152) -> 6 | P152: =IF(Records!Q152="","",Records!Q152) -> 6 | Q152: =AVERAGE(D152:I152) -> 4 | R152: =AVERAGE(J152:M152) -> 3.5 | S152: =AVERAGE(N152:P152) -> 5.6666667 | T152: =COUNT(D152:I152,J152:M152,N152:P152) -> 13
A153: =Records!A153 -> P001 | B153: =Records!B153 -> 2 | C153: =Records!D153 -> One-Euro | D153: =IF(Records!E153="","",Records!E153) -> 5 | E153: =IF(Records!F153="","",Records!F153) -> 4 | F153: =IF(Records!G153="","",6-Records!G153) -> 4 | G153: =IF(Records!H153="","",Records!H153) -> 5 | H153: =IF(Records!I153="","",6-Records!I153) -> 4 | I153: =IF(Records!J153="","",Records!J153) -> 4 | J153: =IF(Records!K153="","",Records!K153) -> 3 | K153: =IF(Records!L153="","",6-Records!L153) -> 3 | L153: =IF(Records!M153="","",Records!M153) -> 5 | M153: =IF(Records!N153="","",6-Records!N153) -> 4 | N153: =IF(Records!O153="","",Records!O153) -> 6 | O153: =IF(Records!P153="","",Records!P153) -> 6 | P153: =IF(Records!Q153="","",Records!Q153) -> 5 | Q153: =AVERAGE(D153:I153) -> 4.3333333 | R153: =AVERAGE(J153:M153) -> 3.75 | S153: =AVERAGE(N153:P153) -> 5.6666667 | T153: =COUNT(D153:I153,J153:M153,N153:P153) -> 13
A154: =Records!A154 -> P002 | B154: =Records!B154 -> 1 | C154: =Records!D154 -> One-Euro | D154: =IF(Records!E154="","",Records!E154) -> 3 | E154: =IF(Records!F154="","",Records!F154) -> 2 | F154: =IF(Records!G154="","",6-Records!G154) -> 3 | G154: =IF(Records!H154="","",Records!H154) -> 2 | H154: =IF(Records!I154="","",6-Records!I154) -> 2 | I154: =IF(Records!J154="","",Records!J154) -> 2 | J154: =IF(Records!K154="","",Records!K154) -> 3 | K154: =IF(Records!L154="","",6-Records!L154) -> 2 | L154: =IF(Records!M154="","",Records!M154) -> 4 | M154: =IF(Records!N154="","",6-Records!N154) -> 3 | N154: =IF(Records!O154="","",Records!O154) -> 3 | O154: =IF(Records!P154="","",Records!P154) -> 3 | P154: =IF(Records!Q154="","",Records!Q154) -> 4 | Q154: =AVERAGE(D154:I154) -> 2.3333333 | R154: =AVERAGE(J154:M154) -> 3 | S154: =AVERAGE(N154:P154) -> 3.3333333 | T154: =COUNT(D154:I154,J154:M154,N154:P154) -> 13
A155: =Records!A155 -> P002 | B155: =Records!B155 -> 2 | C155: =Records!D155 -> EgoAnchor | D155: =IF(Records!E155="","",Records!E155) -> 3 | E155: =IF(Records!F155="","",Records!F155) -> 3 | F155: =IF(Records!G155="","",6-Records!G155) -> 3 | G155: =IF(Records!H155="","",Records!H155) | H155: =IF(Records!I155="","",6-Records!I155) -> 3 | I155: =IF(Records!J155="","",Records!J155) -> 3 | J155: =IF(Records!K155="","",Records!K155) -> 4 | K155: =IF(Records!L155="","",6-Records!L155) -> 3 | L155: =IF(Records!M155="","",Records!M155) -> 3 | M155: =IF(Records!N155="","",6-Records!N155) -> 2 | N155: =IF(Records!O155="","",Records!O155) -> 4 | O155: =IF(Records!P155="","",Records!P155) -> 4 | P155: =IF(Records!Q155="","",Records!Q155) -> 4 | Q155: =AVERAGE(D155:I155) -> 3 | R155: =AVERAGE(J155:M155) -> 3 | S155: =AVERAGE(N155:P155) -> 4 | T155: =COUNT(D155:I155,J155:M155,N155:P155) -> 12
A156: =Records!A156 -> P003 | B156: =Records!B156 -> 1 | C156: =Records!D156 -> EgoAnchor | D156: =IF(Records!E156="","",Records!E156) -> 5 | E156: =IF(Records!F156="","",Records!F156) -> 5 | F156: =IF(Records!G156="","",6-Records!G156) -> 3 | G156: =IF(Records!H156="","",Records!H156) -> 5 | H156: =IF(Records!I156="","",6-Records!I156) -> 5 | I156: =IF(Records!J156="","",Records!J156) -> 5 | J156: =IF(Records!K156="","",Records!K156) -> 5 | K156: =IF(Records!L156="","",6-Records!L156) -> 5 | L156: =IF(Records!M156="","",Records!M156) -> 4 | M156: =IF(Records!N156="","",6-Records!N156) -> 5 | N156: =IF(Records!O156="","",Records!O156) -> 7 | O156: =IF(Records!P156="","",Records!P156) -> 5 | P156: =IF(Records!Q156="","",Records!Q156) -> 7 | Q156: =AVERAGE(D156:I156) -> 4.6666667 | R156: =AVERAGE(J156:M156) -> 4.75 | S156: =AVERAGE(N156:P156) -> 6.3333333 | T156: =COUNT(D156:I156,J156:M156,N156:P156) -> 13
A157: =Records!A157 -> P003 | B157: =Records!B157 -> 2 | C157: =Records!D157 -> One-Euro | D157: =IF(Records!E157="","",Records!E157) -> 4 | E157: =IF(Records!F157="","",Records!F157) -> 3 | F157: =IF(Records!G157="","",6-Records!G157) -> 2 | G157: =IF(Records!H157="","",Records!H157) -> 2 | H157: =IF(Records!I157="","",6-Records!I157) -> 3 | I157: =IF(Records!J157="","",Records!J157) -> 3 | J157: =IF(Records!K157="","",Records!K157) -> 4 | K157: =IF(Records!L157="","",6-Records!L157) -> 4 | L157: =IF(Records!M157="","",Records!M157) -> 3 | M157: =IF(Records!N157="","",6-Records!N157) -> 3 | N157: =IF(Records!O157="","",Records!O157) -> 5 | O157: =IF(Records!P157="","",Records!P157) -> 3 | P157: =IF(Records!Q157="","",Records!Q157) -> 4 | Q157: =AVERAGE(D157:I157) -> 2.8333333 | R157: =AVERAGE(J157:M157) -> 3.5 | S157: =AVERAGE(N157:P157) -> 4 | T157: =COUNT(D157:I157,J157:M157,N157:P157) -> 13
A158: =Records!A158 -> P004 | B158: =Records!B158 -> 1 | C158: =Records!D158 -> One-Euro | D158: =IF(Records!E158="","",Records!E158) -> 4 | E158: =IF(Records!F158="","",Records!F158) -> 3 | F158: =IF(Records!G158="","",6-Records!G158) -> 4 | G158: =IF(Records!H158="","",Records!H158) -> 4 | H158: =IF(Records!I158="","",6-Records!I158) -> 3 | I158: =IF(Records!J158="","",Records!J158) -> 3 | J158: =IF(Records!K158="","",Records!K158) -> 4 | K158: =IF(Records!L158="","",6-Records!L158) -> 3 | L158: =IF(Records!M158="","",Records!M158) -> 3 | M158: =IF(Records!N158="","",6-Records!N158) -> 4 | N158: =IF(Records!O158="","",Records!O158) -> 5 | O158: =IF(Records!P158="","",Records!P158) -> 6 | P158: =IF(Records!Q158="","",Records!Q158) -> 5 | Q158: =AVERAGE(D158:I158) -> 3.5 | R158: =AVERAGE(J158:M158) -> 3.5 | S158: =AVERAGE(N158:P158) -> 5.3333333 | T158: =COUNT(D158:I158,J158:M158,N158:P158) -> 13
A159: =Records!A159 -> P004 | B159: =Records!B159 -> 2 | C159: =Records!D159 -> EgoAnchor | D159: =IF(Records!E159="","",Records!E159) -> 3 | E159: =IF(Records!F159="","",Records!F159) -> 3 | F159: =IF(Records!G159="","",6-Records!G159) -> 3 | G159: =IF(Records!H159="","",Records!H159) -> 2 | H159: =IF(Records!I159="","",6-Records!I159) -> 1 | I159: =IF(Records!J159="","",Records!J159) -> 3 | J159: =IF(Records!K159="","",Records!K159) -> 3 | K159: =IF(Records!L159="","",6-Records!L159) -> 3 | L159: =IF(Records!M159="","",Records!M159) -> 1 | M159: =IF(Records!N159="","",6-Records!N159) -> 3 | N159: =IF(Records!O159="","",Records!O159) -> 5 | O159: =IF(Records!P159="","",Records!P159) -> 4 | P159: =IF(Records!Q159="","",Records!Q159) -> 4 | Q159: =AVERAGE(D159:I159) -> 2.5 | R159: =AVERAGE(J159:M159) -> 2.5 | S159: =AVERAGE(N159:P159) -> 4.3333333 | T159: =COUNT(D159:I159,J159:M159,N159:P159) -> 13
A160: =Records!A160 -> P005 | B160: =Records!B160 -> 1 | C160: =Records!D160 -> One-Euro | D160: =IF(Records!E160="","",Records!E160) -> 2 | E160: =IF(Records!F160="","",Records!F160) -> 1 | F160: =IF(Records!G160="","",6-Records!G160) -> 2 | G160: =IF(Records!H160="","",Records!H160) -> 1 | H160: =IF(Records!I160="","",6-Records!I160) -> 3 | I160: =IF(Records!J160="","",Records!J160) -> 3 | J160: =IF(Records!K160="","",Records!K160) -> 1 | K160: =IF(Records!L160="","",6-Records!L160) -> 1 | L160: =IF(Records!M160="","",Records!M160) -> 1 | M160: =IF(Records!N160="","",6-Records!N160) -> 2 | N160: =IF(Records!O160="","",Records!O160) -> 1 | O160: =IF(Records!P160="","",Records!P160) -> 1 | P160: =IF(Records!Q160="","",Records!Q160) -> 3 | Q160: =AVERAGE(D160:I160) -> 2 | R160: =AVERAGE(J160:M160) -> 1.25 | S160: =AVERAGE(N160:P160) -> 1.6666667 | T160: =COUNT(D160:I160,J160:M160,N160:P160) -> 13
A161: =Records!A161 -> P005 | B161: =Records!B161 -> 2 | C161: =Records!D161 -> EgoAnchor | D161: =IF(Records!E161="","",Records!E161) -> 3 | E161: =IF(Records!F161="","",Records!F161) -> 2 | F161: =IF(Records!G161="","",6-Records!G161) -> 4 | G161: =IF(Records!H161="","",Records!H161) -> 2 | H161: =IF(Records!I161="","",6-Records!I161) -> 3 | I161: =IF(Records!J161="","",Records!J161) -> 3 | J161: =IF(Records!K161="","",Records!K161) -> 1 | K161: =IF(Records!L161="","",6-Records!L161) -> 3 | L161: =IF(Records!M161="","",Records!M161) -> 2 | M161: =IF(Records!N161="","",6-Records!N161) -> 3 | N161: =IF(Records!O161="","",Records!O161) -> 4 | O161: =IF(Records!P161="","",Records!P161) -> 3 | P161: =IF(Records!Q161="","",Records!Q161) -> 3 | Q161: =AVERAGE(D161:I161) -> 2.8333333 | R161: =AVERAGE(J161:M161) -> 2.25 | S161: =AVERAGE(N161:P161) -> 3.3333333 | T161: =COUNT(D161:I161,J161:M161,N161:P161) -> 13
A162: =Records!A162 -> P006 | B162: =Records!B162 -> 1 | C162: =Records!D162 -> EgoAnchor | D162: =IF(Records!E162="","",Records!E162) -> 3 | E162: =IF(Records!F162="","",Records!F162) -> 3 | F162: =IF(Records!G162="","",6-Records!G162) -> 3 | G162: =IF(Records!H162="","",Records!H162) -> 3 | H162: =IF(Records!I162="","",6-Records!I162) -> 4 | I162: =IF(Records!J162="","",Records!J162) -> 3 | J162: =IF(Records!K162="","",Records!K162) -> 2 | K162: =IF(Records!L162="","",6-Records!L162) -> 2 | L162: =IF(Records!M162="","",Records!M162) -> 2 | M162: =IF(Records!N162="","",6-Records!N162) -> 4 | N162: =IF(Records!O162="","",Records!O162) -> 4 | O162: =IF(Records!P162="","",Records!P162) -> 4 | P162: =IF(Records!Q162="","",Records!Q162) -> 4 | Q162: =AVERAGE(D162:I162) -> 3.1666667 | R162: =AVERAGE(J162:M162) -> 2.5 | S162: =AVERAGE(N162:P162) -> 4 | T162: =COUNT(D162:I162,J162:M162,N162:P162) -> 13
A163: =Records!A163 -> P006 | B163: =Records!B163 -> 2 | C163: =Records!D163 -> One-Euro | D163: =IF(Records!E163="","",Records!E163) -> 3 | E163: =IF(Records!F163="","",Records!F163) -> 3 | F163: =IF(Records!G163="","",6-Records!G163) -> 4 | G163: =IF(Records!H163="","",Records!H163) -> 3 | H163: =IF(Records!I163="","",6-Records!I163) -> 3 | I163: =IF(Records!J163="","",Records!J163) -> 3 | J163: =IF(Records!K163="","",Records!K163) -> 3 | K163: =IF(Records!L163="","",6-Records!L163) -> 3 | L163: =IF(Records!M163="","",Records!M163) -> 4 | M163: =IF(Records!N163="","",6-Records!N163) -> 3 | N163: =IF(Records!O163="","",Records!O163) -> 4 | O163: =IF(Records!P163="","",Records!P163) -> 4 | P163: =IF(Records!Q163="","",Records!Q163) -> 3 | Q163: =AVERAGE(D163:I163) -> 3.1666667 | R163: =AVERAGE(J163:M163) -> 3.25 | S163: =AVERAGE(N163:P163) -> 3.6666667 | T163: =COUNT(D163:I163,J163:M163,N163:P163) -> 13
... A199: =Records!A199 -> P024 | B199: =Records!B199 -> 2 | C199: =Records!D199 -> EgoAnchor | D199: =IF(Records!E199="","",Records!E199) -> 5 | E199: =IF(Records!F199="","",Records!F199) -> 5 | F199: =IF(Records!G199="","",6-Records!G199) -> 4 | G199: =IF(Records!H199="","",Records!H199) -> 5 | H199: =IF(Records!I199="","",6-Records!I199) -> 4 | I199: =IF(Records!J199="","",Records!J199) -> 5 | J199: =IF(Records!K199="","",Records!K199) -> 5 | K199: =IF(Records!L199="","",6-Records!L199) -> 5 | L199: =IF(Records!M199="","",Records!M199) -> 5 | M199: =IF(Records!N199="","",6-Records!N199) -> 5 | N199: =IF(Records!O199="","",Records!O199) -> 6 | O199: =IF(Records!P199="","",Records!P199) -> 7 | P199: =IF(Records!Q199="","",Records!Q199) -> 7 | Q199: =AVERAGE(D199:I199) -> 4.6666667 | R199: =AVERAGE(J199:M199) -> 5 | S199: =AVERAGE(N199:P199) -> 6.6666667 | T199: =COUNT(D199:I199,J199:M199,N199:P199) -> 13
A201: D3. 每人每方法（48 行 = 24 人 × 2 方法）：按计划书 6.2 在三个物体上取**均值**（非中位数——三点中位数只落在刻度点上，产生大量配对结平损失效能）。前 24 行 = EgoAnchor，后 24 行 = One-Euro，与 D4 逐行配对
A202: Participant_ID | B202: Condition | C202: Q1 | D202: Q2 | E202: Q9 | F202: AQ_IQ2 | G202: AQ_IQ3 | H202: Q3 | I202: Q8 | J202: AQ_EQ1 | K202: AQ_EQ2 | L202: AQ_EQ3 | M202: AQ_IQ1 | N202: Q6 | O202: Q7 | P202: AQ_EQ | Q202: AQ_IQ | R202: TIA_RC | S202: TIA_UP | T202: STIAS
A203: P001 | B203: EgoAnchor | C203: =AVERAGEIFS(Records!$K$5:$K$148,Records!$A$5:$A$148,$A203,Records!$H$5:$H$148,$B203) -> 5 | D203: =AVERAGEIFS(Records!$L$5:$L$148,Records!$A$5:$A$148,$A203,Records!$H$5:$H$148,$B203) -> 5 | E203: =AVERAGEIFS(Records!$M$5:$M$148,Records!$A$5:$A$148,$A203,Records!$H$5:$H$148,$B203) -> 5.3333333 | F203: =AVERAGEIFS(Records!$O$5:$O$148,Records!$A$5:$A$148,$A203,Records!$H$5:$H$148,$B203) -> 5.3333333 | G203: =AVERAGEIFS(Records!$P$5:$P$148,Records!$A$5:$A$148,$A203,Records!$H$5:$H$148,$B203) -> 5.3333333 | H203: =AVERAGEIFS(Records!$Q$5:$Q$148,Records!$A$5:$A$148,$A203,Records!$H$5:$H$148,$B203) -> 5.3333333 | I203: =AVERAGEIFS(Records!$R$5:$R$148,Records!$A$5:$A$148,$A203,Records!$H$5:$H$148,$B203) -> 6 | J203: =AVERAGEIFS(Records!$S$5:$S$148,Records!$A$5:$A$148,$A203,Records!$H$5:$H$148,$B203) -> 5.6666667 | K203: =AVERAGEIFS(Records!$T$5:$T$148,Records!$A$5:$A$148,$A203,Records!$H$5:$H$148,$B203) -> 5.3333333 | L203: =AVERAGEIFS(Records!$U$5:$U$148,Records!$A$5:$A$148,$A203,Records!$H$5:$H$148,$B203) -> 6 | M203: =AVERAGEIFS(Records!$V$5:$V$148,Records!$A$5:$A$148,$A203,Records!$H$5:$H$148,$B203) -> 5.6666667 | N203: =AVERAGEIFS(Records!$W$5:$W$148,Records!$A$5:$A$148,$A203,Records!$H$5:$H$148,$B203) -> 5.6666667 | O203: =AVERAGEIFS(Records!$X$5:$X$148,Records!$A$5:$A$148,$A203,Records!$H$5:$H$148,$B203) -> 4.6666667 | P203: =AVERAGEIFS($E$5:$E$148,$A$5:$A$148,$A203,$C$5:$C$148,$B203) -> 5.6666667 | Q203: =AVERAGEIFS($F$5:$F$148,$A$5:$A$148,$A203,$C$5:$C$148,$B203) -> 5.4444444 | R203: =AVERAGEIFS($Q$152:$Q$199,$A$152:$A$199,$A203,$C$152:$C$199,$B203) -> 4 | S203: =AVERAGEIFS($R$152:$R$199,$A$152:$A$199,$A203,$C$152:$C$199,$B203) -> 3.5 | T203: =AVERAGEIFS($S$152:$S$199,$A$152:$A$199,$A203,$C$152:$C$199,$B203) -> 5.6666667
A204: P002 | B204: EgoAnchor | C204: =AVERAGEIFS(Records!$K$5:$K$148,Records!$A$5:$A$148,$A204,Records!$H$5:$H$148,$B204) -> 5.3333333 | D204: =AVERAGEIFS(Records!$L$5:$L$148,Records!$A$5:$A$148,$A204,Records!$H$5:$H$148,$B204) -> 4.3333333 | E204: =AVERAGEIFS(Records!$M$5:$M$148,Records!$A$5:$A$148,$A204,Records!$H$5:$H$148,$B204) -> 4 | F204: =AVERAGEIFS(Records!$O$5:$O$148,Records!$A$5:$A$148,$A204,Records!$H$5:$H$148,$B204) -> 4.3333333 | G204: =AVERAGEIFS(Records!$P$5:$P$148,Records!$A$5:$A$148,$A204,Records!$H$5:$H$148,$B204) -> 4.3333333 | H204: =AVERAGEIFS(Records!$Q$5:$Q$148,Records!$A$5:$A$148,$A204,Records!$H$5:$H$148,$B204) -> 4 | I204: =AVERAGEIFS(Records!$R$5:$R$148,Records!$A$5:$A$148,$A204,Records!$H$5:$H$148,$B204) -> 4 | J204: =AVERAGEIFS(Records!$S$5:$S$148,Records!$A$5:$A$148,$A204,Records!$H$5:$H$148,$B204) -> 3 | K204: =AVERAGEIFS(Records!$T$5:$T$148,Records!$A$5:$A$148,$A204,Records!$H$5:$H$148,$B204) -> 4 | L204: =AVERAGEIFS(Records!$U$5:$U$148,Records!$A$5:$A$148,$A204,Records!$H$5:$H$148,$B204) -> 5.3333333 | M204: =AVERAGEIFS(Records!$V$5:$V$148,Records!$A$5:$A$148,$A204,Records!$H$5:$H$148,$B204) -> 5 | N204: =AVERAGEIFS(Records!$W$5:$W$148,Records!$A$5:$A$148,$A204,Records!$H$5:$H$148,$B204) -> 3.3333333 | O204: =AVERAGEIFS(Records!$X$5:$X$148,Records!$A$5:$A$148,$A204,Records!$H$5:$H$148,$B204) -> 3.6666667 | P204: =AVERAGEIFS($E$5:$E$148,$A$5:$A$148,$A204,$C$5:$C$148,$B204) -> 4.1111111 | Q204: =AVERAGEIFS($F$5:$F$148,$A$5:$A$148,$A204,$C$5:$C$148,$B204) -> 4.5555556 | R204: =AVERAGEIFS($Q$152:$Q$199,$A$152:$A$199,$A204,$C$152:$C$199,$B204) -> 3 | S204: =AVERAGEIFS($R$152:$R$199,$A$152:$A$199,$A204,$C$152:$C$199,$B204) -> 3 | T204: =AVERAGEIFS($S$152:$S$199,$A$152:$A$199,$A204,$C$152:$C$199,$B204) -> 4
A205: P003 | B205: EgoAnchor | C205: =AVERAGEIFS(Records!$K$5:$K$148,Records!$A$5:$A$148,$A205,Records!$H$5:$H$148,$B205) -> 7 | D205: =AVERAGEIFS(Records!$L$5:$L$148,Records!$A$5:$A$148,$A205,Records!$H$5:$H$148,$B205) -> 5.6666667 | E205: =AVERAGEIFS(Records!$M$5:$M$148,Records!$A$5:$A$148,$A205,Records!$H$5:$H$148,$B205) -> 5.6666667 | F205: =AVERAGEIFS(Records!$O$5:$O$148,Records!$A$5:$A$148,$A205,Records!$H$5:$H$148,$B205) -> 5 | G205: =AVERAGEIFS(Records!$P$5:$P$148,Records!$A$5:$A$148,$A205,Records!$H$5:$H$148,$B205) -> 6 | H205: =AVERAGEIFS(Records!$Q$5:$Q$148,Records!$A$5:$A$148,$A205,Records!$H$5:$H$148,$B205) -> 7 | I205: =AVERAGEIFS(Records!$R$5:$R$148,Records!$A$5:$A$148,$A205,Records!$H$5:$H$148,$B205) -> 6 | J205: =AVERAGEIFS(Records!$S$5:$S$148,Records!$A$5:$A$148,$A205,Records!$H$5:$H$148,$B205) -> 4.6666667 | K205: =AVERAGEIFS(Records!$T$5:$T$148,Records!$A$5:$A$148,$A205,Records!$H$5:$H$148,$B205) -> 6 | L205: =AVERAGEIFS(Records!$U$5:$U$148,Records!$A$5:$A$148,$A205,Records!$H$5:$H$148,$B205) -> 6.6666667 | M205: =AVERAGEIFS(Records!$V$5:$V$148,Records!$A$5:$A$148,$A205,Records!$H$5:$H$148,$B205) -> 5 | N205: =AVERAGEIFS(Records!$W$5:$W$148,Records!$A$5:$A$148,$A205,Records!$H$5:$H$148,$B205) -> 6.6666667 | O205: =AVERAGEIFS(Records!$X$5:$X$148,Records!$A$5:$A$148,$A205,Records!$H$5:$H$148,$B205) -> 6.3333333 | P205: =AVERAGEIFS($E$5:$E$148,$A$5:$A$148,$A205,$C$5:$C$148,$B205) -> 5.7777778 | Q205: =AVERAGEIFS($F$5:$F$148,$A$5:$A$148,$A205,$C$5:$C$148,$B205) -> 5.3333333 | R205: =AVERAGEIFS($Q$152:$Q$199,$A$152:$A$199,$A205,$C$152:$C$199,$B205) -> 4.6666667 | S205: =AVERAGEIFS($R$152:$R$199,$A$152:$A$199,$A205,$C$152:$C$199,$B205) -> 4.75 | T205: =AVERAGEIFS($S$152:$S$199,$A$152:$A$199,$A205,$C$152:$C$199,$B205) -> 6.3333333
A206: P004 | B206: EgoAnchor | C206: =AVERAGEIFS(Records!$K$5:$K$148,Records!$A$5:$A$148,$A206,Records!$H$5:$H$148,$B206) -> 4 | D206: =AVERAGEIFS(Records!$L$5:$L$148,Records!$A$5:$A$148,$A206,Records!$H$5:$H$148,$B206) -> 3.6666667 | E206: =AVERAGEIFS(Records!$M$5:$M$148,Records!$A$5:$A$148,$A206,Records!$H$5:$H$148,$B206) -> 3.3333333 | F206: =AVERAGEIFS(Records!$O$5:$O$148,Records!$A$5:$A$148,$A206,Records!$H$5:$H$148,$B206) -> 4 | G206: =AVERAGEIFS(Records!$P$5:$P$148,Records!$A$5:$A$148,$A206,Records!$H$5:$H$148,$B206) -> 4.3333333 | H206: =AVERAGEIFS(Records!$Q$5:$Q$148,Records!$A$5:$A$148,$A206,Records!$H$5:$H$148,$B206) -> 3.6666667 | I206: =AVERAGEIFS(Records!$R$5:$R$148,Records!$A$5:$A$148,$A206,Records!$H$5:$H$148,$B206) -> 4.6666667 | J206: =AVERAGEIFS(Records!$S$5:$S$148,Records!$A$5:$A$148,$A206,Records!$H$5:$H$148,$B206) -> 5 | K206: =AVERAGEIFS(Records!$T$5:$T$148,Records!$A$5:$A$148,$A206,Records!$H$5:$H$148,$B206) -> 4.6666667 | L206: =AVERAGEIFS(Records!$U$5:$U$148,Records!$A$5:$A$148,$A206,Records!$H$5:$H$148,$B206) -> 4.6666667 | M206: =AVERAGEIFS(Records!$V$5:$V$148,Records!$A$5:$A$148,$A206,Records!$H$5:$H$148,$B206) -> 4.6666667 | N206: =AVERAGEIFS(Records!$W$5:$W$148,Records!$A$5:$A$148,$A206,Records!$H$5:$H$148,$B206) -> 4.6666667 | O206: =AVERAGEIFS(Records!$X$5:$X$148,Records!$A$5:$A$148,$A206,Records!$H$5:$H$148,$B206) -> 3.3333333 | P206: =AVERAGEIFS($E$5:$E$148,$A$5:$A$148,$A206,$C$5:$C$148,$B206) -> 4.7777778 | Q206: =AVERAGEIFS($F$5:$F$148,$A$5:$A$148,$A206,$C$5:$C$148,$B206) -> 4.3333333 | R206: =AVERAGEIFS($Q$152:$Q$199,$A$152:$A$199,$A206,$C$152:$C$199,$B206) -> 2.5 | S206: =AVERAGEIFS($R$152:$R$199,$A$152:$A$199,$A206,$C$152:$C$199,$B206) -> 2.5 | T206: =AVERAGEIFS($S$152:$S$199,$A$152:$A$199,$A206,$C$152:$C$199,$B206) -> 4.3333333
A207: P005 | B207: EgoAnchor | C207: =AVERAGEIFS(Records!$K$5:$K$148,Records!$A$5:$A$148,$A207,Records!$H$5:$H$148,$B207) -> 4.3333333 | D207: =AVERAGEIFS(Records!$L$5:$L$148,Records!$A$5:$A$148,$A207,Records!$H$5:$H$148,$B207) -> 2.3333333 | E207: =AVERAGEIFS(Records!$M$5:$M$148,Records!$A$5:$A$148,$A207,Records!$H$5:$H$148,$B207) -> 2.6666667 | F207: =AVERAGEIFS(Records!$O$5:$O$148,Records!$A$5:$A$148,$A207,Records!$H$5:$H$148,$B207) -> 3.3333333 | G207: =AVERAGEIFS(Records!$P$5:$P$148,Records!$A$5:$A$148,$A207,Records!$H$5:$H$148,$B207) -> 5 | H207: =AVERAGEIFS(Records!$Q$5:$Q$148,Records!$A$5:$A$148,$A207,Records!$H$5:$H$148,$B207) -> 4.6666667 | I207: =AVERAGEIFS(Records!$R$5:$R$148,Records!$A$5:$A$148,$A207,Records!$H$5:$H$148,$B207) -> 4.3333333 | J207: =AVERAGEIFS(Records!$S$5:$S$148,Records!$A$5:$A$148,$A207,Records!$H$5:$H$148,$B207) -> 4 | K207: =AVERAGEIFS(Records!$T$5:$T$148,Records!$A$5:$A$148,$A207,Records!$H$5:$H$148,$B207) -> 4.6666667 | L207: =AVERAGEIFS(Records!$U$5:$U$148,Records!$A$5:$A$148,$A207,Records!$H$5:$H$148,$B207) -> 4 | M207: =AVERAGEIFS(Records!$V$5:$V$148,Records!$A$5:$A$148,$A207,Records!$H$5:$H$148,$B207) -> 2.3333333 | N207: =AVERAGEIFS(Records!$W$5:$W$148,Records!$A$5:$A$148,$A207,Records!$H$5:$H$148,$B207) -> 4.6666667 | O207: =AVERAGEIFS(Records!$X$5:$X$148,Records!$A$5:$A$148,$A207,Records!$H$5:$H$148,$B207) -> 4.6666667 | P207: =AVERAGEIFS($E$5:$E$148,$A$5:$A$148,$A207,$C$5:$C$148,$B207) -> 4.2222222 | Q207: =AVERAGEIFS($F$5:$F$148,$A$5:$A$148,$A207,$C$5:$C$148,$B207) -> 3.5555556 | R207: =AVERAGEIFS($Q$152:$Q$199,$A$152:$A$199,$A207,$C$152:$C$199,$B207) -> 2.8333333 | S207: =AVERAGEIFS($R$152:$R$199,$A$152:$A$199,$A207,$C$152:$C$199,$B207) -> 2.25 | T207: =AVERAGEIFS($S$152:$S$199,$A$152:$A$199,$A207,$C$152:$C$199,$B207) -> 3.3333333
A208: P006 | B208: EgoAnchor | C208: =AVERAGEIFS(Records!$K$5:$K$148,Records!$A$5:$A$148,$A208,Records!$H$5:$H$148,$B208) -> 4.3333333 | D208: =AVERAGEIFS(Records!$L$5:$L$148,Records!$A$5:$A$148,$A208,Records!$H$5:$H$148,$B208) -> 4 | E208: =AVERAGEIFS(Records!$M$5:$M$148,Records!$A$5:$A$148,$A208,Records!$H$5:$H$148,$B208) -> 4 | F208: =AVERAGEIFS(Records!$O$5:$O$148,Records!$A$5:$A$148,$A208,Records!$H$5:$H$148,$B208) -> 4 | G208: =AVERAGEIFS(Records!$P$5:$P$148,Records!$A$5:$A$148,$A208,Records!$H$5:$H$148,$B208) -> 3.3333333 | H208: =AVERAGEIFS(Records!$Q$5:$Q$148,Records!$A$5:$A$148,$A208,Records!$H$5:$H$148,$B208) -> 4 | I208: =AVERAGEIFS(Records!$R$5:$R$148,Records!$A$5:$A$148,$A208,Records!$H$5:$H$148,$B208) -> 4 | J208: =AVERAGEIFS(Records!$S$5:$S$148,Records!$A$5:$A$148,$A208,Records!$H$5:$H$148,$B208) -> 4 | K208: =AVERAGEIFS(Records!$T$5:$T$148,Records!$A$5:$A$148,$A208,Records!$H$5:$H$148,$B208) -> 4.3333333 | L208: =AVERAGEIFS(Records!$U$5:$U$148,Records!$A$5:$A$148,$A208,Records!$H$5:$H$148,$B208) -> 4.6666667 | M208: =AVERAGEIFS(Records!$V$5:$V$148,Records!$A$5:$A$148,$A208,Records!$H$5:$H$148,$B208) -> 3.6666667 | N208: =AVERAGEIFS(Records!$W$5:$W$148,Records!$A$5:$A$148,$A208,Records!$H$5:$H$148,$B208) -> 3 | O208: =AVERAGEIFS(Records!$X$5:$X$148,Records!$A$5:$A$148,$A208,Records!$H$5:$H$148,$B208) -> 4 | P208: =AVERAGEIFS($E$5:$E$148,$A$5:$A$148,$A208,$C$5:$C$148,$B208) -> 4.3333333 | Q208: =AVERAGEIFS($F$5:$F$148,$A$5:$A$148,$A208,$C$5:$C$148,$B208) -> 3.6666667 | R208: =AVERAGEIFS($Q$152:$Q$199,$A$152:$A$199,$A208,$C$152:$C$199,$B208) -> 3.1666667 | S208: =AVERAGEIFS($R$152:$R$199,$A$152:$A$199,$A208,$C$152:$C$199,$B208) -> 2.5 | T208: =AVERAGEIFS($S$152:$S$199,$A$152:$A$199,$A208,$C$152:$C$199,$B208) -> 4
A209: P007 | B209: EgoAnchor | C209: =AVERAGEIFS(Records!$K$5:$K$148,Records!$A$5:$A$148,$A209,Records!$H$5:$H$148,$B209) -> 7 | D209: =AVERAGEIFS(Records!$L$5:$L$148,Records!$A$5:$A$148,$A209,Records!$H$5:$H$148,$B209) -> 6.3333333 | E209: =AVERAGEIFS(Records!$M$5:$M$148,Records!$A$5:$A$148,$A209,Records!$H$5:$H$148,$B209) -> 7 | F209: =AVERAGEIFS(Records!$O$5:$O$148,Records!$A$5:$A$148,$A209,Records!$H$5:$H$148,$B209) -> 6.6666667 | G209: =AVERAGEIFS(Records!$P$5:$P$148,Records!$A$5:$A$148,$A209,Records!$H$5:$H$148,$B209) -> 6.6666667 | H209: =AVERAGEIFS(Records!$Q$5:$Q$148,Records!$A$5:$A$148,$A209,Records!$H$5:$H$148,$B209) -> 7 | I209: =AVERAGEIFS(Records!$R$5:$R$148,Records!$A$5:$A$148,$A209,Records!$H$5:$H$148,$B209) -> 7 | J209: =AVERAGEIFS(Records!$S$5:$S$148,Records!$A$5:$A$148,$A209,Records!$H$5:$H$148,$B209) -> 6.6666667 | K209: =AVERAGEIFS(Records!$T$5:$T$148,Records!$A$5:$A$148,$A209,Records!$H$5:$H$148,$B209) -> 6 | L209: =AVERAGEIFS(Records!$U$5:$U$148,Records!$A$5:$A$148,$A209,Records!$H$5:$H$148,$B209) -> 7 | M209: =AVERAGEIFS(Records!$V$5:$V$148,Records!$A$5:$A$148,$A209,Records!$H$5:$H$148,$B209) -> 6.3333333 | N209: =AVERAGEIFS(Records!$W$5:$W$148,Records!$A$5:$A$148,$A209,Records!$H$5:$H$148,$B209) -> 7 | O209: =AVERAGEIFS(Records!$X$5:$X$148,Records!$A$5:$A$148,$A209,Records!$H$5:$H$148,$B209) -> 7 | P209: =AVERAGEIFS($E$5:$E$148,$A$5:$A$148,$A209,$C$5:$C$148,$B209) -> 6.5555556 | Q209: =AVERAGEIFS($F$5:$F$148,$A$5:$A$148,$A209,$C$5:$C$148,$B209) -> 6.5555556 | R209: =AVERAGEIFS($Q$152:$Q$199,$A$152:$A$199,$A209,$C$152:$C$199,$B209) -> 5 | S209: =AVERAGEIFS($R$152:$R$199,$A$152:$A$199,$A209,$C$152:$C$199,$B209) -> 4.75 | T209: =AVERAGEIFS($S$152:$S$199,$A$152:$A$199,$A209,$C$152:$C$199,$B209) -> 7
...

Sheet Analysis
A1: 分析结果（合成数据）：绿底 = 公式实时计算；黄底 = Python 写入（Wilcoxon W / p、Holm 校正 p、r_rb 自举 CI、信度 α/ω、TOST p）
A3: A. 主证实家族（7 项；三物体均值 → 配对 Wilcoxon → 家族内 Holm(7)）
A4: 条目 | B4: 简称 | C4: One-Euro Mdn[IQR] | D4: EgoAnchor Mdn[IQR] | E4: 配对差中位 | F4: 配对差均值 | G4: 配对差 SD | H4: dz | I4: W | J4: p_raw | K4: p_Holm | L4: 匹配秩双列 r | M4: r 95%CI
A5: Q1 | B5: 静止稳定 | C5: =TEXT(MEDIAN(Derived!$C$227:$C$250),"0.00")&" ["&TEXT(QUARTILE(Derived!$C$227:$C$250,1),"0.00")&", "&TEXT(QUARTILE(Derived!$C$227:$C$250,3),"0.00")&"]" -> 4.33 [3.67, 4.75] | D5: =TEXT(MEDIAN(Derived!$C$203:$C$226),"0.00")&" ["&TEXT(QUARTILE(Derived!$C$203:$C$226,1),"0.00")&", "&TEXT(QUARTILE(Derived!$C$203:$C$226,3),"0.00")&"]" -> 5.50 [4.58, 6.42] | E5: =MEDIAN(Derived!$B$254:$B$277) -> 0.66666667 | F5: =AVERAGE(Derived!$B$254:$B$277) -> 1.125 | G5: =STDEV.S(Derived!$B$254:$B$277) -> 1.223018 | H5: =AVERAGE(Derived!$B$254:$B$277)/STDEV.S(Derived!$B$254:$B$277) -> 0.91985566 | I5: 16 | J5: 0.0002 | K5: 0.0014 | L5: 0.884 | M5: [+0.66, +1.00]
A6: Q8 | B6: 位置正确 | C6: =TEXT(MEDIAN(Derived!$I$227:$I$250),"0.00")&" ["&TEXT(QUARTILE(Derived!$I$227:$I$250,1),"0.00")&", "&TEXT(QUARTILE(Derived!$I$227:$I$250,3),"0.00")&"]" -> 4.33 [3.58, 5.08] | D6: =TEXT(MEDIAN(Derived!$I$203:$I$226),"0.00")&" ["&TEXT(QUARTILE(Derived!$I$203:$I$226,1),"0.00")&", "&TEXT(QUARTILE(Derived!$I$203:$I$226,3),"0.00")&"]" -> 5.33 [4.33, 6.00] | E6: =MEDIAN(Derived!$C$254:$C$277) -> 0.66666667 | F6: =AVERAGE(Derived!$C$254:$C$277) -> 0.88888889 | G6: =STDEV.S(Derived!$C$254:$C$277) -> 1.0797507 | H6: =AVERAGE(Derived!$C$254:$C$277)/STDEV.S(Derived!$C$254:$C$277) -> 0.82323532 | I6: 20 | J6: 0.0009 | K6: 0.0034 | L6: 0.827 | M6: [+0.55, +0.99]
A7: Q2 | B7: 运动附着 | C7: =TEXT(MEDIAN(Derived!$D$227:$D$250),"0.00")&" ["&TEXT(QUARTILE(Derived!$D$227:$D$250,1),"0.00")&", "&TEXT(QUARTILE(Derived!$D$227:$D$250,3),"0.00")&"]" -> 4.83 [4.25, 5.42] | D7: =TEXT(MEDIAN(Derived!$D$203:$D$226),"0.00")&" ["&TEXT(QUARTILE(Derived!$D$203:$D$226,1),"0.00")&", "&TEXT(QUARTILE(Derived!$D$203:$D$226,3),"0.00")&"]" -> 5.00 [4.00, 5.67] | E7: =MEDIAN(Derived!$D$254:$D$277) -> 0 | F7: =AVERAGE(Derived!$D$254:$D$277) -> -0.013888889 | G7: =STDEV.S(Derived!$D$254:$D$277) -> 0.6843959 | H7: =AVERAGE(Derived!$D$254:$D$277)/STDEV.S(Derived!$D$254:$D$277) -> -0.020293647 | I7: 96.5 | J7: 0.7501 | K7: 0.7501 | L7: -0.081 | M7: [-0.56, +0.42]
